package net.glider.src.strucures;

import java.util.ArrayList;
import java.util.List;
import micdoodle8.mods.galacticraft.core.blocks.GCBlocks;
import micdoodle8.mods.galacticraft.core.items.GCItems;
import micdoodle8.mods.galacticraft.planets.mars.items.MarsItems;
import net.glider.src.items.ItemMod;
import net.glider.src.utils.OreDictItemStack;
import net.minecraft.block.Block;
import net.minecraft.init.Blocks;
import net.minecraft.init.Items;
import net.minecraft.item.ItemStack;
import net.minecraft.util.StatCollector;
import net.minecraft.world.World;
import net.minecraftforge.common.util.ForgeDirection;

public class StructureThall extends StructureRotatable {
	
	boolean hidden;
	static int rot;
	
	public StructureThall(boolean hidden)
	{
		super(hidden);
		this.hidden = hidden;
	}
	
	@Override
	public int nextPossibleValue(int nowV, ForgeDirection dir, int meta)
	{
		int[] order = getPossibleOrder(dir);
		if (nowV == -1)
		{
			return order[0];
		}
		for (int i = 0; i < order.length; i++)
		{
			if (order[i] == nowV)
			{
				if (i + 1 == order.length)
				{
					return order[0];
				} else return order[i + 1];
			}
		}
		
		return nowV++;
	}
	
	public int[] getPossibleOrder(ForgeDirection dir)
	{
		if (dir == ForgeDirection.WEST)
		{
			return new int[] { 0, 1, 2 };
		} else if (dir == ForgeDirection.EAST)
		{
			return new int[] { 2, 3, 0 };
		} else if (dir == ForgeDirection.NORTH)
		{
			return new int[] { 1, 2, 3 };
		} else if (dir == ForgeDirection.SOUTH)
		{
			return new int[] { 3, 0, 1 };
		} else
		{
			return new int[] {};
		}
	}
	
	@Override
	public Structure copy()
	{
		StructureThall Nstr = new StructureThall(hidden);
		Nstr.Configure(placementPos != null ? placementPos.clone() : new int[] { 0, 0, 0 }, placementRotation, placementDir);
		return Nstr;
	}
	
	@Override
	public void setRotation(int rot)
	{
		this.rot = rot;
	}
	
	@Override
	public int getRotation()
	{
		return rot;
	}
	
	@Override
	public boolean isPossible(ForgeDirection dir, int rot, int meta)
	{
		if ((rot == 0 || rot == 1 || rot == 2) && dir == ForgeDirection.WEST)
		{
			return true;
		} else if ((rot == 2 || rot == 3 || rot == 0) && dir == ForgeDirection.EAST)
		{
			return true;
		} else if ((rot == 1 || rot == 2 || rot == 3) && dir == ForgeDirection.NORTH)
		{
			return true;
		} else if ((rot == 3 || rot == 0 || rot == 1) && dir == ForgeDirection.SOUTH)
		{
			return true;
		}
		return false;
	}
	
	public int getMetaFromDirARot(ForgeDirection dir, int rot)
	{
		if (rot == 0)
		{
			return 2;
		} else if (rot == 1)
		{
			return 3;
		} else if (rot == 2)
		{
			return 0;
		} else if (rot == 3)
		{
			return 1;
		}
		return 0;
	}
	
	public ForgeDirection[] getDirs(ForgeDirection dir)
	{
		if (dir == ForgeDirection.WEST)
		{
			if (rot == 0)
			{
				return new ForgeDirection[] { dir, ForgeDirection.NORTH };
			} else if (rot == 1)
			{
				return new ForgeDirection[] { ForgeDirection.SOUTH, ForgeDirection.NORTH };
			} else if (rot == 2)
			{
				return new ForgeDirection[] { dir, ForgeDirection.SOUTH };
			}
		} else if (dir == ForgeDirection.NORTH)
		{
			if (rot == 1)
			{
				return new ForgeDirection[] { dir, ForgeDirection.EAST };
			} else if (rot == 2)
			{
				return new ForgeDirection[] { ForgeDirection.WEST, ForgeDirection.EAST };
			} else if (rot == 3)
			{
				return new ForgeDirection[] { dir, ForgeDirection.WEST };
			}
		} else if (dir == ForgeDirection.EAST)
		{
			if (rot == 0)
			{
				return new ForgeDirection[] { dir, ForgeDirection.NORTH };
			} else if (rot == 3)
			{
				return new ForgeDirection[] { ForgeDirection.NORTH, ForgeDirection.SOUTH };
			} else if (rot == 2)
			{
				return new ForgeDirection[] { dir, ForgeDirection.SOUTH };
			}
		} else if (dir == ForgeDirection.SOUTH)
		{
			if (rot == 1)
			{
				return new ForgeDirection[] { dir, ForgeDirection.EAST };
			} else if (rot == 0)
			{
				return new ForgeDirection[] { ForgeDirection.EAST, ForgeDirection.WEST };
			} else if (rot == 3)
			{
				return new ForgeDirection[] { dir, ForgeDirection.WEST };
			}
		}
		return new ForgeDirection[] {};
	}
	
	@Override
	public void deconstruct(World world, ForgeDirection dir, int x, int y, int z)
	{
		Block block1 = Blocks.air;
		Block block2 = Blocks.air;
		Block block3 = Blocks.air;
		Block block5 = Blocks.air;
		Block block6 = Blocks.air;
		Block block7 = Blocks.air;
		if (dir == ForgeDirection.WEST)
		{
			if (rot == 0)
			{
				
				world.setBlock(x - 8, y - 2, z - 2, block1, 6, 2);
				world.setBlock(x - 8, y - 2, z - 1, block2, 4, 2);
				world.setBlock(x - 8, y - 2, z + 0, block2, 4, 2);
				world.setBlock(x - 8, y - 2, z + 1, block2, 4, 2);
				world.setBlock(x - 8, y - 2, z + 2, block1, 7, 2);
				world.setBlock(x - 8, y - 1, z - 2, block2, 4, 2);
				world.setBlock(x - 8, y - 1, z + 2, block2, 4, 2);
				world.setBlock(x - 8, y + 0, z - 2, block2, 4, 2);
				world.setBlock(x - 8, y + 0, z + 2, block2, 4, 2);
				world.setBlock(x - 8, y + 1, z - 2, block2, 4, 2);
				world.setBlock(x - 8, y + 1, z + 2, block2, 4, 2);
				world.setBlock(x - 8, y + 2, z - 2, block1, 2, 2);
				world.setBlock(x - 8, y + 2, z - 1, block2, 4, 2);
				world.setBlock(x - 8, y + 2, z + 0, block2, 4, 2);
				world.setBlock(x - 8, y + 2, z + 1, block2, 4, 2);
				world.setBlock(x - 8, y + 2, z + 2, block1, 3, 2);
				world.setBlock(x - 7, y - 2, z - 2, block1, 6, 2);
				world.setBlock(x - 7, y - 2, z - 1, block2, 4, 2);
				world.setBlock(x - 7, y - 2, z + 0, block2, 4, 2);
				world.setBlock(x - 7, y - 2, z + 1, block2, 4, 2);
				world.setBlock(x - 7, y - 2, z + 2, block1, 7, 2);
				world.setBlock(x - 7, y - 1, z - 2, block2, 4, 2);
				world.setBlock(x - 7, y - 1, z + 2, block2, 4, 2);
				world.setBlock(x - 7, y + 0, z - 2, block2, 4, 2);
				world.setBlock(x - 7, y + 0, z + 2, block2, 4, 2);
				world.setBlock(x - 7, y + 1, z - 2, block2, 4, 2);
				world.setBlock(x - 7, y + 1, z + 2, block2, 4, 2);
				world.setBlock(x - 7, y + 2, z - 2, block1, 2, 2);
				world.setBlock(x - 7, y + 2, z - 1, block2, 4, 2);
				world.setBlock(x - 7, y + 2, z + 0, block2, 4, 2);
				world.setBlock(x - 7, y + 2, z + 1, block2, 4, 2);
				world.setBlock(x - 7, y + 2, z + 2, block1, 3, 2);
				world.setBlock(x - 6, y - 2, z - 4, block1, 4, 2);
				world.setBlock(x - 6, y - 2, z - 3, block1, 4, 2);
				world.setBlock(x - 6, y - 2, z - 2, block2, 4, 2);
				world.setBlock(x - 6, y - 2, z - 1, block2, 4, 2);
				world.setBlock(x - 6, y - 2, z + 0, block2, 4, 2);
				world.setBlock(x - 6, y - 2, z + 1, block2, 4, 2);
				world.setBlock(x - 6, y - 2, z + 2, block1, 7, 2);
				world.setBlock(x - 6, y - 1, z - 4, block2, 4, 2);
				world.setBlock(x - 6, y - 1, z - 3, block2, 4, 2);
				
				world.setBlock(x - 6, y - 1, z - 2, block3, 0, 2);
				world.setBlock(x - 6, y - 1, z + 2, block2, 4, 2);
				world.setBlock(x - 6, y + 0, z - 4, block2, 4, 2);
				world.setBlock(x - 6, y + 0, z - 3, block2, 4, 2);
				world.setBlock(x - 4, y - 3, z + 0, block2, 0, 2);
				
				world.setBlock(x - 6, y + 0, z + 1, block2, 0, 2);
				world.setBlock(x - 6, y + 0, z + 2, block2, 4, 2);
				world.setBlock(x - 6, y + 1, z - 4, block2, 4, 2);
				world.setBlock(x - 6, y + 1, z - 3, block2, 4, 2);
				world.setBlock(x - 6, y + 1, z - 2, block3, 8, 2);
				world.setBlock(x - 6, y + 1, z + 2, block2, 4, 2);
				world.setBlock(x - 6, y + 2, z - 4, block1, 0, 2);
				world.setBlock(x - 6, y + 2, z - 3, block1, 0, 2);
				world.setBlock(x - 6, y + 2, z - 2, block2, 4, 2);
				world.setBlock(x - 6, y + 2, z - 1, block1, 5, 2);
				world.setBlock(x - 6, y + 2, z + 0, block1, 5, 2);
				world.setBlock(x - 6, y + 2, z + 1, block1, 5, 2);
				world.setBlock(x - 6, y + 2, z + 2, block1, 3, 2);
				world.setBlock(x - 6, y + 3, z - 1, block1, 0, 2);
				world.setBlock(x - 6, y + 3, z + 0, block1, 0, 2);
				world.setBlock(x - 6, y + 3, z + 1, block1, 0, 2);
				world.setBlock(x - 5, y - 2, z - 4, block2, 4, 2);
				world.setBlock(x - 5, y - 2, z - 3, block2, 4, 2);
				world.setBlock(x - 5, y - 2, z - 2, block2, 4, 2);
				world.setBlock(x - 5, y - 2, z - 1, block2, 4, 2);
				world.setBlock(x - 5, y - 2, z + 0, block2, 4, 2);
				world.setBlock(x - 5, y - 2, z + 1, block2, 4, 2);
				world.setBlock(x - 5, y - 2, z + 2, block1, 7, 2);
				world.setBlock(x - 5, y - 1, z + 2, block2, 4, 2);
				world.setBlock(x - 5, y + 0, z + 2, block2, 4, 2);
				world.setBlock(x - 5, y + 1, z + 2, block2, 4, 2);
				world.setBlock(x - 5, y + 2, z - 4, block2, 4, 2);
				world.setBlock(x - 5, y + 2, z - 3, block2, 4, 2);
				world.setBlock(x - 5, y + 2, z - 2, block1, 7, 2);
				world.setBlock(x - 5, y + 2, z + 2, block1, 3, 2);
				world.setBlock(x - 5, y + 3, z - 2, block1, 2, 2);
				world.setBlock(x - 5, y + 3, z - 1, block2, 4, 2);
				world.setBlock(x - 5, y + 3, z + 0, block2, 4, 2);
				world.setBlock(x - 5, y + 3, z + 1, block2, 4, 2);
				world.setBlock(x - 4, y - 2, z - 4, block2, 4, 2);
				world.setBlock(x - 4, y - 2, z - 3, block2, 4, 2);
				world.setBlock(x - 4, y - 2, z - 2, block2, 4, 2);
				world.setBlock(x - 4, y - 2, z - 1, block2, 4, 2);
				world.setBlock(x - 4, y - 2, z + 0, block2, 4, 2);
				world.setBlock(x - 4, y - 2, z + 1, block2, 4, 2);
				world.setBlock(x - 4, y - 2, z + 2, block1, 7, 2);
				world.setBlock(x - 4, y - 1, z + 2, block2, 4, 2);
				world.setBlock(x - 4, y + 0, z + 2, block5, 0, 2);
				world.setBlock(x - 4, y + 1, z + 2, block2, 4, 2);
				world.setBlock(x - 4, y + 2, z - 4, block2, 4, 2);
				world.setBlock(x - 4, y + 2, z - 3, block2, 4, 2);
				world.setBlock(x - 4, y + 2, z - 2, block1, 7, 2);
				world.setBlock(x - 4, y + 2, z + 1, block6, 3, 2);
				world.setBlock(x - 4, y + 2, z + 2, block1, 3, 2);
				world.setBlock(x - 4, y + 3, z - 2, block1, 2, 2);
				world.setBlock(x - 4, y + 3, z - 1, block2, 4, 2);
				world.setBlock(x - 4, y + 3, z + 0, block5, 0, 2);
				world.setBlock(x - 4, y + 3, z + 1, block2, 4, 2);
				world.setBlock(x - 3, y - 2, z - 4, block2, 4, 2);
				world.setBlock(x - 3, y - 2, z - 3, block2, 4, 2);
				world.setBlock(x - 3, y - 2, z - 2, block2, 4, 2);
				world.setBlock(x - 3, y - 2, z - 1, block2, 4, 2);
				world.setBlock(x - 3, y - 2, z + 0, block2, 4, 2);
				world.setBlock(x - 3, y - 2, z + 1, block2, 4, 2);
				world.setBlock(x - 3, y - 2, z + 2, block1, 7, 2);
				world.setBlock(x - 3, y - 1, z + 2, block2, 4, 2);
				world.setBlock(x - 3, y + 0, z + 2, block2, 4, 2);
				world.setBlock(x - 3, y + 1, z + 2, block2, 4, 2);
				world.setBlock(x - 3, y + 2, z - 4, block2, 4, 2);
				world.setBlock(x - 3, y + 2, z - 3, block2, 4, 2);
				world.setBlock(x - 3, y + 2, z - 2, block1, 7, 2);
				world.setBlock(x - 3, y + 2, z + 2, block1, 3, 2);
				world.setBlock(x - 3, y + 3, z - 2, block1, 2, 2);
				world.setBlock(x - 3, y + 3, z - 1, block2, 4, 2);
				world.setBlock(x - 3, y + 3, z + 0, block2, 4, 2);
				world.setBlock(x - 3, y + 3, z + 1, block2, 4, 2);
				world.setBlock(x - 2, y - 2, z - 4, block1, 5, 2);
				world.setBlock(x - 2, y - 2, z - 3, block1, 5, 2);
				world.setBlock(x - 2, y - 2, z - 2, block2, 4, 2);
				world.setBlock(x - 2, y - 2, z - 1, block2, 4, 2);
				world.setBlock(x - 2, y - 2, z + 0, block2, 4, 2);
				world.setBlock(x - 2, y - 2, z + 1, block2, 4, 2);
				world.setBlock(x - 2, y - 2, z + 2, block1, 7, 2);
				world.setBlock(x - 2, y - 1, z - 4, block2, 4, 2);
				world.setBlock(x - 2, y - 1, z - 3, block2, 4, 2);
				world.setBlock(x - 2, y - 1, z - 2, block3, 0, 2);
				world.setBlock(x - 2, y - 1, z + 2, block2, 4, 2);
				world.setBlock(x - 2, y + 0, z - 4, block2, 4, 2);
				world.setBlock(x - 2, y + 0, z - 3, block2, 4, 2);
				world.setBlock(x - 2, y + 0, z + 2, block2, 4, 2);
				world.setBlock(x - 2, y + 1, z - 4, block2, 4, 2);
				world.setBlock(x - 2, y + 1, z - 3, block2, 4, 2);
				world.setBlock(x - 2, y + 1, z - 2, block3, 8, 2);
				world.setBlock(x - 2, y + 1, z + 2, block2, 4, 2);
				world.setBlock(x - 2, y + 2, z - 4, block1, 1, 2);
				world.setBlock(x - 2, y + 2, z - 3, block1, 1, 2);
				world.setBlock(x - 2, y + 2, z - 2, block2, 4, 2);
				world.setBlock(x - 2, y + 2, z - 1, block1, 4, 2);
				world.setBlock(x - 2, y + 2, z + 0, block1, 4, 2);
				world.setBlock(x - 2, y + 2, z + 1, block1, 4, 2);
				world.setBlock(x - 2, y + 2, z + 2, block1, 3, 2);
				world.setBlock(x - 2, y + 3, z - 1, block1, 1, 2);
				world.setBlock(x - 2, y + 3, z + 0, block1, 1, 2);
				world.setBlock(x - 2, y + 3, z + 1, block1, 1, 2);
				world.setBlock(x - 1, y - 2, z - 2, block1, 6, 2);
				world.setBlock(x - 1, y - 2, z - 1, block2, 4, 2);
				world.setBlock(x - 1, y - 2, z + 0, block2, 4, 2);
				world.setBlock(x - 1, y - 2, z + 1, block2, 4, 2);
				world.setBlock(x - 1, y - 2, z + 2, block1, 7, 2);
				world.setBlock(x - 1, y - 1, z - 2, block2, 4, 2);
				world.setBlock(x - 1, y - 1, z + 2, block2, 4, 2);
				world.setBlock(x - 1, y + 0, z - 2, block2, 4, 2);
				world.setBlock(x - 1, y + 0, z + 2, block2, 4, 2);
				world.setBlock(x - 1, y + 1, z - 2, block2, 4, 2);
				world.setBlock(x - 1, y + 1, z + 2, block2, 4, 2);
				world.setBlock(x - 1, y + 2, z - 2, block1, 2, 2);
				world.setBlock(x - 1, y + 2, z - 1, block2, 4, 2);
				world.setBlock(x - 1, y + 2, z + 0, block2, 4, 2);
				world.setBlock(x - 1, y + 2, z + 1, block2, 4, 2);
				world.setBlock(x - 1, y + 2, z + 2, block1, 3, 2);
				world.setBlock(x + 0, y - 2, z - 2, block1, 6, 2);
				world.setBlock(x + 0, y - 2, z - 1, block2, 4, 2);
				world.setBlock(x + 0, y - 2, z + 0, block2, 4, 2);
				world.setBlock(x + 0, y - 2, z + 1, block2, 4, 2);
				world.setBlock(x + 0, y - 2, z + 2, block1, 7, 2);
				world.setBlock(x + 0, y - 1, z - 2, block2, 4, 2);
				world.setBlock(x + 0, y - 1, z + 2, block2, 4, 2);
				world.setBlock(x + 0, y + 0, z - 2, block2, 4, 2);
				world.setBlock(x + 0, y + 0, z + 2, block2, 4, 2);
				world.setBlock(x + 0, y + 1, z - 2, block2, 4, 2);
				world.setBlock(x + 0, y + 1, z + 2, block2, 4, 2);
				world.setBlock(x + 0, y + 2, z - 2, block1, 2, 2);
				world.setBlock(x + 0, y + 2, z - 1, block2, 4, 2);
				world.setBlock(x + 0, y + 2, z + 0, block2, 4, 2);
				world.setBlock(x + 0, y + 2, z + 1, block2, 4, 2);
				world.setBlock(x + 0, y + 2, z + 2, block1, 3, 2);
				
			} else if (rot == 1)
			{
				
				world.setBlock(x - 6, y - 2, z - 4, block1, 4, 2);
				world.setBlock(x - 6, y - 2, z - 3, block1, 4, 2);
				world.setBlock(x - 6, y - 2, z - 2, block1, 4, 2);
				world.setBlock(x - 6, y - 2, z - 1, block1, 4, 2);
				world.setBlock(x - 6, y - 2, z + 0, block1, 4, 2);
				world.setBlock(x - 6, y - 2, z + 1, block1, 4, 2);
				world.setBlock(x - 6, y - 2, z + 2, block1, 4, 2);
				world.setBlock(x - 6, y - 2, z + 3, block1, 4, 2);
				world.setBlock(x - 6, y - 2, z + 4, block1, 4, 2);
				
				world.setBlock(x - 6, y - 1, z - 4, block2, 4, 2);
				world.setBlock(x - 6, y - 1, z - 3, block2, 4, 2);
				world.setBlock(x - 6, y - 1, z - 2, block2, 4, 2);
				world.setBlock(x - 6, y - 1, z - 1, block2, 4, 2);
				world.setBlock(x - 6, y - 1, z + 0, block2, 4, 2);
				world.setBlock(x - 6, y - 1, z + 1, block2, 4, 2);
				world.setBlock(x - 6, y - 1, z + 2, block2, 4, 2);
				world.setBlock(x - 6, y - 1, z + 3, block2, 4, 2);
				world.setBlock(x - 6, y - 1, z + 4, block2, 4, 2);
				world.setBlock(x - 6, y + 0, z - 4, block2, 4, 2);
				world.setBlock(x - 6, y + 0, z - 3, block2, 4, 2);
				world.setBlock(x - 6, y + 0, z - 2, block2, 4, 2);
				world.setBlock(x - 6, y + 0, z - 1, block2, 4, 2);
				
				world.setBlock(x - 6, y + 0, z + 0, block3, 0, 2);
				world.setBlock(x - 6, y + 0, z + 1, block2, 4, 2);
				world.setBlock(x - 6, y + 0, z + 2, block2, 4, 2);
				world.setBlock(x - 6, y + 0, z + 3, block2, 4, 2);
				world.setBlock(x - 6, y + 0, z + 4, block2, 4, 2);
				world.setBlock(x - 6, y + 1, z - 4, block2, 4, 2);
				world.setBlock(x - 6, y + 1, z - 3, block2, 4, 2);
				world.setBlock(x - 6, y + 1, z - 2, block2, 4, 2);
				world.setBlock(x - 6, y + 1, z - 1, block2, 4, 2);
				world.setBlock(x - 6, y + 1, z + 0, block2, 4, 2);
				world.setBlock(x - 6, y + 1, z + 1, block2, 4, 2);
				world.setBlock(x - 6, y + 1, z + 2, block2, 4, 2);
				world.setBlock(x - 6, y + 1, z + 3, block2, 4, 2);
				world.setBlock(x - 6, y + 1, z + 4, block2, 4, 2);
				world.setBlock(x - 6, y + 2, z - 4, block1, 0, 2);
				world.setBlock(x - 6, y + 2, z - 3, block1, 0, 2);
				world.setBlock(x - 6, y + 2, z - 2, block1, 0, 2);
				world.setBlock(x - 6, y + 2, z - 1, block1, 0, 2);
				world.setBlock(x - 6, y + 2, z + 0, block1, 0, 2);
				world.setBlock(x - 6, y + 2, z + 1, block1, 0, 2);
				world.setBlock(x - 6, y + 2, z + 2, block1, 0, 2);
				world.setBlock(x - 6, y + 2, z + 3, block1, 0, 2);
				world.setBlock(x - 6, y + 2, z + 4, block1, 0, 2);
				world.setBlock(x - 5, y - 2, z - 4, block2, 4, 2);
				world.setBlock(x - 5, y - 2, z - 3, block2, 4, 2);
				world.setBlock(x - 5, y - 2, z - 2, block2, 4, 2);
				world.setBlock(x - 5, y - 2, z - 1, block2, 4, 2);
				world.setBlock(x - 5, y - 2, z + 0, block2, 4, 2);
				world.setBlock(x - 5, y - 2, z + 1, block2, 4, 2);
				world.setBlock(x - 5, y - 2, z + 2, block2, 4, 2);
				world.setBlock(x - 5, y - 2, z + 3, block2, 4, 2);
				world.setBlock(x - 5, y - 2, z + 4, block2, 4, 2);
				world.setBlock(x - 4, y - 3, z + 0, block2, 0, 2);
				world.setBlock(x - 5, y + 0, z - 2, block2, 0, 2);
				world.setBlock(x - 5, y + 2, z - 4, block2, 4, 2);
				world.setBlock(x - 5, y + 2, z - 3, block2, 4, 2);
				world.setBlock(x - 5, y + 2, z - 2, block1, 7, 2);
				world.setBlock(x - 5, y + 2, z + 0, block6, 4, 2);
				world.setBlock(x - 5, y + 2, z + 2, block1, 6, 2);
				world.setBlock(x - 5, y + 2, z + 3, block2, 4, 2);
				world.setBlock(x - 5, y + 2, z + 4, block2, 4, 2);
				world.setBlock(x - 5, y + 3, z - 2, block1, 2, 2);
				world.setBlock(x - 5, y + 3, z - 1, block2, 4, 2);
				world.setBlock(x - 5, y + 3, z + 0, block2, 4, 2);
				world.setBlock(x - 5, y + 3, z + 1, block2, 4, 2);
				world.setBlock(x - 5, y + 3, z + 2, block1, 3, 2);
				world.setBlock(x - 4, y - 2, z - 4, block2, 4, 2);
				world.setBlock(x - 4, y - 2, z - 3, block2, 4, 2);
				world.setBlock(x - 4, y - 2, z - 2, block2, 4, 2);
				world.setBlock(x - 4, y - 2, z - 1, block2, 4, 2);
				world.setBlock(x - 4, y - 2, z + 0, block2, 4, 2);
				world.setBlock(x - 4, y - 2, z + 1, block2, 4, 2);
				world.setBlock(x - 4, y - 2, z + 2, block2, 4, 2);
				world.setBlock(x - 4, y - 2, z + 3, block2, 4, 2);
				world.setBlock(x - 4, y - 2, z + 4, block2, 4, 2);
				world.setBlock(x - 4, y + 2, z - 4, block2, 4, 2);
				world.setBlock(x - 4, y + 2, z - 3, block2, 4, 2);
				world.setBlock(x - 4, y + 2, z - 2, block1, 7, 2);
				world.setBlock(x - 4, y + 2, z + 2, block1, 6, 2);
				world.setBlock(x - 4, y + 2, z + 3, block2, 4, 2);
				world.setBlock(x - 4, y + 2, z + 4, block2, 4, 2);
				world.setBlock(x - 4, y + 3, z - 2, block1, 2, 2);
				world.setBlock(x - 4, y + 3, z - 1, block2, 4, 2);
				world.setBlock(x - 4, y + 3, z + 0, block3, 0, 2);
				world.setBlock(x - 4, y + 3, z + 1, block2, 4, 2);
				world.setBlock(x - 4, y + 3, z + 2, block1, 3, 2);
				world.setBlock(x - 3, y - 2, z - 4, block2, 4, 2);
				world.setBlock(x - 3, y - 2, z - 3, block2, 4, 2);
				world.setBlock(x - 3, y - 2, z - 2, block2, 4, 2);
				world.setBlock(x - 3, y - 2, z - 1, block2, 4, 2);
				world.setBlock(x - 3, y - 2, z + 0, block2, 4, 2);
				world.setBlock(x - 3, y - 2, z + 1, block2, 4, 2);
				world.setBlock(x - 3, y - 2, z + 2, block2, 4, 2);
				world.setBlock(x - 3, y - 2, z + 3, block2, 4, 2);
				world.setBlock(x - 3, y - 2, z + 4, block2, 4, 2);
				world.setBlock(x - 3, y + 2, z - 4, block2, 4, 2);
				world.setBlock(x - 3, y + 2, z - 3, block2, 4, 2);
				world.setBlock(x - 3, y + 2, z - 2, block1, 7, 2);
				world.setBlock(x - 3, y + 2, z + 2, block1, 6, 2);
				world.setBlock(x - 3, y + 2, z + 3, block2, 4, 2);
				world.setBlock(x - 3, y + 2, z + 4, block2, 4, 2);
				world.setBlock(x - 3, y + 3, z - 2, block1, 2, 2);
				world.setBlock(x - 3, y + 3, z - 1, block2, 4, 2);
				world.setBlock(x - 3, y + 3, z + 0, block2, 4, 2);
				world.setBlock(x - 3, y + 3, z + 1, block2, 4, 2);
				world.setBlock(x - 3, y + 3, z + 2, block1, 3, 2);
				world.setBlock(x - 2, y - 2, z - 4, block1, 5, 2);
				world.setBlock(x - 2, y - 2, z - 3, block1, 5, 2);
				world.setBlock(x - 2, y - 2, z - 2, block2, 4, 2);
				world.setBlock(x - 2, y - 2, z - 1, block2, 4, 2);
				world.setBlock(x - 2, y - 2, z + 0, block2, 4, 2);
				world.setBlock(x - 2, y - 2, z + 1, block2, 4, 2);
				world.setBlock(x - 2, y - 2, z + 2, block2, 4, 2);
				world.setBlock(x - 2, y - 2, z + 3, block1, 5, 2);
				world.setBlock(x - 2, y - 2, z + 4, block1, 5, 2);
				world.setBlock(x - 2, y - 1, z - 4, block2, 4, 2);
				world.setBlock(x - 2, y - 1, z - 3, block2, 4, 2);
				world.setBlock(x - 2, y - 1, z - 2, block7, 0, 2);
				world.setBlock(x - 2, y - 1, z + 2, block7, 0, 2);
				world.setBlock(x - 2, y - 1, z + 3, block2, 4, 2);
				world.setBlock(x - 2, y - 1, z + 4, block2, 4, 2);
				world.setBlock(x - 2, y + 0, z - 4, block2, 4, 2);
				world.setBlock(x - 2, y + 0, z - 3, block2, 4, 2);
				world.setBlock(x - 2, y + 0, z + 3, block2, 4, 2);
				world.setBlock(x - 2, y + 0, z + 4, block2, 4, 2);
				world.setBlock(x - 2, y + 1, z - 4, block2, 4, 2);
				world.setBlock(x - 2, y + 1, z - 3, block2, 4, 2);
				world.setBlock(x - 2, y + 1, z - 2, block7, 8, 2);
				world.setBlock(x - 2, y + 1, z + 2, block7, 8, 2);
				world.setBlock(x - 2, y + 1, z + 3, block2, 4, 2);
				world.setBlock(x - 2, y + 1, z + 4, block2, 4, 2);
				world.setBlock(x - 2, y + 2, z - 4, block1, 1, 2);
				world.setBlock(x - 2, y + 2, z - 3, block1, 1, 2);
				world.setBlock(x - 2, y + 2, z - 2, block2, 4, 2);
				world.setBlock(x - 2, y + 2, z - 1, block1, 4, 2);
				world.setBlock(x - 2, y + 2, z + 0, block1, 4, 2);
				world.setBlock(x - 2, y + 2, z + 1, block1, 4, 2);
				world.setBlock(x - 2, y + 2, z + 2, block2, 4, 2);
				world.setBlock(x - 2, y + 2, z + 3, block1, 1, 2);
				world.setBlock(x - 2, y + 2, z + 4, block1, 1, 2);
				world.setBlock(x - 2, y + 3, z - 1, block1, 1, 2);
				world.setBlock(x - 2, y + 3, z + 0, block1, 1, 2);
				world.setBlock(x - 2, y + 3, z + 1, block1, 1, 2);
				world.setBlock(x - 1, y - 2, z - 2, block1, 6, 2);
				world.setBlock(x - 1, y - 2, z - 1, block2, 4, 2);
				world.setBlock(x - 1, y - 2, z + 0, block2, 4, 2);
				world.setBlock(x - 1, y - 2, z + 1, block2, 4, 2);
				world.setBlock(x - 1, y - 2, z + 2, block1, 7, 2);
				world.setBlock(x - 1, y - 1, z - 2, block2, 4, 2);
				world.setBlock(x - 1, y - 1, z + 2, block2, 4, 2);
				world.setBlock(x - 1, y + 0, z - 2, block2, 4, 2);
				world.setBlock(x - 1, y + 0, z + 2, block2, 4, 2);
				world.setBlock(x - 1, y + 1, z - 2, block2, 4, 2);
				world.setBlock(x - 1, y + 1, z + 2, block2, 4, 2);
				world.setBlock(x - 1, y + 2, z - 2, block1, 2, 2);
				world.setBlock(x - 1, y + 2, z - 1, block2, 4, 2);
				world.setBlock(x - 1, y + 2, z + 0, block2, 4, 2);
				world.setBlock(x - 1, y + 2, z + 1, block2, 4, 2);
				world.setBlock(x - 1, y + 2, z + 2, block1, 3, 2);
				world.setBlock(x + 0, y - 2, z - 2, block1, 6, 2);
				world.setBlock(x + 0, y - 2, z - 1, block2, 4, 2);
				world.setBlock(x + 0, y - 2, z + 0, block2, 4, 2);
				world.setBlock(x + 0, y - 2, z + 1, block2, 4, 2);
				world.setBlock(x + 0, y - 2, z + 2, block1, 7, 2);
				world.setBlock(x + 0, y - 1, z - 2, block2, 4, 2);
				world.setBlock(x + 0, y - 1, z + 2, block2, 4, 2);
				world.setBlock(x + 0, y + 0, z - 2, block2, 4, 2);
				world.setBlock(x + 0, y + 0, z + 2, block2, 4, 2);
				world.setBlock(x + 0, y + 1, z - 2, block2, 4, 2);
				world.setBlock(x + 0, y + 1, z + 2, block2, 4, 2);
				world.setBlock(x + 0, y + 2, z - 2, block1, 2, 2);
				world.setBlock(x + 0, y + 2, z - 1, block2, 4, 2);
				world.setBlock(x + 0, y + 2, z + 0, block2, 4, 2);
				world.setBlock(x + 0, y + 2, z + 1, block2, 4, 2);
				world.setBlock(x + 0, y + 2, z + 2, block1, 3, 2);
				
			} else if (rot == 2)
			{
				
				world.setBlock(x - 8, y - 2, z - 2, block1, 6, 2);
				
				world.setBlock(x - 8, y - 2, z - 1, block2, 4, 2);
				world.setBlock(x - 8, y - 2, z + 0, block2, 4, 2);
				world.setBlock(x - 8, y - 2, z + 1, block2, 4, 2);
				world.setBlock(x - 8, y - 2, z + 2, block1, 7, 2);
				world.setBlock(x - 8, y - 1, z - 2, block2, 4, 2);
				world.setBlock(x - 8, y - 1, z + 2, block2, 4, 2);
				world.setBlock(x - 8, y + 0, z - 2, block2, 4, 2);
				world.setBlock(x - 8, y + 0, z + 2, block2, 4, 2);
				world.setBlock(x - 8, y + 1, z - 2, block2, 4, 2);
				world.setBlock(x - 8, y + 1, z + 2, block2, 4, 2);
				world.setBlock(x - 8, y + 2, z - 2, block1, 2, 2);
				world.setBlock(x - 8, y + 2, z - 1, block2, 4, 2);
				world.setBlock(x - 8, y + 2, z + 0, block2, 4, 2);
				world.setBlock(x - 8, y + 2, z + 1, block2, 4, 2);
				world.setBlock(x - 8, y + 2, z + 2, block1, 3, 2);
				world.setBlock(x - 7, y - 2, z - 2, block1, 6, 2);
				world.setBlock(x - 7, y - 2, z - 1, block2, 4, 2);
				world.setBlock(x - 7, y - 2, z + 0, block2, 4, 2);
				world.setBlock(x - 7, y - 2, z + 1, block2, 4, 2);
				world.setBlock(x - 7, y - 2, z + 2, block1, 7, 2);
				world.setBlock(x - 7, y - 1, z - 2, block2, 4, 2);
				world.setBlock(x - 7, y - 1, z + 2, block2, 4, 2);
				world.setBlock(x - 7, y + 0, z - 2, block2, 4, 2);
				world.setBlock(x - 7, y + 0, z + 2, block2, 4, 2);
				world.setBlock(x - 7, y + 1, z - 2, block2, 4, 2);
				world.setBlock(x - 7, y + 1, z + 2, block2, 4, 2);
				world.setBlock(x - 7, y + 2, z - 2, block1, 2, 2);
				world.setBlock(x - 7, y + 2, z - 1, block2, 4, 2);
				world.setBlock(x - 7, y + 2, z + 0, block2, 4, 2);
				world.setBlock(x - 7, y + 2, z + 1, block2, 4, 2);
				world.setBlock(x - 7, y + 2, z + 2, block1, 3, 2);
				world.setBlock(x - 6, y - 2, z - 2, block1, 6, 2);
				world.setBlock(x - 6, y - 2, z - 1, block2, 4, 2);
				world.setBlock(x - 6, y - 2, z + 0, block2, 4, 2);
				world.setBlock(x - 6, y - 2, z + 1, block2, 4, 2);
				world.setBlock(x - 6, y - 2, z + 2, block2, 4, 2);
				world.setBlock(x - 6, y - 2, z + 3, block1, 4, 2);
				world.setBlock(x - 6, y - 2, z + 4, block1, 4, 2);
				world.setBlock(x - 6, y - 1, z - 2, block2, 4, 2);
				world.setBlock(x - 6, y - 1, z + 2, block3, 0, 2);
				world.setBlock(x - 6, y - 1, z + 3, block2, 4, 2);
				world.setBlock(x - 6, y - 1, z + 4, block2, 4, 2);
				world.setBlock(x - 6, y + 0, z - 2, block2, 4, 2);
				world.setBlock(x - 6, y + 0, z + 3, block2, 4, 2);
				world.setBlock(x - 6, y + 0, z + 4, block2, 4, 2);
				world.setBlock(x - 6, y + 1, z - 2, block2, 4, 2);
				world.setBlock(x - 6, y + 1, z + 2, block3, 8, 2);
				world.setBlock(x - 6, y + 1, z + 3, block2, 4, 2);
				world.setBlock(x - 6, y + 1, z + 4, block2, 4, 2);
				world.setBlock(x - 6, y + 2, z - 2, block1, 2, 2);
				world.setBlock(x - 6, y + 2, z - 1, block1, 5, 2);
				world.setBlock(x - 6, y + 2, z + 0, block1, 5, 2);
				world.setBlock(x - 6, y + 2, z + 1, block1, 5, 2);
				world.setBlock(x - 6, y + 2, z + 2, block2, 4, 2);
				world.setBlock(x - 6, y + 2, z + 3, block1, 0, 2);
				world.setBlock(x - 6, y + 2, z + 4, block1, 0, 2);
				world.setBlock(x - 6, y + 3, z - 1, block1, 0, 2);
				world.setBlock(x - 6, y + 3, z + 0, block1, 0, 2);
				world.setBlock(x - 6, y + 3, z + 1, block1, 0, 2);
				world.setBlock(x - 5, y - 2, z - 2, block1, 6, 2);
				world.setBlock(x - 5, y - 2, z - 1, block2, 4, 2);
				world.setBlock(x - 5, y - 2, z + 0, block2, 4, 2);
				world.setBlock(x - 5, y - 2, z + 1, block2, 4, 2);
				world.setBlock(x - 5, y - 2, z + 2, block2, 4, 2);
				world.setBlock(x - 5, y - 2, z + 3, block2, 4, 2);
				world.setBlock(x - 5, y - 2, z + 4, block2, 4, 2);
				world.setBlock(x - 5, y - 1, z - 2, block2, 4, 2);
				world.setBlock(x - 5, y + 0, z - 2, block2, 4, 2);
				world.setBlock(x - 5, y + 1, z - 2, block2, 4, 2);
				world.setBlock(x - 5, y + 2, z - 2, block1, 2, 2);
				world.setBlock(x - 5, y + 2, z + 2, block1, 6, 2);
				world.setBlock(x - 5, y + 2, z + 3, block2, 4, 2);
				world.setBlock(x - 5, y + 2, z + 4, block2, 4, 2);
				world.setBlock(x - 5, y + 3, z - 1, block2, 4, 2);
				world.setBlock(x - 5, y + 3, z + 0, block2, 4, 2);
				world.setBlock(x - 5, y + 3, z + 1, block2, 4, 2);
				world.setBlock(x - 5, y + 3, z + 2, block1, 3, 2);
				world.setBlock(x - 4, y - 3, z + 0, block2, 0, 2);
				world.setBlock(x - 4, y - 2, z - 2, block1, 6, 2);
				world.setBlock(x - 4, y - 2, z - 1, block2, 4, 2);
				world.setBlock(x - 4, y - 2, z + 0, block2, 4, 2);
				world.setBlock(x - 4, y - 2, z + 1, block2, 4, 2);
				world.setBlock(x - 4, y - 2, z + 2, block2, 4, 2);
				world.setBlock(x - 4, y - 2, z + 3, block2, 4, 2);
				world.setBlock(x - 4, y - 2, z + 4, block2, 4, 2);
				world.setBlock(x - 4, y - 1, z - 2, block2, 4, 2);
				world.setBlock(x - 4, y + 0, z - 2, block5, 0, 2);
				world.setBlock(x - 4, y + 1, z - 2, block2, 4, 2);
				world.setBlock(x - 4, y + 2, z - 2, block1, 2, 2);
				world.setBlock(x - 4, y + 2, z - 1, block6, 2, 2);
				world.setBlock(x - 4, y + 2, z + 2, block1, 6, 2);
				world.setBlock(x - 4, y + 2, z + 3, block2, 4, 2);
				world.setBlock(x - 4, y + 2, z + 4, block2, 4, 2);
				world.setBlock(x - 4, y + 3, z - 1, block2, 4, 2);
				world.setBlock(x - 4, y + 3, z + 0, block5, 0, 2);
				world.setBlock(x - 4, y + 3, z + 1, block2, 4, 2);
				world.setBlock(x - 4, y + 3, z + 2, block1, 3, 2);
				world.setBlock(x - 3, y - 2, z - 2, block1, 6, 2);
				world.setBlock(x - 3, y - 2, z - 1, block2, 4, 2);
				world.setBlock(x - 3, y - 2, z + 0, block2, 4, 2);
				world.setBlock(x - 3, y - 2, z + 1, block2, 4, 2);
				world.setBlock(x - 3, y - 2, z + 2, block2, 4, 2);
				world.setBlock(x - 3, y - 2, z + 3, block2, 4, 2);
				world.setBlock(x - 3, y - 2, z + 4, block2, 4, 2);
				world.setBlock(x - 3, y - 1, z - 2, block2, 4, 2);
				world.setBlock(x - 3, y + 0, z - 2, block2, 4, 2);
				world.setBlock(x - 3, y + 1, z - 2, block2, 4, 2);
				world.setBlock(x - 3, y + 2, z - 2, block1, 2, 2);
				world.setBlock(x - 3, y + 2, z + 2, block1, 6, 2);
				world.setBlock(x - 3, y + 2, z + 3, block2, 4, 2);
				world.setBlock(x - 3, y + 2, z + 4, block2, 4, 2);
				world.setBlock(x - 3, y + 3, z - 1, block2, 4, 2);
				world.setBlock(x - 3, y + 3, z + 0, block2, 4, 2);
				world.setBlock(x - 3, y + 3, z + 1, block2, 4, 2);
				world.setBlock(x - 3, y + 3, z + 2, block1, 3, 2);
				world.setBlock(x - 2, y - 2, z - 2, block1, 6, 2);
				world.setBlock(x - 2, y - 2, z - 1, block2, 4, 2);
				world.setBlock(x - 2, y - 2, z + 0, block2, 4, 2);
				world.setBlock(x - 2, y - 2, z + 1, block2, 4, 2);
				world.setBlock(x - 2, y - 2, z + 2, block2, 4, 2);
				world.setBlock(x - 2, y - 2, z + 3, block1, 5, 2);
				world.setBlock(x - 2, y - 2, z + 4, block1, 5, 2);
				world.setBlock(x - 2, y - 1, z - 2, block2, 4, 2);
				world.setBlock(x - 2, y - 1, z + 2, block3, 0, 2);
				world.setBlock(x - 2, y - 1, z + 3, block2, 4, 2);
				world.setBlock(x - 2, y - 1, z + 4, block2, 4, 2);
				world.setBlock(x - 2, y + 0, z - 2, block2, 4, 2);
				world.setBlock(x - 2, y + 0, z - 1, block2, 0, 2);
				world.setBlock(x - 2, y + 0, z + 3, block2, 4, 2);
				world.setBlock(x - 2, y + 0, z + 4, block2, 4, 2);
				world.setBlock(x - 2, y + 1, z - 2, block2, 4, 2);
				world.setBlock(x - 2, y + 1, z + 2, block3, 8, 2);
				world.setBlock(x - 2, y + 1, z + 3, block2, 4, 2);
				world.setBlock(x - 2, y + 1, z + 4, block2, 4, 2);
				world.setBlock(x - 2, y + 2, z - 2, block1, 2, 2);
				world.setBlock(x - 2, y + 2, z - 1, block1, 4, 2);
				world.setBlock(x - 2, y + 2, z + 0, block1, 4, 2);
				world.setBlock(x - 2, y + 2, z + 1, block1, 4, 2);
				world.setBlock(x - 2, y + 2, z + 2, block2, 4, 2);
				world.setBlock(x - 2, y + 2, z + 3, block1, 1, 2);
				world.setBlock(x - 2, y + 2, z + 4, block1, 1, 2);
				world.setBlock(x - 2, y + 3, z - 1, block1, 1, 2);
				world.setBlock(x - 2, y + 3, z + 0, block1, 1, 2);
				world.setBlock(x - 2, y + 3, z + 1, block1, 1, 2);
				world.setBlock(x - 1, y - 2, z - 2, block1, 6, 2);
				world.setBlock(x - 1, y - 2, z - 1, block2, 4, 2);
				world.setBlock(x - 1, y - 2, z + 0, block2, 4, 2);
				world.setBlock(x - 1, y - 2, z + 1, block2, 4, 2);
				world.setBlock(x - 1, y - 2, z + 2, block1, 7, 2);
				world.setBlock(x - 1, y - 1, z - 2, block2, 4, 2);
				world.setBlock(x - 1, y - 1, z + 2, block2, 4, 2);
				world.setBlock(x - 1, y + 0, z - 2, block2, 4, 2);
				world.setBlock(x - 1, y + 0, z + 2, block2, 4, 2);
				world.setBlock(x - 1, y + 1, z - 2, block2, 4, 2);
				world.setBlock(x - 1, y + 1, z + 2, block2, 4, 2);
				world.setBlock(x - 1, y + 2, z - 2, block1, 2, 2);
				world.setBlock(x - 1, y + 2, z - 1, block2, 4, 2);
				world.setBlock(x - 1, y + 2, z + 0, block2, 4, 2);
				world.setBlock(x - 1, y + 2, z + 1, block2, 4, 2);
				world.setBlock(x - 1, y + 2, z + 2, block1, 3, 2);
				world.setBlock(x + 0, y - 2, z - 2, block1, 6, 2);
				world.setBlock(x + 0, y - 2, z - 1, block2, 4, 2);
				world.setBlock(x + 0, y - 2, z + 0, block2, 4, 2);
				world.setBlock(x + 0, y - 2, z + 1, block2, 4, 2);
				world.setBlock(x + 0, y - 2, z + 2, block1, 7, 2);
				world.setBlock(x + 0, y - 1, z - 2, block2, 4, 2);
				world.setBlock(x + 0, y - 1, z + 2, block2, 4, 2);
				world.setBlock(x + 0, y + 0, z - 2, block2, 4, 2);
				world.setBlock(x + 0, y + 0, z + 2, block2, 4, 2);
				world.setBlock(x + 0, y + 1, z - 2, block2, 4, 2);
				world.setBlock(x + 0, y + 1, z + 2, block2, 4, 2);
				world.setBlock(x + 0, y + 2, z - 2, block1, 2, 2);
				world.setBlock(x + 0, y + 2, z - 1, block2, 4, 2);
				world.setBlock(x + 0, y + 2, z + 0, block2, 4, 2);
				world.setBlock(x + 0, y + 2, z + 1, block2, 4, 2);
				world.setBlock(x + 0, y + 2, z + 2, block1, 3, 2);
				
			}
		} else if (dir == ForgeDirection.EAST)
		{
			if (rot == 0)
			{
				
				world.setBlock(x + 0, y - 2, z - 2, block1, 6, 2);
				
				world.setBlock(x + 0, y - 2, z - 1, block2, 4, 2);
				world.setBlock(x + 0, y - 2, z + 0, block2, 4, 2);
				world.setBlock(x + 0, y - 2, z + 1, block2, 4, 2);
				world.setBlock(x + 0, y - 2, z + 2, block1, 7, 2);
				world.setBlock(x + 0, y - 1, z - 2, block2, 4, 2);
				world.setBlock(x + 0, y - 1, z + 2, block2, 4, 2);
				world.setBlock(x + 0, y + 0, z - 2, block2, 4, 2);
				world.setBlock(x + 0, y + 0, z + 2, block2, 4, 2);
				world.setBlock(x + 0, y + 1, z - 2, block2, 4, 2);
				world.setBlock(x + 0, y + 1, z + 2, block2, 4, 2);
				world.setBlock(x + 0, y + 2, z - 2, block1, 2, 2);
				world.setBlock(x + 0, y + 2, z - 1, block2, 4, 2);
				world.setBlock(x + 0, y + 2, z + 0, block2, 4, 2);
				world.setBlock(x + 0, y + 2, z + 1, block2, 4, 2);
				world.setBlock(x + 0, y + 2, z + 2, block1, 3, 2);
				world.setBlock(x + 1, y - 2, z - 2, block1, 6, 2);
				world.setBlock(x + 1, y - 2, z - 1, block2, 4, 2);
				world.setBlock(x + 1, y - 2, z + 0, block2, 4, 2);
				world.setBlock(x + 1, y - 2, z + 1, block2, 4, 2);
				world.setBlock(x + 1, y - 2, z + 2, block1, 7, 2);
				world.setBlock(x + 1, y - 1, z - 2, block2, 4, 2);
				world.setBlock(x + 1, y - 1, z + 2, block2, 4, 2);
				world.setBlock(x + 1, y + 0, z - 2, block2, 4, 2);
				world.setBlock(x + 1, y + 0, z + 2, block2, 4, 2);
				world.setBlock(x + 1, y + 1, z - 2, block2, 4, 2);
				world.setBlock(x + 1, y + 1, z + 2, block2, 4, 2);
				world.setBlock(x + 1, y + 2, z - 2, block1, 2, 2);
				world.setBlock(x + 1, y + 2, z - 1, block2, 4, 2);
				world.setBlock(x + 1, y + 2, z + 0, block2, 4, 2);
				world.setBlock(x + 1, y + 2, z + 1, block2, 4, 2);
				world.setBlock(x + 1, y + 2, z + 2, block1, 3, 2);
				world.setBlock(x + 2, y - 2, z - 4, block1, 4, 2);
				world.setBlock(x + 2, y - 2, z - 3, block1, 4, 2);
				world.setBlock(x + 2, y - 2, z - 2, block2, 4, 2);
				world.setBlock(x + 2, y - 2, z - 1, block2, 4, 2);
				world.setBlock(x + 2, y - 2, z + 0, block2, 4, 2);
				world.setBlock(x + 2, y - 2, z + 1, block2, 4, 2);
				world.setBlock(x + 2, y - 2, z + 2, block1, 7, 2);
				world.setBlock(x + 2, y - 1, z - 4, block2, 4, 2);
				world.setBlock(x + 2, y - 1, z - 3, block2, 4, 2);
				
				world.setBlock(x + 2, y - 1, z - 2, block3, 0, 2);
				world.setBlock(x + 2, y - 1, z + 2, block2, 4, 2);
				world.setBlock(x + 2, y + 0, z - 4, block2, 4, 2);
				world.setBlock(x + 2, y + 0, z - 3, block2, 4, 2);
				world.setBlock(x + 4, y - 3, z + 0, block2, 0, 2);
				
				world.setBlock(x + 2, y + 0, z + 1, block2, 0, 2);
				world.setBlock(x + 2, y + 0, z + 2, block2, 4, 2);
				world.setBlock(x + 2, y + 1, z - 4, block2, 4, 2);
				world.setBlock(x + 2, y + 1, z - 3, block2, 4, 2);
				world.setBlock(x + 2, y + 1, z - 2, block3, 8, 2);
				world.setBlock(x + 2, y + 1, z + 2, block2, 4, 2);
				world.setBlock(x + 2, y + 2, z - 4, block1, 0, 2);
				world.setBlock(x + 2, y + 2, z - 3, block1, 0, 2);
				world.setBlock(x + 2, y + 2, z - 2, block2, 4, 2);
				world.setBlock(x + 2, y + 2, z - 1, block1, 5, 2);
				world.setBlock(x + 2, y + 2, z + 0, block1, 5, 2);
				world.setBlock(x + 2, y + 2, z + 1, block1, 5, 2);
				world.setBlock(x + 2, y + 2, z + 2, block1, 3, 2);
				world.setBlock(x + 2, y + 3, z - 1, block1, 0, 2);
				world.setBlock(x + 2, y + 3, z + 0, block1, 0, 2);
				world.setBlock(x + 2, y + 3, z + 1, block1, 0, 2);
				world.setBlock(x + 3, y - 2, z - 4, block2, 4, 2);
				world.setBlock(x + 3, y - 2, z - 3, block2, 4, 2);
				world.setBlock(x + 3, y - 2, z - 2, block2, 4, 2);
				world.setBlock(x + 3, y - 2, z - 1, block2, 4, 2);
				world.setBlock(x + 3, y - 2, z + 0, block2, 4, 2);
				world.setBlock(x + 3, y - 2, z + 1, block2, 4, 2);
				world.setBlock(x + 3, y - 2, z + 2, block1, 7, 2);
				world.setBlock(x + 3, y - 1, z + 2, block2, 4, 2);
				world.setBlock(x + 3, y + 0, z + 2, block2, 4, 2);
				world.setBlock(x + 3, y + 1, z + 2, block2, 4, 2);
				world.setBlock(x + 3, y + 2, z - 4, block2, 4, 2);
				world.setBlock(x + 3, y + 2, z - 3, block2, 4, 2);
				world.setBlock(x + 3, y + 2, z - 2, block1, 7, 2);
				world.setBlock(x + 3, y + 2, z + 2, block1, 3, 2);
				world.setBlock(x + 3, y + 3, z - 2, block1, 2, 2);
				world.setBlock(x + 3, y + 3, z - 1, block2, 4, 2);
				world.setBlock(x + 3, y + 3, z + 0, block2, 4, 2);
				world.setBlock(x + 3, y + 3, z + 1, block2, 4, 2);
				world.setBlock(x + 4, y - 2, z - 4, block2, 4, 2);
				world.setBlock(x + 4, y - 2, z - 3, block2, 4, 2);
				world.setBlock(x + 4, y - 2, z - 2, block2, 4, 2);
				world.setBlock(x + 4, y - 2, z - 1, block2, 4, 2);
				world.setBlock(x + 4, y - 2, z + 0, block2, 4, 2);
				world.setBlock(x + 4, y - 2, z + 1, block2, 4, 2);
				world.setBlock(x + 4, y - 2, z + 2, block1, 7, 2);
				world.setBlock(x + 4, y - 1, z + 2, block2, 4, 2);
				world.setBlock(x + 4, y + 0, z + 2, block5, 0, 2);
				world.setBlock(x + 4, y + 1, z + 2, block2, 4, 2);
				world.setBlock(x + 4, y + 2, z - 4, block2, 4, 2);
				world.setBlock(x + 4, y + 2, z - 3, block2, 4, 2);
				world.setBlock(x + 4, y + 2, z - 2, block1, 7, 2);
				world.setBlock(x + 4, y + 2, z + 1, block6, 3, 2);
				world.setBlock(x + 4, y + 2, z + 2, block1, 3, 2);
				world.setBlock(x + 4, y + 3, z - 2, block1, 2, 2);
				world.setBlock(x + 4, y + 3, z - 1, block2, 4, 2);
				world.setBlock(x + 4, y + 3, z + 0, block5, 0, 2);
				world.setBlock(x + 4, y + 3, z + 1, block2, 4, 2);
				world.setBlock(x + 5, y - 2, z - 4, block2, 4, 2);
				world.setBlock(x + 5, y - 2, z - 3, block2, 4, 2);
				world.setBlock(x + 5, y - 2, z - 2, block2, 4, 2);
				world.setBlock(x + 5, y - 2, z - 1, block2, 4, 2);
				world.setBlock(x + 5, y - 2, z + 0, block2, 4, 2);
				world.setBlock(x + 5, y - 2, z + 1, block2, 4, 2);
				world.setBlock(x + 5, y - 2, z + 2, block1, 7, 2);
				world.setBlock(x + 5, y - 1, z + 2, block2, 4, 2);
				world.setBlock(x + 5, y + 0, z + 2, block2, 4, 2);
				world.setBlock(x + 5, y + 1, z + 2, block2, 4, 2);
				world.setBlock(x + 5, y + 2, z - 4, block2, 4, 2);
				world.setBlock(x + 5, y + 2, z - 3, block2, 4, 2);
				world.setBlock(x + 5, y + 2, z - 2, block1, 7, 2);
				world.setBlock(x + 5, y + 2, z + 2, block1, 3, 2);
				world.setBlock(x + 5, y + 3, z - 2, block1, 2, 2);
				world.setBlock(x + 5, y + 3, z - 1, block2, 4, 2);
				world.setBlock(x + 5, y + 3, z + 0, block2, 4, 2);
				world.setBlock(x + 5, y + 3, z + 1, block2, 4, 2);
				world.setBlock(x + 6, y - 2, z - 4, block1, 5, 2);
				world.setBlock(x + 6, y - 2, z - 3, block1, 5, 2);
				world.setBlock(x + 6, y - 2, z - 2, block2, 4, 2);
				world.setBlock(x + 6, y - 2, z - 1, block2, 4, 2);
				world.setBlock(x + 6, y - 2, z + 0, block2, 4, 2);
				world.setBlock(x + 6, y - 2, z + 1, block2, 4, 2);
				world.setBlock(x + 6, y - 2, z + 2, block1, 7, 2);
				world.setBlock(x + 6, y - 1, z - 4, block2, 4, 2);
				world.setBlock(x + 6, y - 1, z - 3, block2, 4, 2);
				world.setBlock(x + 6, y - 1, z - 2, block3, 0, 2);
				world.setBlock(x + 6, y - 1, z + 2, block2, 4, 2);
				world.setBlock(x + 6, y + 0, z - 4, block2, 4, 2);
				world.setBlock(x + 6, y + 0, z - 3, block2, 4, 2);
				world.setBlock(x + 6, y + 0, z + 2, block2, 4, 2);
				world.setBlock(x + 6, y + 1, z - 4, block2, 4, 2);
				world.setBlock(x + 6, y + 1, z - 3, block2, 4, 2);
				world.setBlock(x + 6, y + 1, z - 2, block3, 8, 2);
				world.setBlock(x + 6, y + 1, z + 2, block2, 4, 2);
				world.setBlock(x + 6, y + 2, z - 4, block1, 1, 2);
				world.setBlock(x + 6, y + 2, z - 3, block1, 1, 2);
				world.setBlock(x + 6, y + 2, z - 2, block2, 4, 2);
				world.setBlock(x + 6, y + 2, z - 1, block1, 4, 2);
				world.setBlock(x + 6, y + 2, z + 0, block1, 4, 2);
				world.setBlock(x + 6, y + 2, z + 1, block1, 4, 2);
				world.setBlock(x + 6, y + 2, z + 2, block1, 3, 2);
				world.setBlock(x + 6, y + 3, z - 1, block1, 1, 2);
				world.setBlock(x + 6, y + 3, z + 0, block1, 1, 2);
				world.setBlock(x + 6, y + 3, z + 1, block1, 1, 2);
				world.setBlock(x + 7, y - 2, z - 2, block1, 6, 2);
				world.setBlock(x + 7, y - 2, z - 1, block2, 4, 2);
				world.setBlock(x + 7, y - 2, z + 0, block2, 4, 2);
				world.setBlock(x + 7, y - 2, z + 1, block2, 4, 2);
				world.setBlock(x + 7, y - 2, z + 2, block1, 7, 2);
				world.setBlock(x + 7, y - 1, z - 2, block2, 4, 2);
				world.setBlock(x + 7, y - 1, z + 2, block2, 4, 2);
				world.setBlock(x + 7, y + 0, z - 2, block2, 4, 2);
				world.setBlock(x + 7, y + 0, z + 2, block2, 4, 2);
				world.setBlock(x + 7, y + 1, z - 2, block2, 4, 2);
				world.setBlock(x + 7, y + 1, z + 2, block2, 4, 2);
				world.setBlock(x + 7, y + 2, z - 2, block1, 2, 2);
				world.setBlock(x + 7, y + 2, z - 1, block2, 4, 2);
				world.setBlock(x + 7, y + 2, z + 0, block2, 4, 2);
				world.setBlock(x + 7, y + 2, z + 1, block2, 4, 2);
				world.setBlock(x + 7, y + 2, z + 2, block1, 3, 2);
				world.setBlock(x + 8, y - 2, z - 2, block1, 6, 2);
				world.setBlock(x + 8, y - 2, z - 1, block2, 4, 2);
				world.setBlock(x + 8, y - 2, z + 0, block2, 4, 2);
				world.setBlock(x + 8, y - 2, z + 1, block2, 4, 2);
				world.setBlock(x + 8, y - 2, z + 2, block1, 7, 2);
				world.setBlock(x + 8, y - 1, z - 2, block2, 4, 2);
				world.setBlock(x + 8, y - 1, z + 2, block2, 4, 2);
				world.setBlock(x + 8, y + 0, z - 2, block2, 4, 2);
				world.setBlock(x + 8, y + 0, z + 2, block2, 4, 2);
				world.setBlock(x + 8, y + 1, z - 2, block2, 4, 2);
				world.setBlock(x + 8, y + 1, z + 2, block2, 4, 2);
				world.setBlock(x + 8, y + 2, z - 2, block1, 2, 2);
				world.setBlock(x + 8, y + 2, z - 1, block2, 4, 2);
				world.setBlock(x + 8, y + 2, z + 0, block2, 4, 2);
				world.setBlock(x + 8, y + 2, z + 1, block2, 4, 2);
				world.setBlock(x + 8, y + 2, z + 2, block1, 3, 2);
				
			} else if (rot == 3)
			{
				
				world.setBlock(x + 0, y - 2, z - 2, block1, 6, 2);
				
				world.setBlock(x + 0, y - 2, z - 1, block2, 4, 2);
				world.setBlock(x + 0, y - 2, z + 0, block2, 4, 2);
				world.setBlock(x + 0, y - 2, z + 1, block2, 4, 2);
				world.setBlock(x + 0, y - 2, z + 2, block1, 7, 2);
				world.setBlock(x + 0, y - 1, z - 2, block2, 4, 2);
				world.setBlock(x + 0, y - 1, z + 2, block2, 4, 2);
				world.setBlock(x + 0, y + 0, z - 2, block2, 4, 2);
				world.setBlock(x + 0, y + 0, z + 2, block2, 4, 2);
				world.setBlock(x + 0, y + 1, z - 2, block2, 4, 2);
				world.setBlock(x + 0, y + 1, z + 2, block2, 4, 2);
				world.setBlock(x + 0, y + 2, z - 2, block1, 2, 2);
				world.setBlock(x + 0, y + 2, z - 1, block2, 4, 2);
				world.setBlock(x + 0, y + 2, z + 0, block2, 4, 2);
				world.setBlock(x + 0, y + 2, z + 1, block2, 4, 2);
				world.setBlock(x + 0, y + 2, z + 2, block1, 3, 2);
				world.setBlock(x + 1, y - 2, z - 2, block1, 6, 2);
				world.setBlock(x + 1, y - 2, z - 1, block2, 4, 2);
				world.setBlock(x + 1, y - 2, z + 0, block2, 4, 2);
				world.setBlock(x + 1, y - 2, z + 1, block2, 4, 2);
				world.setBlock(x + 1, y - 2, z + 2, block1, 7, 2);
				world.setBlock(x + 1, y - 1, z - 2, block2, 4, 2);
				world.setBlock(x + 1, y - 1, z + 2, block2, 4, 2);
				world.setBlock(x + 1, y + 0, z - 2, block2, 4, 2);
				world.setBlock(x + 1, y + 0, z + 2, block2, 4, 2);
				world.setBlock(x + 1, y + 1, z - 2, block2, 4, 2);
				world.setBlock(x + 1, y + 1, z + 2, block2, 4, 2);
				world.setBlock(x + 1, y + 2, z - 2, block1, 2, 2);
				world.setBlock(x + 1, y + 2, z - 1, block2, 4, 2);
				world.setBlock(x + 1, y + 2, z + 0, block2, 4, 2);
				world.setBlock(x + 1, y + 2, z + 1, block2, 4, 2);
				world.setBlock(x + 1, y + 2, z + 2, block1, 3, 2);
				world.setBlock(x + 2, y - 2, z - 4, block1, 4, 2);
				world.setBlock(x + 2, y - 2, z - 3, block1, 4, 2);
				world.setBlock(x + 2, y - 2, z - 2, block2, 4, 2);
				world.setBlock(x + 2, y - 2, z - 1, block2, 4, 2);
				world.setBlock(x + 2, y - 2, z + 0, block2, 4, 2);
				world.setBlock(x + 2, y - 2, z + 1, block2, 4, 2);
				world.setBlock(x + 2, y - 2, z + 2, block2, 4, 2);
				world.setBlock(x + 2, y - 2, z + 3, block1, 4, 2);
				world.setBlock(x + 2, y - 2, z + 4, block1, 4, 2);
				world.setBlock(x + 2, y - 1, z - 4, block2, 4, 2);
				world.setBlock(x + 2, y - 1, z - 3, block2, 4, 2);
				
				world.setBlock(x + 2, y - 1, z - 2, block3, 0, 2);
				world.setBlock(x + 2, y - 1, z + 2, block3, 0, 2);
				world.setBlock(x + 2, y - 1, z + 3, block2, 4, 2);
				world.setBlock(x + 2, y - 1, z + 4, block2, 4, 2);
				world.setBlock(x + 2, y + 0, z - 4, block2, 4, 2);
				world.setBlock(x + 2, y + 0, z - 3, block2, 4, 2);
				world.setBlock(x + 2, y + 0, z + 3, block2, 4, 2);
				world.setBlock(x + 2, y + 0, z + 4, block2, 4, 2);
				world.setBlock(x + 2, y + 1, z - 4, block2, 4, 2);
				world.setBlock(x + 2, y + 1, z - 3, block2, 4, 2);
				world.setBlock(x + 2, y + 1, z - 2, block3, 8, 2);
				world.setBlock(x + 2, y + 1, z + 2, block3, 8, 2);
				world.setBlock(x + 2, y + 1, z + 3, block2, 4, 2);
				world.setBlock(x + 2, y + 1, z + 4, block2, 4, 2);
				world.setBlock(x + 2, y + 2, z - 4, block1, 0, 2);
				world.setBlock(x + 2, y + 2, z - 3, block1, 0, 2);
				world.setBlock(x + 2, y + 2, z - 2, block2, 4, 2);
				world.setBlock(x + 2, y + 2, z - 1, block1, 5, 2);
				world.setBlock(x + 2, y + 2, z + 0, block1, 5, 2);
				world.setBlock(x + 2, y + 2, z + 1, block1, 5, 2);
				world.setBlock(x + 2, y + 2, z + 2, block2, 4, 2);
				world.setBlock(x + 2, y + 2, z + 3, block1, 0, 2);
				world.setBlock(x + 2, y + 2, z + 4, block1, 0, 2);
				world.setBlock(x + 2, y + 3, z - 1, block1, 0, 2);
				world.setBlock(x + 2, y + 3, z + 0, block1, 0, 2);
				world.setBlock(x + 2, y + 3, z + 1, block1, 0, 2);
				world.setBlock(x + 3, y - 2, z - 4, block2, 4, 2);
				world.setBlock(x + 3, y - 2, z - 3, block2, 4, 2);
				world.setBlock(x + 3, y - 2, z - 2, block2, 4, 2);
				world.setBlock(x + 3, y - 2, z - 1, block2, 4, 2);
				world.setBlock(x + 3, y - 2, z + 0, block2, 4, 2);
				world.setBlock(x + 3, y - 2, z + 1, block2, 4, 2);
				world.setBlock(x + 3, y - 2, z + 2, block2, 4, 2);
				world.setBlock(x + 3, y - 2, z + 3, block2, 4, 2);
				world.setBlock(x + 3, y - 2, z + 4, block2, 4, 2);
				world.setBlock(x + 3, y + 2, z - 4, block2, 4, 2);
				world.setBlock(x + 3, y + 2, z - 3, block2, 4, 2);
				world.setBlock(x + 3, y + 2, z - 2, block1, 7, 2);
				world.setBlock(x + 3, y + 2, z + 2, block1, 6, 2);
				world.setBlock(x + 3, y + 2, z + 3, block2, 4, 2);
				world.setBlock(x + 3, y + 2, z + 4, block2, 4, 2);
				world.setBlock(x + 3, y + 3, z - 2, block1, 2, 2);
				world.setBlock(x + 3, y + 3, z - 1, block2, 4, 2);
				world.setBlock(x + 3, y + 3, z + 0, block2, 4, 2);
				world.setBlock(x + 3, y + 3, z + 1, block2, 4, 2);
				world.setBlock(x + 3, y + 3, z + 2, block1, 3, 2);
				world.setBlock(x + 4, y - 3, z + 0, block2, 0, 2);
				world.setBlock(x + 5, y + 0, z + 2, block2, 0, 2);
				world.setBlock(x + 4, y - 2, z - 4, block2, 4, 2);
				world.setBlock(x + 4, y - 2, z - 3, block2, 4, 2);
				world.setBlock(x + 4, y - 2, z - 2, block2, 4, 2);
				world.setBlock(x + 4, y - 2, z - 1, block2, 4, 2);
				world.setBlock(x + 4, y - 2, z + 0, block2, 4, 2);
				world.setBlock(x + 4, y - 2, z + 1, block2, 4, 2);
				world.setBlock(x + 4, y - 2, z + 2, block2, 4, 2);
				world.setBlock(x + 4, y - 2, z + 3, block2, 4, 2);
				world.setBlock(x + 4, y - 2, z + 4, block2, 4, 2);
				world.setBlock(x + 4, y + 2, z - 4, block2, 4, 2);
				world.setBlock(x + 4, y + 2, z - 3, block2, 4, 2);
				world.setBlock(x + 4, y + 2, z - 2, block1, 7, 2);
				world.setBlock(x + 4, y + 2, z + 2, block1, 6, 2);
				world.setBlock(x + 4, y + 2, z + 3, block2, 4, 2);
				world.setBlock(x + 4, y + 2, z + 4, block2, 4, 2);
				world.setBlock(x + 4, y + 3, z - 2, block1, 2, 2);
				world.setBlock(x + 4, y + 3, z - 1, block2, 4, 2);
				world.setBlock(x + 4, y + 3, z + 0, block5, 0, 2);
				world.setBlock(x + 4, y + 3, z + 1, block2, 4, 2);
				world.setBlock(x + 4, y + 3, z + 2, block1, 3, 2);
				world.setBlock(x + 5, y - 2, z - 4, block2, 4, 2);
				world.setBlock(x + 5, y - 2, z - 3, block2, 4, 2);
				world.setBlock(x + 5, y - 2, z - 2, block2, 4, 2);
				world.setBlock(x + 5, y - 2, z - 1, block2, 4, 2);
				world.setBlock(x + 5, y - 2, z + 0, block2, 4, 2);
				world.setBlock(x + 5, y - 2, z + 1, block2, 4, 2);
				world.setBlock(x + 5, y - 2, z + 2, block2, 4, 2);
				world.setBlock(x + 5, y - 2, z + 3, block2, 4, 2);
				world.setBlock(x + 5, y - 2, z + 4, block2, 4, 2);
				world.setBlock(x + 5, y + 2, z - 4, block2, 4, 2);
				world.setBlock(x + 5, y + 2, z - 3, block2, 4, 2);
				world.setBlock(x + 5, y + 2, z - 2, block1, 7, 2);
				world.setBlock(x + 5, y + 2, z + 0, block6, 5, 2);
				world.setBlock(x + 5, y + 2, z + 2, block1, 6, 2);
				world.setBlock(x + 5, y + 2, z + 3, block2, 4, 2);
				world.setBlock(x + 5, y + 2, z + 4, block2, 4, 2);
				world.setBlock(x + 5, y + 3, z - 2, block1, 2, 2);
				world.setBlock(x + 5, y + 3, z - 1, block2, 4, 2);
				world.setBlock(x + 5, y + 3, z + 0, block2, 4, 2);
				world.setBlock(x + 5, y + 3, z + 1, block2, 4, 2);
				world.setBlock(x + 5, y + 3, z + 2, block1, 3, 2);
				world.setBlock(x + 6, y - 2, z - 4, block1, 5, 2);
				world.setBlock(x + 6, y - 2, z - 3, block1, 5, 2);
				world.setBlock(x + 6, y - 2, z - 2, block1, 5, 2);
				world.setBlock(x + 6, y - 2, z - 1, block1, 5, 2);
				world.setBlock(x + 6, y - 2, z + 0, block1, 5, 2);
				world.setBlock(x + 6, y - 2, z + 1, block1, 5, 2);
				world.setBlock(x + 6, y - 2, z + 2, block1, 5, 2);
				world.setBlock(x + 6, y - 2, z + 3, block1, 5, 2);
				world.setBlock(x + 6, y - 2, z + 4, block1, 5, 2);
				world.setBlock(x + 6, y - 1, z - 4, block2, 4, 2);
				world.setBlock(x + 6, y - 1, z - 3, block2, 4, 2);
				world.setBlock(x + 6, y - 1, z - 2, block2, 4, 2);
				world.setBlock(x + 6, y - 1, z - 1, block2, 4, 2);
				world.setBlock(x + 6, y - 1, z + 0, block2, 4, 2);
				world.setBlock(x + 6, y - 1, z + 1, block2, 4, 2);
				world.setBlock(x + 6, y - 1, z + 2, block2, 4, 2);
				world.setBlock(x + 6, y - 1, z + 3, block2, 4, 2);
				world.setBlock(x + 6, y - 1, z + 4, block2, 4, 2);
				world.setBlock(x + 6, y + 0, z - 4, block2, 4, 2);
				world.setBlock(x + 6, y + 0, z - 3, block2, 4, 2);
				world.setBlock(x + 6, y + 0, z - 2, block2, 4, 2);
				world.setBlock(x + 6, y + 0, z - 1, block2, 4, 2);
				world.setBlock(x + 6, y + 0, z + 0, block5, 0, 2);
				world.setBlock(x + 6, y + 0, z + 1, block2, 4, 2);
				world.setBlock(x + 6, y + 0, z + 2, block2, 4, 2);
				world.setBlock(x + 6, y + 0, z + 3, block2, 4, 2);
				world.setBlock(x + 6, y + 0, z + 4, block2, 4, 2);
				world.setBlock(x + 6, y + 1, z - 4, block2, 4, 2);
				world.setBlock(x + 6, y + 1, z - 3, block2, 4, 2);
				world.setBlock(x + 6, y + 1, z - 2, block2, 4, 2);
				world.setBlock(x + 6, y + 1, z - 1, block2, 4, 2);
				world.setBlock(x + 6, y + 1, z + 0, block2, 4, 2);
				world.setBlock(x + 6, y + 1, z + 1, block2, 4, 2);
				world.setBlock(x + 6, y + 1, z + 2, block2, 4, 2);
				world.setBlock(x + 6, y + 1, z + 3, block2, 4, 2);
				world.setBlock(x + 6, y + 1, z + 4, block2, 4, 2);
				world.setBlock(x + 6, y + 2, z - 4, block1, 1, 2);
				world.setBlock(x + 6, y + 2, z - 3, block1, 1, 2);
				world.setBlock(x + 6, y + 2, z - 2, block1, 1, 2);
				world.setBlock(x + 6, y + 2, z - 1, block1, 1, 2);
				world.setBlock(x + 6, y + 2, z + 0, block1, 1, 2);
				world.setBlock(x + 6, y + 2, z + 1, block1, 1, 2);
				world.setBlock(x + 6, y + 2, z + 2, block1, 1, 2);
				world.setBlock(x + 6, y + 2, z + 3, block1, 1, 2);
				world.setBlock(x + 6, y + 2, z + 4, block1, 1, 2);
				
			} else if (rot == 2)
			{
				
				world.setBlock(x + 0, y - 2, z - 2, block1, 6, 2);
				
				world.setBlock(x + 0, y - 2, z - 1, block2, 4, 2);
				world.setBlock(x + 0, y - 2, z + 0, block2, 4, 2);
				world.setBlock(x + 0, y - 2, z + 1, block2, 4, 2);
				world.setBlock(x + 0, y - 2, z + 2, block1, 7, 2);
				world.setBlock(x + 0, y - 1, z - 2, block2, 4, 2);
				world.setBlock(x + 0, y - 1, z + 2, block2, 4, 2);
				world.setBlock(x + 0, y + 0, z - 2, block2, 4, 2);
				world.setBlock(x + 0, y + 0, z + 2, block2, 4, 2);
				world.setBlock(x + 0, y + 1, z - 2, block2, 4, 2);
				world.setBlock(x + 0, y + 1, z + 2, block2, 4, 2);
				world.setBlock(x + 0, y + 2, z - 2, block1, 2, 2);
				world.setBlock(x + 0, y + 2, z - 1, block2, 4, 2);
				world.setBlock(x + 0, y + 2, z + 0, block2, 4, 2);
				world.setBlock(x + 0, y + 2, z + 1, block2, 4, 2);
				world.setBlock(x + 0, y + 2, z + 2, block1, 3, 2);
				world.setBlock(x + 1, y - 2, z - 2, block1, 6, 2);
				world.setBlock(x + 1, y - 2, z - 1, block2, 4, 2);
				world.setBlock(x + 1, y - 2, z + 0, block2, 4, 2);
				world.setBlock(x + 1, y - 2, z + 1, block2, 4, 2);
				world.setBlock(x + 1, y - 2, z + 2, block1, 7, 2);
				world.setBlock(x + 1, y - 1, z - 2, block2, 4, 2);
				world.setBlock(x + 1, y - 1, z + 2, block2, 4, 2);
				world.setBlock(x + 1, y + 0, z - 2, block2, 4, 2);
				world.setBlock(x + 1, y + 0, z + 2, block2, 4, 2);
				world.setBlock(x + 1, y + 1, z - 2, block2, 4, 2);
				world.setBlock(x + 1, y + 1, z + 2, block2, 4, 2);
				world.setBlock(x + 1, y + 2, z - 2, block1, 2, 2);
				world.setBlock(x + 1, y + 2, z - 1, block2, 4, 2);
				world.setBlock(x + 1, y + 2, z + 0, block2, 4, 2);
				world.setBlock(x + 1, y + 2, z + 1, block2, 4, 2);
				world.setBlock(x + 1, y + 2, z + 2, block1, 3, 2);
				world.setBlock(x + 2, y - 2, z - 2, block1, 6, 2);
				world.setBlock(x + 2, y - 2, z - 1, block2, 4, 2);
				world.setBlock(x + 2, y - 2, z + 0, block2, 4, 2);
				world.setBlock(x + 2, y - 2, z + 1, block2, 4, 2);
				world.setBlock(x + 2, y - 2, z + 2, block2, 4, 2);
				world.setBlock(x + 2, y - 2, z + 3, block1, 4, 2);
				world.setBlock(x + 2, y - 2, z + 4, block1, 4, 2);
				world.setBlock(x + 2, y - 1, z - 2, block2, 4, 2);
				
				world.setBlock(x + 2, y - 1, z + 2, block3, 0, 2);
				world.setBlock(x + 2, y - 1, z + 3, block2, 4, 2);
				world.setBlock(x + 2, y - 1, z + 4, block2, 4, 2);
				world.setBlock(x + 2, y + 0, z - 2, block2, 4, 2);
				world.setBlock(x + 2, y + 0, z + 3, block2, 4, 2);
				world.setBlock(x + 2, y + 0, z + 4, block2, 4, 2);
				world.setBlock(x + 2, y + 1, z - 2, block2, 4, 2);
				world.setBlock(x + 2, y + 1, z + 2, block3, 8, 2);
				world.setBlock(x + 2, y + 1, z + 3, block2, 4, 2);
				world.setBlock(x + 2, y + 1, z + 4, block2, 4, 2);
				world.setBlock(x + 2, y + 2, z - 2, block1, 2, 2);
				world.setBlock(x + 2, y + 2, z - 1, block1, 5, 2);
				world.setBlock(x + 2, y + 2, z + 0, block1, 5, 2);
				world.setBlock(x + 2, y + 2, z + 1, block1, 5, 2);
				world.setBlock(x + 2, y + 2, z + 2, block2, 4, 2);
				world.setBlock(x + 2, y + 2, z + 3, block1, 0, 2);
				world.setBlock(x + 2, y + 2, z + 4, block1, 0, 2);
				world.setBlock(x + 2, y + 3, z - 1, block1, 0, 2);
				world.setBlock(x + 2, y + 3, z + 0, block1, 0, 2);
				world.setBlock(x + 2, y + 3, z + 1, block1, 0, 2);
				world.setBlock(x + 3, y - 2, z - 2, block1, 6, 2);
				world.setBlock(x + 3, y - 2, z - 1, block2, 4, 2);
				world.setBlock(x + 3, y - 2, z + 0, block2, 4, 2);
				world.setBlock(x + 3, y - 2, z + 1, block2, 4, 2);
				world.setBlock(x + 3, y - 2, z + 2, block2, 4, 2);
				world.setBlock(x + 3, y - 2, z + 3, block2, 4, 2);
				world.setBlock(x + 3, y - 2, z + 4, block2, 4, 2);
				world.setBlock(x + 3, y - 1, z - 2, block2, 4, 2);
				world.setBlock(x + 3, y + 0, z - 2, block2, 4, 2);
				world.setBlock(x + 3, y + 1, z - 2, block2, 4, 2);
				world.setBlock(x + 3, y + 2, z - 2, block1, 2, 2);
				world.setBlock(x + 3, y + 2, z + 2, block1, 6, 2);
				world.setBlock(x + 3, y + 2, z + 3, block2, 4, 2);
				world.setBlock(x + 3, y + 2, z + 4, block2, 4, 2);
				world.setBlock(x + 3, y + 3, z - 1, block2, 4, 2);
				world.setBlock(x + 3, y + 3, z + 0, block2, 4, 2);
				world.setBlock(x + 3, y + 3, z + 1, block2, 4, 2);
				world.setBlock(x + 3, y + 3, z + 2, block1, 3, 2);
				world.setBlock(x + 4, y - 3, z + 0, block2, 0, 2);
				world.setBlock(x + 4, y - 2, z - 2, block1, 6, 2);
				world.setBlock(x + 4, y - 2, z - 1, block2, 4, 2);
				world.setBlock(x + 4, y - 2, z + 0, block2, 4, 2);
				world.setBlock(x + 4, y - 2, z + 1, block2, 4, 2);
				world.setBlock(x + 4, y - 2, z + 2, block2, 4, 2);
				world.setBlock(x + 4, y - 2, z + 3, block2, 4, 2);
				world.setBlock(x + 4, y - 2, z + 4, block2, 4, 2);
				world.setBlock(x + 4, y - 1, z - 2, block2, 4, 2);
				world.setBlock(x + 4, y + 0, z - 2, block5, 0, 2);
				world.setBlock(x + 4, y + 1, z - 2, block2, 4, 2);
				world.setBlock(x + 4, y + 2, z - 2, block1, 2, 2);
				world.setBlock(x + 4, y + 2, z - 1, block6, 2, 2);
				world.setBlock(x + 4, y + 2, z + 2, block1, 6, 2);
				world.setBlock(x + 4, y + 2, z + 3, block2, 4, 2);
				world.setBlock(x + 4, y + 2, z + 4, block2, 4, 2);
				world.setBlock(x + 4, y + 3, z - 1, block2, 4, 2);
				world.setBlock(x + 4, y + 3, z + 0, block5, 0, 2);
				world.setBlock(x + 4, y + 3, z + 1, block2, 4, 2);
				world.setBlock(x + 4, y + 3, z + 2, block1, 3, 2);
				world.setBlock(x + 5, y - 2, z - 2, block1, 6, 2);
				world.setBlock(x + 5, y - 2, z - 1, block2, 4, 2);
				world.setBlock(x + 5, y - 2, z + 0, block2, 4, 2);
				world.setBlock(x + 5, y - 2, z + 1, block2, 4, 2);
				world.setBlock(x + 5, y - 2, z + 2, block2, 4, 2);
				world.setBlock(x + 5, y - 2, z + 3, block2, 4, 2);
				world.setBlock(x + 5, y - 2, z + 4, block2, 4, 2);
				world.setBlock(x + 5, y - 1, z - 2, block2, 4, 2);
				world.setBlock(x + 5, y + 0, z - 2, block2, 4, 2);
				world.setBlock(x + 5, y + 1, z - 2, block2, 4, 2);
				world.setBlock(x + 5, y + 2, z - 2, block1, 2, 2);
				world.setBlock(x + 5, y + 2, z + 2, block1, 6, 2);
				world.setBlock(x + 5, y + 2, z + 3, block2, 4, 2);
				world.setBlock(x + 5, y + 2, z + 4, block2, 4, 2);
				world.setBlock(x + 5, y + 3, z - 1, block2, 4, 2);
				world.setBlock(x + 5, y + 3, z + 0, block2, 4, 2);
				world.setBlock(x + 5, y + 3, z + 1, block2, 4, 2);
				world.setBlock(x + 5, y + 3, z + 2, block1, 3, 2);
				world.setBlock(x + 6, y - 2, z - 2, block1, 6, 2);
				world.setBlock(x + 6, y - 2, z - 1, block2, 4, 2);
				world.setBlock(x + 6, y - 2, z + 0, block2, 4, 2);
				world.setBlock(x + 6, y - 2, z + 1, block2, 4, 2);
				world.setBlock(x + 6, y - 2, z + 2, block2, 4, 2);
				world.setBlock(x + 6, y - 2, z + 3, block1, 5, 2);
				world.setBlock(x + 6, y - 2, z + 4, block1, 5, 2);
				world.setBlock(x + 6, y - 1, z - 2, block2, 4, 2);
				world.setBlock(x + 6, y - 1, z + 2, block3, 0, 2);
				world.setBlock(x + 6, y - 1, z + 3, block2, 4, 2);
				world.setBlock(x + 6, y - 1, z + 4, block2, 4, 2);
				world.setBlock(x + 6, y + 0, z - 2, block2, 4, 2);
				world.setBlock(x + 6, y + 0, z - 1, block2, 0, 2);
				world.setBlock(x + 6, y + 0, z + 3, block2, 4, 2);
				world.setBlock(x + 6, y + 0, z + 4, block2, 4, 2);
				world.setBlock(x + 6, y + 1, z - 2, block2, 4, 2);
				world.setBlock(x + 6, y + 1, z + 2, block3, 8, 2);
				world.setBlock(x + 6, y + 1, z + 3, block2, 4, 2);
				world.setBlock(x + 6, y + 1, z + 4, block2, 4, 2);
				world.setBlock(x + 6, y + 2, z - 2, block1, 2, 2);
				world.setBlock(x + 6, y + 2, z - 1, block1, 4, 2);
				world.setBlock(x + 6, y + 2, z + 0, block1, 4, 2);
				world.setBlock(x + 6, y + 2, z + 1, block1, 4, 2);
				world.setBlock(x + 6, y + 2, z + 2, block2, 4, 2);
				world.setBlock(x + 6, y + 2, z + 3, block1, 1, 2);
				world.setBlock(x + 6, y + 2, z + 4, block1, 1, 2);
				world.setBlock(x + 6, y + 3, z - 1, block1, 1, 2);
				world.setBlock(x + 6, y + 3, z + 0, block1, 1, 2);
				world.setBlock(x + 6, y + 3, z + 1, block1, 1, 2);
				world.setBlock(x + 7, y - 2, z - 2, block1, 6, 2);
				world.setBlock(x + 7, y - 2, z - 1, block2, 4, 2);
				world.setBlock(x + 7, y - 2, z + 0, block2, 4, 2);
				world.setBlock(x + 7, y - 2, z + 1, block2, 4, 2);
				world.setBlock(x + 7, y - 2, z + 2, block1, 7, 2);
				world.setBlock(x + 7, y - 1, z - 2, block2, 4, 2);
				world.setBlock(x + 7, y - 1, z + 2, block2, 4, 2);
				world.setBlock(x + 7, y + 0, z - 2, block2, 4, 2);
				world.setBlock(x + 7, y + 0, z + 2, block2, 4, 2);
				world.setBlock(x + 7, y + 1, z - 2, block2, 4, 2);
				world.setBlock(x + 7, y + 1, z + 2, block2, 4, 2);
				world.setBlock(x + 7, y + 2, z - 2, block1, 2, 2);
				world.setBlock(x + 7, y + 2, z - 1, block2, 4, 2);
				world.setBlock(x + 7, y + 2, z + 0, block2, 4, 2);
				world.setBlock(x + 7, y + 2, z + 1, block2, 4, 2);
				world.setBlock(x + 7, y + 2, z + 2, block1, 3, 2);
				world.setBlock(x + 8, y - 2, z - 2, block1, 6, 2);
				world.setBlock(x + 8, y - 2, z - 1, block2, 4, 2);
				world.setBlock(x + 8, y - 2, z + 0, block2, 4, 2);
				world.setBlock(x + 8, y - 2, z + 1, block2, 4, 2);
				world.setBlock(x + 8, y - 2, z + 2, block1, 7, 2);
				world.setBlock(x + 8, y - 1, z - 2, block2, 4, 2);
				world.setBlock(x + 8, y - 1, z + 2, block2, 4, 2);
				world.setBlock(x + 8, y + 0, z - 2, block2, 4, 2);
				world.setBlock(x + 8, y + 0, z + 2, block2, 4, 2);
				world.setBlock(x + 8, y + 1, z - 2, block2, 4, 2);
				world.setBlock(x + 8, y + 1, z + 2, block2, 4, 2);
				world.setBlock(x + 8, y + 2, z - 2, block1, 2, 2);
				world.setBlock(x + 8, y + 2, z - 1, block2, 4, 2);
				world.setBlock(x + 8, y + 2, z + 0, block2, 4, 2);
				world.setBlock(x + 8, y + 2, z + 1, block2, 4, 2);
				world.setBlock(x + 8, y + 2, z + 2, block1, 3, 2);
				
			}
		} else if (dir == ForgeDirection.SOUTH)
		{
			if (rot == 3)
			{
				
				world.setBlock(x - 4, y - 2, z + 2, block1, 6, 2);
				
				world.setBlock(x - 4, y - 2, z + 3, block2, 4, 2);
				world.setBlock(x - 4, y - 2, z + 4, block2, 4, 2);
				world.setBlock(x - 4, y - 2, z + 5, block2, 4, 2);
				world.setBlock(x - 4, y - 2, z + 6, block1, 7, 2);
				world.setBlock(x - 4, y - 1, z + 2, block2, 4, 2);
				world.setBlock(x - 4, y - 1, z + 6, block2, 4, 2);
				world.setBlock(x - 4, y + 0, z + 2, block2, 4, 2);
				world.setBlock(x - 4, y + 0, z + 6, block2, 4, 2);
				world.setBlock(x - 4, y + 1, z + 2, block2, 4, 2);
				world.setBlock(x - 4, y + 1, z + 6, block2, 4, 2);
				world.setBlock(x - 4, y + 2, z + 2, block1, 2, 2);
				world.setBlock(x - 4, y + 2, z + 3, block2, 4, 2);
				world.setBlock(x - 4, y + 2, z + 4, block2, 4, 2);
				world.setBlock(x - 4, y + 2, z + 5, block2, 4, 2);
				world.setBlock(x - 4, y + 2, z + 6, block1, 3, 2);
				world.setBlock(x - 3, y - 2, z + 2, block1, 6, 2);
				world.setBlock(x - 3, y - 2, z + 3, block2, 4, 2);
				world.setBlock(x - 3, y - 2, z + 4, block2, 4, 2);
				world.setBlock(x - 3, y - 2, z + 5, block2, 4, 2);
				world.setBlock(x - 3, y - 2, z + 6, block1, 7, 2);
				world.setBlock(x - 3, y - 1, z + 2, block2, 4, 2);
				world.setBlock(x - 3, y - 1, z + 6, block2, 4, 2);
				world.setBlock(x - 3, y + 0, z + 2, block2, 4, 2);
				world.setBlock(x - 3, y + 0, z + 6, block2, 4, 2);
				world.setBlock(x - 3, y + 1, z + 2, block2, 4, 2);
				world.setBlock(x - 3, y + 1, z + 6, block2, 4, 2);
				world.setBlock(x - 3, y + 2, z + 2, block1, 2, 2);
				world.setBlock(x - 3, y + 2, z + 3, block2, 4, 2);
				world.setBlock(x - 3, y + 2, z + 4, block2, 4, 2);
				world.setBlock(x - 3, y + 2, z + 5, block2, 4, 2);
				world.setBlock(x - 3, y + 2, z + 6, block1, 3, 2);
				world.setBlock(x - 2, y - 2, z + 0, block1, 4, 2);
				world.setBlock(x - 2, y - 2, z + 1, block1, 4, 2);
				world.setBlock(x - 2, y - 2, z + 2, block2, 4, 2);
				world.setBlock(x - 2, y - 2, z + 3, block2, 4, 2);
				world.setBlock(x - 2, y - 2, z + 4, block2, 4, 2);
				world.setBlock(x - 2, y - 2, z + 5, block2, 4, 2);
				world.setBlock(x - 2, y - 2, z + 6, block2, 4, 2);
				world.setBlock(x - 2, y - 2, z + 7, block1, 4, 2);
				world.setBlock(x - 2, y - 2, z + 8, block1, 4, 2);
				world.setBlock(x - 2, y - 1, z + 0, block2, 4, 2);
				world.setBlock(x - 2, y - 1, z + 1, block2, 4, 2);
				
				world.setBlock(x - 2, y - 1, z + 2, block3, 0, 2);
				world.setBlock(x - 2, y - 1, z + 6, block3, 0, 2);
				world.setBlock(x - 2, y - 1, z + 7, block2, 4, 2);
				world.setBlock(x - 2, y - 1, z + 8, block2, 4, 2);
				world.setBlock(x - 2, y + 0, z + 0, block2, 4, 2);
				world.setBlock(x - 2, y + 0, z + 1, block2, 4, 2);
				world.setBlock(x - 2, y + 0, z + 7, block2, 4, 2);
				world.setBlock(x - 2, y + 0, z + 8, block2, 4, 2);
				world.setBlock(x - 2, y + 1, z + 0, block2, 4, 2);
				world.setBlock(x - 2, y + 1, z + 1, block2, 4, 2);
				world.setBlock(x - 2, y + 1, z + 2, block3, 8, 2);
				world.setBlock(x - 2, y + 1, z + 6, block3, 8, 2);
				world.setBlock(x - 2, y + 1, z + 7, block2, 4, 2);
				world.setBlock(x - 2, y + 1, z + 8, block2, 4, 2);
				world.setBlock(x - 2, y + 2, z + 0, block1, 0, 2);
				world.setBlock(x - 2, y + 2, z + 1, block1, 0, 2);
				world.setBlock(x - 2, y + 2, z + 2, block2, 4, 2);
				world.setBlock(x - 2, y + 2, z + 3, block1, 5, 2);
				world.setBlock(x - 2, y + 2, z + 4, block1, 5, 2);
				world.setBlock(x - 2, y + 2, z + 5, block1, 5, 2);
				world.setBlock(x - 2, y + 2, z + 6, block2, 4, 2);
				world.setBlock(x - 2, y + 2, z + 7, block1, 0, 2);
				world.setBlock(x - 2, y + 2, z + 8, block1, 0, 2);
				world.setBlock(x - 2, y + 3, z + 3, block1, 0, 2);
				world.setBlock(x - 2, y + 3, z + 4, block1, 0, 2);
				world.setBlock(x - 2, y + 3, z + 5, block1, 0, 2);
				world.setBlock(x - 1, y - 2, z + 0, block2, 4, 2);
				world.setBlock(x - 1, y - 2, z + 1, block2, 4, 2);
				world.setBlock(x - 1, y - 2, z + 2, block2, 4, 2);
				world.setBlock(x - 1, y - 2, z + 3, block2, 4, 2);
				world.setBlock(x - 1, y - 2, z + 4, block2, 4, 2);
				world.setBlock(x - 1, y - 2, z + 5, block2, 4, 2);
				world.setBlock(x - 1, y - 2, z + 6, block2, 4, 2);
				world.setBlock(x - 1, y - 2, z + 7, block2, 4, 2);
				world.setBlock(x - 1, y - 2, z + 8, block2, 4, 2);
				world.setBlock(x - 1, y + 2, z + 0, block2, 4, 2);
				world.setBlock(x - 1, y + 2, z + 1, block2, 4, 2);
				world.setBlock(x - 1, y + 2, z + 2, block1, 7, 2);
				world.setBlock(x - 1, y + 2, z + 6, block1, 6, 2);
				world.setBlock(x - 1, y + 2, z + 7, block2, 4, 2);
				world.setBlock(x - 1, y + 2, z + 8, block2, 4, 2);
				world.setBlock(x - 1, y + 3, z + 2, block1, 2, 2);
				world.setBlock(x - 1, y + 3, z + 3, block2, 4, 2);
				world.setBlock(x - 1, y + 3, z + 4, block2, 4, 2);
				world.setBlock(x - 1, y + 3, z + 5, block2, 4, 2);
				world.setBlock(x - 1, y + 3, z + 6, block1, 3, 2);
				world.setBlock(x + 0, y - 3, z + 4, block2, 0, 2);
				
				world.setBlock(x + 1, y + 0, z + 6, block2, 0, 2);
				world.setBlock(x + 0, y - 2, z + 0, block2, 4, 2);
				world.setBlock(x + 0, y - 2, z + 1, block2, 4, 2);
				world.setBlock(x + 0, y - 2, z + 2, block2, 4, 2);
				world.setBlock(x + 0, y - 2, z + 3, block2, 4, 2);
				world.setBlock(x + 0, y - 2, z + 4, block2, 4, 2);
				world.setBlock(x + 0, y - 2, z + 5, block2, 4, 2);
				world.setBlock(x + 0, y - 2, z + 6, block2, 4, 2);
				world.setBlock(x + 0, y - 2, z + 7, block2, 4, 2);
				world.setBlock(x + 0, y - 2, z + 8, block2, 4, 2);
				world.setBlock(x + 0, y + 2, z + 0, block2, 4, 2);
				world.setBlock(x + 0, y + 2, z + 1, block2, 4, 2);
				world.setBlock(x + 0, y + 2, z + 2, block1, 7, 2);
				world.setBlock(x + 0, y + 2, z + 6, block1, 6, 2);
				world.setBlock(x + 0, y + 2, z + 7, block2, 4, 2);
				world.setBlock(x + 0, y + 2, z + 8, block2, 4, 2);
				world.setBlock(x + 0, y + 3, z + 2, block1, 2, 2);
				world.setBlock(x + 0, y + 3, z + 3, block2, 4, 2);
				world.setBlock(x + 0, y + 3, z + 4, block5, 0, 2);
				world.setBlock(x + 0, y + 3, z + 5, block2, 4, 2);
				world.setBlock(x + 0, y + 3, z + 6, block1, 3, 2);
				world.setBlock(x + 1, y - 2, z + 0, block2, 4, 2);
				world.setBlock(x + 1, y - 2, z + 1, block2, 4, 2);
				world.setBlock(x + 1, y - 2, z + 2, block2, 4, 2);
				world.setBlock(x + 1, y - 2, z + 3, block2, 4, 2);
				world.setBlock(x + 1, y - 2, z + 4, block2, 4, 2);
				world.setBlock(x + 1, y - 2, z + 5, block2, 4, 2);
				world.setBlock(x + 1, y - 2, z + 6, block2, 4, 2);
				world.setBlock(x + 1, y - 2, z + 7, block2, 4, 2);
				world.setBlock(x + 1, y - 2, z + 8, block2, 4, 2);
				world.setBlock(x + 1, y + 2, z + 0, block2, 4, 2);
				world.setBlock(x + 1, y + 2, z + 1, block2, 4, 2);
				world.setBlock(x + 1, y + 2, z + 2, block1, 7, 2);
				world.setBlock(x + 1, y + 2, z + 4, block6, 5, 2);
				world.setBlock(x + 1, y + 2, z + 6, block1, 6, 2);
				world.setBlock(x + 1, y + 2, z + 7, block2, 4, 2);
				world.setBlock(x + 1, y + 2, z + 8, block2, 4, 2);
				world.setBlock(x + 1, y + 3, z + 2, block1, 2, 2);
				world.setBlock(x + 1, y + 3, z + 3, block2, 4, 2);
				world.setBlock(x + 1, y + 3, z + 4, block2, 4, 2);
				world.setBlock(x + 1, y + 3, z + 5, block2, 4, 2);
				world.setBlock(x + 1, y + 3, z + 6, block1, 3, 2);
				world.setBlock(x + 2, y - 2, z + 0, block1, 5, 2);
				world.setBlock(x + 2, y - 2, z + 1, block1, 5, 2);
				world.setBlock(x + 2, y - 2, z + 2, block1, 5, 2);
				world.setBlock(x + 2, y - 2, z + 3, block1, 5, 2);
				world.setBlock(x + 2, y - 2, z + 4, block1, 5, 2);
				world.setBlock(x + 2, y - 2, z + 5, block1, 5, 2);
				world.setBlock(x + 2, y - 2, z + 6, block1, 5, 2);
				world.setBlock(x + 2, y - 2, z + 7, block1, 5, 2);
				world.setBlock(x + 2, y - 2, z + 8, block1, 5, 2);
				world.setBlock(x + 2, y - 1, z + 0, block2, 4, 2);
				world.setBlock(x + 2, y - 1, z + 1, block2, 4, 2);
				world.setBlock(x + 2, y - 1, z + 2, block2, 4, 2);
				world.setBlock(x + 2, y - 1, z + 3, block2, 4, 2);
				world.setBlock(x + 2, y - 1, z + 4, block2, 4, 2);
				world.setBlock(x + 2, y - 1, z + 5, block2, 4, 2);
				world.setBlock(x + 2, y - 1, z + 6, block2, 4, 2);
				world.setBlock(x + 2, y - 1, z + 7, block2, 4, 2);
				world.setBlock(x + 2, y - 1, z + 8, block2, 4, 2);
				world.setBlock(x + 2, y + 0, z + 0, block2, 4, 2);
				world.setBlock(x + 2, y + 0, z + 1, block2, 4, 2);
				world.setBlock(x + 2, y + 0, z + 2, block2, 4, 2);
				world.setBlock(x + 2, y + 0, z + 3, block2, 4, 2);
				world.setBlock(x + 2, y + 0, z + 4, block5, 0, 2);
				world.setBlock(x + 2, y + 0, z + 5, block2, 4, 2);
				world.setBlock(x + 2, y + 0, z + 6, block2, 4, 2);
				world.setBlock(x + 2, y + 0, z + 7, block2, 4, 2);
				world.setBlock(x + 2, y + 0, z + 8, block2, 4, 2);
				world.setBlock(x + 2, y + 1, z + 0, block2, 4, 2);
				world.setBlock(x + 2, y + 1, z + 1, block2, 4, 2);
				world.setBlock(x + 2, y + 1, z + 2, block2, 4, 2);
				world.setBlock(x + 2, y + 1, z + 3, block2, 4, 2);
				world.setBlock(x + 2, y + 1, z + 4, block2, 4, 2);
				world.setBlock(x + 2, y + 1, z + 5, block2, 4, 2);
				world.setBlock(x + 2, y + 1, z + 6, block2, 4, 2);
				world.setBlock(x + 2, y + 1, z + 7, block2, 4, 2);
				world.setBlock(x + 2, y + 1, z + 8, block2, 4, 2);
				world.setBlock(x + 2, y + 2, z + 0, block1, 1, 2);
				world.setBlock(x + 2, y + 2, z + 1, block1, 1, 2);
				world.setBlock(x + 2, y + 2, z + 2, block1, 1, 2);
				world.setBlock(x + 2, y + 2, z + 3, block1, 1, 2);
				world.setBlock(x + 2, y + 2, z + 4, block1, 1, 2);
				world.setBlock(x + 2, y + 2, z + 5, block1, 1, 2);
				world.setBlock(x + 2, y + 2, z + 6, block1, 1, 2);
				world.setBlock(x + 2, y + 2, z + 7, block1, 1, 2);
				world.setBlock(x + 2, y + 2, z + 8, block1, 1, 2);
				
			} else if (rot == 1)
			{
				
				world.setBlock(x - 2, y - 2, z + 0, block1, 4, 2);
				world.setBlock(x - 2, y - 2, z + 1, block1, 4, 2);
				world.setBlock(x - 2, y - 2, z + 2, block1, 4, 2);
				world.setBlock(x - 2, y - 2, z + 3, block1, 4, 2);
				world.setBlock(x - 2, y - 2, z + 4, block1, 4, 2);
				world.setBlock(x - 2, y - 2, z + 5, block1, 4, 2);
				world.setBlock(x - 2, y - 2, z + 6, block1, 4, 2);
				world.setBlock(x - 2, y - 2, z + 7, block1, 4, 2);
				world.setBlock(x - 2, y - 2, z + 8, block1, 4, 2);
				
				world.setBlock(x - 2, y - 1, z + 0, block2, 4, 2);
				world.setBlock(x - 2, y - 1, z + 1, block2, 4, 2);
				world.setBlock(x - 2, y - 1, z + 2, block2, 4, 2);
				world.setBlock(x - 2, y - 1, z + 3, block2, 4, 2);
				world.setBlock(x - 2, y - 1, z + 4, block2, 4, 2);
				world.setBlock(x - 2, y - 1, z + 5, block2, 4, 2);
				world.setBlock(x - 2, y - 1, z + 6, block2, 4, 2);
				world.setBlock(x - 2, y - 1, z + 7, block2, 4, 2);
				world.setBlock(x - 2, y - 1, z + 8, block2, 4, 2);
				world.setBlock(x - 2, y + 0, z + 0, block2, 4, 2);
				world.setBlock(x - 2, y + 0, z + 1, block2, 4, 2);
				world.setBlock(x - 2, y + 0, z + 2, block2, 4, 2);
				world.setBlock(x - 2, y + 0, z + 3, block2, 4, 2);
				
				world.setBlock(x - 2, y + 0, z + 4, block3, 0, 2);
				world.setBlock(x - 2, y + 0, z + 5, block2, 4, 2);
				world.setBlock(x - 2, y + 0, z + 6, block2, 4, 2);
				world.setBlock(x - 2, y + 0, z + 7, block2, 4, 2);
				world.setBlock(x - 2, y + 0, z + 8, block2, 4, 2);
				world.setBlock(x - 2, y + 1, z + 0, block2, 4, 2);
				world.setBlock(x - 2, y + 1, z + 1, block2, 4, 2);
				world.setBlock(x - 2, y + 1, z + 2, block2, 4, 2);
				world.setBlock(x - 2, y + 1, z + 3, block2, 4, 2);
				world.setBlock(x - 2, y + 1, z + 4, block2, 4, 2);
				world.setBlock(x - 2, y + 1, z + 5, block2, 4, 2);
				world.setBlock(x - 2, y + 1, z + 6, block2, 4, 2);
				world.setBlock(x - 2, y + 1, z + 7, block2, 4, 2);
				world.setBlock(x - 2, y + 1, z + 8, block2, 4, 2);
				world.setBlock(x - 2, y + 2, z + 0, block1, 0, 2);
				world.setBlock(x - 2, y + 2, z + 1, block1, 0, 2);
				world.setBlock(x - 2, y + 2, z + 2, block1, 0, 2);
				world.setBlock(x - 2, y + 2, z + 3, block1, 0, 2);
				world.setBlock(x - 2, y + 2, z + 4, block1, 0, 2);
				world.setBlock(x - 2, y + 2, z + 5, block1, 0, 2);
				world.setBlock(x - 2, y + 2, z + 6, block1, 0, 2);
				world.setBlock(x - 2, y + 2, z + 7, block1, 0, 2);
				world.setBlock(x - 2, y + 2, z + 8, block1, 0, 2);
				world.setBlock(x - 1, y - 2, z + 0, block2, 4, 2);
				world.setBlock(x - 1, y - 2, z + 1, block2, 4, 2);
				world.setBlock(x - 1, y - 2, z + 2, block2, 4, 2);
				world.setBlock(x - 1, y - 2, z + 3, block2, 4, 2);
				world.setBlock(x - 1, y - 2, z + 4, block2, 4, 2);
				world.setBlock(x - 1, y - 2, z + 5, block2, 4, 2);
				world.setBlock(x - 1, y - 2, z + 6, block2, 4, 2);
				world.setBlock(x - 1, y - 2, z + 7, block2, 4, 2);
				world.setBlock(x - 1, y - 2, z + 8, block2, 4, 2);
				
				world.setBlock(x + 0, y - 3, z + 4, block2, 0, 2);
				world.setBlock(x - 1, y + 0, z + 2, block2, 0, 2);
				world.setBlock(x - 1, y + 2, z + 0, block2, 4, 2);
				world.setBlock(x - 1, y + 2, z + 1, block2, 4, 2);
				world.setBlock(x - 1, y + 2, z + 2, block1, 7, 2);
				world.setBlock(x - 1, y + 2, z + 4, block6, 4, 2);
				world.setBlock(x - 1, y + 2, z + 6, block1, 6, 2);
				world.setBlock(x - 1, y + 2, z + 7, block2, 4, 2);
				world.setBlock(x - 1, y + 2, z + 8, block2, 4, 2);
				world.setBlock(x - 1, y + 3, z + 2, block1, 2, 2);
				world.setBlock(x - 1, y + 3, z + 3, block2, 4, 2);
				world.setBlock(x - 1, y + 3, z + 4, block2, 4, 2);
				world.setBlock(x - 1, y + 3, z + 5, block2, 4, 2);
				world.setBlock(x - 1, y + 3, z + 6, block1, 3, 2);
				world.setBlock(x + 0, y - 2, z + 0, block2, 4, 2);
				world.setBlock(x + 0, y - 2, z + 1, block2, 4, 2);
				world.setBlock(x + 0, y - 2, z + 2, block2, 4, 2);
				world.setBlock(x + 0, y - 2, z + 3, block2, 4, 2);
				world.setBlock(x + 0, y - 2, z + 4, block2, 4, 2);
				world.setBlock(x + 0, y - 2, z + 5, block2, 4, 2);
				world.setBlock(x + 0, y - 2, z + 6, block2, 4, 2);
				world.setBlock(x + 0, y - 2, z + 7, block2, 4, 2);
				world.setBlock(x + 0, y - 2, z + 8, block2, 4, 2);
				world.setBlock(x + 0, y + 2, z + 0, block2, 4, 2);
				world.setBlock(x + 0, y + 2, z + 1, block2, 4, 2);
				world.setBlock(x + 0, y + 2, z + 2, block1, 7, 2);
				world.setBlock(x + 0, y + 2, z + 6, block1, 6, 2);
				world.setBlock(x + 0, y + 2, z + 7, block2, 4, 2);
				world.setBlock(x + 0, y + 2, z + 8, block2, 4, 2);
				world.setBlock(x + 0, y + 3, z + 2, block1, 2, 2);
				world.setBlock(x + 0, y + 3, z + 3, block2, 4, 2);
				world.setBlock(x + 0, y + 3, z + 4, block3, 0, 2);
				world.setBlock(x + 0, y + 3, z + 5, block2, 4, 2);
				world.setBlock(x + 0, y + 3, z + 6, block1, 3, 2);
				world.setBlock(x + 1, y - 2, z + 0, block2, 4, 2);
				world.setBlock(x + 1, y - 2, z + 1, block2, 4, 2);
				world.setBlock(x + 1, y - 2, z + 2, block2, 4, 2);
				world.setBlock(x + 1, y - 2, z + 3, block2, 4, 2);
				world.setBlock(x + 1, y - 2, z + 4, block2, 4, 2);
				world.setBlock(x + 1, y - 2, z + 5, block2, 4, 2);
				world.setBlock(x + 1, y - 2, z + 6, block2, 4, 2);
				world.setBlock(x + 1, y - 2, z + 7, block2, 4, 2);
				world.setBlock(x + 1, y - 2, z + 8, block2, 4, 2);
				world.setBlock(x + 1, y + 2, z + 0, block2, 4, 2);
				world.setBlock(x + 1, y + 2, z + 1, block2, 4, 2);
				world.setBlock(x + 1, y + 2, z + 2, block1, 7, 2);
				world.setBlock(x + 1, y + 2, z + 6, block1, 6, 2);
				world.setBlock(x + 1, y + 2, z + 7, block2, 4, 2);
				world.setBlock(x + 1, y + 2, z + 8, block2, 4, 2);
				world.setBlock(x + 1, y + 3, z + 2, block1, 2, 2);
				world.setBlock(x + 1, y + 3, z + 3, block2, 4, 2);
				world.setBlock(x + 1, y + 3, z + 4, block2, 4, 2);
				world.setBlock(x + 1, y + 3, z + 5, block2, 4, 2);
				world.setBlock(x + 1, y + 3, z + 6, block1, 3, 2);
				world.setBlock(x + 2, y - 2, z + 0, block1, 5, 2);
				world.setBlock(x + 2, y - 2, z + 1, block1, 5, 2);
				world.setBlock(x + 2, y - 2, z + 2, block2, 4, 2);
				world.setBlock(x + 2, y - 2, z + 3, block2, 4, 2);
				world.setBlock(x + 2, y - 2, z + 4, block2, 4, 2);
				world.setBlock(x + 2, y - 2, z + 5, block2, 4, 2);
				world.setBlock(x + 2, y - 2, z + 6, block2, 4, 2);
				world.setBlock(x + 2, y - 2, z + 7, block1, 5, 2);
				world.setBlock(x + 2, y - 2, z + 8, block1, 5, 2);
				world.setBlock(x + 2, y - 1, z + 0, block2, 4, 2);
				world.setBlock(x + 2, y - 1, z + 1, block2, 4, 2);
				world.setBlock(x + 2, y - 1, z + 2, block7, 0, 2);
				world.setBlock(x + 2, y - 1, z + 6, block7, 0, 2);
				world.setBlock(x + 2, y - 1, z + 7, block2, 4, 2);
				world.setBlock(x + 2, y - 1, z + 8, block2, 4, 2);
				world.setBlock(x + 2, y + 0, z + 0, block2, 4, 2);
				world.setBlock(x + 2, y + 0, z + 1, block2, 4, 2);
				world.setBlock(x + 2, y + 0, z + 7, block2, 4, 2);
				world.setBlock(x + 2, y + 0, z + 8, block2, 4, 2);
				world.setBlock(x + 2, y + 1, z + 0, block2, 4, 2);
				world.setBlock(x + 2, y + 1, z + 1, block2, 4, 2);
				world.setBlock(x + 2, y + 1, z + 2, block7, 8, 2);
				world.setBlock(x + 2, y + 1, z + 6, block7, 8, 2);
				world.setBlock(x + 2, y + 1, z + 7, block2, 4, 2);
				world.setBlock(x + 2, y + 1, z + 8, block2, 4, 2);
				world.setBlock(x + 2, y + 2, z + 0, block1, 1, 2);
				world.setBlock(x + 2, y + 2, z + 1, block1, 1, 2);
				world.setBlock(x + 2, y + 2, z + 2, block2, 4, 2);
				world.setBlock(x + 2, y + 2, z + 3, block1, 4, 2);
				world.setBlock(x + 2, y + 2, z + 4, block1, 4, 2);
				world.setBlock(x + 2, y + 2, z + 5, block1, 4, 2);
				world.setBlock(x + 2, y + 2, z + 6, block2, 4, 2);
				world.setBlock(x + 2, y + 2, z + 7, block1, 1, 2);
				world.setBlock(x + 2, y + 2, z + 8, block1, 1, 2);
				world.setBlock(x + 2, y + 3, z + 3, block1, 1, 2);
				world.setBlock(x + 2, y + 3, z + 4, block1, 1, 2);
				world.setBlock(x + 2, y + 3, z + 5, block1, 1, 2);
				world.setBlock(x + 3, y - 2, z + 2, block1, 6, 2);
				world.setBlock(x + 3, y - 2, z + 3, block2, 4, 2);
				world.setBlock(x + 3, y - 2, z + 4, block2, 4, 2);
				world.setBlock(x + 3, y - 2, z + 5, block2, 4, 2);
				world.setBlock(x + 3, y - 2, z + 6, block1, 7, 2);
				world.setBlock(x + 3, y - 1, z + 2, block2, 4, 2);
				world.setBlock(x + 3, y - 1, z + 6, block2, 4, 2);
				world.setBlock(x + 3, y + 0, z + 2, block2, 4, 2);
				world.setBlock(x + 3, y + 0, z + 6, block2, 4, 2);
				world.setBlock(x + 3, y + 1, z + 2, block2, 4, 2);
				world.setBlock(x + 3, y + 1, z + 6, block2, 4, 2);
				world.setBlock(x + 3, y + 2, z + 2, block1, 2, 2);
				world.setBlock(x + 3, y + 2, z + 3, block2, 4, 2);
				world.setBlock(x + 3, y + 2, z + 4, block2, 4, 2);
				world.setBlock(x + 3, y + 2, z + 5, block2, 4, 2);
				world.setBlock(x + 3, y + 2, z + 6, block1, 3, 2);
				world.setBlock(x + 4, y - 2, z + 2, block1, 6, 2);
				world.setBlock(x + 4, y - 2, z + 3, block2, 4, 2);
				world.setBlock(x + 4, y - 2, z + 4, block2, 4, 2);
				world.setBlock(x + 4, y - 2, z + 5, block2, 4, 2);
				world.setBlock(x + 4, y - 2, z + 6, block1, 7, 2);
				world.setBlock(x + 4, y - 1, z + 2, block2, 4, 2);
				world.setBlock(x + 4, y - 1, z + 6, block2, 4, 2);
				world.setBlock(x + 4, y + 0, z + 2, block2, 4, 2);
				world.setBlock(x + 4, y + 0, z + 6, block2, 4, 2);
				world.setBlock(x + 4, y + 1, z + 2, block2, 4, 2);
				world.setBlock(x + 4, y + 1, z + 6, block2, 4, 2);
				world.setBlock(x + 4, y + 2, z + 2, block1, 2, 2);
				world.setBlock(x + 4, y + 2, z + 3, block2, 4, 2);
				world.setBlock(x + 4, y + 2, z + 4, block2, 4, 2);
				world.setBlock(x + 4, y + 2, z + 5, block2, 4, 2);
				world.setBlock(x + 4, y + 2, z + 6, block1, 3, 2);
				
			} else if (rot == 0)
			{
				
				world.setBlock(x - 4, y - 2, z + 2, block1, 6, 2);
				
				world.setBlock(x - 4, y - 2, z + 3, block2, 4, 2);
				world.setBlock(x - 4, y - 2, z + 4, block2, 4, 2);
				world.setBlock(x - 4, y - 2, z + 5, block2, 4, 2);
				world.setBlock(x - 4, y - 2, z + 6, block1, 7, 2);
				world.setBlock(x - 4, y - 1, z + 2, block2, 4, 2);
				world.setBlock(x - 4, y - 1, z + 6, block2, 4, 2);
				world.setBlock(x - 4, y + 0, z + 2, block2, 4, 2);
				world.setBlock(x - 4, y + 0, z + 6, block2, 4, 2);
				world.setBlock(x - 4, y + 1, z + 2, block2, 4, 2);
				world.setBlock(x - 4, y + 1, z + 6, block2, 4, 2);
				world.setBlock(x - 4, y + 2, z + 2, block1, 2, 2);
				world.setBlock(x - 4, y + 2, z + 3, block2, 4, 2);
				world.setBlock(x - 4, y + 2, z + 4, block2, 4, 2);
				world.setBlock(x - 4, y + 2, z + 5, block2, 4, 2);
				world.setBlock(x - 4, y + 2, z + 6, block1, 3, 2);
				world.setBlock(x - 3, y - 2, z + 2, block1, 6, 2);
				world.setBlock(x - 3, y - 2, z + 3, block2, 4, 2);
				world.setBlock(x - 3, y - 2, z + 4, block2, 4, 2);
				world.setBlock(x - 3, y - 2, z + 5, block2, 4, 2);
				world.setBlock(x - 3, y - 2, z + 6, block1, 7, 2);
				world.setBlock(x - 3, y - 1, z + 2, block2, 4, 2);
				world.setBlock(x - 3, y - 1, z + 6, block2, 4, 2);
				world.setBlock(x - 3, y + 0, z + 2, block2, 4, 2);
				world.setBlock(x - 3, y + 0, z + 6, block2, 4, 2);
				world.setBlock(x - 3, y + 1, z + 2, block2, 4, 2);
				world.setBlock(x - 3, y + 1, z + 6, block2, 4, 2);
				world.setBlock(x - 3, y + 2, z + 2, block1, 2, 2);
				world.setBlock(x - 3, y + 2, z + 3, block2, 4, 2);
				world.setBlock(x - 3, y + 2, z + 4, block2, 4, 2);
				world.setBlock(x - 3, y + 2, z + 5, block2, 4, 2);
				world.setBlock(x - 3, y + 2, z + 6, block1, 3, 2);
				world.setBlock(x - 2, y - 2, z + 0, block1, 4, 2);
				world.setBlock(x - 2, y - 2, z + 1, block1, 4, 2);
				world.setBlock(x - 2, y - 2, z + 2, block2, 4, 2);
				world.setBlock(x - 2, y - 2, z + 3, block2, 4, 2);
				world.setBlock(x - 2, y - 2, z + 4, block2, 4, 2);
				world.setBlock(x - 2, y - 2, z + 5, block2, 4, 2);
				world.setBlock(x - 2, y - 2, z + 6, block1, 7, 2);
				world.setBlock(x - 2, y - 1, z + 0, block2, 4, 2);
				world.setBlock(x - 2, y - 1, z + 1, block2, 4, 2);
				
				world.setBlock(x - 2, y - 1, z + 2, block3, 0, 2);
				world.setBlock(x - 2, y - 1, z + 6, block2, 4, 2);
				world.setBlock(x - 2, y + 0, z + 0, block2, 4, 2);
				world.setBlock(x - 2, y + 0, z + 1, block2, 4, 2);
				world.setBlock(x + 0, y - 3, z + 4, block2, 0, 2);
				
				world.setBlock(x - 2, y + 0, z + 5, block2, 0, 2);
				world.setBlock(x - 2, y + 0, z + 6, block2, 4, 2);
				world.setBlock(x - 2, y + 1, z + 0, block2, 4, 2);
				world.setBlock(x - 2, y + 1, z + 1, block2, 4, 2);
				world.setBlock(x - 2, y + 1, z + 2, block3, 8, 2);
				world.setBlock(x - 2, y + 1, z + 6, block2, 4, 2);
				world.setBlock(x - 2, y + 2, z + 0, block1, 0, 2);
				world.setBlock(x - 2, y + 2, z + 1, block1, 0, 2);
				world.setBlock(x - 2, y + 2, z + 2, block2, 4, 2);
				world.setBlock(x - 2, y + 2, z + 3, block1, 5, 2);
				world.setBlock(x - 2, y + 2, z + 4, block1, 5, 2);
				world.setBlock(x - 2, y + 2, z + 5, block1, 5, 2);
				world.setBlock(x - 2, y + 2, z + 6, block1, 3, 2);
				world.setBlock(x - 2, y + 3, z + 3, block1, 0, 2);
				world.setBlock(x - 2, y + 3, z + 4, block1, 0, 2);
				world.setBlock(x - 2, y + 3, z + 5, block1, 0, 2);
				world.setBlock(x - 1, y - 2, z + 0, block2, 4, 2);
				world.setBlock(x - 1, y - 2, z + 1, block2, 4, 2);
				world.setBlock(x - 1, y - 2, z + 2, block2, 4, 2);
				world.setBlock(x - 1, y - 2, z + 3, block2, 4, 2);
				world.setBlock(x - 1, y - 2, z + 4, block2, 4, 2);
				world.setBlock(x - 1, y - 2, z + 5, block2, 4, 2);
				world.setBlock(x - 1, y - 2, z + 6, block1, 7, 2);
				world.setBlock(x - 1, y - 1, z + 6, block2, 4, 2);
				world.setBlock(x - 1, y + 0, z + 6, block2, 4, 2);
				world.setBlock(x - 1, y + 1, z + 6, block2, 4, 2);
				world.setBlock(x - 1, y + 2, z + 0, block2, 4, 2);
				world.setBlock(x - 1, y + 2, z + 1, block2, 4, 2);
				world.setBlock(x - 1, y + 2, z + 2, block1, 7, 2);
				world.setBlock(x - 1, y + 2, z + 6, block1, 3, 2);
				world.setBlock(x - 1, y + 3, z + 2, block1, 2, 2);
				world.setBlock(x - 1, y + 3, z + 3, block2, 4, 2);
				world.setBlock(x - 1, y + 3, z + 4, block2, 4, 2);
				world.setBlock(x - 1, y + 3, z + 5, block2, 4, 2);
				world.setBlock(x + 0, y - 2, z + 0, block2, 4, 2);
				world.setBlock(x + 0, y - 2, z + 1, block2, 4, 2);
				world.setBlock(x + 0, y - 2, z + 2, block2, 4, 2);
				world.setBlock(x + 0, y - 2, z + 3, block2, 4, 2);
				world.setBlock(x + 0, y - 2, z + 4, block2, 4, 2);
				world.setBlock(x + 0, y - 2, z + 5, block2, 4, 2);
				world.setBlock(x + 0, y - 2, z + 6, block1, 7, 2);
				world.setBlock(x + 0, y - 1, z + 6, block2, 4, 2);
				world.setBlock(x + 0, y + 0, z + 6, block5, 0, 2);
				world.setBlock(x + 0, y + 1, z + 6, block2, 4, 2);
				world.setBlock(x + 0, y + 2, z + 0, block2, 4, 2);
				world.setBlock(x + 0, y + 2, z + 1, block2, 4, 2);
				world.setBlock(x + 0, y + 2, z + 2, block1, 7, 2);
				world.setBlock(x + 0, y + 2, z + 5, block6, 3, 2);
				world.setBlock(x + 0, y + 2, z + 6, block1, 3, 2);
				world.setBlock(x + 0, y + 3, z + 2, block1, 2, 2);
				world.setBlock(x + 0, y + 3, z + 3, block2, 4, 2);
				world.setBlock(x + 0, y + 3, z + 4, block5, 0, 2);
				world.setBlock(x + 0, y + 3, z + 5, block2, 4, 2);
				world.setBlock(x + 1, y - 2, z + 0, block2, 4, 2);
				world.setBlock(x + 1, y - 2, z + 1, block2, 4, 2);
				world.setBlock(x + 1, y - 2, z + 2, block2, 4, 2);
				world.setBlock(x + 1, y - 2, z + 3, block2, 4, 2);
				world.setBlock(x + 1, y - 2, z + 4, block2, 4, 2);
				world.setBlock(x + 1, y - 2, z + 5, block2, 4, 2);
				world.setBlock(x + 1, y - 2, z + 6, block1, 7, 2);
				world.setBlock(x + 1, y - 1, z + 6, block2, 4, 2);
				world.setBlock(x + 1, y + 0, z + 6, block2, 4, 2);
				world.setBlock(x + 1, y + 1, z + 6, block2, 4, 2);
				world.setBlock(x + 1, y + 2, z + 0, block2, 4, 2);
				world.setBlock(x + 1, y + 2, z + 1, block2, 4, 2);
				world.setBlock(x + 1, y + 2, z + 2, block1, 7, 2);
				world.setBlock(x + 1, y + 2, z + 6, block1, 3, 2);
				world.setBlock(x + 1, y + 3, z + 2, block1, 2, 2);
				world.setBlock(x + 1, y + 3, z + 3, block2, 4, 2);
				world.setBlock(x + 1, y + 3, z + 4, block2, 4, 2);
				world.setBlock(x + 1, y + 3, z + 5, block2, 4, 2);
				world.setBlock(x + 2, y - 2, z + 0, block1, 5, 2);
				world.setBlock(x + 2, y - 2, z + 1, block1, 5, 2);
				world.setBlock(x + 2, y - 2, z + 2, block2, 4, 2);
				world.setBlock(x + 2, y - 2, z + 3, block2, 4, 2);
				world.setBlock(x + 2, y - 2, z + 4, block2, 4, 2);
				world.setBlock(x + 2, y - 2, z + 5, block2, 4, 2);
				world.setBlock(x + 2, y - 2, z + 6, block1, 7, 2);
				world.setBlock(x + 2, y - 1, z + 0, block2, 4, 2);
				world.setBlock(x + 2, y - 1, z + 1, block2, 4, 2);
				world.setBlock(x + 2, y - 1, z + 2, block3, 0, 2);
				world.setBlock(x + 2, y - 1, z + 6, block2, 4, 2);
				world.setBlock(x + 2, y + 0, z + 0, block2, 4, 2);
				world.setBlock(x + 2, y + 0, z + 1, block2, 4, 2);
				world.setBlock(x + 2, y + 0, z + 6, block2, 4, 2);
				world.setBlock(x + 2, y + 1, z + 0, block2, 4, 2);
				world.setBlock(x + 2, y + 1, z + 1, block2, 4, 2);
				world.setBlock(x + 2, y + 1, z + 2, block3, 8, 2);
				world.setBlock(x + 2, y + 1, z + 6, block2, 4, 2);
				world.setBlock(x + 2, y + 2, z + 0, block1, 1, 2);
				world.setBlock(x + 2, y + 2, z + 1, block1, 1, 2);
				world.setBlock(x + 2, y + 2, z + 2, block2, 4, 2);
				world.setBlock(x + 2, y + 2, z + 3, block1, 4, 2);
				world.setBlock(x + 2, y + 2, z + 4, block1, 4, 2);
				world.setBlock(x + 2, y + 2, z + 5, block1, 4, 2);
				world.setBlock(x + 2, y + 2, z + 6, block1, 3, 2);
				world.setBlock(x + 2, y + 3, z + 3, block1, 1, 2);
				world.setBlock(x + 2, y + 3, z + 4, block1, 1, 2);
				world.setBlock(x + 2, y + 3, z + 5, block1, 1, 2);
				world.setBlock(x + 3, y - 2, z + 2, block1, 6, 2);
				world.setBlock(x + 3, y - 2, z + 3, block2, 4, 2);
				world.setBlock(x + 3, y - 2, z + 4, block2, 4, 2);
				world.setBlock(x + 3, y - 2, z + 5, block2, 4, 2);
				world.setBlock(x + 3, y - 2, z + 6, block1, 7, 2);
				world.setBlock(x + 3, y - 1, z + 2, block2, 4, 2);
				world.setBlock(x + 3, y - 1, z + 6, block2, 4, 2);
				world.setBlock(x + 3, y + 0, z + 2, block2, 4, 2);
				world.setBlock(x + 3, y + 0, z + 6, block2, 4, 2);
				world.setBlock(x + 3, y + 1, z + 2, block2, 4, 2);
				world.setBlock(x + 3, y + 1, z + 6, block2, 4, 2);
				world.setBlock(x + 3, y + 2, z + 2, block1, 2, 2);
				world.setBlock(x + 3, y + 2, z + 3, block2, 4, 2);
				world.setBlock(x + 3, y + 2, z + 4, block2, 4, 2);
				world.setBlock(x + 3, y + 2, z + 5, block2, 4, 2);
				world.setBlock(x + 3, y + 2, z + 6, block1, 3, 2);
				world.setBlock(x + 4, y - 2, z + 2, block1, 6, 2);
				world.setBlock(x + 4, y - 2, z + 3, block2, 4, 2);
				world.setBlock(x + 4, y - 2, z + 4, block2, 4, 2);
				world.setBlock(x + 4, y - 2, z + 5, block2, 4, 2);
				world.setBlock(x + 4, y - 2, z + 6, block1, 7, 2);
				world.setBlock(x + 4, y - 1, z + 2, block2, 4, 2);
				world.setBlock(x + 4, y - 1, z + 6, block2, 4, 2);
				world.setBlock(x + 4, y + 0, z + 2, block2, 4, 2);
				world.setBlock(x + 4, y + 0, z + 6, block2, 4, 2);
				world.setBlock(x + 4, y + 1, z + 2, block2, 4, 2);
				world.setBlock(x + 4, y + 1, z + 6, block2, 4, 2);
				world.setBlock(x + 4, y + 2, z + 2, block1, 2, 2);
				world.setBlock(x + 4, y + 2, z + 3, block2, 4, 2);
				world.setBlock(x + 4, y + 2, z + 4, block2, 4, 2);
				world.setBlock(x + 4, y + 2, z + 5, block2, 4, 2);
				world.setBlock(x + 4, y + 2, z + 6, block1, 3, 2);
				
			}
		} else if (dir == ForgeDirection.NORTH)
		{
			if (rot == 1)
			{
				
				world.setBlock(x - 2, y - 2, z - 8, block1, 4, 2);
				world.setBlock(x - 2, y - 2, z - 7, block1, 4, 2);
				world.setBlock(x - 2, y - 2, z - 6, block1, 4, 2);
				world.setBlock(x - 2, y - 2, z - 5, block1, 4, 2);
				world.setBlock(x - 2, y - 2, z - 4, block1, 4, 2);
				world.setBlock(x - 2, y - 2, z - 3, block1, 4, 2);
				world.setBlock(x - 2, y - 2, z - 2, block1, 4, 2);
				world.setBlock(x - 2, y - 2, z - 1, block1, 4, 2);
				world.setBlock(x - 2, y - 2, z + 0, block1, 4, 2);
				
				world.setBlock(x - 2, y - 1, z - 8, block2, 4, 2);
				world.setBlock(x - 2, y - 1, z - 7, block2, 4, 2);
				world.setBlock(x - 2, y - 1, z - 6, block2, 4, 2);
				world.setBlock(x - 2, y - 1, z - 5, block2, 4, 2);
				world.setBlock(x - 2, y - 1, z - 4, block2, 4, 2);
				world.setBlock(x - 2, y - 1, z - 3, block2, 4, 2);
				world.setBlock(x - 2, y - 1, z - 2, block2, 4, 2);
				world.setBlock(x - 2, y - 1, z - 1, block2, 4, 2);
				world.setBlock(x - 2, y - 1, z + 0, block2, 4, 2);
				world.setBlock(x - 2, y + 0, z - 8, block2, 4, 2);
				world.setBlock(x - 2, y + 0, z - 7, block2, 4, 2);
				world.setBlock(x - 2, y + 0, z - 6, block2, 4, 2);
				world.setBlock(x - 2, y + 0, z - 5, block2, 4, 2);
				
				world.setBlock(x - 2, y + 0, z - 4, block3, 0, 2);
				world.setBlock(x - 2, y + 0, z - 3, block2, 4, 2);
				world.setBlock(x - 2, y + 0, z - 2, block2, 4, 2);
				world.setBlock(x - 2, y + 0, z - 1, block2, 4, 2);
				world.setBlock(x - 2, y + 0, z + 0, block2, 4, 2);
				world.setBlock(x - 2, y + 1, z - 8, block2, 4, 2);
				world.setBlock(x - 2, y + 1, z - 7, block2, 4, 2);
				world.setBlock(x - 2, y + 1, z - 6, block2, 4, 2);
				world.setBlock(x - 2, y + 1, z - 5, block2, 4, 2);
				world.setBlock(x - 2, y + 1, z - 4, block2, 4, 2);
				world.setBlock(x - 2, y + 1, z - 3, block2, 4, 2);
				world.setBlock(x - 2, y + 1, z - 2, block2, 4, 2);
				world.setBlock(x - 2, y + 1, z - 1, block2, 4, 2);
				world.setBlock(x - 2, y + 1, z + 0, block2, 4, 2);
				world.setBlock(x - 2, y + 2, z - 8, block1, 0, 2);
				world.setBlock(x - 2, y + 2, z - 7, block1, 0, 2);
				world.setBlock(x - 2, y + 2, z - 6, block1, 0, 2);
				world.setBlock(x - 2, y + 2, z - 5, block1, 0, 2);
				world.setBlock(x - 2, y + 2, z - 4, block1, 0, 2);
				world.setBlock(x - 2, y + 2, z - 3, block1, 0, 2);
				world.setBlock(x - 2, y + 2, z - 2, block1, 0, 2);
				world.setBlock(x - 2, y + 2, z - 1, block1, 0, 2);
				world.setBlock(x - 2, y + 2, z + 0, block1, 0, 2);
				world.setBlock(x - 1, y - 2, z - 8, block2, 4, 2);
				world.setBlock(x - 1, y - 2, z - 7, block2, 4, 2);
				world.setBlock(x - 1, y - 2, z - 6, block2, 4, 2);
				world.setBlock(x - 1, y - 2, z - 5, block2, 4, 2);
				world.setBlock(x - 1, y - 2, z - 4, block2, 4, 2);
				world.setBlock(x - 1, y - 2, z - 3, block2, 4, 2);
				world.setBlock(x - 1, y - 2, z - 2, block2, 4, 2);
				world.setBlock(x - 1, y - 2, z - 1, block2, 4, 2);
				world.setBlock(x - 1, y - 2, z + 0, block2, 4, 2);
				
				world.setBlock(x + 0, y - 3, z - 4, block2, 0, 2);
				world.setBlock(x - 1, y + 0, z - 6, block2, 0, 2);
				world.setBlock(x - 1, y + 2, z - 8, block2, 4, 2);
				world.setBlock(x - 1, y + 2, z - 7, block2, 4, 2);
				world.setBlock(x - 1, y + 2, z - 6, block1, 7, 2);
				world.setBlock(x - 1, y + 2, z - 4, block6, 4, 2);
				world.setBlock(x - 1, y + 2, z - 2, block1, 6, 2);
				world.setBlock(x - 1, y + 2, z - 1, block2, 4, 2);
				world.setBlock(x - 1, y + 2, z + 0, block2, 4, 2);
				world.setBlock(x - 1, y + 3, z - 6, block1, 2, 2);
				world.setBlock(x - 1, y + 3, z - 5, block2, 4, 2);
				world.setBlock(x - 1, y + 3, z - 4, block2, 4, 2);
				world.setBlock(x - 1, y + 3, z - 3, block2, 4, 2);
				world.setBlock(x - 1, y + 3, z - 2, block1, 3, 2);
				world.setBlock(x + 0, y - 2, z - 8, block2, 4, 2);
				world.setBlock(x + 0, y - 2, z - 7, block2, 4, 2);
				world.setBlock(x + 0, y - 2, z - 6, block2, 4, 2);
				world.setBlock(x + 0, y - 2, z - 5, block2, 4, 2);
				world.setBlock(x + 0, y - 2, z - 4, block2, 4, 2);
				world.setBlock(x + 0, y - 2, z - 3, block2, 4, 2);
				world.setBlock(x + 0, y - 2, z - 2, block2, 4, 2);
				world.setBlock(x + 0, y - 2, z - 1, block2, 4, 2);
				world.setBlock(x + 0, y - 2, z + 0, block2, 4, 2);
				world.setBlock(x + 0, y + 2, z - 8, block2, 4, 2);
				world.setBlock(x + 0, y + 2, z - 7, block2, 4, 2);
				world.setBlock(x + 0, y + 2, z - 6, block1, 7, 2);
				world.setBlock(x + 0, y + 2, z - 2, block1, 6, 2);
				world.setBlock(x + 0, y + 2, z - 1, block2, 4, 2);
				world.setBlock(x + 0, y + 2, z + 0, block2, 4, 2);
				world.setBlock(x + 0, y + 3, z - 6, block1, 2, 2);
				world.setBlock(x + 0, y + 3, z - 5, block2, 4, 2);
				world.setBlock(x + 0, y + 3, z - 4, block3, 0, 2);
				world.setBlock(x + 0, y + 3, z - 3, block2, 4, 2);
				world.setBlock(x + 0, y + 3, z - 2, block1, 3, 2);
				world.setBlock(x + 1, y - 2, z - 8, block2, 4, 2);
				world.setBlock(x + 1, y - 2, z - 7, block2, 4, 2);
				world.setBlock(x + 1, y - 2, z - 6, block2, 4, 2);
				world.setBlock(x + 1, y - 2, z - 5, block2, 4, 2);
				world.setBlock(x + 1, y - 2, z - 4, block2, 4, 2);
				world.setBlock(x + 1, y - 2, z - 3, block2, 4, 2);
				world.setBlock(x + 1, y - 2, z - 2, block2, 4, 2);
				world.setBlock(x + 1, y - 2, z - 1, block2, 4, 2);
				world.setBlock(x + 1, y - 2, z + 0, block2, 4, 2);
				world.setBlock(x + 1, y + 2, z - 8, block2, 4, 2);
				world.setBlock(x + 1, y + 2, z - 7, block2, 4, 2);
				world.setBlock(x + 1, y + 2, z - 6, block1, 7, 2);
				world.setBlock(x + 1, y + 2, z - 2, block1, 6, 2);
				world.setBlock(x + 1, y + 2, z - 1, block2, 4, 2);
				world.setBlock(x + 1, y + 2, z + 0, block2, 4, 2);
				world.setBlock(x + 1, y + 3, z - 6, block1, 2, 2);
				world.setBlock(x + 1, y + 3, z - 5, block2, 4, 2);
				world.setBlock(x + 1, y + 3, z - 4, block2, 4, 2);
				world.setBlock(x + 1, y + 3, z - 3, block2, 4, 2);
				world.setBlock(x + 1, y + 3, z - 2, block1, 3, 2);
				world.setBlock(x + 2, y - 2, z - 8, block1, 5, 2);
				world.setBlock(x + 2, y - 2, z - 7, block1, 5, 2);
				world.setBlock(x + 2, y - 2, z - 6, block2, 4, 2);
				world.setBlock(x + 2, y - 2, z - 5, block2, 4, 2);
				world.setBlock(x + 2, y - 2, z - 4, block2, 4, 2);
				world.setBlock(x + 2, y - 2, z - 3, block2, 4, 2);
				world.setBlock(x + 2, y - 2, z - 2, block2, 4, 2);
				world.setBlock(x + 2, y - 2, z - 1, block1, 5, 2);
				world.setBlock(x + 2, y - 2, z + 0, block1, 5, 2);
				world.setBlock(x + 2, y - 1, z - 8, block2, 4, 2);
				world.setBlock(x + 2, y - 1, z - 7, block2, 4, 2);
				world.setBlock(x + 2, y - 1, z - 6, block7, 0, 2);
				world.setBlock(x + 2, y - 1, z - 2, block7, 0, 2);
				world.setBlock(x + 2, y - 1, z - 1, block2, 4, 2);
				world.setBlock(x + 2, y - 1, z + 0, block2, 4, 2);
				world.setBlock(x + 2, y + 0, z - 8, block2, 4, 2);
				world.setBlock(x + 2, y + 0, z - 7, block2, 4, 2);
				world.setBlock(x + 2, y + 0, z - 1, block2, 4, 2);
				world.setBlock(x + 2, y + 0, z + 0, block2, 4, 2);
				world.setBlock(x + 2, y + 1, z - 8, block2, 4, 2);
				world.setBlock(x + 2, y + 1, z - 7, block2, 4, 2);
				world.setBlock(x + 2, y + 1, z - 6, block7, 8, 2);
				world.setBlock(x + 2, y + 1, z - 2, block7, 8, 2);
				world.setBlock(x + 2, y + 1, z - 1, block2, 4, 2);
				world.setBlock(x + 2, y + 1, z + 0, block2, 4, 2);
