package net.glider.src.strucures;

import java.util.ArrayList;
import java.util.List;
import micdoodle8.mods.galacticraft.core.blocks.GCBlocks;
import micdoodle8.mods.galacticraft.core.items.GCItems;
import micdoodle8.mods.galacticraft.planets.mars.items.MarsItems;
import net.glider.src.blocks.BlockContainerMod;
import net.glider.src.items.ItemMod;
import net.glider.src.tiles.TileEntityInfo;
import net.glider.src.utils.ForgeDirectionUtils;
import net.glider.src.utils.OreDictItemStack;
import net.minecraft.block.Block;
import net.minecraft.init.Blocks;
import net.minecraft.init.Items;
import net.minecraft.item.ItemStack;
import net.minecraft.util.StatCollector;
import net.minecraft.world.World;
import net.minecraftforge.common.util.ForgeDirection;

public class StructureCrossroad extends Structure {
	
	private boolean hidden;
	Block block1 = BlockContainerMod.BlockInfo;
	
	public StructureCrossroad(boolean hidden)
	{
		super(hidden);
		this.hidden = hidden;
	}
	
	@Override
	public Structure copy()
	{
		StructureCrossroad Nstr = new StructureCrossroad(hidden);
		Nstr.Configure(placementPos.clone(), placementRotation, placementDir);
		return Nstr;
	}
	
	public ForgeDirection[] getDirs(ForgeDirection dir)
	{
		if (dir == ForgeDirection.WEST)
		{
			return new ForgeDirection[] { ForgeDirection.NORTH, dir, ForgeDirection.SOUTH };
		} else if (dir == ForgeDirection.NORTH)
		{
			return new ForgeDirection[] { ForgeDirection.EAST, dir, ForgeDirection.WEST };
		} else if (dir == ForgeDirection.EAST)
		{
			return new ForgeDirection[] { ForgeDirection.SOUTH, dir, ForgeDirection.NORTH };
		} else if (dir == ForgeDirection.SOUTH)
		{
			return new ForgeDirection[] { ForgeDirection.WEST, dir, ForgeDirection.EAST };
		} else if (dir == ForgeDirection.UNKNOWN)
		{
			return new ForgeDirection[] { ForgeDirection.WEST, ForgeDirection.SOUTH, ForgeDirection.EAST, ForgeDirection.NORTH };
		} else return new ForgeDirection[] {};
	}
	
	public static int[] ChangePosForDir(ForgeDirection dir, ForgeDirection Ndir, int x, int y, int z)
	{
		int[] Spos = new int[] { x, y, z };
		if (dir != Ndir)
		{
			Spos = ForgeDirectionUtils.IncreaseByDir(dir, Spos, 4);
			Spos = ForgeDirectionUtils.IncreaseByDir(Ndir, Spos, 5);
		} else
		{
			Spos = ForgeDirectionUtils.IncreaseByDir(dir, Spos, 9);
		}
		
		return Spos;
	}
	
	@Override
	public void deconstruct(World world, ForgeDirection dir, int x, int y, int z)
	{
		if (dir == ForgeDirection.WEST)
		{
			// world.setBlock(x+-8, y+-3, z+-4, block1,5,2);
			Block block2 = Blocks.air;
			world.setBlock(x + -8, y + -2, z + -2, block2, 6, 2);
			Block block3 = Blocks.air;
			world.setBlock(x + -8, y + -2, z + -1, block3, 4, 2);
			world.setBlock(x + -8, y + -2, z + 0, block3, 4, 2);
			world.setBlock(x + -8, y + -2, z + 1, block3, 4, 2);
			world.setBlock(x + -8, y + -2, z + 2, block2, 7, 2);
			world.setBlock(x + -8, y + -1, z + -2, block3, 4, 2);
			world.setBlock(x + -8, y + -1, z + 2, block3, 4, 2);
			world.setBlock(x + -8, y + 0, z + -2, block3, 4, 2);
			// world.setBlock(x+-8, y+0, z+0, block1,4,2);
			world.setBlock(x + -8, y + 0, z + 2, block3, 4, 2);
			world.setBlock(x + -8, y + 1, z + -2, block3, 4, 2);
			world.setBlock(x + -8, y + 1, z + 2, block3, 4, 2);
			world.setBlock(x + -8, y + 2, z + -2, block2, 2, 2);
			world.setBlock(x + -8, y + 2, z + -1, block3, 4, 2);
			world.setBlock(x + -8, y + 2, z + 0, block3, 4, 2);
			world.setBlock(x + -8, y + 2, z + 1, block3, 4, 2);
			world.setBlock(x + -8, y + 2, z + 2, block2, 3, 2);
			world.setBlock(x + -7, y + -2, z + -2, block2, 6, 2);
			world.setBlock(x + -7, y + -2, z + -1, block3, 4, 2);
			world.setBlock(x + -7, y + -2, z + 0, block3, 4, 2);
			world.setBlock(x + -7, y + -2, z + 1, block3, 4, 2);
			world.setBlock(x + -7, y + -2, z + 2, block2, 7, 2);
			world.setBlock(x + -7, y + -1, z + -2, block3, 4, 2);
			world.setBlock(x + -7, y + -1, z + 2, block3, 4, 2);
			world.setBlock(x + -7, y + 0, z + -2, block3, 4, 2);
			world.setBlock(x + -7, y + 0, z + 2, block3, 4, 2);
			world.setBlock(x + -7, y + 1, z + -2, block3, 4, 2);
			world.setBlock(x + -7, y + 1, z + 2, block3, 4, 2);
			world.setBlock(x + -7, y + 2, z + -2, block2, 2, 2);
			world.setBlock(x + -7, y + 2, z + -1, block3, 4, 2);
			world.setBlock(x + -7, y + 2, z + 0, block3, 4, 2);
			world.setBlock(x + -7, y + 2, z + 1, block3, 4, 2);
			world.setBlock(x + -7, y + 2, z + 2, block2, 3, 2);
			world.setBlock(x + -7, y + 3, z + -1, block2, 0, 2);
			world.setBlock(x + -7, y + 3, z + 0, block2, 0, 2);
			world.setBlock(x + -7, y + 3, z + 1, block2, 0, 2);
			world.setBlock(x + -6, y + -2, z + -4, block2, 4, 2);
			world.setBlock(x + -6, y + -2, z + -3, block2, 4, 2);
			world.setBlock(x + -6, y + -2, z + -2, block3, 4, 2);
			world.setBlock(x + -6, y + -2, z + -1, block3, 4, 2);
			world.setBlock(x + -6, y + -2, z + 0, block3, 4, 2);
			world.setBlock(x + -6, y + -2, z + 1, block3, 4, 2);
			world.setBlock(x + -6, y + -2, z + 2, block3, 4, 2);
			world.setBlock(x + -6, y + -2, z + 3, block2, 4, 2);
			world.setBlock(x + -6, y + -2, z + 4, block2, 4, 2);
			world.setBlock(x + -6, y + -1, z + -4, block3, 4, 2);
			world.setBlock(x + -6, y + -1, z + -3, block3, 4, 2);
			Block block4 = Blocks.air;
			world.setBlock(x + -6, y + -1, z + -2, block4, 0, 2);
			world.setBlock(x + -6, y + -1, z + 2, block4, 0, 2);
			world.setBlock(x + -6, y + -1, z + 3, block3, 4, 2);
			world.setBlock(x + -6, y + -1, z + 4, block3, 4, 2);
			world.setBlock(x + -6, y + 0, z + -4, block3, 4, 2);
			world.setBlock(x + -6, y + 0, z + -3, block3, 4, 2);
			world.setBlock(x + -6, y + 0, z + 3, block3, 4, 2);
			world.setBlock(x + -6, y + 0, z + 4, block3, 4, 2);
			world.setBlock(x + -6, y + 1, z + -4, block3, 4, 2);
			world.setBlock(x + -6, y + 1, z + -3, block3, 4, 2);
			Block block5 = Blocks.air;
			world.setBlock(x + -6, y + 1, z + -2, block5, 2, 2);
			world.setBlock(x + -6, y + 1, z + 2, block4, 8, 2);
			world.setBlock(x + -6, y + 1, z + 3, block3, 4, 2);
			world.setBlock(x + -6, y + 1, z + 4, block3, 4, 2);
			world.setBlock(x + -6, y + 2, z + -4, block2, 0, 2);
			world.setBlock(x + -6, y + 2, z + -3, block2, 0, 2);
			world.setBlock(x + -6, y + 2, z + -2, block3, 4, 2);
			world.setBlock(x + -6, y + 2, z + -1, block2, 5, 2);
			world.setBlock(x + -6, y + 2, z + 0, block2, 5, 2);
			world.setBlock(x + -6, y + 2, z + 1, block2, 5, 2);
			world.setBlock(x + -6, y + 2, z + 2, block3, 4, 2);
			world.setBlock(x + -6, y + 2, z + 3, block2, 0, 2);
			world.setBlock(x + -6, y + 2, z + 4, block2, 0, 2);
			world.setBlock(x + -6, y + 3, z + -1, block3, 4, 2);
			world.setBlock(x + -6, y + 3, z + 0, block3, 4, 2);
			world.setBlock(x + -6, y + 3, z + 1, block3, 4, 2);
			world.setBlock(x + -5, y + -2, z + -4, block3, 4, 2);
			world.setBlock(x + -5, y + -2, z + -3, block3, 4, 2);
			world.setBlock(x + -5, y + -2, z + -2, block3, 4, 2);
			world.setBlock(x + -5, y + -2, z + -1, block3, 4, 2);
			world.setBlock(x + -5, y + -2, z + 0, block3, 4, 2);
			world.setBlock(x + -5, y + -2, z + 1, block3, 4, 2);
			world.setBlock(x + -5, y + -2, z + 2, block3, 4, 2);
			world.setBlock(x + -5, y + -2, z + 3, block3, 4, 2);
			world.setBlock(x + -5, y + -2, z + 4, block3, 4, 2);
			world.setBlock(x + -5, y + 2, z + -4, block3, 4, 2);
			world.setBlock(x + -5, y + 2, z + -3, block3, 4, 2);
			world.setBlock(x + -5, y + 2, z + -2, block2, 7, 2);
			world.setBlock(x + -5, y + 2, z + 2, block2, 6, 2);
			world.setBlock(x + -5, y + 2, z + 3, block3, 4, 2);
			world.setBlock(x + -5, y + 2, z + 4, block3, 4, 2);
			world.setBlock(x + -5, y + 3, z + -3, block2, 2, 2);
			world.setBlock(x + -5, y + 3, z + -2, block3, 4, 2);
			world.setBlock(x + -5, y + 3, z + -1, block3, 4, 2);
			world.setBlock(x + -5, y + 3, z + 0, block3, 4, 2);
			world.setBlock(x + -5, y + 3, z + 1, block3, 4, 2);
			world.setBlock(x + -5, y + 3, z + 2, block3, 4, 2);
			world.setBlock(x + -5, y + 3, z + 3, block2, 3, 2);
			world.setBlock(x + -4, y + -2, z + -4, block3, 4, 2);
			world.setBlock(x + -4, y + -2, z + -3, block3, 4, 2);
			world.setBlock(x + -4, y + -2, z + -2, block3, 4, 2);
			world.setBlock(x + -4, y + -2, z + -1, block3, 4, 2);
			Block block6 = Blocks.air;
			world.setBlock(x + -4, y + -2, z + 0, block6, 0, 2);
			// world.setTileEntity(p_147455_1_, p_147455_2_, p_147455_3_,
			// p_147455_4_);
			world.setBlock(x + -4, y + -2, z + 1, block3, 4, 2);
			world.setBlock(x + -4, y + -2, z + 2, block3, 4, 2);
			world.setBlock(x + -4, y + -2, z + 3, block3, 4, 2);
			world.setBlock(x + -4, y + -2, z + 4, block3, 4, 2);
			// world.setBlock(x+-4, y+0, z+-4, block1,4,2);
			// world.setBlock(x+-4, y+0, z+4, block1,4,2);
			world.setBlock(x + -4, y + 2, z + -4, block3, 4, 2);
			world.setBlock(x + -4, y + 2, z + -3, block3, 4, 2);
			world.setBlock(x + -4, y + 2, z + -2, block2, 7, 2);
			world.setBlock(x + -4, y + 2, z + 2, block2, 6, 2);
			world.setBlock(x + -4, y + 2, z + 3, block3, 4, 2);
			world.setBlock(x + -4, y + 2, z + 4, block3, 4, 2);
			world.setBlock(x + -4, y + 3, z + -3, block2, 2, 2);
			world.setBlock(x + -4, y + 3, z + -2, block3, 4, 2);
			world.setBlock(x + -4, y + 3, z + -1, block3, 4, 2);
			world.setBlock(x + -4, y + 3, z + 0, block6, 0, 2);
			world.setBlock(x + -4, y + 3, z + 1, block3, 4, 2);
			world.setBlock(x + -4, y + 3, z + 2, block3, 4, 2);
			world.setBlock(x + -4, y + 3, z + 3, block2, 3, 2);
			world.setBlock(x + -3, y + -2, z + -4, block3, 4, 2);
			world.setBlock(x + -3, y + -2, z + -3, block3, 4, 2);
			world.setBlock(x + -3, y + -2, z + -2, block3, 4, 2);
			world.setBlock(x + -3, y + -2, z + -1, block3, 4, 2);
			world.setBlock(x + -3, y + -2, z + 0, block3, 4, 2);
			world.setBlock(x + -3, y + -2, z + 1, block3, 4, 2);
			world.setBlock(x + -3, y + -2, z + 2, block3, 4, 2);
			world.setBlock(x + -3, y + -2, z + 3, block3, 4, 2);
			world.setBlock(x + -3, y + -2, z + 4, block3, 4, 2);
			world.setBlock(x + -3, y + 2, z + -4, block3, 4, 2);
			world.setBlock(x + -3, y + 2, z + -3, block3, 4, 2);
			world.setBlock(x + -3, y + 2, z + -2, block2, 7, 2);
			world.setBlock(x + -3, y + 2, z + 2, block2, 6, 2);
			world.setBlock(x + -3, y + 2, z + 3, block3, 4, 2);
			world.setBlock(x + -3, y + 2, z + 4, block3, 4, 2);
			world.setBlock(x + -3, y + 3, z + -3, block2, 2, 2);
			world.setBlock(x + -3, y + 3, z + -2, block3, 4, 2);
			world.setBlock(x + -3, y + 3, z + -1, block3, 4, 2);
			world.setBlock(x + -3, y + 3, z + 0, block3, 4, 2);
			world.setBlock(x + -3, y + 3, z + 1, block3, 4, 2);
			world.setBlock(x + -3, y + 3, z + 2, block3, 4, 2);
			world.setBlock(x + -3, y + 3, z + 3, block2, 3, 2);
			world.setBlock(x + -2, y + -2, z + -4, block2, 5, 2);
			world.setBlock(x + -2, y + -2, z + -3, block2, 5, 2);
			world.setBlock(x + -2, y + -2, z + -2, block3, 4, 2);
			world.setBlock(x + -2, y + -2, z + -1, block3, 4, 2);
			world.setBlock(x + -2, y + -2, z + 0, block3, 4, 2);
			world.setBlock(x + -2, y + -2, z + 1, block3, 4, 2);
			world.setBlock(x + -2, y + -2, z + 2, block3, 4, 2);
			world.setBlock(x + -2, y + -2, z + 3, block2, 5, 2);
			world.setBlock(x + -2, y + -2, z + 4, block2, 5, 2);
			world.setBlock(x + -2, y + -1, z + -4, block3, 4, 2);
			world.setBlock(x + -2, y + -1, z + -3, block3, 4, 2);
			world.setBlock(x + -2, y + -1, z + -2, block4, 0, 2);
			world.setBlock(x + -2, y + -1, z + 2, block4, 0, 2);
			world.setBlock(x + -2, y + -1, z + 3, block3, 4, 2);
			world.setBlock(x + -2, y + -1, z + 4, block3, 4, 2);
			world.setBlock(x + -2, y + 0, z + -4, block3, 4, 2);
			world.setBlock(x + -2, y + 0, z + -3, block3, 4, 2);
			world.setBlock(x + -2, y + 0, z + 3, block3, 4, 2);
			world.setBlock(x + -2, y + 0, z + 4, block3, 4, 2);
			world.setBlock(x + -2, y + 1, z + -4, block3, 4, 2);
			world.setBlock(x + -2, y + 1, z + -3, block3, 4, 2);
			world.setBlock(x + -2, y + 1, z + -2, block4, 8, 2);
			world.setBlock(x + -2, y + 1, z + 2, block5, 3, 2);
			world.setBlock(x + -2, y + 1, z + 3, block3, 4, 2);
			world.setBlock(x + -2, y + 1, z + 4, block3, 4, 2);
			world.setBlock(x + -2, y + 2, z + -4, block2, 1, 2);
			world.setBlock(x + -2, y + 2, z + -3, block2, 1, 2);
			world.setBlock(x + -2, y + 2, z + -2, block3, 4, 2);
			world.setBlock(x + -2, y + 2, z + -1, block2, 4, 2);
			world.setBlock(x + -2, y + 2, z + 0, block2, 4, 2);
			world.setBlock(x + -2, y + 2, z + 1, block2, 4, 2);
			world.setBlock(x + -2, y + 2, z + 2, block3, 4, 2);
			world.setBlock(x + -2, y + 2, z + 3, block2, 1, 2);
			world.setBlock(x + -2, y + 2, z + 4, block2, 1, 2);
			world.setBlock(x + -2, y + 3, z + -1, block3, 4, 2);
			world.setBlock(x + -2, y + 3, z + 0, block3, 4, 2);
			world.setBlock(x + -2, y + 3, z + 1, block3, 4, 2);
			world.setBlock(x + -1, y + -2, z + -2, block2, 6, 2);
			world.setBlock(x + -1, y + -2, z + -1, block3, 4, 2);
			world.setBlock(x + -1, y + -2, z + 0, block3, 4, 2);
			world.setBlock(x + -1, y + -2, z + 1, block3, 4, 2);
			world.setBlock(x + -1, y + -2, z + 2, block2, 7, 2);
			world.setBlock(x + -1, y + -1, z + -2, block3, 4, 2);
			world.setBlock(x + -1, y + -1, z + 2, block3, 4, 2);
			world.setBlock(x + -1, y + 0, z + -2, block3, 4, 2);
			world.setBlock(x + -1, y + 0, z + 2, block3, 4, 2);
			world.setBlock(x + -1, y + 1, z + -2, block3, 4, 2);
			world.setBlock(x + -1, y + 1, z + 2, block3, 4, 2);
			world.setBlock(x + -1, y + 2, z + -2, block2, 2, 2);
			world.setBlock(x + -1, y + 2, z + -1, block3, 4, 2);
			world.setBlock(x + -1, y + 2, z + 0, block3, 4, 2);
			world.setBlock(x + -1, y + 2, z + 1, block3, 4, 2);
			world.setBlock(x + -1, y + 2, z + 2, block2, 3, 2);
			world.setBlock(x + -1, y + 3, z + -1, block2, 1, 2);
			world.setBlock(x + -1, y + 3, z + 0, block2, 1, 2);
			world.setBlock(x + -1, y + 3, z + 1, block2, 1, 2);
			world.setBlock(x + 0, y + -2, z + -2, block2, 6, 2);
			world.setBlock(x + 0, y + -2, z + -1, block3, 4, 2);
			world.setBlock(x + 0, y + -2, z + 0, block3, 4, 2);
			world.setBlock(x + 0, y + -2, z + 1, block3, 4, 2);
			world.setBlock(x + 0, y + -2, z + 2, block2, 7, 2);
			world.setBlock(x + 0, y + -1, z + -2, block3, 4, 2);
			world.setBlock(x + 0, y + -1, z + 2, block3, 4, 2);
			world.setBlock(x + 0, y + 0, z + -2, block3, 4, 2);
			// world.setBlock(x+0, y+0, z+0, block1,4,2);
			world.setBlock(x + 0, y + 0, z + 2, block3, 4, 2);
			world.setBlock(x + 0, y + 1, z + -2, block3, 4, 2);
			world.setBlock(x + 0, y + 1, z + 2, block3, 4, 2);
			world.setBlock(x + 0, y + 2, z + -2, block2, 2, 2);
			world.setBlock(x + 0, y + 2, z + -1, block3, 4, 2);
			world.setBlock(x + 0, y + 2, z + 0, block3, 4, 2);
			world.setBlock(x + 0, y + 2, z + 1, block3, 4, 2);
			world.setBlock(x + 0, y + 2, z + 2, block2, 3, 2);
			// world.setBlock(x+0, y+4, z+4, block1,14,2);
			// BuildHandler.buildInfoPoint(world, dir,
			// getUnlocalizedName(),x+-4, y+-3, z+0, 0,x,y,z);
			
			world.setBlock(x + -4, y + -3, z + 0, Blocks.air, 3, 2);
			
			int[] pos = new int[] { x, y, z };
			pos = ForgeDirectionUtils.IncreaseByDir(dir, pos, 2);
			pos = ForgeDirectionUtils.IncreaseByDir(ForgeDirectionUtils.turnClockwise(dir), pos, 2);
			world.setBlock(pos[0], pos[1], pos[2], Blocks.air, 0, 2);
			pos = ForgeDirectionUtils.IncreaseByDir(ForgeDirectionUtils.turnAgainstClockwise(dir), pos, 4);
			world.setBlock(pos[0], pos[1], pos[2], Blocks.air, 0, 2);
			pos = ForgeDirectionUtils.IncreaseByDir(dir, pos, 4);
			world.setBlock(pos[0], pos[1], pos[2], Blocks.air, 0, 2);
			pos = ForgeDirectionUtils.IncreaseByDir(ForgeDirectionUtils.turnClockwise(dir), pos, 4);
			world.setBlock(pos[0], pos[1], pos[2], Blocks.air, 0, 2);
			
		} else if (dir == ForgeDirection.NORTH)
		{
			// world.setBlock(x+-4, y+-3, z+-8, block1,5,2);
			Block block2 = Blocks.air;
			world.setBlock(x + -4, y + -2, z + -6, block2, 6, 2);
			Block block3 = Blocks.air;
			world.setBlock(x + -4, y + -2, z + -5, block3, 4, 2);
			world.setBlock(x + -4, y + -2, z + -4, block3, 4, 2);
			world.setBlock(x + -4, y + -2, z + -3, block3, 4, 2);
			world.setBlock(x + -4, y + -2, z + -2, block2, 7, 2);
			world.setBlock(x + -4, y + -1, z + -6, block3, 4, 2);
			world.setBlock(x + -4, y + -1, z + -2, block3, 4, 2);
			world.setBlock(x + -4, y + 0, z + -6, block3, 4, 2);
			// world.setBlock(x+-4, y+0, z+-4, block1,4,2);
			world.setBlock(x + -4, y + 0, z + -2, block3, 4, 2);
			world.setBlock(x + -4, y + 1, z + -6, block3, 4, 2);
			world.setBlock(x + -4, y + 1, z + -2, block3, 4, 2);
			world.setBlock(x + -4, y + 2, z + -6, block2, 2, 2);
			world.setBlock(x + -4, y + 2, z + -5, block3, 4, 2);
			world.setBlock(x + -4, y + 2, z + -4, block3, 4, 2);
			world.setBlock(x + -4, y + 2, z + -3, block3, 4, 2);
			world.setBlock(x + -4, y + 2, z + -2, block2, 3, 2);
			world.setBlock(x + -3, y + -2, z + -6, block2, 6, 2);
			world.setBlock(x + -3, y + -2, z + -5, block3, 4, 2);
			world.setBlock(x + -3, y + -2, z + -4, block3, 4, 2);
			world.setBlock(x + -3, y + -2, z + -3, block3, 4, 2);
			world.setBlock(x + -3, y + -2, z + -2, block2, 7, 2);
			world.setBlock(x + -3, y + -1, z + -6, block3, 4, 2);
			world.setBlock(x + -3, y + -1, z + -2, block3, 4, 2);
			world.setBlock(x + -3, y + 0, z + -6, block3, 4, 2);
			world.setBlock(x + -3, y + 0, z + -2, block3, 4, 2);
			world.setBlock(x + -3, y + 1, z + -6, block3, 4, 2);
			world.setBlock(x + -3, y + 1, z + -2, block3, 4, 2);
			world.setBlock(x + -3, y + 2, z + -6, block2, 2, 2);
			world.setBlock(x + -3, y + 2, z + -5, block3, 4, 2);
			world.setBlock(x + -3, y + 2, z + -4, block3, 4, 2);
			world.setBlock(x + -3, y + 2, z + -3, block3, 4, 2);
			world.setBlock(x + -3, y + 2, z + -2, block2, 3, 2);
			world.setBlock(x + -3, y + 3, z + -5, block2, 0, 2);
			world.setBlock(x + -3, y + 3, z + -4, block2, 0, 2);
			world.setBlock(x + -3, y + 3, z + -3, block2, 0, 2);
			world.setBlock(x + -2, y + -2, z + -8, block2, 4, 2);
			world.setBlock(x + -2, y + -2, z + -7, block2, 4, 2);
			world.setBlock(x + -2, y + -2, z + -6, block3, 4, 2);
			world.setBlock(x + -2, y + -2, z + -5, block3, 4, 2);
			world.setBlock(x + -2, y + -2, z + -4, block3, 4, 2);
			world.setBlock(x + -2, y + -2, z + -3, block3, 4, 2);
			world.setBlock(x + -2, y + -2, z + -2, block3, 4, 2);
			world.setBlock(x + -2, y + -2, z + -1, block2, 4, 2);
			world.setBlock(x + -2, y + -2, z + 0, block2, 4, 2);
			world.setBlock(x + -2, y + -1, z + -8, block3, 4, 2);
			world.setBlock(x + -2, y + -1, z + -7, block3, 4, 2);
			Block block4 = Blocks.air;
			world.setBlock(x + -2, y + -1, z + -6, block4, 0, 2);
			world.setBlock(x + -2, y + -1, z + -2, block4, 0, 2);
			world.setBlock(x + -2, y + -1, z + -1, block3, 4, 2);
			world.setBlock(x + -2, y + -1, z + 0, block3, 4, 2);
			world.setBlock(x + -2, y + 0, z + -8, block3, 4, 2);
			world.setBlock(x + -2, y + 0, z + -7, block3, 4, 2);
			world.setBlock(x + -2, y + 0, z + -1, block3, 4, 2);
			world.setBlock(x + -2, y + 0, z + 0, block3, 4, 2);
			world.setBlock(x + -2, y + 1, z + -8, block3, 4, 2);
			world.setBlock(x + -2, y + 1, z + -7, block3, 4, 2);
			Block block5 = Blocks.air;
			world.setBlock(x + -2, y + 1, z + -6, block5, 2, 2);
			world.setBlock(x + -2, y + 1, z + -2, block4, 8, 2);
			world.setBlock(x + -2, y + 1, z + -1, block3, 4, 2);
			world.setBlock(x + -2, y + 1, z + 0, block3, 4, 2);
			world.setBlock(x + -2, y + 2, z + -8, block2, 0, 2);
			world.setBlock(x + -2, y + 2, z + -7, block2, 0, 2);
			world.setBlock(x + -2, y + 2, z + -6, block3, 4, 2);
			world.setBlock(x + -2, y + 2, z + -5, block2, 5, 2);
			world.setBlock(x + -2, y + 2, z + -4, block2, 5, 2);
			world.setBlock(x + -2, y + 2, z + -3, block2, 5, 2);
			world.setBlock(x + -2, y + 2, z + -2, block3, 4, 2);
			world.setBlock(x + -2, y + 2, z + -1, block2, 0, 2);
			world.setBlock(x + -2, y + 2, z + 0, block2, 0, 2);
			world.setBlock(x + -2, y + 3, z + -5, block3, 4, 2);
			world.setBlock(x + -2, y + 3, z + -4, block3, 4, 2);
			world.setBlock(x + -2, y + 3, z + -3, block3, 4, 2);
			world.setBlock(x + -1, y + -2, z + -8, block3, 4, 2);
			world.setBlock(x + -1, y + -2, z + -7, block3, 4, 2);
			world.setBlock(x + -1, y + -2, z + -6, block3, 4, 2);
			world.setBlock(x + -1, y + -2, z + -5, block3, 4, 2);
			world.setBlock(x + -1, y + -2, z + -4, block3, 4, 2);
			world.setBlock(x + -1, y + -2, z + -3, block3, 4, 2);
			world.setBlock(x + -1, y + -2, z + -2, block3, 4, 2);
			world.setBlock(x + -1, y + -2, z + -1, block3, 4, 2);
			world.setBlock(x + -1, y + -2, z + 0, block3, 4, 2);
			world.setBlock(x + -1, y + 2, z + -8, block3, 4, 2);
			world.setBlock(x + -1, y + 2, z + -7, block3, 4, 2);
			world.setBlock(x + -1, y + 2, z + -6, block2, 7, 2);
			world.setBlock(x + -1, y + 2, z + -2, block2, 6, 2);
			world.setBlock(x + -1, y + 2, z + -1, block3, 4, 2);
			world.setBlock(x + -1, y + 2, z + 0, block3, 4, 2);
			world.setBlock(x + -1, y + 3, z + -7, block2, 2, 2);
			world.setBlock(x + -1, y + 3, z + -6, block3, 4, 2);
			world.setBlock(x + -1, y + 3, z + -5, block3, 4, 2);
			world.setBlock(x + -1, y + 3, z + -4, block3, 4, 2);
			world.setBlock(x + -1, y + 3, z + -3, block3, 4, 2);
			world.setBlock(x + -1, y + 3, z + -2, block3, 4, 2);
			world.setBlock(x + -1, y + 3, z + -1, block2, 3, 2);
			world.setBlock(x + 0, y + -2, z + -8, block3, 4, 2);
			world.setBlock(x + 0, y + -2, z + -7, block3, 4, 2);
			world.setBlock(x + 0, y + -2, z + -6, block3, 4, 2);
			world.setBlock(x + 0, y + -2, z + -5, block3, 4, 2);
			Block block6 = Blocks.air;
			world.setBlock(x + 0, y + -2, z + -4, block6, 0, 2);
			world.setBlock(x + 0, y + -2, z + -3, block3, 4, 2);
			world.setBlock(x + 0, y + -2, z + -2, block3, 4, 2);
			world.setBlock(x + 0, y + -2, z + -1, block3, 4, 2);
			world.setBlock(x + 0, y + -2, z + 0, block3, 4, 2);
			// world.setBlock(x+0, y+0, z+-8, block1,4,2);
			// world.setBlock(x+0, y+0, z+0, block1,4,2);
			world.setBlock(x + 0, y + 2, z + -8, block3, 4, 2);
			world.setBlock(x + 0, y + 2, z + -7, block3, 4, 2);
			world.setBlock(x + 0, y + 2, z + -6, block2, 7, 2);
			world.setBlock(x + 0, y + 2, z + -2, block2, 6, 2);
			world.setBlock(x + 0, y + 2, z + -1, block3, 4, 2);
			world.setBlock(x + 0, y + 2, z + 0, block3, 4, 2);
			world.setBlock(x + 0, y + 3, z + -7, block2, 2, 2);
			world.setBlock(x + 0, y + 3, z + -6, block3, 4, 2);
			world.setBlock(x + 0, y + 3, z + -5, block3, 4, 2);
			world.setBlock(x + 0, y + 3, z + -4, block6, 0, 2);
			world.setBlock(x + 0, y + 3, z + -3, block3, 4, 2);
			world.setBlock(x + 0, y + 3, z + -2, block3, 4, 2);
			world.setBlock(x + 0, y + 3, z + -1, block2, 3, 2);
			world.setBlock(x + 1, y + -2, z + -8, block3, 4, 2);
			world.setBlock(x + 1, y + -2, z + -7, block3, 4, 2);
			world.setBlock(x + 1, y + -2, z + -6, block3, 4, 2);
			world.setBlock(x + 1, y + -2, z + -5, block3, 4, 2);
			world.setBlock(x + 1, y + -2, z + -4, block3, 4, 2);
			world.setBlock(x + 1, y + -2, z + -3, block3, 4, 2);
			world.setBlock(x + 1, y + -2, z + -2, block3, 4, 2);
			world.setBlock(x + 1, y + -2, z + -1, block3, 4, 2);
			world.setBlock(x + 1, y + -2, z + 0, block3, 4, 2);
			world.setBlock(x + 1, y + 2, z + -8, block3, 4, 2);
			world.setBlock(x + 1, y + 2, z + -7, block3, 4, 2);
			world.setBlock(x + 1, y + 2, z + -6, block2, 7, 2);
			world.setBlock(x + 1, y + 2, z + -2, block2, 6, 2);
			world.setBlock(x + 1, y + 2, z + -1, block3, 4, 2);
			world.setBlock(x + 1, y + 2, z + 0, block3, 4, 2);
			world.setBlock(x + 1, y + 3, z + -7, block2, 2, 2);
			world.setBlock(x + 1, y + 3, z + -6, block3, 4, 2);
			world.setBlock(x + 1, y + 3, z + -5, block3, 4, 2);
			world.setBlock(x + 1, y + 3, z + -4, block3, 4, 2);
			world.setBlock(x + 1, y + 3, z + -3, block3, 4, 2);
			world.setBlock(x + 1, y + 3, z + -2, block3, 4, 2);
			world.setBlock(x + 1, y + 3, z + -1, block2, 3, 2);
			world.setBlock(x + 2, y + -2, z + -8, block2, 5, 2);
			world.setBlock(x + 2, y + -2, z + -7, block2, 5, 2);
			world.setBlock(x + 2, y + -2, z + -6, block3, 4, 2);
			world.setBlock(x + 2, y + -2, z + -5, block3, 4, 2);
			world.setBlock(x + 2, y + -2, z + -4, block3, 4, 2);
			world.setBlock(x + 2, y + -2, z + -3, block3, 4, 2);
			world.setBlock(x + 2, y + -2, z + -2, block3, 4, 2);
			world.setBlock(x + 2, y + -2, z + -1, block2, 5, 2);
			world.setBlock(x + 2, y + -2, z + 0, block2, 5, 2);
			world.setBlock(x + 2, y + -1, z + -8, block3, 4, 2);
			world.setBlock(x + 2, y + -1, z + -7, block3, 4, 2);
			world.setBlock(x + 2, y + -1, z + -6, block4, 0, 2);
			world.setBlock(x + 2, y + -1, z + -2, block4, 0, 2);
			world.setBlock(x + 2, y + -1, z + -1, block3, 4, 2);
			world.setBlock(x + 2, y + -1, z + 0, block3, 4, 2);
			world.setBlock(x + 2, y + 0, z + -8, block3, 4, 2);
			world.setBlock(x + 2, y + 0, z + -7, block3, 4, 2);
			world.setBlock(x + 2, y + 0, z + -1, block3, 4, 2);
			world.setBlock(x + 2, y + 0, z + 0, block3, 4, 2);
			world.setBlock(x + 2, y + 1, z + -8, block3, 4, 2);
			world.setBlock(x + 2, y + 1, z + -7, block3, 4, 2);
			world.setBlock(x + 2, y + 1, z + -6, block4, 8, 2);
			world.setBlock(x + 2, y + 1, z + -2, block5, 3, 2);
			world.setBlock(x + 2, y + 1, z + -1, block3, 4, 2);
			world.setBlock(x + 2, y + 1, z + 0, block3, 4, 2);
			world.setBlock(x + 2, y + 2, z + -8, block2, 1, 2);
			world.setBlock(x + 2, y + 2, z + -7, block2, 1, 2);
			world.setBlock(x + 2, y + 2, z + -6, block3, 4, 2);
			world.setBlock(x + 2, y + 2, z + -5, block2, 4, 2);
			world.setBlock(x + 2, y + 2, z + -4, block2, 4, 2);
			world.setBlock(x + 2, y + 2, z + -3, block2, 4, 2);
			world.setBlock(x + 2, y + 2, z + -2, block3, 4, 2);
			world.setBlock(x + 2, y + 2, z + -1, block2, 1, 2);
			world.setBlock(x + 2, y + 2, z + 0, block2, 1, 2);
			world.setBlock(x + 2, y + 3, z + -5, block3, 4, 2);
			world.setBlock(x + 2, y + 3, z + -4, block3, 4, 2);
			world.setBlock(x + 2, y + 3, z + -3, block3, 4, 2);
			world.setBlock(x + 3, y + -2, z + -6, block2, 6, 2);
			world.setBlock(x + 3, y + -2, z + -5, block3, 4, 2);
			world.setBlock(x + 3, y + -2, z + -4, block3, 4, 2);
			world.setBlock(x + 3, y + -2, z + -3, block3, 4, 2);
			world.setBlock(x + 3, y + -2, z + -2, block2, 7, 2);
			world.setBlock(x + 3, y + -1, z + -6, block3, 4, 2);
			world.setBlock(x + 3, y + -1, z + -2, block3, 4, 2);
			world.setBlock(x + 3, y + 0, z + -6, block3, 4, 2);
			world.setBlock(x + 3, y + 0, z + -2, block3, 4, 2);
			world.setBlock(x + 3, y + 1, z + -6, block3, 4, 2);
			world.setBlock(x + 3, y + 1, z + -2, block3, 4, 2);
			world.setBlock(x + 3, y + 2, z + -6, block2, 2, 2);
			world.setBlock(x + 3, y + 2, z + -5, block3, 4, 2);
			world.setBlock(x + 3, y + 2, z + -4, block3, 4, 2);
			world.setBlock(x + 3, y + 2, z + -3, block3, 4, 2);
			world.setBlock(x + 3, y + 2, z + -2, block2, 3, 2);
			world.setBlock(x + 3, y + 3, z + -5, block2, 1, 2);
			world.setBlock(x + 3, y + 3, z + -4, block2, 1, 2);
			world.setBlock(x + 3, y + 3, z + -3, block2, 1, 2);
			world.setBlock(x + 4, y + -2, z + -6, block2, 6, 2);
			world.setBlock(x + 4, y + -2, z + -5, block3, 4, 2);
			world.setBlock(x + 4, y + -2, z + -4, block3, 4, 2);
			world.setBlock(x + 4, y + -2, z + -3, block3, 4, 2);
			world.setBlock(x + 4, y + -2, z + -2, block2, 7, 2);
			world.setBlock(x + 4, y + -1, z + -6, block3, 4, 2);
			world.setBlock(x + 4, y + -1, z + -2, block3, 4, 2);
			world.setBlock(x + 4, y + 0, z + -6, block3, 4, 2);
			// world.setBlock(x+4, y+0, z+-4, block1,4,2);
			world.setBlock(x + 4, y + 0, z + -2, block3, 4, 2);
			world.setBlock(x + 4, y + 1, z + -6, block3, 4, 2);
			world.setBlock(x + 4, y + 1, z + -2, block3, 4, 2);
			world.setBlock(x + 4, y + 2, z + -6, block2, 2, 2);
			world.setBlock(x + 4, y + 2, z + -5, block3, 4, 2);
			world.setBlock(x + 4, y + 2, z + -4, block3, 4, 2);
			world.setBlock(x + 4, y + 2, z + -3, block3, 4, 2);
			world.setBlock(x + 4, y + 2, z + -2, block2, 3, 2);
			// world.setBlock(x+4, y+4, z+0, block1,14,2);
			// BuildHandler.buildInfoPoint(world, dir, getUnlocalizedName(),x+0,
			// y+-3, z+-4, 0,x,y,z);
			
			world.setBlock(x + 0, y + -3, z + -4, Blocks.air, 3, 2);
			
			int[] pos = new int[] { x, y, z };
			pos = ForgeDirectionUtils.IncreaseByDir(dir, pos, 2);
			pos = ForgeDirectionUtils.IncreaseByDir(ForgeDirectionUtils.turnClockwise(dir), pos, 2);
			world.setBlock(pos[0], pos[1], pos[2], Blocks.air, 0, 2);
			pos = ForgeDirectionUtils.IncreaseByDir(ForgeDirectionUtils.turnAgainstClockwise(dir), pos, 4);
			world.setBlock(pos[0], pos[1], pos[2], Blocks.air, 0, 2);
			pos = ForgeDirectionUtils.IncreaseByDir(dir, pos, 4);
			world.setBlock(pos[0], pos[1], pos[2], Blocks.air, 0, 2);
			pos = ForgeDirectionUtils.IncreaseByDir(ForgeDirectionUtils.turnClockwise(dir), pos, 4);
			world.setBlock(pos[0], pos[1], pos[2], Blocks.air, 0, 2);
			
		} else if (dir == ForgeDirection.EAST)
		{
			
			Block block2 = Blocks.air;
			Block block3 = Blocks.air;
			Block block6 = Blocks.air;
			Block block4 = Blocks.air;
			Block block5 = Blocks.air;
			
			// world.setBlock(x+0, y+-3, z+-4, block1,5,2);
			
			world.setBlock(x + 0, y + -2, z + -2, block2, 6, 2);
			// Block block3 = id:432;
			world.setBlock(x + 0, y + -2, z + -1, block3, 4, 2);
			world.setBlock(x + 0, y + -2, z + 0, block3, 4, 2);
			world.setBlock(x + 0, y + -2, z + 1, block3, 4, 2);
			world.setBlock(x + 0, y + -2, z + 2, block2, 7, 2);
			world.setBlock(x + 0, y + -1, z + -2, block3, 4, 2);
			world.setBlock(x + 0, y + -1, z + 2, block3, 4, 2);
			world.setBlock(x + 0, y + 0, z + -2, block3, 4, 2);
			// world.setBlock(x+0, y+0, z+0, block1,4,2);
			world.setBlock(x + 0, y + 0, z + 2, block3, 4, 2);
			world.setBlock(x + 0, y + 1, z + -2, block3, 4, 2);
			world.setBlock(x + 0, y + 1, z + 2, block3, 4, 2);
			world.setBlock(x + 0, y + 2, z + -2, block2, 2, 2);
			world.setBlock(x + 0, y + 2, z + -1, block3, 4, 2);
			world.setBlock(x + 0, y + 2, z + 0, block3, 4, 2);
			world.setBlock(x + 0, y + 2, z + 1, block3, 4, 2);
			world.setBlock(x + 0, y + 2, z + 2, block2, 3, 2);
			world.setBlock(x + 1, y + -2, z + -2, block2, 6, 2);
			world.setBlock(x + 1, y + -2, z + -1, block3, 4, 2);
			world.setBlock(x + 1, y + -2, z + 0, block3, 4, 2);
			world.setBlock(x + 1, y + -2, z + 1, block3, 4, 2);
			world.setBlock(x + 1, y + -2, z + 2, block2, 7, 2);
			world.setBlock(x + 1, y + -1, z + -2, block3, 4, 2);
			world.setBlock(x + 1, y + -1, z + 2, block3, 4, 2);
			world.setBlock(x + 1, y + 0, z + -2, block3, 4, 2);
			world.setBlock(x + 1, y + 0, z + 2, block3, 4, 2);
			world.setBlock(x + 1, y + 1, z + -2, block3, 4, 2);
			world.setBlock(x + 1, y + 1, z + 2, block3, 4, 2);
			world.setBlock(x + 1, y + 2, z + -2, block2, 2, 2);
			world.setBlock(x + 1, y + 2, z + -1, block3, 4, 2);
			world.setBlock(x + 1, y + 2, z + 0, block3, 4, 2);
			world.setBlock(x + 1, y + 2, z + 1, block3, 4, 2);
			world.setBlock(x + 1, y + 2, z + 2, block2, 3, 2);
			world.setBlock(x + 1, y + 3, z + -1, block2, 0, 2);
			world.setBlock(x + 1, y + 3, z + 0, block2, 0, 2);
			world.setBlock(x + 1, y + 3, z + 1, block2, 0, 2);
			world.setBlock(x + 2, y + -2, z + -4, block2, 4, 2);
			world.setBlock(x + 2, y + -2, z + -3, block2, 4, 2);
			world.setBlock(x + 2, y + -2, z + -2, block3, 4, 2);
			world.setBlock(x + 2, y + -2, z + -1, block3, 4, 2);
			world.setBlock(x + 2, y + -2, z + 0, block3, 4, 2);
			world.setBlock(x + 2, y + -2, z + 1, block3, 4, 2);
			world.setBlock(x + 2, y + -2, z + 2, block3, 4, 2);
			world.setBlock(x + 2, y + -2, z + 3, block2, 4, 2);
			world.setBlock(x + 2, y + -2, z + 4, block2, 4, 2);
			world.setBlock(x + 2, y + -1, z + -4, block3, 4, 2);
			world.setBlock(x + 2, y + -1, z + -3, block3, 4, 2);
			// Block block4 = id:459;
			world.setBlock(x + 2, y + -1, z + -2, block4, 0, 2);
			world.setBlock(x + 2, y + -1, z + 2, block4, 0, 2);
			world.setBlock(x + 2, y + -1, z + 3, block3, 4, 2);
			world.setBlock(x + 2, y + -1, z + 4, block3, 4, 2);
			world.setBlock(x + 2, y + 0, z + -4, block3, 4, 2);
			world.setBlock(x + 2, y + 0, z + -3, block3, 4, 2);
			world.setBlock(x + 2, y + 0, z + 3, block3, 4, 2);
			world.setBlock(x + 2, y + 0, z + 4, block3, 4, 2);
			world.setBlock(x + 2, y + 1, z + -4, block3, 4, 2);
			world.setBlock(x + 2, y + 1, z + -3, block3, 4, 2);
			// Block block5 = id:452;
			world.setBlock(x + 2, y + 1, z + -2, block5, 2, 2);
			world.setBlock(x + 2, y + 1, z + 2, block4, 8, 2);
			world.setBlock(x + 2, y + 1, z + 3, block3, 4, 2);
			world.setBlock(x + 2, y + 1, z + 4, block3, 4, 2);
			world.setBlock(x + 2, y + 2, z + -4, block2, 0, 2);
			world.setBlock(x + 2, y + 2, z + -3, block2, 0, 2);
			world.setBlock(x + 2, y + 2, z + -2, block3, 4, 2);
			world.setBlock(x + 2, y + 2, z + -1, block2, 5, 2);
			world.setBlock(x + 2, y + 2, z + 0, block2, 5, 2);
			world.setBlock(x + 2, y + 2, z + 1, block2, 5, 2);
			world.setBlock(x + 2, y + 2, z + 2, block3, 4, 2);
			world.setBlock(x + 2, y + 2, z + 3, block2, 0, 2);
			world.setBlock(x + 2, y + 2, z + 4, block2, 0, 2);
			world.setBlock(x + 2, y + 3, z + -1, block3, 4, 2);
			world.setBlock(x + 2, y + 3, z + 0, block3, 4, 2);
			world.setBlock(x + 2, y + 3, z + 1, block3, 4, 2);
			world.setBlock(x + 3, y + -2, z + -4, block3, 4, 2);
			world.setBlock(x + 3, y + -2, z + -3, block3, 4, 2);
			world.setBlock(x + 3, y + -2, z + -2, block3, 4, 2);
			world.setBlock(x + 3, y + -2, z + -1, block3, 4, 2);
			world.setBlock(x + 3, y + -2, z + 0, block3, 4, 2);
			world.setBlock(x + 3, y + -2, z + 1, block3, 4, 2);
			world.setBlock(x + 3, y + -2, z + 2, block3, 4, 2);
			world.setBlock(x + 3, y + -2, z + 3, block3, 4, 2);
			world.setBlock(x + 3, y + -2, z + 4, block3, 4, 2);
			world.setBlock(x + 3, y + 2, z + -4, block3, 4, 2);
			world.setBlock(x + 3, y + 2, z + -3, block3, 4, 2);
			world.setBlock(x + 3, y + 2, z + -2, block2, 7, 2);
			world.setBlock(x + 3, y + 2, z + 2, block2, 6, 2);
			world.setBlock(x + 3, y + 2, z + 3, block3, 4, 2);
			world.setBlock(x + 3, y + 2, z + 4, block3, 4, 2);
			world.setBlock(x + 3, y + 3, z + -3, block2, 2, 2);
			world.setBlock(x + 3, y + 3, z + -2, block3, 4, 2);
			world.setBlock(x + 3, y + 3, z + -1, block3, 4, 2);
			world.setBlock(x + 3, y + 3, z + 0, block3, 4, 2);
			world.setBlock(x + 3, y + 3, z + 1, block3, 4, 2);
			world.setBlock(x + 3, y + 3, z + 2, block3, 4, 2);
			world.setBlock(x + 3, y + 3, z + 3, block2, 3, 2);
			world.setBlock(x + 4, y + -2, z + -4, block3, 4, 2);
			world.setBlock(x + 4, y + -2, z + -3, block3, 4, 2);
			world.setBlock(x + 4, y + -2, z + -2, block3, 4, 2);
			world.setBlock(x + 4, y + -2, z + -1, block3, 4, 2);
			// Block block6 = id:505;
			world.setBlock(x + 4, y + -2, z + 0, block6, 0, 2);
			world.setBlock(x + 4, y + -2, z + 1, block3, 4, 2);
			world.setBlock(x + 4, y + -2, z + 2, block3, 4, 2);
			world.setBlock(x + 4, y + -2, z + 3, block3, 4, 2);
			world.setBlock(x + 4, y + -2, z + 4, block3, 4, 2);
			// world.setBlock(x+4, y+0, z+-4, block1,4,2);
			// world.setBlock(x+4, y+0, z+4, block1,4,2);
			world.setBlock(x + 4, y + 2, z + -4, block3, 4, 2);
			world.setBlock(x + 4, y + 2, z + -3, block3, 4, 2);
			world.setBlock(x + 4, y + 2, z + -2, block2, 7, 2);
			world.setBlock(x + 4, y + 2, z + 2, block2, 6, 2);
			world.setBlock(x + 4, y + 2, z + 3, block3, 4, 2);
			world.setBlock(x + 4, y + 2, z + 4, block3, 4, 2);
			world.setBlock(x + 4, y + 3, z + -3, block2, 2, 2);
			world.setBlock(x + 4, y + 3, z + -2, block3, 4, 2);
			world.setBlock(x + 4, y + 3, z + -1, block3, 4, 2);
			world.setBlock(x + 4, y + 3, z + 0, block6, 0, 2);
			world.setBlock(x + 4, y + 3, z + 1, block3, 4, 2);
			world.setBlock(x + 4, y + 3, z + 2, block3, 4, 2);
			world.setBlock(x + 4, y + 3, z + 3, block2, 3, 2);
			world.setBlock(x + 5, y + -2, z + -4, block3, 4, 2);
			world.setBlock(x + 5, y + -2, z + -3, block3, 4, 2);
			world.setBlock(x + 5, y + -2, z + -2, block3, 4, 2);
			world.setBlock(x + 5, y + -2, z + -1, block3, 4, 2);
			world.setBlock(x + 5, y + -2, z + 0, block3, 4, 2);
			world.setBlock(x + 5, y + -2, z + 1, block3, 4, 2);
			world.setBlock(x + 5, y + -2, z + 2, block3, 4, 2);
			world.setBlock(x + 5, y + -2, z + 3, block3, 4, 2);
			world.setBlock(x + 5, y + -2, z + 4, block3, 4, 2);
			world.setBlock(x + 5, y + 2, z + -4, block3, 4, 2);
			world.setBlock(x + 5, y + 2, z + -3, block3, 4, 2);
			world.setBlock(x + 5, y + 2, z + -2, block2, 7, 2);
			world.setBlock(x + 5, y + 2, z + 2, block2, 6, 2);
			world.setBlock(x + 5, y + 2, z + 3, block3, 4, 2);
			world.setBlock(x + 5, y + 2, z + 4, block3, 4, 2);
			world.setBlock(x + 5, y + 3, z + -3, block2, 2, 2);
			world.setBlock(x + 5, y + 3, z + -2, block3, 4, 2);
			world.setBlock(x + 5, y + 3, z + -1, block3, 4, 2);
			world.setBlock(x + 5, y + 3, z + 0, block3, 4, 2);
			world.setBlock(x + 5, y + 3, z + 1, block3, 4, 2);
			world.setBlock(x + 5, y + 3, z + 2, block3, 4, 2);
			world.setBlock(x + 5, y + 3, z + 3, block2, 3, 2);
			world.setBlock(x + 6, y + -2, z + -4, block2, 5, 2);
			world.setBlock(x + 6, y + -2, z + -3, block2, 5, 2);
			world.setBlock(x + 6, y + -2, z + -2, block3, 4, 2);
			world.setBlock(x + 6, y + -2, z + -1, block3, 4, 2);
			world.setBlock(x + 6, y + -2, z + 0, block3, 4, 2);
			world.setBlock(x + 6, y + -2, z + 1, block3, 4, 2);
			world.setBlock(x + 6, y + -2, z + 2, block3, 4, 2);
			world.setBlock(x + 6, y + -2, z + 3, block2, 5, 2);
			world.setBlock(x + 6, y + -2, z + 4, block2, 5, 2);
			world.setBlock(x + 6, y + -1, z + -4, block3, 4, 2);
			world.setBlock(x + 6, y + -1, z + -3, block3, 4, 2);
			world.setBlock(x + 6, y + -1, z + -2, block4, 0, 2);
			world.setBlock(x + 6, y + -1, z + 2, block4, 0, 2);
			world.setBlock(x + 6, y + -1, z + 3, block3, 4, 2);
			world.setBlock(x + 6, y + -1, z + 4, block3, 4, 2);
			world.setBlock(x + 6, y + 0, z + -4, block3, 4, 2);
			world.setBlock(x + 6, y + 0, z + -3, block3, 4, 2);
			world.setBlock(x + 6, y + 0, z + 3, block3, 4, 2);
			world.setBlock(x + 6, y + 0, z + 4, block3, 4, 2);
			world.setBlock(x + 6, y + 1, z + -4, block3, 4, 2);
			world.setBlock(x + 6, y + 1, z + -3, block3, 4, 2);
			world.setBlock(x + 6, y + 1, z + -2, block4, 8, 2);
			world.setBlock(x + 6, y + 1, z + 2, block5, 3, 2);
			world.setBlock(x + 6, y + 1, z + 3, block3, 4, 2);
			world.setBlock(x + 6, y + 1, z + 4, block3, 4, 2);
			world.setBlock(x + 6, y + 2, z + -4, block2, 1, 2);
			world.setBlock(x + 6, y + 2, z + -3, block2, 1, 2);
			world.setBlock(x + 6, y + 2, z + -2, block3, 4, 2);
			world.setBlock(x + 6, y + 2, z + -1, block2, 4, 2);
			world.setBlock(x + 6, y + 2, z + 0, block2, 4, 2);
			world.setBlock(x + 6, y + 2, z + 1, block2, 4, 2);
			world.setBlock(x + 6, y + 2, z + 2, block3, 4, 2);
			world.setBlock(x + 6, y + 2, z + 3, block2, 1, 2);
			world.setBlock(x + 6, y + 2, z + 4, block2, 1, 2);
			world.setBlock(x + 6, y + 3, z + -1, block3, 4, 2);
			world.setBlock(x + 6, y + 3, z + 0, block3, 4, 2);
			world.setBlock(x + 6, y + 3, z + 1, block3, 4, 2);
			world.setBlock(x + 7, y + -2, z + -2, block2, 6, 2);
			world.setBlock(x + 7, y + -2, z + -1, block3, 4, 2);
			world.setBlock(x + 7, y + -2, z + 0, block3, 4, 2);
			world.setBlock(x + 7, y + -2, z + 1, block3, 4, 2);
			world.setBlock(x + 7, y + -2, z + 2, block2, 7, 2);
			world.setBlock(x + 7, y + -1, z + -2, block3, 4, 2);
			world.setBlock(x + 7, y + -1, z + 2, block3, 4, 2);
			world.setBlock(x + 7, y + 0, z + -2, block3, 4, 2);
			world.setBlock(x + 7, y + 0, z + 2, block3, 4, 2);
			world.setBlock(x + 7, y + 1, z + -2, block3, 4, 2);
			world.setBlock(x + 7, y + 1, z + 2, block3, 4, 2);
			world.setBlock(x + 7, y + 2, z + -2, block2, 2, 2);
			world.setBlock(x + 7, y + 2, z + -1, block3, 4, 2);
			world.setBlock(x + 7, y + 2, z + 0, block3, 4, 2);
			world.setBlock(x + 7, y + 2, z + 1, block3, 4, 2);
			world.setBlock(x + 7, y + 2, z + 2, block2, 3, 2);
			world.setBlock(x + 7, y + 3, z + -1, block2, 1, 2);
			world.setBlock(x + 7, y + 3, z + 0, block2, 1, 2);
			world.setBlock(x + 7, y + 3, z + 1, block2, 1, 2);
			world.setBlock(x + 8, y + -2, z + -2, block2, 6, 2);
			world.setBlock(x + 8, y + -2, z + -1, block3, 4, 2);
			world.setBlock(x + 8, y + -2, z + 0, block3, 4, 2);
			world.setBlock(x + 8, y + -2, z + 1, block3, 4, 2);
			world.setBlock(x + 8, y + -2, z + 2, block2, 7, 2);
			world.setBlock(x + 8, y + -1, z + -2, block3, 4, 2);
			world.setBlock(x + 8, y + -1, z + 2, block3, 4, 2);
			world.setBlock(x + 8, y + 0, z + -2, block3, 4, 2);
			// world.setBlock(x+8, y+0, z+0, block1,4,2);
			world.setBlock(x + 8, y + 0, z + 2, block3, 4, 2);
			world.setBlock(x + 8, y + 1, z + -2, block3, 4, 2);
			world.setBlock(x + 8, y + 1, z + 2, block3, 4, 2);
			world.setBlock(x + 8, y + 2, z + -2, block2, 2, 2);
			world.setBlock(x + 8, y + 2, z + -1, block3, 4, 2);
			world.setBlock(x + 8, y + 2, z + 0, block3, 4, 2);
			world.setBlock(x + 8, y + 2, z + 1, block3, 4, 2);
			world.setBlock(x + 8, y + 2, z + 2, block2, 3, 2);
			// world.setBlock(x+8, y+4, z+4, block1,14,2);
			
			// BuildHandler.buildInfoPoint(world, dir, getUnlocalizedName(),x+4,
			// y+-3, z+0,0,x,y,z);
			
			world.setBlock(x + 4, y + -3, z + 0, Blocks.air, 3, 2);
			
			int[] pos = new int[] { x, y, z };
			pos = ForgeDirectionUtils.IncreaseByDir(dir, pos, 2);
			pos = ForgeDirectionUtils.IncreaseByDir(ForgeDirectionUtils.turnClockwise(dir), pos, 2);
			world.setBlock(pos[0], pos[1], pos[2], Blocks.air, 0, 2);
			pos = ForgeDirectionUtils.IncreaseByDir(ForgeDirectionUtils.turnAgainstClockwise(dir), pos, 4);
			world.setBlock(pos[0], pos[1], pos[2], Blocks.air, 0, 2);
			pos = ForgeDirectionUtils.IncreaseByDir(dir, pos, 4);
			world.setBlock(pos[0], pos[1], pos[2], Blocks.air, 0, 2);
			pos = ForgeDirectionUtils.IncreaseByDir(ForgeDirectionUtils.turnClockwise(dir), pos, 4);
			world.setBlock(pos[0], pos[1], pos[2], Blocks.air, 0, 2);
			
		} else if (dir == ForgeDirection.SOUTH)
		{
			Block block2 = Blocks.air;
			Block block3 = Blocks.air;
			Block block6 = Blocks.air;
			Block block4 = Blocks.air;
			Block block5 = Blocks.air;
			
			// world.setBlock(x+-4, y+-3, z+0, block1,5,2);
			// Block block2 = id:454;
			world.setBlock(x + -4, y + -2, z + 2, block2, 6, 2);
			// Block block3 = id:432;
			world.setBlock(x + -4, y + -2, z + 3, block3, 4, 2);
			world.setBlock(x + -4, y + -2, z + 4, block3, 4, 2);
			world.setBlock(x + -4, y + -2, z + 5, block3, 4, 2);
			world.setBlock(x + -4, y + -2, z + 6, block2, 7, 2);
			world.setBlock(x + -4, y + -1, z + 2, block3, 4, 2);
			world.setBlock(x + -4, y + -1, z + 6, block3, 4, 2);
			world.setBlock(x + -4, y + 0, z + 2, block3, 4, 2);
			// world.setBlock(x+-4, y+0, z+4, block1,4,2);
			world.setBlock(x + -4, y + 0, z + 6, block3, 4, 2);
			world.setBlock(x + -4, y + 1, z + 2, block3, 4, 2);
			world.setBlock(x + -4, y + 1, z + 6, block3, 4, 2);
			world.setBlock(x + -4, y + 2, z + 2, block2, 2, 2);
			world.setBlock(x + -4, y + 2, z + 3, block3, 4, 2);
			world.setBlock(x + -4, y + 2, z + 4, block3, 4, 2);
			world.setBlock(x + -4, y + 2, z + 5, block3, 4, 2);
			world.setBlock(x + -4, y + 2, z + 6, block2, 3, 2);
			world.setBlock(x + -3, y + -2, z + 2, block2, 6, 2);
			world.setBlock(x + -3, y + -2, z + 3, block3, 4, 2);
			world.setBlock(x + -3, y + -2, z + 4, block3, 4, 2);
			world.setBlock(x + -3, y + -2, z + 5, block3, 4, 2);
			world.setBlock(x + -3, y + -2, z + 6, block2, 7, 2);
			world.setBlock(x + -3, y + -1, z + 2, block3, 4, 2);
			world.setBlock(x + -3, y + -1, z + 6, block3, 4, 2);
			world.setBlock(x + -3, y + 0, z + 2, block3, 4, 2);
			world.setBlock(x + -3, y + 0, z + 6, block3, 4, 2);
			world.setBlock(x + -3, y + 1, z + 2, block3, 4, 2);
			world.setBlock(x + -3, y + 1, z + 6, block3, 4, 2);
			world.setBlock(x + -3, y + 2, z + 2, block2, 2, 2);
			world.setBlock(x + -3, y + 2, z + 3, block3, 4, 2);
			world.setBlock(x + -3, y + 2, z + 4, block3, 4, 2);
			world.setBlock(x + -3, y + 2, z + 5, block3, 4, 2);
			world.setBlock(x + -3, y + 2, z + 6, block2, 3, 2);
			world.setBlock(x + -3, y + 3, z + 3, block2, 0, 2);
			world.setBlock(x + -3, y + 3, z + 4, block2, 0, 2);
			world.setBlock(x + -3, y + 3, z + 5, block2, 0, 2);
			world.setBlock(x + -2, y + -2, z + 0, block2, 4, 2);
			world.setBlock(x + -2, y + -2, z + 1, block2, 4, 2);
			world.setBlock(x + -2, y + -2, z + 2, block3, 4, 2);
			world.setBlock(x + -2, y + -2, z + 3, block3, 4, 2);
			world.setBlock(x + -2, y + -2, z + 4, block3, 4, 2);
			world.setBlock(x + -2, y + -2, z + 5, block3, 4, 2);
			world.setBlock(x + -2, y + -2, z + 6, block3, 4, 2);
			world.setBlock(x + -2, y + -2, z + 7, block2, 4, 2);
			world.setBlock(x + -2, y + -2, z + 8, block2, 4, 2);
			world.setBlock(x + -2, y + -1, z + 0, block3, 4, 2);
			world.setBlock(x + -2, y + -1, z + 1, block3, 4, 2);
			// Block block4 = id:459;
			world.setBlock(x + -2, y + -1, z + 2, block4, 0, 2);
			world.setBlock(x + -2, y + -1, z + 6, block4, 0, 2);
			world.setBlock(x + -2, y + -1, z + 7, block3, 4, 2);
			world.setBlock(x + -2, y + -1, z + 8, block3, 4, 2);
			world.setBlock(x + -2, y + 0, z + 0, block3, 4, 2);
			world.setBlock(x + -2, y + 0, z + 1, block3, 4, 2);
			world.setBlock(x + -2, y + 0, z + 7, block3, 4, 2);
			world.setBlock(x + -2, y + 0, z + 8, block3, 4, 2);
			world.setBlock(x + -2, y + 1, z + 0, block3, 4, 2);
			world.setBlock(x + -2, y + 1, z + 1, block3, 4, 2);
			// Block block5 = id:452;
			world.setBlock(x + -2, y + 1, z + 2, block5, 2, 2);
			world.setBlock(x + -2, y + 1, z + 6, block4, 8, 2);
			world.setBlock(x + -2, y + 1, z + 7, block3, 4, 2);
			world.setBlock(x + -2, y + 1, z + 8, block3, 4, 2);
			world.setBlock(x + -2, y + 2, z + 0, block2, 0, 2);
			world.setBlock(x + -2, y + 2, z + 1, block2, 0, 2);
			world.setBlock(x + -2, y + 2, z + 2, block3, 4, 2);
			world.setBlock(x + -2, y + 2, z + 3, block2, 5, 2);
			world.setBlock(x + -2, y + 2, z + 4, block2, 5, 2);
			world.setBlock(x + -2, y + 2, z + 5, block2, 5, 2);
			world.setBlock(x + -2, y + 2, z + 6, block3, 4, 2);
			world.setBlock(x + -2, y + 2, z + 7, block2, 0, 2);
			world.setBlock(x + -2, y + 2, z + 8, block2, 0, 2);
			world.setBlock(x + -2, y + 3, z + 3, block3, 4, 2);
			world.setBlock(x + -2, y + 3, z + 4, block3, 4, 2);
			world.setBlock(x + -2, y + 3, z + 5, block3, 4, 2);
			world.setBlock(x + -1, y + -2, z + 0, block3, 4, 2);
			world.setBlock(x + -1, y + -2, z + 1, block3, 4, 2);
			world.setBlock(x + -1, y + -2, z + 2, block3, 4, 2);
			world.setBlock(x + -1, y + -2, z + 3, block3, 4, 2);
			world.setBlock(x + -1, y + -2, z + 4, block3, 4, 2);
			world.setBlock(x + -1, y + -2, z + 5, block3, 4, 2);
			world.setBlock(x + -1, y + -2, z + 6, block3, 4, 2);
			world.setBlock(x + -1, y + -2, z + 7, block3, 4, 2);
			world.setBlock(x + -1, y + -2, z + 8, block3, 4, 2);
			world.setBlock(x + -1, y + 2, z + 0, block3, 4, 2);
			world.setBlock(x + -1, y + 2, z + 1, block3, 4, 2);
			world.setBlock(x + -1, y + 2, z + 2, block2, 7, 2);
			world.setBlock(x + -1, y + 2, z + 6, block2, 6, 2);
			world.setBlock(x + -1, y + 2, z + 7, block3, 4, 2);
			world.setBlock(x + -1, y + 2, z + 8, block3, 4, 2);
			world.setBlock(x + -1, y + 3, z + 1, block2, 2, 2);
			world.setBlock(x + -1, y + 3, z + 2, block3, 4, 2);
			world.setBlock(x + -1, y + 3, z + 3, block3, 4, 2);
			world.setBlock(x + -1, y + 3, z + 4, block3, 4, 2);
			world.setBlock(x + -1, y + 3, z + 5, block3, 4, 2);
			world.setBlock(x + -1, y + 3, z + 6, block3, 4, 2);
			world.setBlock(x + -1, y + 3, z + 7, block2, 3, 2);
			world.setBlock(x + 0, y + -2, z + 0, block3, 4, 2);
			world.setBlock(x + 0, y + -2, z + 1, block3, 4, 2);
			world.setBlock(x + 0, y + -2, z + 2, block3, 4, 2);
			world.setBlock(x + 0, y + -2, z + 3, block3, 4, 2);
			// Block block6 = id:505;
			world.setBlock(x + 0, y + -2, z + 4, block6, 0, 2);
			world.setBlock(x + 0, y + -2, z + 5, block3, 4, 2);
			world.setBlock(x + 0, y + -2, z + 6, block3, 4, 2);
			world.setBlock(x + 0, y + -2, z + 7, block3, 4, 2);
			world.setBlock(x + 0, y + -2, z + 8, block3, 4, 2);
			// world.setBlock(x+0, y+0, z+0, block1,4,2);
			// world.setBlock(x+0, y+0, z+8, block1,4,2);
			world.setBlock(x + 0, y + 2, z + 0, block3, 4, 2);
			world.setBlock(x + 0, y + 2, z + 1, block3, 4, 2);
			world.setBlock(x + 0, y + 2, z + 2, block2, 7, 2);
			world.setBlock(x + 0, y + 2, z + 6, block2, 6, 2);
			world.setBlock(x + 0, y + 2, z + 7, block3, 4, 2);
			world.setBlock(x + 0, y + 2, z + 8, block3, 4, 2);
			world.setBlock(x + 0, y + 3, z + 1, block2, 2, 2);
			world.setBlock(x + 0, y + 3, z + 2, block3, 4, 2);
			world.setBlock(x + 0, y + 3, z + 3, block3, 4, 2);
			world.setBlock(x + 0, y + 3, z + 4, block6, 0, 2);
			world.setBlock(x + 0, y + 3, z + 5, block3, 4, 2);
			world.setBlock(x + 0, y + 3, z + 6, block3, 4, 2);
			world.setBlock(x + 0, y + 3, z + 7, block2, 3, 2);
			world.setBlock(x + 1, y + -2, z + 0, block3, 4, 2);
			world.setBlock(x + 1, y + -2, z + 1, block3, 4, 2);
			world.setBlock(x + 1, y + -2, z + 2, block3, 4, 2);
			world.setBlock(x + 1, y + -2, z + 3, block3, 4, 2);
			world.setBlock(x + 1, y + -2, z + 4, block3, 4, 2);
			world.setBlock(x + 1, y + -2, z + 5, block3, 4, 2);
			world.setBlock(x + 1, y + -2, z + 6, block3, 4, 2);
			world.setBlock(x + 1, y + -2, z + 7, block3, 4, 2);
			world.setBlock(x + 1, y + -2, z + 8, block3, 4, 2);
			world.setBlock(x + 1, y + 2, z + 0, block3, 4, 2);
			world.setBlock(x + 1, y + 2, z + 1, block3, 4, 2);
			world.setBlock(x + 1, y + 2, z + 2, block2, 7, 2);
			world.setBlock(x + 1, y + 2, z + 6, block2, 6, 2);
			world.setBlock(x + 1, y + 2, z + 7, block3, 4, 2);
			world.setBlock(x + 1, y + 2, z + 8, block3, 4, 2);
			world.setBlock(x + 1, y + 3, z + 1, block2, 2, 2);
			world.setBlock(x + 1, y + 3, z + 2, block3, 4, 2);
			world.setBlock(x + 1, y + 3, z + 3, block3, 4, 2);
			world.setBlock(x + 1, y + 3, z + 4, block3, 4, 2);
			world.setBlock(x + 1, y + 3, z + 5, block3, 4, 2);
			world.setBlock(x + 1, y + 3, z + 6, block3, 4, 2);
			world.setBlock(x + 1, y + 3, z + 7, block2, 3, 2);
			world.setBlock(x + 2, y + -2, z + 0, block2, 5, 2);
			world.setBlock(x + 2, y + -2, z + 1, block2, 5, 2);
			world.setBlock(x + 2, y + -2, z + 2, block3, 4, 2);
			world.setBlock(x + 2, y + -2, z + 3, block3, 4, 2);
			world.setBlock(x + 2, y + -2, z + 4, block3, 4, 2);
			world.setBlock(x + 2, y + -2, z + 5, block3, 4, 2);
			world.setBlock(x + 2, y + -2, z + 6, block3, 4, 2);
			world.setBlock(x + 2, y + -2, z + 7, block2, 5, 2);
			world.setBlock(x + 2, y + -2, z + 8, block2, 5, 2);
			world.setBlock(x + 2, y + -1, z + 0, block3, 4, 2);
			world.setBlock(x + 2, y + -1, z + 1, block3, 4, 2);
			world.setBlock(x + 2, y + -1, z + 2, block4, 0, 2);
			world.setBlock(x + 2, y + -1, z + 6, block4, 0, 2);
			world.setBlock(x + 2, y + -1, z + 7, block3, 4, 2);
			world.setBlock(x + 2, y + -1, z + 8, block3, 4, 2);
			world.setBlock(x + 2, y + 0, z + 0, block3, 4, 2);
			world.setBlock(x + 2, y + 0, z + 1, block3, 4, 2);
			world.setBlock(x + 2, y + 0, z + 7, block3, 4, 2);
			world.setBlock(x + 2, y + 0, z + 8, block3, 4, 2);
			world.setBlock(x + 2, y + 1, z + 0, block3, 4, 2);
			world.setBlock(x + 2, y + 1, z + 1, block3, 4, 2);
			world.setBlock(x + 2, y + 1, z + 2, block4, 8, 2);
			world.setBlock(x + 2, y + 1, z + 6, block5, 3, 2);
			world.setBlock(x + 2, y + 1, z + 7, block3, 4, 2);
			world.setBlock(x + 2, y + 1, z + 8, block3, 4, 2);
			world.setBlock(x + 2, y + 2, z + 0, block2, 1, 2);
			world.setBlock(x + 2, y + 2, z + 1, block2, 1, 2);
			world.setBlock(x + 2, y + 2, z + 2, block3, 4, 2);
			world.setBlock(x + 2, y + 2, z + 3, block2, 4, 2);
			world.setBlock(x + 2, y + 2, z + 4, block2, 4, 2);
			world.setBlock(x + 2, y + 2, z + 5, block2, 4, 2);
			world.setBlock(x + 2, y + 2, z + 6, block3, 4, 2);
			world.setBlock(x + 2, y + 2, z + 7, block2, 1, 2);
			world.setBlock(x + 2, y + 2, z + 8, block2, 1, 2);
			world.setBlock(x + 2, y + 3, z + 3, block3, 4, 2);
			world.setBlock(x + 2, y + 3, z + 4, block3, 4, 2);
			world.setBlock(x + 2, y + 3, z + 5, block3, 4, 2);
			world.setBlock(x + 3, y + -2, z + 2, block2, 6, 2);
			world.setBlock(x + 3, y + -2, z + 3, block3, 4, 2);
			world.setBlock(x + 3, y + -2, z + 4, block3, 4, 2);
			world.setBlock(x + 3, y + -2, z + 5, block3, 4, 2);
			world.setBlock(x + 3, y + -2, z + 6, block2, 7, 2);
			world.setBlock(x + 3, y + -1, z + 2, block3, 4, 2);
			world.setBlock(x + 3, y + -1, z + 6, block3, 4, 2);
			world.setBlock(x + 3, y + 0, z + 2, block3, 4, 2);
			world.setBlock(x + 3, y + 0, z + 6, block3, 4, 2);
			world.setBlock(x + 3, y + 1, z + 2, block3, 4, 2);
			world.setBlock(x + 3, y + 1, z + 6, block3, 4, 2);
			world.setBlock(x + 3, y + 2, z + 2, block2, 2, 2);
			world.setBlock(x + 3, y + 2, z + 3, block3, 4, 2);
			world.setBlock(x + 3, y + 2, z + 4, block3, 4, 2);
			world.setBlock(x + 3, y + 2, z + 5, block3, 4, 2);
			world.setBlock(x + 3, y + 2, z + 6, block2, 3, 2);
			world.setBlock(x + 3, y + 3, z + 3, block2, 1, 2);
			world.setBlock(x + 3, y + 3, z + 4, block2, 1, 2);
			world.setBlock(x + 3, y + 3, z + 5, block2, 1, 2);
			world.setBlock(x + 4, y + -2, z + 2, block2, 6, 2);
			world.setBlock(x + 4, y + -2, z + 3, block3, 4, 2);
			world.setBlock(x + 4, y + -2, z + 4, block3, 4, 2);
			world.setBlock(x + 4, y + -2, z + 5, block3, 4, 2);
			world.setBlock(x + 4, y + -2, z + 6, block2, 7, 2);
			world.setBlock(x + 4, y + -1, z + 2, block3, 4, 2);
			world.setBlock(x + 4, y + -1, z + 6, block3, 4, 2);
			world.setBlock(x + 4, y + 0, z + 2, block3, 4, 2);
			// world.setBlock(x+4, y+0, z+4, block1,4,2);
			world.setBlock(x + 4, y + 0, z + 6, block3, 4, 2);
			world.setBlock(x + 4, y + 1, z + 2, block3, 4, 2);
			world.setBlock(x + 4, y + 1, z + 6, block3, 4, 2);
			world.setBlock(x + 4, y + 2, z + 2, block2, 2, 2);
			world.setBlock(x + 4, y + 2, z + 3, block3, 4, 2);
			world.setBlock(x + 4, y + 2, z + 4, block3, 4, 2);
			world.setBlock(x + 4, y + 2, z + 5, block3, 4, 2);
			world.setBlock(x + 4, y + 2, z + 6, block2, 3, 2);
			// world.setBlock(x+4, y+4, z+8, block1,14,2);
			// BuildHandler.buildInfoPoint(world, dir, getUnlocalizedName(),x+0,
			// y+-3, z+4, 0,x,y,z);
			
			world.setBlock(x + 0, y + -3, z + 4, Blocks.air, 3, 2);
			
			int[] pos = new int[] { x, y, z };
			pos = ForgeDirectionUtils.IncreaseByDir(dir, pos, 2);
			pos = ForgeDirectionUtils.IncreaseByDir(ForgeDirectionUtils.turnClockwise(dir), pos, 2);
			world.setBlock(pos[0], pos[1], pos[2], Blocks.air, 0, 2);
			pos = ForgeDirectionUtils.IncreaseByDir(ForgeDirectionUtils.turnAgainstClockwise(dir), pos, 4);
			world.setBlock(pos[0], pos[1], pos[2], Blocks.air, 0, 2);
			pos = ForgeDirectionUtils.IncreaseByDir(dir, pos, 4);
			world.setBlock(pos[0], pos[1], pos[2], Blocks.air, 0, 2);
			pos = ForgeDirectionUtils.IncreaseByDir(ForgeDirectionUtils.turnClockwise(dir), pos, 4);
			world.setBlock(pos[0], pos[1], pos[2], Blocks.air, 0, 2);
			
		}
	}
	
	@Override
	public void Build(World world, ForgeDirection dir, int x, int y, int z)
	{
		
		if (dir == ForgeDirection.WEST)
		{
			// world.setBlock(x+-8, y+-3, z+-4, block1,5,2);
			Block block2 = GCBlocks.tinStairs1;
			world.setBlock(x + -8, y + -2, z + -2, block2, 6, 2);
			Block block3 = GCBlocks.basicBlock;
			world.setBlock(x + -8, y + -2, z + -1, block3, 4, 2);
			world.setBlock(x + -8, y + -2, z + 0, block3, 4, 2);
			world.setBlock(x + -8, y + -2, z + 1, block3, 4, 2);
			world.setBlock(x + -8, y + -2, z + 2, block2, 7, 2);
			world.setBlock(x + -8, y + -1, z + -2, block3, 4, 2);
			world.setBlock(x + -8, y + -1, z + 2, block3, 4, 2);
			world.setBlock(x + -8, y + 0, z + -2, block3, 4, 2);
			// world.setBlock(x+-8, y+0, z+0, block1,4,2);
			world.setBlock(x + -8, y + 0, z + 2, block3, 4, 2);
			world.setBlock(x + -8, y + 1, z + -2, block3, 4, 2);
			world.setBlock(x + -8, y + 1, z + 2, block3, 4, 2);
			world.setBlock(x + -8, y + 2, z + -2, block2, 2, 2);
			world.setBlock(x + -8, y + 2, z + -1, block3, 4, 2);
			world.setBlock(x + -8, y + 2, z + 0, block3, 4, 2);
			world.setBlock(x + -8, y + 2, z + 1, block3, 4, 2);
			world.setBlock(x + -8, y + 2, z + 2, block2, 3, 2);
			world.setBlock(x + -7, y + -2, z + -2, block2, 6, 2);
			world.setBlock(x + -7, y + -2, z + -1, block3, 4, 2);
			world.setBlock(x + -7, y + -2, z + 0, block3, 4, 2);
			world.setBlock(x + -7, y + -2, z + 1, block3, 4, 2);
			world.setBlock(x + -7, y + -2, z + 2, block2, 7, 2);
			world.setBlock(x + -7, y + -1, z + -2, block3, 4, 2);
			world.setBlock(x + -7, y + -1, z + 2, block3, 4, 2);
			world.setBlock(x + -7, y + 0, z + -2, block3, 4, 2);
			world.setBlock(x + -7, y + 0, z + 2, block3, 4, 2);
			world.setBlock(x + -7, y + 1, z + -2, block3, 4, 2);
			world.setBlock(x + -7, y + 1, z + 2, block3, 4, 2);
			world.setBlock(x + -7, y + 2, z + -2, block2, 2, 2);
			world.setBlock(x + -7, y + 2, z + -1, block3, 4, 2);
			world.setBlock(x + -7, y + 2, z + 0, block3, 4, 2);
			world.setBlock(x + -7, y + 2, z + 1, block3, 4, 2);
			world.setBlock(x + -7, y + 2, z + 2, block2, 3, 2);
			world.setBlock(x + -7, y + 3, z + -1, block2, 0, 2);
			world.setBlock(x + -7, y + 3, z + 0, block2, 0, 2);
			world.setBlock(x + -7, y + 3, z + 1, block2, 0, 2);
			world.setBlock(x + -6, y + -2, z + -4, block2, 4, 2);
			world.setBlock(x + -6, y + -2, z + -3, block2, 4, 2);
			world.setBlock(x + -6, y + -2, z + -2, block3, 4, 2);
			world.setBlock(x + -6, y + -2, z + -1, block3, 4, 2);
			world.setBlock(x + -6, y + -2, z + 0, block3, 4, 2);
			world.setBlock(x + -6, y + -2, z + 1, block3, 4, 2);
			world.setBlock(x + -6, y + -2, z + 2, block3, 4, 2);
			world.setBlock(x + -6, y + -2, z + 3, block2, 4, 2);
			world.setBlock(x + -6, y + -2, z + 4, block2, 4, 2);
			world.setBlock(x + -6, y + -1, z + -4, block3, 4, 2);
			world.setBlock(x + -6, y + -1, z + -3, block3, 4, 2);
			Block block4 = GCBlocks.slabGCHalf;
			world.setBlock(x + -6, y + -1, z + -2, block4, 0, 2);
			world.setBlock(x + -6, y + -1, z + 2, block4, 0, 2);
			world.setBlock(x + -6, y + -1, z + 3, block3, 4, 2);
			world.setBlock(x + -6, y + -1, z + 4, block3, 4, 2);
			world.setBlock(x + -6, y + 0, z + -4, block3, 4, 2);
			world.setBlock(x + -6, y + 0, z + -3, block3, 4, 2);
			world.setBlock(x + -6, y + 0, z + 3, block3, 4, 2);
			world.setBlock(x + -6, y + 0, z + 4, block3, 4, 2);
			world.setBlock(x + -6, y + 1, z + -4, block3, 4, 2);
			world.setBlock(x + -6, y + 1, z + -3, block3, 4, 2);
			Block block5 = GCBlocks.brightLamp;
			world.setBlock(x + -6, y + 1, z + -2, block5, 2, 2);
			world.setBlock(x + -6, y + 1, z + 2, block4, 8, 2);
			world.setBlock(x + -6, y + 1, z + 3, block3, 4, 2);
			world.setBlock(x + -6, y + 1, z + 4, block3, 4, 2);
			world.setBlock(x + -6, y + 2, z + -4, block2, 0, 2);
			world.setBlock(x + -6, y + 2, z + -3, block2, 0, 2);
			world.setBlock(x + -6, y + 2, z + -2, block3, 4, 2);
			world.setBlock(x + -6, y + 2, z + -1, block2, 5, 2);
			world.setBlock(x + -6, y + 2, z + 0, block2, 5, 2);
			world.setBlock(x + -6, y + 2, z + 1, block2, 5, 2);
			world.setBlock(x + -6, y + 2, z + 2, block3, 4, 2);
			world.setBlock(x + -6, y + 2, z + 3, block2, 0, 2);
			world.setBlock(x + -6, y + 2, z + 4, block2, 0, 2);
			world.setBlock(x + -6, y + 3, z + -1, block3, 4, 2);
			world.setBlock(x + -6, y + 3, z + 0, block3, 4, 2);
			world.setBlock(x + -6, y + 3, z + 1, block3, 4, 2);
			world.setBlock(x + -5, y + -2, z + -4, block3, 4, 2);
			world.setBlock(x + -5, y + -2, z + -3, block3, 4, 2);
			world.setBlock(x + -5, y + -2, z + -2, block3, 4, 2);
			world.setBlock(x + -5, y + -2, z + -1, block3, 4, 2);
			world.setBlock(x + -5, y + -2, z + 0, block3, 4, 2);
			world.setBlock(x + -5, y + -2, z + 1, block3, 4, 2);
			world.setBlock(x + -5, y + -2, z + 2, block3, 4, 2);
			world.setBlock(x + -5, y + -2, z + 3, block3, 4, 2);
			world.setBlock(x + -5, y + -2, z + 4, block3, 4, 2);
			world.setBlock(x + -5, y + 2, z + -4, block3, 4, 2);
			world.setBlock(x + -5, y + 2, z + -3, block3, 4, 2);
			world.setBlock(x + -5, y + 2, z + -2, block2, 7, 2);
			world.setBlock(x + -5, y + 2, z + 2, block2, 6, 2);
			world.setBlock(x + -5, y + 2, z + 3, block3, 4, 2);
			world.setBlock(x + -5, y + 2, z + 4, block3, 4, 2);
			world.setBlock(x + -5, y + 3, z + -3, block2, 2, 2);
			world.setBlock(x + -5, y + 3, z + -2, block3, 4, 2);
			world.setBlock(x + -5, y + 3, z + -1, block3, 4, 2);
			world.setBlock(x + -5, y + 3, z + 0, block3, 4, 2);
			world.setBlock(x + -5, y + 3, z + 1, block3, 4, 2);
			world.setBlock(x + -5, y + 3, z + 2, block3, 4, 2);
			world.setBlock(x + -5, y + 3, z + 3, block2, 3, 2);
			world.setBlock(x + -4, y + -2, z + -4, block3, 4, 2);
			world.setBlock(x + -4, y + -2, z + -3, block3, 4, 2);
			world.setBlock(x + -4, y + -2, z + -2, block3, 4, 2);
			world.setBlock(x + -4, y + -2, z + -1, block3, 4, 2);
			BuildHandler.buildBuildPoint(world, x - 4, y - 2, z, 2);
			// world.setTileEntity(p_147455_1_, p_147455_2_, p_147455_3_,
			// p_147455_4_);
			world.setBlock(x + -4, y + -2, z + 1, block3, 4, 2);
			world.setBlock(x + -4, y + -2, z + 2, block3, 4, 2);
			world.setBlock(x + -4, y + -2, z + 3, block3, 4, 2);
			world.setBlock(x + -4, y + -2, z + 4, block3, 4, 2);
			// world.setBlock(x+-4, y+0, z+-4, block1,4,2);
			// world.setBlock(x+-4, y+0, z+4, block1,4,2);
			world.setBlock(x + -4, y + 2, z + -4, block3, 4, 2);
			world.setBlock(x + -4, y + 2, z + -3, block3, 4, 2);
			world.setBlock(x + -4, y + 2, z + -2, block2, 7, 2);
			world.setBlock(x + -4, y + 2, z + 2, block2, 6, 2);
			world.setBlock(x + -4, y + 2, z + 3, block3, 4, 2);
			world.setBlock(x + -4, y + 2, z + 4, block3, 4, 2);
			world.setBlock(x + -4, y + 3, z + -3, block2, 2, 2);
			world.setBlock(x + -4, y + 3, z + -2, block3, 4, 2);
			world.setBlock(x + -4, y + 3, z + -1, block3, 4, 2);
			BuildHandler.buildBuildPoint(world, x - 4, y + 3, z, 4);
			world.setBlock(x + -4, y + 3, z + 1, block3, 4, 2);
			world.setBlock(x + -4, y + 3, z + 2, block3, 4, 2);
			world.setBlock(x + -4, y + 3, z + 3, block2, 3, 2);
			world.setBlock(x + -3, y + -2, z + -4, block3, 4, 2);
			world.setBlock(x + -3, y + -2, z + -3, block3, 4, 2);
			world.setBlock(x + -3, y + -2, z + -2, block3, 4, 2);
			world.setBlock(x + -3, y + -2, z + -1, block3, 4, 2);
			world.setBlock(x + -3, y + -2, z + 0, block3, 4, 2);
			world.setBlock(x + -3, y + -2, z + 1, block3, 4, 2);
			world.setBlock(x + -3, y + -2, z + 2, block3, 4, 2);
			world.setBlock(x + -3, y + -2, z + 3, block3, 4, 2);
			world.setBlock(x + -3, y + -2, z + 4, block3, 4, 2);
			world.setBlock(x + -3, y + 2, z + -4, block3, 4, 2);
			world.setBlock(x + -3, y + 2, z + -3, block3, 4, 2);
			world.setBlock(x + -3, y + 2, z + -2, block2, 7, 2);
			world.setBlock(x + -3, y + 2, z + 2, block2, 6, 2);
			world.setBlock(x + -3, y + 2, z + 3, block3, 4, 2);
			world.setBlock(x + -3, y + 2, z + 4, block3, 4, 2);
			world.setBlock(x + -3, y + 3, z + -3, block2, 2, 2);
			world.setBlock(x + -3, y + 3, z + -2, block3, 4, 2);
			world.setBlock(x + -3, y + 3, z + -1, block3, 4, 2);
			world.setBlock(x + -3, y + 3, z + 0, block3, 4, 2);
			world.setBlock(x + -3, y + 3, z + 1, block3, 4, 2);
			world.setBlock(x + -3, y + 3, z + 2, block3, 4, 2);
			world.setBlock(x + -3, y + 3, z + 3, block2, 3, 2);
			world.setBlock(x + -2, y + -2, z + -4, block2, 5, 2);
			world.setBlock(x + -2, y + -2, z + -3, block2, 5, 2);
			world.setBlock(x + -2, y + -2, z + -2, block3, 4, 2);
			world.setBlock(x + -2, y + -2, z + -1, block3, 4, 2);
			world.setBlock(x + -2, y + -2, z + 0, block3, 4, 2);
			world.setBlock(x + -2, y + -2, z + 1, block3, 4, 2);
			world.setBlock(x + -2, y + -2, z + 2, block3, 4, 2);
			world.setBlock(x + -2, y + -2, z + 3, block2, 5, 2);
			world.setBlock(x + -2, y + -2, z + 4, block2, 5, 2);
			world.setBlock(x + -2, y + -1, z + -4, block3, 4, 2);
			world.setBlock(x + -2, y + -1, z + -3, block3, 4, 2);
			world.setBlock(x + -2, y + -1, z + -2, block4, 0, 2);
			world.setBlock(x + -2, y + -1, z + 2, block4, 0, 2);
			world.setBlock(x + -2, y + -1, z + 3, block3, 4, 2);
			world.setBlock(x + -2, y + -1, z + 4, block3, 4, 2);
			world.setBlock(x + -2, y + 0, z + -4, block3, 4, 2);
			world.setBlock(x + -2, y + 0, z + -3, block3, 4, 2);
			world.setBlock(x + -2, y + 0, z + 3, block3, 4, 2);
			world.setBlock(x + -2, y + 0, z + 4, block3, 4, 2);
			world.setBlock(x + -2, y + 1, z + -4, block3, 4, 2);
			world.setBlock(x + -2, y + 1, z + -3, block3, 4, 2);
			world.setBlock(x + -2, y + 1, z + -2, block4, 8, 2);
			world.setBlock(x + -2, y + 1, z + 2, block5, 3, 2);
			world.setBlock(x + -2, y + 1, z + 3, block3, 4, 2);
			world.setBlock(x + -2, y + 1, z + 4, block3, 4, 2);
			world.setBlock(x + -2, y + 2, z + -4, block2, 1, 2);
			world.setBlock(x + -2, y + 2, z + -3, block2, 1, 2);
			world.setBlock(x + -2, y + 2, z + -2, block3, 4, 2);
			world.setBlock(x + -2, y + 2, z + -1, block2, 4, 2);
			world.setBlock(x + -2, y + 2, z + 0, block2, 4, 2);
			world.setBlock(x + -2, y + 2, z + 1, block2, 4, 2);
			world.setBlock(x + -2, y + 2, z + 2, block3, 4, 2);
			world.setBlock(x + -2, y + 2, z + 3, block2, 1, 2);
			world.setBlock(x + -2, y + 2, z + 4, block2, 1, 2);
			world.setBlock(x + -2, y + 3, z + -1, block3, 4, 2);
			world.setBlock(x + -2, y + 3, z + 0, block3, 4, 2);
			world.setBlock(x + -2, y + 3, z + 1, block3, 4, 2);
			world.setBlock(x + -1, y + -2, z + -2, block2, 6, 2);
			world.setBlock(x + -1, y + -2, z + -1, block3, 4, 2);
			world.setBlock(x + -1, y + -2, z + 0, block3, 4, 2);
			world.setBlock(x + -1, y + -2, z + 1, block3, 4, 2);
			world.setBlock(x + -1, y + -2, z + 2, block2, 7, 2);
			world.setBlock(x + -1, y + -1, z + -2, block3, 4, 2);
			world.setBlock(x + -1, y + -1, z + 2, block3, 4, 2);
			world.setBlock(x + -1, y + 0, z + -2, block3, 4, 2);
			world.setBlock(x + -1, y + 0, z + 2, block3, 4, 2);
			world.setBlock(x + -1, y + 1, z + -2, block3, 4, 2);
			world.setBlock(x + -1, y + 1, z + 2, block3, 4, 2);
			world.setBlock(x + -1, y + 2, z + -2, block2, 2, 2);
			world.setBlock(x + -1, y + 2, z + -1, block3, 4, 2);
			world.setBlock(x + -1, y + 2, z + 0, block3, 4, 2);
			world.setBlock(x + -1, y + 2, z + 1, block3, 4, 2);
			world.setBlock(x + -1, y + 2, z + 2, block2, 3, 2);
			world.setBlock(x + -1, y + 3, z + -1, block2, 1, 2);
			world.setBlock(x + -1, y + 3, z + 0, block2, 1, 2);
			world.setBlock(x + -1, y + 3, z + 1, block2, 1, 2);
			world.setBlock(x + 0, y + -2, z + -2, block2, 6, 2);
			world.setBlock(x + 0, y + -2, z + -1, block3, 4, 2);
			world.setBlock(x + 0, y + -2, z + 0, block3, 4, 2);
			world.setBlock(x + 0, y + -2, z + 1, block3, 4, 2);
			world.setBlock(x + 0, y + -2, z + 2, block2, 7, 2);
			world.setBlock(x + 0, y + -1, z + -2, block3, 4, 2);
			world.setBlock(x + 0, y + -1, z + 2, block3, 4, 2);
			world.setBlock(x + 0, y + 0, z + -2, block3, 4, 2);
			// world.setBlock(x+0, y+0, z+0, block1,4,2);
			world.setBlock(x + 0, y + 0, z + 2, block3, 4, 2);
			world.setBlock(x + 0, y + 1, z + -2, block3, 4, 2);
			world.setBlock(x + 0, y + 1, z + 2, block3, 4, 2);
			world.setBlock(x + 0, y + 2, z + -2, block2, 2, 2);
			world.setBlock(x + 0, y + 2, z + -1, block3, 4, 2);
			world.setBlock(x + 0, y + 2, z + 0, block3, 4, 2);
			world.setBlock(x + 0, y + 2, z + 1, block3, 4, 2);
			world.setBlock(x + 0, y + 2, z + 2, block2, 3, 2);
			// world.setBlock(x+0, y+4, z+4, block1,14,2);
			BuildHandler.buildInfoPoint(world, dir, getUnlocalizedName(), x + -4, y + -3, z + 0, 0, x, y, z);
			
			int[] pos = new int[] { x, y, z };
			pos = ForgeDirectionUtils.IncreaseByDir(dir, pos, 2);
			pos = ForgeDirectionUtils.IncreaseByDir(ForgeDirectionUtils.turnClockwise(dir), pos, 2);
			
			BuildHandler.buildRemoveInfoPoint(world, dir, getUnlocalizedName(), pos[0], pos[1], pos[2], 0, x + -4, y + -3, z + 0);
			
		} else if (dir == ForgeDirection.NORTH)
		{
			// world.setBlock(x+-4, y+-3, z+-8, block1,5,2);
			Block block2 = GCBlocks.tinStairs1;
			world.setBlock(x + -4, y + -2, z + -6, block2, 6, 2);
			Block block3 = GCBlocks.basicBlock;
			world.setBlock(x + -4, y + -2, z + -5, block3, 4, 2);
			world.setBlock(x + -4, y + -2, z + -4, block3, 4, 2);
			world.setBlock(x + -4, y + -2, z + -3, block3, 4, 2);
			world.setBlock(x + -4, y + -2, z + -2, block2, 7, 2);
			world.setBlock(x + -4, y + -1, z + -6, block3, 4, 2);
			world.setBlock(x + -4, y + -1, z + -2, block3, 4, 2);
			world.setBlock(x + -4, y + 0, z + -6, block3, 4, 2);
			// world.setBlock(x+-4, y+0, z+-4, block1,4,2);
			world.setBlock(x + -4, y + 0, z + -2, block3, 4, 2);
			world.setBlock(x + -4, y + 1, z + -6, block3, 4, 2);
			world.setBlock(x + -4, y + 1, z + -2, block3, 4, 2);
			world.setBlock(x + -4, y + 2, z + -6, block2, 2, 2);
			world.setBlock(x + -4, y + 2, z + -5, block3, 4, 2);
			world.setBlock(x + -4, y + 2, z + -4, block3, 4, 2);
			world.setBlock(x + -4, y + 2, z + -3, block3, 4, 2);
			world.setBlock(x + -4, y + 2, z + -2, block2, 3, 2);
			world.setBlock(x + -3, y + -2, z + -6, block2, 6, 2);
			world.setBlock(x + -3, y + -2, z + -5, block3, 4, 2);
			world.setBlock(x + -3, y + -2, z + -4, block3, 4, 2);
			world.setBlock(x + -3, y + -2, z + -3, block3, 4, 2);
			world.setBlock(x + -3, y + -2, z + -2, block2, 7, 2);
			world.setBlock(x + -3, y + -1, z + -6, block3, 4, 2);
			world.setBlock(x + -3, y + -1, z + -2, block3, 4, 2);
			world.setBlock(x + -3, y + 0, z + -6, block3, 4, 2);
			world.setBlock(x + -3, y + 0, z + -2, block3, 4, 2);
			world.setBlock(x + -3, y + 1, z + -6, block3, 4, 2);
			world.setBlock(x + -3, y + 1, z + -2, block3, 4, 2);
			world.setBlock(x + -3, y + 2, z + -6, block2, 2, 2);
			world.setBlock(x + -3, y + 2, z + -5, block3, 4, 2);
			world.setBlock(x + -3, y + 2, z + -4, block3, 4, 2);
			world.setBlock(x + -3, y + 2, z + -3, block3, 4, 2);
			world.setBlock(x + -3, y + 2, z + -2, block2, 3, 2);
			world.setBlock(x + -3, y + 3, z + -5, block2, 0, 2);
			world.setBlock(x + -3, y + 3, z + -4, block2, 0, 2);
			world.setBlock(x + -3, y + 3, z + -3, block2, 0, 2);
			world.setBlock(x + -2, y + -2, z + -8, block2, 4, 2);
			world.setBlock(x + -2, y + -2, z + -7, block2, 4, 2);
			world.setBlock(x + -2, y + -2, z + -6, block3, 4, 2);
			world.setBlock(x + -2, y + -2, z + -5, block3, 4, 2);
			world.setBlock(x + -2, y + -2, z + -4, block3, 4, 2);
			world.setBlock(x + -2, y + -2, z + -3, block3, 4, 2);
			world.setBlock(x + -2, y + -2, z + -2, block3, 4, 2);
			world.setBlock(x + -2, y + -2, z + -1, block2, 4, 2);
			world.setBlock(x + -2, y + -2, z + 0, block2, 4, 2);
			world.setBlock(x + -2, y + -1, z + -8, block3, 4, 2);
			world.setBlock(x + -2, y + -1, z + -7, block3, 4, 2);
			Block block4 = GCBlocks.slabGCHalf;
			world.setBlock(x + -2, y + -1, z + -6, block4, 0, 2);
			world.setBlock(x + -2, y + -1, z + -2, block4, 0, 2);
			world.setBlock(x + -2, y + -1, z + -1, block3, 4, 2);
			world.setBlock(x + -2, y + -1, z + 0, block3, 4, 2);
			world.setBlock(x + -2, y + 0, z + -8, block3, 4, 2);
			world.setBlock(x + -2, y + 0, z + -7, block3, 4, 2);
			world.setBlock(x + -2, y + 0, z + -1, block3, 4, 2);
			world.setBlock(x + -2, y + 0, z + 0, block3, 4, 2);
			world.setBlock(x + -2, y + 1, z + -8, block3, 4, 2);
			world.setBlock(x + -2, y + 1, z + -7, block3, 4, 2);
			Block block5 = GCBlocks.brightLamp;
			world.setBlock(x + -2, y + 1, z + -6, block5, 2, 2);
			world.setBlock(x + -2, y + 1, z + -2, block4, 8, 2);
			world.setBlock(x + -2, y + 1, z + -1, block3, 4, 2);
			world.setBlock(x + -2, y + 1, z + 0, block3, 4, 2);
			world.setBlock(x + -2, y + 2, z + -8, block2, 0, 2);
			world.setBlock(x + -2, y + 2, z + -7, block2, 0, 2);
			world.setBlock(x + -2, y + 2, z + -6, block3, 4, 2);
			world.setBlock(x + -2, y + 2, z + -5, block2, 5, 2);
			world.setBlock(x + -2, y + 2, z + -4, block2, 5, 2);
			world.setBlock(x + -2, y + 2, z + -3, block2, 5, 2);
			world.setBlock(x + -2, y + 2, z + -2, block3, 4, 2);
			world.setBlock(x + -2, y + 2, z + -1, block2, 0, 2);
			world.setBlock(x + -2, y + 2, z + 0, block2, 0, 2);
			world.setBlock(x + -2, y + 3, z + -5, block3, 4, 2);
			world.setBlock(x + -2, y + 3, z + -4, block3, 4, 2);
			world.setBlock(x + -2, y + 3, z + -3, block3, 4, 2);
			world.setBlock(x + -1, y + -2, z + -8, block3, 4, 2);
			world.setBlock(x + -1, y + -2, z + -7, block3, 4, 2);
			world.setBlock(x + -1, y + -2, z + -6, block3, 4, 2);
			world.setBlock(x + -1, y + -2, z + -5, block3, 4, 2);
			world.setBlock(x + -1, y + -2, z + -4, block3, 4, 2);
			world.setBlock(x + -1, y + -2, z + -3, block3, 4, 2);
			world.setBlock(x + -1, y + -2, z + -2, block3, 4, 2);
			world.setBlock(x + -1, y + -2, z + -1, block3, 4, 2);
			world.setBlock(x + -1, y + -2, z + 0, block3, 4, 2);
			world.setBlock(x + -1, y + 2, z + -8, block3, 4, 2);
			world.setBlock(x + -1, y + 2, z + -7, block3, 4, 2);
			world.setBlock(x + -1, y + 2, z + -6, block2, 7, 2);
			world.setBlock(x + -1, y + 2, z + -2, block2, 6, 2);
			world.setBlock(x + -1, y + 2, z + -1, block3, 4, 2);
			world.setBlock(x + -1, y + 2, z + 0, block3, 4, 2);
			world.setBlock(x + -1, y + 3, z + -7, block2, 2, 2);
			world.setBlock(x + -1, y + 3, z + -6, block3, 4, 2);
			world.setBlock(x + -1, y + 3, z + -5, block3, 4, 2);
			world.setBlock(x + -1, y + 3, z + -4, block3, 4, 2);
			world.setBlock(x + -1, y + 3, z + -3, block3, 4, 2);
			world.setBlock(x + -1, y + 3, z + -2, block3, 4, 2);
			world.setBlock(x + -1, y + 3, z + -1, block2, 3, 2);
			world.setBlock(x + 0, y + -2, z + -8, block3, 4, 2);
			world.setBlock(x + 0, y + -2, z + -7, block3, 4, 2);
			world.setBlock(x + 0, y + -2, z + -6, block3, 4, 2);
			world.setBlock(x + 0, y + -2, z + -5, block3, 4, 2);
			BuildHandler.buildBuildPoint(world, x, y - 2, z - 4, 2);
			world.setBlock(x + 0, y + -2, z + -3, block3, 4, 2);
			world.setBlock(x + 0, y + -2, z + -2, block3, 4, 2);
			world.setBlock(x + 0, y + -2, z + -1, block3, 4, 2);
			world.setBlock(x + 0, y + -2, z + 0, block3, 4, 2);
			// world.setBlock(x+0, y+0, z+-8, block1,4,2);
			// world.setBlock(x+0, y+0, z+0, block1,4,2);
			world.setBlock(x + 0, y + 2, z + -8, block3, 4, 2);
			world.setBlock(x + 0, y + 2, z + -7, block3, 4, 2);
			world.setBlock(x + 0, y + 2, z + -6, block2, 7, 2);
			world.setBlock(x + 0, y + 2, z + -2, block2, 6, 2);
			world.setBlock(x + 0, y + 2, z + -1, block3, 4, 2);
			world.setBlock(x + 0, y + 2, z + 0, block3, 4, 2);
			world.setBlock(x + 0, y + 3, z + -7, block2, 2, 2);
			world.setBlock(x + 0, y + 3, z + -6, block3, 4, 2);
			world.setBlock(x + 0, y + 3, z + -5, block3, 4, 2);
			BuildHandler.buildBuildPoint(world, x, y + 3, z - 4, 4);
			world.setBlock(x + 0, y + 3, z + -3, block3, 4, 2);
			world.setBlock(x + 0, y + 3, z + -2, block3, 4, 2);
			world.setBlock(x + 0, y + 3, z + -1, block2, 3, 2);
			world.setBlock(x + 1, y + -2, z + -8, block3, 4, 2);
			world.setBlock(x + 1, y + -2, z + -7, block3, 4, 2);
			world.setBlock(x + 1, y + -2, z + -6, block3, 4, 2);
			world.setBlock(x + 1, y + -2, z + -5, block3, 4, 2);
			world.setBlock(x + 1, y + -2, z + -4, block3, 4, 2);
			world.setBlock(x + 1, y + -2, z + -3, block3, 4, 2);
			world.setBlock(x + 1, y + -2, z + -2, block3, 4, 2);
			world.setBlock(x + 1, y + -2, z + -1, block3, 4, 2);
			world.setBlock(x + 1, y + -2, z + 0, block3, 4, 2);
			world.setBlock(x + 1, y + 2, z + -8, block3, 4, 2);
			world.setBlock(x + 1, y + 2, z + -7, block3, 4, 2);
			world.setBlock(x + 1, y + 2, z + -6, block2, 7, 2);
			world.setBlock(x + 1, y + 2, z + -2, block2, 6, 2);
			world.setBlock(x + 1, y + 2, z + -1, block3, 4, 2);
			world.setBlock(x + 1, y + 2, z + 0, block3, 4, 2);
			world.setBlock(x + 1, y + 3, z + -7, block2, 2, 2);
			world.setBlock(x + 1, y + 3, z + -6, block3, 4, 2);
			world.setBlock(x + 1, y + 3, z + -5, block3, 4, 2);
			world.setBlock(x + 1, y + 3, z + -4, block3, 4, 2);
			world.setBlock(x + 1, y + 3, z + -3, block3, 4, 2);
			world.setBlock(x + 1, y + 3, z + -2, block3, 4, 2);
			world.setBlock(x + 1, y + 3, z + -1, block2, 3, 2);
			world.setBlock(x + 2, y + -2, z + -8, block2, 5, 2);
			world.setBlock(x + 2, y + -2, z + -7, block2, 5, 2);
			world.setBlock(x + 2, y + -2, z + -6, block3, 4, 2);
			world.setBlock(x + 2, y + -2, z + -5, block3, 4, 2);
			world.setBlock(x + 2, y + -2, z + -4, block3, 4, 2);
			world.setBlock(x + 2, y + -2, z + -3, block3, 4, 2);
			world.setBlock(x + 2, y + -2, z + -2, block3, 4, 2);
			world.setBlock(x + 2, y + -2, z + -1, block2, 5, 2);
			world.setBlock(x + 2, y + -2, z + 0, block2, 5, 2);
			world.setBlock(x + 2, y + -1, z + -8, block3, 4, 2);
			world.setBlock(x + 2, y + -1, z + -7, block3, 4, 2);
			world.setBlock(x + 2, y + -1, z + -6, block4, 0, 2);
			world.setBlock(x + 2, y + -1, z + -2, block4, 0, 2);
			world.setBlock(x + 2, y + -1, z + -1, block3, 4, 2);
			world.setBlock(x + 2, y + -1, z + 0, block3, 4, 2);
			world.setBlock(x + 2, y + 0, z + -8, block3, 4, 2);
			world.setBlock(x + 2, y + 0, z + -7, block3, 4, 2);
			world.setBlock(x + 2, y + 0, z + -1, block3, 4, 2);
			world.setBlock(x + 2, y + 0, z + 0, block3, 4, 2);
			world.setBlock(x + 2, y + 1, z + -8, block3, 4, 2);
			world.setBlock(x + 2, y + 1, z + -7, block3, 4, 2);
			world.setBlock(x + 2, y + 1, z + -6, block4, 8, 2);
			world.setBlock(x + 2, y + 1, z + -2, block5, 3, 2);
			world.setBlock(x + 2, y + 1, z + -1, block3, 4, 2);
			world.setBlock(x + 2, y + 1, z + 0, block3, 4, 2);
			world.setBlock(x + 2, y + 2, z + -8, block2, 1, 2);
			world.setBlock(x + 2, y + 2, z + -7, block2, 1, 2);
			world.setBlock(x + 2, y + 2, z + -6, block3, 4, 2);
			world.setBlock(x + 2, y + 2, z + -5, block2, 4, 2);
			world.setBlock(x + 2, y + 2, z + -4, block2, 4, 2);
			world.setBlock(x + 2, y + 2, z + -3, block2, 4, 2);
			world.setBlock(x + 2, y + 2, z + -2, block3, 4, 2);
			world.setBlock(x + 2, y + 2, z + -1, block2, 1, 2);
			world.setBlock(x + 2, y + 2, z + 0, block2, 1, 2);
			world.setBlock(x + 2, y + 3, z + -5, block3, 4, 2);
			world.setBlock(x + 2, y + 3, z + -4, block3, 4, 2);
			world.setBlock(x + 2, y + 3, z + -3, block3, 4, 2);
			world.setBlock(x + 3, y + -2, z + -6, block2, 6, 2);
			world.setBlock(x + 3, y + -2, z + -5, block3, 4, 2);
			world.setBlock(x + 3, y + -2, z + -4, block3, 4, 2);
			world.setBlock(x + 3, y + -2, z + -3, block3, 4, 2);
			world.setBlock(x + 3, y + -2, z + -2, block2, 7, 2);
			world.setBlock(x + 3, y + -1, z + -6, block3, 4, 2);
			world.setBlock(x + 3, y + -1, z + -2, block3, 4, 2);
			world.setBlock(x + 3, y + 0, z + -6, block3, 4, 2);
			world.setBlock(x + 3, y + 0, z + -2, block3, 4, 2);
			world.setBlock(x + 3, y + 1, z + -6, block3, 4, 2);
			world.setBlock(x + 3, y + 1, z + -2, block3, 4, 2);
			world.setBlock(x + 3, y + 2, z + -6, block2, 2, 2);
			world.setBlock(x + 3, y + 2, z + -5, block3, 4, 2);
			world.setBlock(x + 3, y + 2, z + -4, block3, 4, 2);
			world.setBlock(x + 3, y + 2, z + -3, block3, 4, 2);
			world.setBlock(x + 3, y + 2, z + -2, block2, 3, 2);
			world.setBlock(x + 3, y + 3, z + -5, block2, 1, 2);
			world.setBlock(x + 3, y + 3, z + -4, block2, 1, 2);
			world.setBlock(x + 3, y + 3, z + -3, block2, 1, 2);
			world.setBlock(x + 4, y + -2, z + -6, block2, 6, 2);
			world.setBlock(x + 4, y + -2, z + -5, block3, 4, 2);
			world.setBlock(x + 4, y + -2, z + -4, block3, 4, 2);
			world.setBlock(x + 4, y + -2, z + -3, block3, 4, 2);
			world.setBlock(x + 4, y + -2, z + -2, block2, 7, 2);
			world.setBlock(x + 4, y + -1, z + -6, block3, 4, 2);
			world.setBlock(x + 4, y + -1, z + -2, block3, 4, 2);
			world.setBlock(x + 4, y + 0, z + -6, block3, 4, 2);
			// world.setBlock(x+4, y+0, z+-4, block1,4,2);
			world.setBlock(x + 4, y + 0, z + -2, block3, 4, 2);
			world.setBlock(x + 4, y + 1, z + -6, block3, 4, 2);
			world.setBlock(x + 4, y + 1, z + -2, block3, 4, 2);
			world.setBlock(x + 4, y + 2, z + -6, block2, 2, 2);
			world.setBlock(x + 4, y + 2, z + -5, block3, 4, 2);
			world.setBlock(x + 4, y + 2, z + -4, block3, 4, 2);
			world.setBlock(x + 4, y + 2, z + -3, block3, 4, 2);
			world.setBlock(x + 4, y + 2, z + -2, block2, 3, 2);
			// world.setBlock(x+4, y+4, z+0, block1,14,2);
			BuildHandler.buildInfoPoint(world, dir, getUnlocalizedName(), x + 0, y + -3, z + -4, 0, x, y, z);
			
			int[] pos = new int[] { x, y, z };
			pos = ForgeDirectionUtils.IncreaseByDir(dir, pos, 2);
			pos = ForgeDirectionUtils.IncreaseByDir(ForgeDirectionUtils.turnClockwise(dir), pos, 2);
			
			BuildHandler.buildRemoveInfoPoint(world, dir, getUnlocalizedName(), pos[0], pos[1], pos[2], 0, x + 0, y + -3, z + -4);
			
		} else if (dir == ForgeDirection.EAST)
		{
			
			Block block2 = GCBlocks.tinStairs1;
			Block block3 = GCBlocks.basicBlock;
			Block block4 = GCBlocks.slabGCHalf;
			Block block5 = GCBlocks.brightLamp;
			
			// world.setBlock(x+0, y+-3, z+-4, block1,5,2);
			
			world.setBlock(x + 0, y + -2, z + -2, block2, 6, 2);
			// Block block3 = id:432;
			world.setBlock(x + 0, y + -2, z + -1, block3, 4, 2);
			world.setBlock(x + 0, y + -2, z + 0, block3, 4, 2);
			world.setBlock(x + 0, y + -2, z + 1, block3, 4, 2);
			world.setBlock(x + 0, y + -2, z + 2, block2, 7, 2);
			world.setBlock(x + 0, y + -1, z + -2, block3, 4, 2);
			world.setBlock(x + 0, y + -1, z + 2, block3, 4, 2);
			world.setBlock(x + 0, y + 0, z + -2, block3, 4, 2);
			// world.setBlock(x+0, y+0, z+0, block1,4,2);
			world.setBlock(x + 0, y + 0, z + 2, block3, 4, 2);
			world.setBlock(x + 0, y + 1, z + -2, block3, 4, 2);
			world.setBlock(x + 0, y + 1, z + 2, block3, 4, 2);
			world.setBlock(x + 0, y + 2, z + -2, block2, 2, 2);
			world.setBlock(x + 0, y + 2, z + -1, block3, 4, 2);
			world.setBlock(x + 0, y + 2, z + 0, block3, 4, 2);
			world.setBlock(x + 0, y + 2, z + 1, block3, 4, 2);
			world.setBlock(x + 0, y + 2, z + 2, block2, 3, 2);
			world.setBlock(x + 1, y + -2, z + -2, block2, 6, 2);
			world.setBlock(x + 1, y + -2, z + -1, block3, 4, 2);
			world.setBlock(x + 1, y + -2, z + 0, block3, 4, 2);
			world.setBlock(x + 1, y + -2, z + 1, block3, 4, 2);
			world.setBlock(x + 1, y + -2, z + 2, block2, 7, 2);
			world.setBlock(x + 1, y + -1, z + -2, block3, 4, 2);
			world.setBlock(x + 1, y + -1, z + 2, block3, 4, 2);
			world.setBlock(x + 1, y + 0, z + -2, block3, 4, 2);
			world.setBlock(x + 1, y + 0, z + 2, block3, 4, 2);
			world.setBlock(x + 1, y + 1, z + -2, block3, 4, 2);
			world.setBlock(x + 1, y + 1, z + 2, block3, 4, 2);
			world.setBlock(x + 1, y + 2, z + -2, block2, 2, 2);
			world.setBlock(x + 1, y + 2, z + -1, block3, 4, 2);
			world.setBlock(x + 1, y + 2, z + 0, block3, 4, 2);
			world.setBlock(x + 1, y + 2, z + 1, block3, 4, 2);
			world.setBlock(x + 1, y + 2, z + 2, block2, 3, 2);
			world.setBlock(x + 1, y + 3, z + -1, block2, 0, 2);
			world.setBlock(x + 1, y + 3, z + 0, block2, 0, 2);
			world.setBlock(x + 1, y + 3, z + 1, block2, 0, 2);
			world.setBlock(x + 2, y + -2, z + -4, block2, 4, 2);
			world.setBlock(x + 2, y + -2, z + -3, block2, 4, 2);
			world.setBlock(x + 2, y + -2, z + -2, block3, 4, 2);
			world.setBlock(x + 2, y + -2, z + -1, block3, 4, 2);
			world.setBlock(x + 2, y + -2, z + 0, block3, 4, 2);
			world.setBlock(x + 2, y + -2, z + 1, block3, 4, 2);
			world.setBlock(x + 2, y + -2, z + 2, block3, 4, 2);
			world.setBlock(x + 2, y + -2, z + 3, block2, 4, 2);
			world.setBlock(x + 2, y + -2, z + 4, block2, 4, 2);
			world.setBlock(x + 2, y + -1, z + -4, block3, 4, 2);
			world.setBlock(x + 2, y + -1, z + -3, block3, 4, 2);
			// Block block4 = id:459;
			world.setBlock(x + 2, y + -1, z + -2, block4, 0, 2);
			world.setBlock(x + 2, y + -1, z + 2, block4, 0, 2);
			world.setBlock(x + 2, y + -1, z + 3, block3, 4, 2);
			world.setBlock(x + 2, y + -1, z + 4, block3, 4, 2);
			world.setBlock(x + 2, y + 0, z + -4, block3, 4, 2);
			world.setBlock(x + 2, y + 0, z + -3, block3, 4, 2);
			world.setBlock(x + 2, y + 0, z + 3, block3, 4, 2);
			world.setBlock(x + 2, y + 0, z + 4, block3, 4, 2);
			world.setBlock(x + 2, y + 1, z + -4, block3, 4, 2);
			world.setBlock(x + 2, y + 1, z + -3, block3, 4, 2);
			// Block block5 = id:452;
			world.setBlock(x + 2, y + 1, z + -2, block5, 2, 2);
			world.setBlock(x + 2, y + 1, z + 2, block4, 8, 2);
			world.setBlock(x + 2, y + 1, z + 3, block3, 4, 2);
			world.setBlock(x + 2, y + 1, z + 4, block3, 4, 2);
			world.setBlock(x + 2, y + 2, z + -4, block2, 0, 2);
			world.setBlock(x + 2, y + 2, z + -3, block2, 0, 2);
			world.setBlock(x + 2, y + 2, z + -2, block3, 4, 2);
			world.setBlock(x + 2, y + 2, z + -1, block2, 5, 2);
			world.setBlock(x + 2, y + 2, z + 0, block2, 5, 2);
			world.setBlock(x + 2, y + 2, z + 1, block2, 5, 2);
			world.setBlock(x + 2, y + 2, z + 2, block3, 4, 2);
			world.setBlock(x + 2, y + 2, z + 3, block2, 0, 2);
			world.setBlock(x + 2, y + 2, z + 4, block2, 0, 2);
			world.setBlock(x + 2, y + 3, z + -1, block3, 4, 2);
			world.setBlock(x + 2, y + 3, z + 0, block3, 4, 2);
			world.setBlock(x + 2, y + 3, z + 1, block3, 4, 2);
			world.setBlock(x + 3, y + -2, z + -4, block3, 4, 2);
			world.setBlock(x + 3, y + -2, z + -3, block3, 4, 2);
			world.setBlock(x + 3, y + -2, z + -2, block3, 4, 2);
			world.setBlock(x + 3, y + -2, z + -1, block3, 4, 2);
			world.setBlock(x + 3, y + -2, z + 0, block3, 4, 2);
			world.setBlock(x + 3, y + -2, z + 1, block3, 4, 2);
			world.setBlock(x + 3, y + -2, z + 2, block3, 4, 2);
			world.setBlock(x + 3, y + -2, z + 3, block3, 4, 2);
			world.setBlock(x + 3, y + -2, z + 4, block3, 4, 2);
			world.setBlock(x + 3, y + 2, z + -4, block3, 4, 2);
			world.setBlock(x + 3, y + 2, z + -3, block3, 4, 2);
			world.setBlock(x + 3, y + 2, z + -2, block2, 7, 2);
			world.setBlock(x + 3, y + 2, z + 2, block2, 6, 2);
			world.setBlock(x + 3, y + 2, z + 3, block3, 4, 2);
			world.setBlock(x + 3, y + 2, z + 4, block3, 4, 2);
			world.setBlock(x + 3, y + 3, z + -3, block2, 2, 2);
			world.setBlock(x + 3, y + 3, z + -2, block3, 4, 2);
			world.setBlock(x + 3, y + 3, z + -1, block3, 4, 2);
			world.setBlock(x + 3, y + 3, z + 0, block3, 4, 2);
			world.setBlock(x + 3, y + 3, z + 1, block3, 4, 2);
			world.setBlock(x + 3, y + 3, z + 2, block3, 4, 2);
			world.setBlock(x + 3, y + 3, z + 3, block2, 3, 2);
			world.setBlock(x + 4, y + -2, z + -4, block3, 4, 2);
			world.setBlock(x + 4, y + -2, z + -3, block3, 4, 2);
			world.setBlock(x + 4, y + -2, z + -2, block3, 4, 2);
			world.setBlock(x + 4, y + -2, z + -1, block3, 4, 2);
			// Block block6 = id:505;
			BuildHandler.buildBuildPoint(world, x + 4, y - 2, z, 2);
			world.setBlock(x + 4, y + -2, z + 1, block3, 4, 2);
			world.setBlock(x + 4, y + -2, z + 2, block3, 4, 2);
			world.setBlock(x + 4, y + -2, z + 3, block3, 4, 2);
			world.setBlock(x + 4, y + -2, z + 4, block3, 4, 2);
			// world.setBlock(x+4, y+0, z+-4, block1,4,2);
			// world.setBlock(x+4, y+0, z+4, block1,4,2);
			world.setBlock(x + 4, y + 2, z + -4, block3, 4, 2);
			world.setBlock(x + 4, y + 2, z + -3, block3, 4, 2);
			world.setBlock(x + 4, y + 2, z + -2, block2, 7, 2);
			world.setBlock(x + 4, y + 2, z + 2, block2, 6, 2);
			world.setBlock(x + 4, y + 2, z + 3, block3, 4, 2);
			world.setBlock(x + 4, y + 2, z + 4, block3, 4, 2);
			world.setBlock(x + 4, y + 3, z + -3, block2, 2, 2);
			world.setBlock(x + 4, y + 3, z + -2, block3, 4, 2);
			world.setBlock(x + 4, y + 3, z + -1, block3, 4, 2);
			BuildHandler.buildBuildPoint(world, x + 4, y + 3, z, 4);
			world.setBlock(x + 4, y + 3, z + 1, block3, 4, 2);
			world.setBlock(x + 4, y + 3, z + 2, block3, 4, 2);
			world.setBlock(x + 4, y + 3, z + 3, block2, 3, 2);
			world.setBlock(x + 5, y + -2, z + -4, block3, 4, 2);
			world.setBlock(x + 5, y + -2, z + -3, block3, 4, 2);
			world.setBlock(x + 5, y + -2, z + -2, block3, 4, 2);
			world.setBlock(x + 5, y + -2, z + -1, block3, 4, 2);
			world.setBlock(x + 5, y + -2, z + 0, block3, 4, 2);
			world.setBlock(x + 5, y + -2, z + 1, block3, 4, 2);
			world.setBlock(x + 5, y + -2, z + 2, block3, 4, 2);
			world.setBlock(x + 5, y + -2, z + 3, block3, 4, 2);
			world.setBlock(x + 5, y + -2, z + 4, block3, 4, 2);
			world.setBlock(x + 5, y + 2, z + -4, block3, 4, 2);
			world.setBlock(x + 5, y + 2, z + -3, block3, 4, 2);
			world.setBlock(x + 5, y + 2, z + -2, block2, 7, 2);
			world.setBlock(x + 5, y + 2, z + 2, block2, 6, 2);
			world.setBlock(x + 5, y + 2, z + 3, block3, 4, 2);
			world.setBlock(x + 5, y + 2, z + 4, block3, 4, 2);
			world.setBlock(x + 5, y + 3, z + -3, block2, 2, 2);
			world.setBlock(x + 5, y + 3, z + -2, block3, 4, 2);
			world.setBlock(x + 5, y + 3, z + -1, block3, 4, 2);
			world.setBlock(x + 5, y + 3, z + 0, block3, 4, 2);
			world.setBlock(x + 5, y + 3, z + 1, block3, 4, 2);
			world.setBlock(x + 5, y + 3, z + 2, block3, 4, 2);
			world.setBlock(x + 5, y + 3, z + 3, block2, 3, 2);
			world.setBlock(x + 6, y + -2, z + -4, block2, 5, 2);
			world.setBlock(x + 6, y + -2, z + -3, block2, 5, 2);
			world.setBlock(x + 6, y + -2, z + -2, block3, 4, 2);
			world.setBlock(x + 6, y + -2, z + -1, block3, 4, 2);
			world.setBlock(x + 6, y + -2, z + 0, block3, 4, 2);
			world.setBlock(x + 6, y + -2, z + 1, block3, 4, 2);
			world.setBlock(x + 6, y + -2, z + 2, block3, 4, 2);
			world.setBlock(x + 6, y + -2, z + 3, block2, 5, 2);
			world.setBlock(x + 6, y + -2, z + 4, block2, 5, 2);
			world.setBlock(x + 6, y + -1, z + -4, block3, 4, 2);
			world.setBlock(x + 6, y + -1, z + -3, block3, 4, 2);
			world.setBlock(x + 6, y + -1, z + -2, block4, 0, 2);
			world.setBlock(x + 6, y + -1, z + 2, block4, 0, 2);
			world.setBlock(x + 6, y + -1, z + 3, block3, 4, 2);
			world.setBlock(x + 6, y + -1, z + 4, block3, 4, 2);
			world.setBlock(x + 6, y + 0, z + -4, block3, 4, 2);
			world.setBlock(x + 6, y + 0, z + -3, block3, 4, 2);
			world.setBlock(x + 6, y + 0, z + 3, block3, 4, 2);
			world.setBlock(x + 6, y + 0, z + 4, block3, 4, 2);
			world.setBlock(x + 6, y + 1, z + -4, block3, 4, 2);
			world.setBlock(x + 6, y + 1, z + -3, block3, 4, 2);
			world.setBlock(x + 6, y + 1, z + -2, block4, 8, 2);
			world.setBlock(x + 6, y + 1, z + 2, block5, 3, 2);
			world.setBlock(x + 6, y + 1, z + 3, block3, 4, 2);
			world.setBlock(x + 6, y + 1, z + 4, block3, 4, 2);
			world.setBlock(x + 6, y + 2, z + -4, block2, 1, 2);
			world.setBlock(x + 6, y + 2, z + -3, block2, 1, 2);
			world.setBlock(x + 6, y + 2, z + -2, block3, 4, 2);
			world.setBlock(x + 6, y + 2, z + -1, block2, 4, 2);
			world.setBlock(x + 6, y + 2, z + 0, block2, 4, 2);
			world.setBlock(x + 6, y + 2, z + 1, block2, 4, 2);
			world.setBlock(x + 6, y + 2, z + 2, block3, 4, 2);
			world.setBlock(x + 6, y + 2, z + 3, block2, 1, 2);
			world.setBlock(x + 6, y + 2, z + 4, block2, 1, 2);
			world.setBlock(x + 6, y + 3, z + -1, block3, 4, 2);
			world.setBlock(x + 6, y + 3, z + 0, block3, 4, 2);
			world.setBlock(x + 6, y + 3, z + 1, block3, 4, 2);
			world.setBlock(x + 7, y + -2, z + -2, block2, 6, 2);
			world.setBlock(x + 7, y + -2, z + -1, block3, 4, 2);
			world.setBlock(x + 7, y + -2, z + 0, block3, 4, 2);
			world.setBlock(x + 7, y + -2, z + 1, block3, 4, 2);
			world.setBlock(x + 7, y + -2, z + 2, block2, 7, 2);
			world.setBlock(x + 7, y + -1, z + -2, block3, 4, 2);
			world.setBlock(x + 7, y + -1, z + 2, block3, 4, 2);
			world.setBlock(x + 7, y + 0, z + -2, block3, 4, 2);
			world.setBlock(x + 7, y + 0, z + 2, block3, 4, 2);
			world.setBlock(x + 7, y + 1, z + -2, block3, 4, 2);
			world.setBlock(x + 7, y + 1, z + 2, block3, 4, 2);
			world.setBlock(x + 7, y + 2, z + -2, block2, 2, 2);
			world.setBlock(x + 7, y + 2, z + -1, block3, 4, 2);
			world.setBlock(x + 7, y + 2, z + 0, block3, 4, 2);
			world.setBlock(x + 7, y + 2, z + 1, block3, 4, 2);
			world.setBlock(x + 7, y + 2, z + 2, block2, 3, 2);
			world.setBlock(x + 7, y + 3, z + -1, block2, 1, 2);
			world.setBlock(x + 7, y + 3, z + 0, block2, 1, 2);
			world.setBlock(x + 7, y + 3, z + 1, block2, 1, 2);
			world.setBlock(x + 8, y + -2, z + -2, block2, 6, 2);
			world.setBlock(x + 8, y + -2, z + -1, block3, 4, 2);
			world.setBlock(x + 8, y + -2, z + 0, block3, 4, 2);
			world.setBlock(x + 8, y + -2, z + 1, block3, 4, 2);
			world.setBlock(x + 8, y + -2, z + 2, block2, 7, 2);
			world.setBlock(x + 8, y + -1, z + -2, block3, 4, 2);
			world.setBlock(x + 8, y + -1, z + 2, block3, 4, 2);
			world.setBlock(x + 8, y + 0, z + -2, block3, 4, 2);
			// world.setBlock(x+8, y+0, z+0, block1,4,2);
			world.setBlock(x + 8, y + 0, z + 2, block3, 4, 2);
			world.setBlock(x + 8, y + 1, z + -2, block3, 4, 2);
			world.setBlock(x + 8, y + 1, z + 2, block3, 4, 2);
			world.setBlock(x + 8, y + 2, z + -2, block2, 2, 2);
			world.setBlock(x + 8, y + 2, z + -1, block3, 4, 2);
			world.setBlock(x + 8, y + 2, z + 0, block3, 4, 2);
			world.setBlock(x + 8, y + 2, z + 1, block3, 4, 2);
			world.setBlock(x + 8, y + 2, z + 2, block2, 3, 2);
			// world.setBlock(x+8, y+4, z+4, block1,14,2);
			
			BuildHandler.buildInfoPoint(world, dir, getUnlocalizedName(), x + 4, y + -3, z + 0, 0, x, y, z);
			
			int[] pos = new int[] { x, y, z };
			pos = ForgeDirectionUtils.IncreaseByDir(dir, pos, 2);
			pos = ForgeDirectionUtils.IncreaseByDir(ForgeDirectionUtils.turnClockwise(dir), pos, 2);
			
			BuildHandler.buildRemoveInfoPoint(world, dir, getUnlocalizedName(), pos[0], pos[1], pos[2], 0, x + 4, y + -3, z + 0);
			
		} else if (dir == ForgeDirection.SOUTH)
		{
			Block block2 = GCBlocks.tinStairs1;
			Block block3 = GCBlocks.basicBlock;
			Block block4 = GCBlocks.slabGCHalf;
			Block block5 = GCBlocks.brightLamp;
			
			// world.setBlock(x+-4, y+-3, z+0, block1,5,2);
			// Block block2 = id:454;
			world.setBlock(x + -4, y + -2, z + 2, block2, 6, 2);
			// Block block3 = id:432;
			world.setBlock(x + -4, y + -2, z + 3, block3, 4, 2);
			world.setBlock(x + -4, y + -2, z + 4, block3, 4, 2);
			world.setBlock(x + -4, y + -2, z + 5, block3, 4, 2);
			world.setBlock(x + -4, y + -2, z + 6, block2, 7, 2);
			world.setBlock(x + -4, y + -1, z + 2, block3, 4, 2);
			world.setBlock(x + -4, y + -1, z + 6, block3, 4, 2);
			world.setBlock(x + -4, y + 0, z + 2, block3, 4, 2);
			// world.setBlock(x+-4, y+0, z+4, block1,4,2);
			world.setBlock(x + -4, y + 0, z + 6, block3, 4, 2);
			world.setBlock(x + -4, y + 1, z + 2, block3, 4, 2);
			world.setBlock(x + -4, y + 1, z + 6, block3, 4, 2);
			world.setBlock(x + -4, y + 2, z + 2, block2, 2, 2);
			world.setBlock(x + -4, y + 2, z + 3, block3, 4, 2);
			world.setBlock(x + -4, y + 2, z + 4, block3, 4, 2);
			world.setBlock(x + -4, y + 2, z + 5, block3, 4, 2);
			world.setBlock(x + -4, y + 2, z + 6, block2, 3, 2);
			world.setBlock(x + -3, y + -2, z + 2, block2, 6, 2);
			world.setBlock(x + -3, y + -2, z + 3, block3, 4, 2);
			world.setBlock(x + -3, y + -2, z + 4, block3, 4, 2);
			world.setBlock(x + -3, y + -2, z + 5, block3, 4, 2);
			world.setBlock(x + -3, y + -2, z + 6, block2, 7, 2);
			world.setBlock(x + -3, y + -1, z + 2, block3, 4, 2);
			world.setBlock(x + -3, y + -1, z + 6, block3, 4, 2);
			world.setBlock(x + -3, y + 0, z + 2, block3, 4, 2);
			world.setBlock(x + -3, y + 0, z + 6, block3, 4, 2);
			world.setBlock(x + -3, y + 1, z + 2, block3, 4, 2);
			world.setBlock(x + -3, y + 1, z + 6, block3, 4, 2);
			world.setBlock(x + -3, y + 2, z + 2, block2, 2, 2);
			world.setBlock(x + -3, y + 2, z + 3, block3, 4, 2);
			world.setBlock(x + -3, y + 2, z + 4, block3, 4, 2);
			world.setBlock(x + -3, y + 2, z + 5, block3, 4, 2);
			world.setBlock(x + -3, y + 2, z + 6, block2, 3, 2);
			world.setBlock(x + -3, y + 3, z + 3, block2, 0, 2);
			world.setBlock(x + -3, y + 3, z + 4, block2, 0, 2);
			world.setBlock(x + -3, y + 3, z + 5, block2, 0, 2);
			world.setBlock(x + -2, y + -2, z + 0, block2, 4, 2);
			world.setBlock(x + -2, y + -2, z + 1, block2, 4, 2);
			world.setBlock(x + -2, y + -2, z + 2, block3, 4, 2);
			world.setBlock(x + -2, y + -2, z + 3, block3, 4, 2);
			world.setBlock(x + -2, y + -2, z + 4, block3, 4, 2);
			world.setBlock(x + -2, y + -2, z + 5, block3, 4, 2);
			world.setBlock(x + -2, y + -2, z + 6, block3, 4, 2);
			world.setBlock(x + -2, y + -2, z + 7, block2, 4, 2);
			world.setBlock(x + -2, y + -2, z + 8, block2, 4, 2);
			world.setBlock(x + -2, y + -1, z + 0, block3, 4, 2);
			world.setBlock(x + -2, y + -1, z + 1, block3, 4, 2);
			// Block block4 = id:459;
			world.setBlock(x + -2, y + -1, z + 2, block4, 0, 2);
			world.setBlock(x + -2, y + -1, z + 6, block4, 0, 2);
			world.setBlock(x + -2, y + -1, z + 7, block3, 4, 2);
			world.setBlock(x + -2, y + -1, z + 8, block3, 4, 2);
			world.setBlock(x + -2, y + 0, z + 0, block3, 4, 2);
			world.setBlock(x + -2, y + 0, z + 1, block3, 4, 2);
			world.setBlock(x + -2, y + 0, z + 7, block3, 4, 2);
			world.setBlock(x + -2, y + 0, z + 8, block3, 4, 2);
			world.setBlock(x + -2, y + 1, z + 0, block3, 4, 2);
			world.setBlock(x + -2, y + 1, z + 1, block3, 4, 2);
			// Block block5 = id:452;
			world.setBlock(x + -2, y + 1, z + 2, block5, 2, 2);
			world.setBlock(x + -2, y + 1, z + 6, block4, 8, 2);
			world.setBlock(x + -2, y + 1, z + 7, block3, 4, 2);
			world.setBlock(x + -2, y + 1, z + 8, block3, 4, 2);
			world.setBlock(x + -2, y + 2, z + 0, block2, 0, 2);
			world.setBlock(x + -2, y + 2, z + 1, block2, 0, 2);
			world.setBlock(x + -2, y + 2, z + 2, block3, 4, 2);
			world.setBlock(x + -2, y + 2, z + 3, block2, 5, 2);
			world.setBlock(x + -2, y + 2, z + 4, block2, 5, 2);
			world.setBlock(x + -2, y + 2, z + 5, block2, 5, 2);
			world.setBlock(x + -2, y + 2, z + 6, block3, 4, 2);
			world.setBlock(x + -2, y + 2, z + 7, block2, 0, 2);
			world.setBlock(x + -2, y + 2, z + 8, block2, 0, 2);
			world.setBlock(x + -2, y + 3, z + 3, block3, 4, 2);
			world.setBlock(x + -2, y + 3, z + 4, block3, 4, 2);
			world.setBlock(x + -2, y + 3, z + 5, block3, 4, 2);
			world.setBlock(x + -1, y + -2, z + 0, block3, 4, 2);
			world.setBlock(x + -1, y + -2, z + 1, block3, 4, 2);
			world.setBlock(x + -1, y + -2, z + 2, block3, 4, 2);
			world.setBlock(x + -1, y + -2, z + 3, block3, 4, 2);
			world.setBlock(x + -1, y + -2, z + 4, block3, 4, 2);
			world.setBlock(x + -1, y + -2, z + 5, block3, 4, 2);
			world.setBlock(x + -1, y + -2, z + 6, block3, 4, 2);
			world.setBlock(x + -1, y + -2, z + 7, block3, 4, 2);
			world.setBlock(x + -1, y + -2, z + 8, block3, 4, 2);
			world.setBlock(x + -1, y + 2, z + 0, block3, 4, 2);
			world.setBlock(x + -1, y + 2, z + 1, block3, 4, 2);
			world.setBlock(x + -1, y + 2, z + 2, block2, 7, 2);
			world.setBlock(x + -1, y + 2, z + 6, block2, 6, 2);
			world.setBlock(x + -1, y + 2, z + 7, block3, 4, 2);
			world.setBlock(x + -1, y + 2, z + 8, block3, 4, 2);
			world.setBlock(x + -1, y + 3, z + 1, block2, 2, 2);
			world.setBlock(x + -1, y + 3, z + 2, block3, 4, 2);
			world.setBlock(x + -1, y + 3, z + 3, block3, 4, 2);
			world.setBlock(x + -1, y + 3, z + 4, block3, 4, 2);
			world.setBlock(x + -1, y + 3, z + 5, block3, 4, 2);
			world.setBlock(x + -1, y + 3, z + 6, block3, 4, 2);
			world.setBlock(x + -1, y + 3, z + 7, block2, 3, 2);
			world.setBlock(x + 0, y + -2, z + 0, block3, 4, 2);
			world.setBlock(x + 0, y + -2, z + 1, block3, 4, 2);
			world.setBlock(x + 0, y + -2, z + 2, block3, 4, 2);
			world.setBlock(x + 0, y + -2, z + 3, block3, 4, 2);
			// Block block6 = id:505;
			BuildHandler.buildBuildPoint(world, x, y - 2, z + 4, 2);
			world.setBlock(x + 0, y + -2, z + 5, block3, 4, 2);
			world.setBlock(x + 0, y + -2, z + 6, block3, 4, 2);
			world.setBlock(x + 0, y + -2, z + 7, block3, 4, 2);
			world.setBlock(x + 0, y + -2, z + 8, block3, 4, 2);
			// world.setBlock(x+0, y+0, z+0, block1,4,2);
			// world.setBlock(x+0, y+0, z+8, block1,4,2);
			world.setBlock(x + 0, y + 2, z + 0, block3, 4, 2);
			world.setBlock(x + 0, y + 2, z + 1, block3, 4, 2);
			world.setBlock(x + 0, y + 2, z + 2, block2, 7, 2);
			world.setBlock(x + 0, y + 2, z + 6, block2, 6, 2);
			world.setBlock(x + 0, y + 2, z + 7, block3, 4, 2);
			world.setBlock(x + 0, y + 2, z + 8, block3, 4, 2);
			world.setBlock(x + 0, y + 3, z + 1, block2, 2, 2);
			world.setBlock(x + 0, y + 3, z + 2, block3, 4, 2);
			world.setBlock(x + 0, y + 3, z + 3, block3, 4, 2);
			BuildHandler.buildBuildPoint(world, x, y + 3, z + 4, 4);
			world.setBlock(x + 0, y + 3, z + 5, block3, 4, 2);
			world.setBlock(x + 0, y + 3, z + 6, block3, 4, 2);
			world.setBlock(x + 0, y + 3, z + 7, block2, 3, 2);
			world.setBlock(x + 1, y + -2, z + 0, block3, 4, 2);
			world.setBlock(x + 1, y + -2, z + 1, block3, 4, 2);
			world.setBlock(x + 1, y + -2, z + 2, block3, 4, 2);
			world.setBlock(x + 1, y + -2, z + 3, block3, 4, 2);
			world.setBlock(x + 1, y + -2, z + 4, block3, 4, 2);
			world.setBlock(x + 1, y + -2, z + 5, block3, 4, 2);
