package net.glider.src.strucures;

import java.util.ArrayList;
import java.util.List;
import micdoodle8.mods.galacticraft.core.blocks.GCBlocks;
import micdoodle8.mods.galacticraft.core.items.GCItems;
import net.glider.src.items.ItemMod;
import net.glider.src.utils.OreDictItemStack;
import net.minecraft.block.Block;
import net.minecraft.init.Blocks;
import net.minecraft.item.ItemStack;
import net.minecraft.util.StatCollector;
import net.minecraft.world.World;
import net.minecraftforge.common.util.ForgeDirection;

public class StructureGreenHouse extends Structure {
	
	public StructureGreenHouse()
	{
		super(false);
	}
	
	@Override
	public void Build(World world, ForgeDirection dir, int x, int y, int z)
	{
		Block block1 = GCBlocks.tinStairs1;
		world.setBlock(x - 11, y + 1, z - 10, block1, 2, 2);
		Block block2 = GCBlocks.basicBlock;
		world.setBlock(x - 11, y + 1, z - 9, block2, 4, 2);
		world.setBlock(x - 11, y + 1, z - 8, block2, 4, 2);
		world.setBlock(x - 11, y + 1, z - 7, block2, 4, 2);
		world.setBlock(x - 11, y + 1, z - 6, block2, 4, 2);
		world.setBlock(x - 11, y + 1, z - 5, block2, 4, 2);
		world.setBlock(x - 11, y + 1, z - 4, block2, 4, 2);
		world.setBlock(x - 11, y + 1, z - 3, block2, 4, 2);
		world.setBlock(x - 11, y + 1, z - 2, block2, 4, 2);
		world.setBlock(x - 11, y + 1, z - 1, block2, 4, 2);
		world.setBlock(x - 11, y + 1, z + 0, block2, 4, 2);
		world.setBlock(x - 11, y + 1, z + 1, block1, 3, 2);
		world.setBlock(x - 11, y + 2, z - 9, block2, 4, 2);
		world.setBlock(x - 11, y + 2, z - 8, block2, 4, 2);
		world.setBlock(x - 11, y + 2, z - 7, block2, 4, 2);
		world.setBlock(x - 11, y + 2, z - 6, block2, 4, 2);
		world.setBlock(x - 11, y + 2, z - 5, block2, 4, 2);
		world.setBlock(x - 11, y + 2, z - 4, block2, 4, 2);
		world.setBlock(x - 11, y + 2, z - 3, block2, 4, 2);
		world.setBlock(x - 11, y + 2, z - 2, block2, 4, 2);
		world.setBlock(x - 11, y + 2, z - 1, block2, 4, 2);
		world.setBlock(x - 11, y + 2, z + 0, block2, 4, 2);
		world.setBlock(x - 11, y + 3, z - 9, block1, 0, 2);
		world.setBlock(x - 11, y + 3, z - 8, block1, 0, 2);
		world.setBlock(x - 11, y + 3, z - 7, block1, 0, 2);
		world.setBlock(x - 11, y + 3, z - 6, block1, 0, 2);
		world.setBlock(x - 11, y + 3, z - 5, block1, 0, 2);
		world.setBlock(x - 11, y + 3, z - 4, block1, 0, 2);
		world.setBlock(x - 11, y + 3, z - 3, block1, 0, 2);
		world.setBlock(x - 11, y + 3, z - 2, block1, 0, 2);
		world.setBlock(x - 11, y + 3, z - 1, block1, 0, 2);
		world.setBlock(x - 11, y + 3, z + 0, block1, 0, 2);
		Block block3 = Blocks.air;
		world.setBlock(x - 10, y + 0, z - 9, block3, 0, 2);
		world.setBlock(x - 10, y + 0, z - 8, block3, 0, 2);
		world.setBlock(x - 10, y + 0, z - 7, block3, 0, 2);
		world.setBlock(x - 10, y + 0, z - 6, block3, 0, 2);
		world.setBlock(x - 10, y + 0, z - 5, block3, 0, 2);
		world.setBlock(x - 10, y + 0, z - 4, block3, 0, 2);
		world.setBlock(x - 10, y + 0, z - 3, block3, 0, 2);
		world.setBlock(x - 10, y + 0, z - 2, block3, 0, 2);
		world.setBlock(x - 10, y + 0, z - 1, block3, 0, 2);
		world.setBlock(x - 10, y + 0, z + 0, block3, 0, 2);
		world.setBlock(x - 10, y + 1, z - 11, block1, 0, 2);
		world.setBlock(x - 10, y + 1, z - 10, block2, 4, 2);
		world.setBlock(x - 10, y + 1, z + 1, block2, 4, 2);
		world.setBlock(x - 10, y + 1, z + 2, block1, 0, 2);
		world.setBlock(x - 10, y + 2, z - 10, block2, 4, 2);
		world.setBlock(x - 10, y + 2, z + 1, block2, 4, 2);
		world.setBlock(x - 10, y + 3, z - 10, block2, 4, 2);
		Block block4 = Blocks.glass;
		world.setBlock(x - 10, y + 3, z - 9, block4, 0, 2);
		world.setBlock(x - 10, y + 3, z - 8, block4, 0, 2);
		world.setBlock(x - 10, y + 3, z - 7, block4, 0, 2);
		world.setBlock(x - 10, y + 3, z - 6, block4, 0, 2);
		world.setBlock(x - 10, y + 3, z - 5, block4, 0, 2);
		world.setBlock(x - 10, y + 3, z - 4, block4, 0, 2);
		world.setBlock(x - 10, y + 3, z - 3, block4, 0, 2);
		world.setBlock(x - 10, y + 3, z - 2, block4, 0, 2);
		world.setBlock(x - 10, y + 3, z - 1, block4, 0, 2);
		world.setBlock(x - 10, y + 3, z + 0, block4, 0, 2);
		world.setBlock(x - 10, y + 3, z + 1, block2, 4, 2);
		world.setBlock(x - 9, y - 6, z - 8, block1, 4, 2);
		world.setBlock(x - 9, y - 6, z - 7, block1, 4, 2);
		world.setBlock(x - 9, y - 6, z - 6, block1, 4, 2);
		world.setBlock(x - 9, y - 6, z - 5, block1, 4, 2);
		world.setBlock(x - 9, y - 6, z - 4, block1, 4, 2);
		world.setBlock(x - 9, y - 6, z - 3, block1, 4, 2);
		world.setBlock(x - 9, y - 6, z - 2, block1, 4, 2);
		world.setBlock(x - 9, y - 6, z - 1, block1, 4, 2);
		world.setBlock(x - 9, y - 5, z - 8, block3, 0, 2);
		world.setBlock(x - 9, y - 5, z - 7, block3, 0, 2);
		world.setBlock(x - 9, y - 5, z - 6, block3, 0, 2);
		world.setBlock(x - 9, y - 5, z - 5, block3, 0, 2);
		world.setBlock(x - 9, y - 5, z - 4, block3, 0, 2);
		world.setBlock(x - 9, y - 5, z - 3, block3, 0, 2);
		world.setBlock(x - 9, y - 5, z - 2, block3, 0, 2);
		world.setBlock(x - 9, y - 5, z - 1, block3, 0, 2);
		world.setBlock(x - 9, y + 0, z - 10, block3, 0, 2);
		world.setBlock(x - 9, y + 0, z - 9, block3, 0, 2);
		world.setBlock(x - 9, y + 0, z - 8, block3, 0, 2);
		world.setBlock(x - 9, y + 0, z - 7, block3, 0, 2);
		world.setBlock(x - 9, y + 0, z - 6, block3, 0, 2);
		world.setBlock(x - 9, y + 0, z - 5, block3, 0, 2);
		world.setBlock(x - 9, y + 0, z - 4, block3, 0, 2);
		world.setBlock(x - 9, y + 0, z - 3, block3, 0, 2);
		world.setBlock(x - 9, y + 0, z - 2, block3, 0, 2);
		world.setBlock(x - 9, y + 0, z - 1, block3, 0, 2);
		world.setBlock(x - 9, y + 0, z + 0, block3, 0, 2);
		world.setBlock(x - 9, y + 0, z + 1, block3, 0, 2);
		world.setBlock(x - 9, y + 1, z - 11, block2, 4, 2);
		world.setBlock(x - 9, y + 1, z + 2, block2, 4, 2);
		world.setBlock(x - 9, y + 2, z - 11, block2, 4, 2);
		world.setBlock(x - 9, y + 2, z + 2, block2, 4, 2);
		world.setBlock(x - 9, y + 3, z - 11, block1, 2, 2);
		world.setBlock(x - 9, y + 3, z - 10, block4, 0, 2);
		world.setBlock(x - 9, y + 3, z - 9, block4, 0, 2);
		world.setBlock(x - 9, y + 3, z - 8, block4, 0, 2);
		world.setBlock(x - 9, y + 3, z - 7, block4, 0, 2);
		world.setBlock(x - 9, y + 3, z - 6, block4, 0, 2);
		world.setBlock(x - 9, y + 3, z - 5, block4, 0, 2);
		world.setBlock(x - 9, y + 3, z - 4, block4, 0, 2);
		world.setBlock(x - 9, y + 3, z - 3, block4, 0, 2);
		world.setBlock(x - 9, y + 3, z - 2, block4, 0, 2);
		world.setBlock(x - 9, y + 3, z - 1, block4, 0, 2);
		world.setBlock(x - 9, y + 3, z + 0, block4, 0, 2);
		world.setBlock(x - 9, y + 3, z + 1, block4, 0, 2);
		world.setBlock(x - 9, y + 3, z + 2, block1, 3, 2);
		world.setBlock(x - 8, y - 6, z - 9, block1, 6, 2);
		world.setBlock(x - 8, y - 6, z - 8, block2, 4, 2);
		world.setBlock(x - 8, y - 6, z - 7, block2, 4, 2);
		world.setBlock(x - 8, y - 6, z - 6, block2, 4, 2);
		world.setBlock(x - 8, y - 6, z - 5, block2, 4, 2);
		world.setBlock(x - 8, y - 6, z - 4, block2, 4, 2);
		world.setBlock(x - 8, y - 6, z - 3, block2, 4, 2);
		world.setBlock(x - 8, y - 6, z - 2, block2, 4, 2);
		world.setBlock(x - 8, y - 6, z - 1, block2, 4, 2);
		world.setBlock(x - 8, y - 6, z + 0, block1, 7, 2);
		world.setBlock(x - 8, y - 5, z - 9, block3, 0, 2);
		world.setBlock(x - 8, y - 5, z - 8, block3, 0, 2);
		world.setBlock(x - 8, y - 5, z - 7, block3, 0, 2);
		world.setBlock(x - 8, y - 5, z - 6, block3, 0, 2);
		world.setBlock(x - 8, y - 5, z - 5, block3, 0, 2);
		world.setBlock(x - 8, y - 5, z - 4, block3, 0, 2);
		world.setBlock(x - 8, y - 5, z - 3, block3, 0, 2);
		world.setBlock(x - 8, y - 5, z - 2, block3, 0, 2);
		world.setBlock(x - 8, y - 5, z - 1, block3, 0, 2);
		world.setBlock(x - 8, y - 5, z + 0, block3, 0, 2);
		world.setBlock(x - 8, y + 0, z - 10, block3, 0, 2);
		world.setBlock(x - 8, y + 0, z - 9, block3, 0, 2);
		world.setBlock(x - 8, y + 0, z - 8, block3, 0, 2);
		world.setBlock(x - 8, y + 0, z - 7, block3, 0, 2);
		world.setBlock(x - 8, y + 0, z - 6, block3, 0, 2);
		world.setBlock(x - 8, y + 0, z - 5, block3, 0, 2);
		world.setBlock(x - 8, y + 0, z - 4, block3, 0, 2);
		world.setBlock(x - 8, y + 0, z - 3, block3, 0, 2);
		world.setBlock(x - 8, y + 0, z - 2, block3, 0, 2);
		world.setBlock(x - 8, y + 0, z - 1, block3, 0, 2);
		world.setBlock(x - 8, y + 0, z + 0, block3, 0, 2);
		world.setBlock(x - 8, y + 0, z + 1, block3, 0, 2);
		world.setBlock(x - 8, y + 1, z - 11, block2, 4, 2);
		world.setBlock(x - 8, y + 1, z + 2, block2, 4, 2);
		world.setBlock(x - 8, y + 2, z - 11, block2, 4, 2);
		world.setBlock(x - 8, y + 2, z + 2, block2, 4, 2);
		world.setBlock(x - 8, y + 3, z - 11, block1, 2, 2);
		world.setBlock(x - 8, y + 3, z - 10, block4, 0, 2);
		world.setBlock(x - 8, y + 3, z - 9, block4, 0, 2);
		world.setBlock(x - 8, y + 3, z - 8, block4, 0, 2);
		world.setBlock(x - 8, y + 3, z - 7, block4, 0, 2);
		world.setBlock(x - 8, y + 3, z - 6, block4, 0, 2);
		world.setBlock(x - 8, y + 3, z - 5, block4, 0, 2);
		world.setBlock(x - 8, y + 3, z - 4, block4, 0, 2);
		world.setBlock(x - 8, y + 3, z - 3, block4, 0, 2);
		world.setBlock(x - 8, y + 3, z - 2, block4, 0, 2);
		world.setBlock(x - 8, y + 3, z - 1, block4, 0, 2);
		world.setBlock(x - 8, y + 3, z + 0, block4, 0, 2);
		world.setBlock(x - 8, y + 3, z + 1, block4, 0, 2);
		world.setBlock(x - 8, y + 3, z + 2, block1, 3, 2);
		world.setBlock(x - 7, y - 6, z - 9, block1, 6, 2);
		world.setBlock(x - 7, y - 6, z - 8, block2, 4, 2);
		world.setBlock(x - 7, y - 6, z - 7, block2, 4, 2);
		world.setBlock(x - 7, y - 6, z - 6, block2, 4, 2);
		world.setBlock(x - 7, y - 6, z - 5, block2, 4, 2);
		world.setBlock(x - 7, y - 6, z - 4, block2, 4, 2);
		world.setBlock(x - 7, y - 6, z - 3, block2, 4, 2);
		world.setBlock(x - 7, y - 6, z - 2, block2, 4, 2);
		world.setBlock(x - 7, y - 6, z - 1, block2, 4, 2);
		world.setBlock(x - 7, y - 6, z + 0, block1, 7, 2);
		world.setBlock(x - 7, y - 5, z - 9, block3, 0, 2);
		world.setBlock(x - 7, y - 5, z - 8, block3, 0, 2);
		world.setBlock(x - 7, y - 5, z - 7, block3, 0, 2);
		world.setBlock(x - 7, y - 5, z - 6, block3, 0, 2);
		world.setBlock(x - 7, y - 5, z - 5, block3, 0, 2);
		world.setBlock(x - 7, y - 5, z - 4, block3, 0, 2);
		world.setBlock(x - 7, y - 5, z - 3, block3, 0, 2);
		world.setBlock(x - 7, y - 5, z - 2, block3, 0, 2);
		world.setBlock(x - 7, y - 5, z - 1, block3, 0, 2);
		world.setBlock(x - 7, y - 5, z + 0, block3, 0, 2);
		world.setBlock(x - 7, y + 0, z - 10, block3, 0, 2);
		world.setBlock(x - 7, y + 0, z - 9, block3, 0, 2);
		world.setBlock(x - 7, y + 0, z - 8, block3, 0, 2);
		world.setBlock(x - 7, y + 0, z - 7, block3, 0, 2);
		world.setBlock(x - 7, y + 0, z - 6, block3, 0, 2);
		world.setBlock(x - 7, y + 0, z - 5, block3, 0, 2);
		world.setBlock(x - 7, y + 0, z - 4, block3, 0, 2);
		world.setBlock(x - 7, y + 0, z - 3, block3, 0, 2);
		world.setBlock(x - 7, y + 0, z - 2, block3, 0, 2);
		world.setBlock(x - 7, y + 0, z - 1, block3, 0, 2);
		world.setBlock(x - 7, y + 0, z + 0, block3, 0, 2);
		world.setBlock(x - 7, y + 0, z + 1, block3, 0, 2);
		world.setBlock(x - 7, y + 1, z - 11, block2, 4, 2);
		world.setBlock(x - 7, y + 1, z + 2, block2, 4, 2);
		world.setBlock(x - 7, y + 2, z - 11, block2, 4, 2);
		world.setBlock(x - 7, y + 2, z + 2, block2, 4, 2);
		world.setBlock(x - 7, y + 3, z - 11, block1, 2, 2);
		world.setBlock(x - 7, y + 3, z - 10, block4, 0, 2);
		world.setBlock(x - 7, y + 3, z - 9, block4, 0, 2);
		world.setBlock(x - 7, y + 3, z - 8, block4, 0, 2);
		world.setBlock(x - 7, y + 3, z - 7, block4, 0, 2);
		world.setBlock(x - 7, y + 3, z - 6, block4, 0, 2);
		world.setBlock(x - 7, y + 3, z - 5, block4, 0, 2);
		world.setBlock(x - 7, y + 3, z - 4, block4, 0, 2);
		world.setBlock(x - 7, y + 3, z - 3, block4, 0, 2);
		world.setBlock(x - 7, y + 3, z - 2, block4, 0, 2);
		world.setBlock(x - 7, y + 3, z - 1, block4, 0, 2);
		world.setBlock(x - 7, y + 3, z + 0, block4, 0, 2);
		world.setBlock(x - 7, y + 3, z + 1, block4, 0, 2);
		world.setBlock(x - 7, y + 3, z + 2, block1, 3, 2);
		world.setBlock(x - 6, y - 6, z - 9, block1, 6, 2);
		world.setBlock(x - 6, y - 6, z - 8, block2, 4, 2);
		world.setBlock(x - 6, y - 6, z - 7, block2, 4, 2);
		world.setBlock(x - 6, y - 6, z - 6, block2, 4, 2);
		world.setBlock(x - 6, y - 6, z - 5, block2, 4, 2);
		world.setBlock(x - 6, y - 6, z - 4, block2, 4, 2);
		world.setBlock(x - 6, y - 6, z - 3, block2, 4, 2);
		world.setBlock(x - 6, y - 6, z - 2, block2, 4, 2);
		world.setBlock(x - 6, y - 6, z - 1, block2, 4, 2);
		world.setBlock(x - 6, y - 6, z + 0, block1, 7, 2);
		world.setBlock(x - 6, y - 5, z - 9, block3, 0, 2);
		world.setBlock(x - 6, y - 5, z - 8, block3, 0, 2);
		world.setBlock(x - 6, y - 5, z - 7, block3, 0, 2);
		world.setBlock(x - 6, y - 5, z - 6, block3, 0, 2);
		world.setBlock(x - 6, y - 5, z - 5, block3, 0, 2);
		world.setBlock(x - 6, y - 5, z - 4, block3, 0, 2);
		world.setBlock(x - 6, y - 5, z - 3, block3, 0, 2);
		world.setBlock(x - 6, y - 5, z - 2, block3, 0, 2);
		world.setBlock(x - 6, y - 5, z - 1, block3, 0, 2);
		world.setBlock(x - 6, y - 5, z + 0, block3, 0, 2);
		world.setBlock(x - 6, y + 0, z - 10, block3, 0, 2);
		world.setBlock(x - 6, y + 0, z - 9, block3, 0, 2);
		world.setBlock(x - 6, y + 0, z - 8, block3, 0, 2);
		world.setBlock(x - 6, y + 0, z - 7, block3, 0, 2);
		world.setBlock(x - 6, y + 0, z - 6, block3, 0, 2);
		world.setBlock(x - 6, y + 0, z - 5, block3, 0, 2);
		world.setBlock(x - 6, y + 0, z - 4, block3, 0, 2);
		world.setBlock(x - 6, y + 0, z - 3, block3, 0, 2);
		world.setBlock(x - 6, y + 0, z - 2, block3, 0, 2);
		world.setBlock(x - 6, y + 0, z - 1, block3, 0, 2);
		world.setBlock(x - 6, y + 0, z + 0, block3, 0, 2);
		world.setBlock(x - 6, y + 0, z + 1, block3, 0, 2);
		world.setBlock(x - 6, y + 1, z - 11, block2, 4, 2);
		world.setBlock(x - 6, y + 1, z + 2, block2, 4, 2);
		world.setBlock(x - 6, y + 2, z - 11, block2, 4, 2);
		world.setBlock(x - 6, y + 2, z + 2, block2, 4, 2);
		world.setBlock(x - 6, y + 3, z - 11, block1, 2, 2);
		world.setBlock(x - 6, y + 3, z - 10, block4, 0, 2);
		world.setBlock(x - 6, y + 3, z - 9, block4, 0, 2);
		world.setBlock(x - 6, y + 3, z - 8, block4, 0, 2);
		world.setBlock(x - 6, y + 3, z - 7, block4, 0, 2);
		world.setBlock(x - 6, y + 3, z - 6, block4, 0, 2);
		world.setBlock(x - 6, y + 3, z - 5, block4, 0, 2);
		world.setBlock(x - 6, y + 3, z - 4, block4, 0, 2);
		world.setBlock(x - 6, y + 3, z - 3, block4, 0, 2);
		world.setBlock(x - 6, y + 3, z - 2, block4, 0, 2);
		world.setBlock(x - 6, y + 3, z - 1, block4, 0, 2);
		world.setBlock(x - 6, y + 3, z + 0, block4, 0, 2);
		world.setBlock(x - 6, y + 3, z + 1, block4, 0, 2);
		world.setBlock(x - 6, y + 3, z + 2, block1, 3, 2);
		world.setBlock(x - 5, y - 6, z - 9, block1, 6, 2);
		world.setBlock(x - 5, y - 6, z - 8, block2, 4, 2);
		world.setBlock(x - 5, y - 6, z - 7, block2, 4, 2);
		world.setBlock(x - 5, y - 6, z - 6, block2, 4, 2);
		world.setBlock(x - 5, y - 6, z - 5, block2, 4, 2);
		world.setBlock(x - 5, y - 6, z - 4, block2, 4, 2);
		world.setBlock(x - 5, y - 6, z - 3, block2, 4, 2);
		world.setBlock(x - 5, y - 6, z - 2, block2, 4, 2);
		world.setBlock(x - 5, y - 6, z - 1, block2, 4, 2);
		world.setBlock(x - 5, y - 6, z + 0, block1, 7, 2);
		world.setBlock(x - 5, y - 5, z - 9, block3, 0, 2);
		world.setBlock(x - 5, y - 5, z - 8, block3, 0, 2);
		world.setBlock(x - 5, y - 5, z - 7, block3, 0, 2);
		world.setBlock(x - 5, y - 5, z - 6, block3, 0, 2);
		world.setBlock(x - 5, y - 5, z - 5, block3, 0, 2);
		world.setBlock(x - 5, y - 5, z - 4, block3, 0, 2);
		world.setBlock(x - 5, y - 5, z - 3, block3, 0, 2);
		world.setBlock(x - 5, y - 5, z - 2, block3, 0, 2);
		world.setBlock(x - 5, y - 5, z - 1, block3, 0, 2);
		world.setBlock(x - 5, y - 5, z + 0, block3, 0, 2);
		world.setBlock(x - 5, y + 0, z - 10, block3, 0, 2);
		world.setBlock(x - 5, y + 0, z - 9, block3, 0, 2);
		world.setBlock(x - 5, y + 0, z - 8, block3, 0, 2);
		world.setBlock(x - 5, y + 0, z - 7, block3, 0, 2);
		world.setBlock(x - 5, y + 0, z - 6, block3, 0, 2);
		world.setBlock(x - 5, y + 0, z - 5, block3, 0, 2);
		world.setBlock(x - 5, y + 0, z - 4, block3, 0, 2);
		world.setBlock(x - 5, y + 0, z - 3, block3, 0, 2);
		world.setBlock(x - 5, y + 0, z - 2, block3, 0, 2);
		world.setBlock(x - 5, y + 0, z - 1, block3, 0, 2);
		world.setBlock(x - 5, y + 0, z + 0, block3, 0, 2);
		world.setBlock(x - 5, y + 0, z + 1, block3, 0, 2);
		world.setBlock(x - 5, y + 1, z - 11, block2, 4, 2);
		world.setBlock(x - 5, y + 1, z + 2, block2, 4, 2);
		world.setBlock(x - 5, y + 2, z - 11, block2, 4, 2);
		world.setBlock(x - 5, y + 2, z + 2, block2, 4, 2);
		world.setBlock(x - 5, y + 3, z - 11, block1, 2, 2);
		world.setBlock(x - 5, y + 3, z - 10, block4, 0, 2);
		world.setBlock(x - 5, y + 3, z - 9, block4, 0, 2);
		world.setBlock(x - 5, y + 3, z - 8, block4, 0, 2);
		world.setBlock(x - 5, y + 3, z - 7, block4, 0, 2);
		world.setBlock(x - 5, y + 3, z - 6, block4, 0, 2);
		world.setBlock(x - 5, y + 3, z - 5, block4, 0, 2);
		world.setBlock(x - 5, y + 3, z - 4, block4, 0, 2);
		world.setBlock(x - 5, y + 3, z - 3, block4, 0, 2);
		world.setBlock(x - 5, y + 3, z - 2, block4, 0, 2);
		world.setBlock(x - 5, y + 3, z - 1, block4, 0, 2);
		world.setBlock(x - 5, y + 3, z + 0, block4, 0, 2);
		world.setBlock(x - 5, y + 3, z + 1, block4, 0, 2);
		world.setBlock(x - 5, y + 3, z + 2, block1, 3, 2);
		world.setBlock(x - 4, y - 6, z - 9, block1, 6, 2);
		world.setBlock(x - 4, y - 6, z - 8, block2, 4, 2);
		world.setBlock(x - 4, y - 6, z - 7, block2, 4, 2);
		world.setBlock(x - 4, y - 6, z - 6, block2, 4, 2);
		world.setBlock(x - 4, y - 6, z - 5, block2, 4, 2);
		world.setBlock(x - 4, y - 6, z - 4, block2, 4, 2);
		world.setBlock(x - 4, y - 6, z - 3, block2, 4, 2);
		world.setBlock(x - 4, y - 6, z - 2, block2, 4, 2);
		world.setBlock(x - 4, y - 6, z - 1, block2, 4, 2);
		world.setBlock(x - 4, y - 6, z + 0, block1, 7, 2);
		world.setBlock(x - 4, y - 5, z - 9, block3, 0, 2);
		world.setBlock(x - 4, y - 5, z - 8, block3, 0, 2);
		world.setBlock(x - 4, y - 5, z - 7, block3, 0, 2);
		world.setBlock(x - 4, y - 5, z - 6, block3, 0, 2);
		world.setBlock(x - 4, y - 5, z - 5, block3, 0, 2);
		world.setBlock(x - 4, y - 5, z - 4, block3, 0, 2);
		world.setBlock(x - 4, y - 5, z - 3, block3, 0, 2);
		world.setBlock(x - 4, y - 5, z - 2, block3, 0, 2);
		world.setBlock(x - 4, y - 5, z - 1, block3, 0, 2);
		world.setBlock(x - 4, y - 5, z + 0, block3, 0, 2);
		world.setBlock(x - 4, y + 0, z - 10, block3, 0, 2);
		world.setBlock(x - 4, y + 0, z - 9, block3, 0, 2);
		world.setBlock(x - 4, y + 0, z - 8, block3, 0, 2);
		world.setBlock(x - 4, y + 0, z - 7, block3, 0, 2);
		world.setBlock(x - 4, y + 0, z - 6, block3, 0, 2);
		world.setBlock(x - 4, y + 0, z - 5, block3, 0, 2);
		world.setBlock(x - 4, y + 0, z - 4, block3, 0, 2);
		world.setBlock(x - 4, y + 0, z - 3, block3, 0, 2);
		world.setBlock(x - 4, y + 0, z - 2, block3, 0, 2);
		world.setBlock(x - 4, y + 0, z - 1, block3, 0, 2);
		world.setBlock(x - 4, y + 0, z + 0, block3, 0, 2);
		world.setBlock(x - 4, y + 0, z + 1, block3, 0, 2);
		world.setBlock(x - 4, y + 1, z - 11, block2, 4, 2);
		world.setBlock(x - 4, y + 1, z + 2, block2, 4, 2);
		world.setBlock(x - 4, y + 2, z - 11, block2, 4, 2);
		world.setBlock(x - 4, y + 2, z + 2, block2, 4, 2);
		world.setBlock(x - 4, y + 3, z - 11, block1, 2, 2);
		world.setBlock(x - 4, y + 3, z - 10, block4, 0, 2);
		world.setBlock(x - 4, y + 3, z - 9, block4, 0, 2);
		world.setBlock(x - 4, y + 3, z - 8, block4, 0, 2);
		world.setBlock(x - 4, y + 3, z - 7, block4, 0, 2);
		world.setBlock(x - 4, y + 3, z - 6, block4, 0, 2);
		world.setBlock(x - 4, y + 3, z - 5, block4, 0, 2);
		world.setBlock(x - 4, y + 3, z - 4, block4, 0, 2);
		world.setBlock(x - 4, y + 3, z - 3, block4, 0, 2);
		world.setBlock(x - 4, y + 3, z - 2, block4, 0, 2);
		world.setBlock(x - 4, y + 3, z - 1, block4, 0, 2);
		world.setBlock(x - 4, y + 3, z + 0, block4, 0, 2);
		world.setBlock(x - 4, y + 3, z + 1, block4, 0, 2);
		world.setBlock(x - 4, y + 3, z + 2, block1, 3, 2);
		world.setBlock(x - 3, y - 6, z - 9, block1, 6, 2);
		world.setBlock(x - 3, y - 6, z - 8, block2, 4, 2);
		world.setBlock(x - 3, y - 6, z - 7, block2, 4, 2);
		world.setBlock(x - 3, y - 6, z - 6, block2, 4, 2);
		world.setBlock(x - 3, y - 6, z - 5, block2, 4, 2);
		world.setBlock(x - 3, y - 6, z - 4, block2, 4, 2);
		world.setBlock(x - 3, y - 6, z - 3, block2, 4, 2);
		world.setBlock(x - 3, y - 6, z - 2, block2, 4, 2);
		world.setBlock(x - 3, y - 6, z - 1, block2, 4, 2);
		world.setBlock(x - 3, y - 6, z + 0, block1, 7, 2);
		world.setBlock(x - 3, y - 5, z - 9, block3, 0, 2);
		world.setBlock(x - 3, y - 5, z - 8, block3, 0, 2);
		world.setBlock(x - 3, y - 5, z - 7, block3, 0, 2);
		world.setBlock(x - 3, y - 5, z - 6, block3, 0, 2);
		world.setBlock(x - 3, y - 5, z - 5, block3, 0, 2);
		world.setBlock(x - 3, y - 5, z - 4, block3, 0, 2);
		world.setBlock(x - 3, y - 5, z - 3, block3, 0, 2);
		world.setBlock(x - 3, y - 5, z - 2, block3, 0, 2);
		world.setBlock(x - 3, y - 5, z - 1, block3, 0, 2);
		world.setBlock(x - 3, y - 5, z + 0, block3, 0, 2);
		world.setBlock(x - 3, y + 0, z - 10, block3, 0, 2);
		world.setBlock(x - 3, y + 0, z - 9, block3, 0, 2);
		world.setBlock(x - 3, y + 0, z - 8, block3, 0, 2);
		world.setBlock(x - 3, y + 0, z - 7, block3, 0, 2);
		world.setBlock(x - 3, y + 0, z - 6, block3, 0, 2);
		world.setBlock(x - 3, y + 0, z - 5, block3, 0, 2);
		world.setBlock(x - 3, y + 0, z - 4, block3, 0, 2);
		world.setBlock(x - 3, y + 0, z - 3, block3, 0, 2);
		world.setBlock(x - 3, y + 0, z - 2, block3, 0, 2);
		world.setBlock(x - 3, y + 0, z - 1, block3, 0, 2);
		world.setBlock(x - 3, y + 0, z + 0, block3, 0, 2);
		world.setBlock(x - 3, y + 0, z + 1, block3, 0, 2);
		world.setBlock(x - 3, y + 1, z - 11, block2, 4, 2);
		world.setBlock(x - 3, y + 1, z + 2, block2, 4, 2);
		world.setBlock(x - 3, y + 2, z - 11, block2, 4, 2);
		world.setBlock(x - 3, y + 2, z + 2, block2, 4, 2);
		world.setBlock(x - 3, y + 3, z - 11, block1, 2, 2);
		world.setBlock(x - 3, y + 3, z - 10, block4, 0, 2);
		world.setBlock(x - 3, y + 3, z - 9, block4, 0, 2);
		world.setBlock(x - 3, y + 3, z - 8, block4, 0, 2);
		world.setBlock(x - 3, y + 3, z - 7, block4, 0, 2);
		world.setBlock(x - 3, y + 3, z - 6, block4, 0, 2);
		world.setBlock(x - 3, y + 3, z - 5, block4, 0, 2);
		world.setBlock(x - 3, y + 3, z - 4, block4, 0, 2);
		world.setBlock(x - 3, y + 3, z - 3, block4, 0, 2);
		world.setBlock(x - 3, y + 3, z - 2, block4, 0, 2);
		world.setBlock(x - 3, y + 3, z - 1, block4, 0, 2);
		world.setBlock(x - 3, y + 3, z + 0, block4, 0, 2);
		world.setBlock(x - 3, y + 3, z + 1, block4, 0, 2);
		world.setBlock(x - 3, y + 3, z + 2, block1, 3, 2);
		world.setBlock(x - 2, y - 6, z - 9, block1, 6, 2);
		world.setBlock(x - 2, y - 6, z - 8, block2, 4, 2);
		world.setBlock(x - 2, y - 6, z - 7, block2, 4, 2);
		world.setBlock(x - 2, y - 6, z - 6, block2, 4, 2);
		world.setBlock(x - 2, y - 6, z - 5, block2, 4, 2);
		world.setBlock(x - 2, y - 6, z - 4, block2, 4, 2);
		world.setBlock(x - 2, y - 6, z - 3, block2, 4, 2);
		world.setBlock(x - 2, y - 6, z - 2, block2, 4, 2);
		world.setBlock(x - 2, y - 6, z - 1, block2, 4, 2);
		world.setBlock(x - 2, y - 6, z + 0, block1, 7, 2);
		world.setBlock(x - 2, y - 5, z - 9, block3, 0, 2);
		world.setBlock(x - 2, y - 5, z - 8, block3, 0, 2);
		world.setBlock(x - 2, y - 5, z - 7, block3, 0, 2);
		world.setBlock(x - 2, y - 5, z - 6, block3, 0, 2);
		world.setBlock(x - 2, y - 5, z - 5, block3, 0, 2);
		world.setBlock(x - 2, y - 5, z - 4, block3, 0, 2);
		world.setBlock(x - 2, y - 5, z - 3, block3, 0, 2);
		world.setBlock(x - 2, y - 5, z - 2, block3, 0, 2);
		world.setBlock(x - 2, y - 5, z - 1, block3, 0, 2);
		world.setBlock(x - 2, y - 5, z + 0, block3, 0, 2);
		world.setBlock(x - 2, y + 0, z - 10, block3, 0, 2);
		world.setBlock(x - 2, y + 0, z - 9, block3, 0, 2);
		world.setBlock(x - 2, y + 0, z - 8, block3, 0, 2);
		world.setBlock(x - 2, y + 0, z - 7, block3, 0, 2);
		world.setBlock(x - 2, y + 0, z - 6, block3, 0, 2);
		world.setBlock(x - 2, y + 0, z - 5, block3, 0, 2);
		world.setBlock(x - 2, y + 0, z - 4, block3, 0, 2);
		world.setBlock(x - 2, y + 0, z - 3, block3, 0, 2);
		world.setBlock(x - 2, y + 0, z - 2, block3, 0, 2);
		world.setBlock(x - 2, y + 0, z - 1, block3, 0, 2);
		world.setBlock(x - 2, y + 0, z + 0, block3, 0, 2);
		world.setBlock(x - 2, y + 0, z + 1, block3, 0, 2);
		world.setBlock(x - 2, y + 1, z - 11, block2, 4, 2);
		world.setBlock(x - 2, y + 1, z + 2, block2, 4, 2);
		world.setBlock(x - 2, y + 2, z - 11, block2, 4, 2);
		world.setBlock(x - 2, y + 2, z + 2, block2, 4, 2);
		world.setBlock(x - 2, y + 3, z - 11, block1, 2, 2);
		world.setBlock(x - 2, y + 3, z - 10, block4, 0, 2);
		world.setBlock(x - 2, y + 3, z - 9, block4, 0, 2);
		world.setBlock(x - 2, y + 3, z - 8, block4, 0, 2);
		world.setBlock(x - 2, y + 3, z - 7, block4, 0, 2);
		world.setBlock(x - 2, y + 3, z - 6, block4, 0, 2);
		world.setBlock(x - 2, y + 3, z - 5, block4, 0, 2);
		world.setBlock(x - 2, y + 3, z - 4, block4, 0, 2);
		world.setBlock(x - 2, y + 3, z - 3, block4, 0, 2);
		world.setBlock(x - 2, y + 3, z - 2, block4, 0, 2);
		world.setBlock(x - 2, y + 3, z - 1, block4, 0, 2);
		world.setBlock(x - 2, y + 3, z + 0, block4, 0, 2);
		world.setBlock(x - 2, y + 3, z + 1, block4, 0, 2);
		world.setBlock(x - 2, y + 3, z + 2, block1, 3, 2);
		world.setBlock(x - 1, y - 6, z - 9, block1, 6, 2);
		world.setBlock(x - 1, y - 6, z - 8, block2, 4, 2);
		world.setBlock(x - 1, y - 6, z - 7, block2, 4, 2);
		world.setBlock(x - 1, y - 6, z - 6, block2, 4, 2);
		world.setBlock(x - 1, y - 6, z - 5, block2, 4, 2);
		world.setBlock(x - 1, y - 6, z - 4, block2, 4, 2);
		world.setBlock(x - 1, y - 6, z - 3, block2, 4, 2);
		world.setBlock(x - 1, y - 6, z - 2, block2, 4, 2);
		world.setBlock(x - 1, y - 6, z - 1, block2, 4, 2);
		world.setBlock(x - 1, y - 6, z + 0, block1, 7, 2);
		world.setBlock(x - 1, y - 5, z - 9, block3, 0, 2);
		world.setBlock(x - 1, y - 5, z - 8, block3, 0, 2);
		world.setBlock(x - 1, y - 5, z - 7, block3, 0, 2);
		world.setBlock(x - 1, y - 5, z - 6, block3, 0, 2);
		world.setBlock(x - 1, y - 5, z - 5, block3, 0, 2);
		world.setBlock(x - 1, y - 5, z - 4, block3, 0, 2);
		world.setBlock(x - 1, y - 5, z - 3, block3, 0, 2);
		world.setBlock(x - 1, y - 5, z - 2, block3, 0, 2);
		world.setBlock(x - 1, y - 5, z - 1, block3, 0, 2);
		world.setBlock(x - 1, y - 5, z + 0, block3, 0, 2);
		world.setBlock(x - 1, y + 0, z - 10, block3, 0, 2);
		world.setBlock(x - 1, y + 0, z - 9, block3, 0, 2);
		world.setBlock(x - 1, y + 0, z - 8, block3, 0, 2);
		world.setBlock(x - 1, y + 0, z - 7, block3, 0, 2);
		world.setBlock(x - 1, y + 0, z - 6, block3, 0, 2);
		world.setBlock(x - 1, y + 0, z - 5, block3, 0, 2);
		world.setBlock(x - 1, y + 0, z - 4, block3, 0, 2);
		world.setBlock(x - 1, y + 0, z - 3, block3, 0, 2);
		world.setBlock(x - 1, y + 0, z - 2, block3, 0, 2);
		world.setBlock(x - 1, y + 0, z - 1, block3, 0, 2);
		world.setBlock(x - 1, y + 0, z + 0, block3, 0, 2);
		world.setBlock(x - 1, y + 0, z + 1, block3, 0, 2);
		world.setBlock(x - 1, y + 1, z - 11, block2, 4, 2);
		world.setBlock(x - 1, y + 1, z + 2, block2, 4, 2);
		world.setBlock(x - 1, y + 2, z - 11, block2, 4, 2);
		world.setBlock(x - 1, y + 2, z + 2, block2, 4, 2);
		world.setBlock(x - 1, y + 3, z - 11, block1, 2, 2);
		world.setBlock(x - 1, y + 3, z - 10, block4, 0, 2);
		world.setBlock(x - 1, y + 3, z - 9, block4, 0, 2);
		world.setBlock(x - 1, y + 3, z - 8, block4, 0, 2);
		world.setBlock(x - 1, y + 3, z - 7, block4, 0, 2);
		world.setBlock(x - 1, y + 3, z - 6, block4, 0, 2);
		world.setBlock(x - 1, y + 3, z - 5, block4, 0, 2);
		world.setBlock(x - 1, y + 3, z - 4, block4, 0, 2);
		world.setBlock(x - 1, y + 3, z - 3, block4, 0, 2);
		world.setBlock(x - 1, y + 3, z - 2, block4, 0, 2);
		world.setBlock(x - 1, y + 3, z - 1, block4, 0, 2);
		world.setBlock(x - 1, y + 3, z + 0, block4, 0, 2);
		world.setBlock(x - 1, y + 3, z + 1, block4, 0, 2);
		world.setBlock(x - 1, y + 3, z + 2, block1, 3, 2);
		world.setBlock(x + 0, y - 6, z - 8, block1, 5, 2);
		world.setBlock(x + 0, y - 6, z - 7, block1, 5, 2);
		world.setBlock(x + 0, y - 6, z - 6, block1, 5, 2);
		world.setBlock(x + 0, y - 6, z - 5, block1, 5, 2);
		world.setBlock(x + 0, y - 6, z - 4, block1, 5, 2);
		world.setBlock(x + 0, y - 6, z - 3, block1, 5, 2);
		world.setBlock(x + 0, y - 6, z - 2, block1, 5, 2);
		world.setBlock(x + 0, y - 6, z - 1, block1, 5, 2);
		world.setBlock(x + 0, y - 5, z - 8, block3, 0, 2);
		world.setBlock(x + 0, y - 5, z - 7, block3, 0, 2);
		world.setBlock(x + 0, y - 5, z - 6, block3, 0, 2);
		world.setBlock(x + 0, y - 5, z - 5, block3, 0, 2);
		world.setBlock(x + 0, y - 5, z - 4, block3, 0, 2);
		world.setBlock(x + 0, y - 5, z - 3, block3, 0, 2);
		world.setBlock(x + 0, y - 5, z - 2, block3, 0, 2);
		world.setBlock(x + 0, y - 5, z - 1, block3, 0, 2);
		world.setBlock(x + 0, y + 0, z - 10, block3, 0, 2);
		world.setBlock(x + 0, y + 0, z - 9, block3, 0, 2);
		world.setBlock(x + 0, y + 0, z - 8, block3, 0, 2);
		world.setBlock(x + 0, y + 0, z - 7, block3, 0, 2);
		world.setBlock(x + 0, y + 0, z - 6, block3, 0, 2);
		world.setBlock(x + 0, y + 0, z - 5, block3, 0, 2);
		world.setBlock(x + 0, y + 0, z - 4, block3, 0, 2);
		world.setBlock(x + 0, y + 0, z - 3, block3, 0, 2);
		world.setBlock(x + 0, y + 0, z - 2, block3, 0, 2);
		world.setBlock(x + 0, y + 0, z - 1, block3, 0, 2);
		world.setBlock(x + 0, y + 0, z + 0, block3, 0, 2);
		world.setBlock(x + 0, y + 0, z + 1, block3, 0, 2);
		world.setBlock(x + 0, y + 1, z - 11, block2, 4, 2);
		world.setBlock(x + 0, y + 1, z + 2, block2, 4, 2);
		world.setBlock(x + 0, y + 2, z - 11, block2, 4, 2);
		world.setBlock(x + 0, y + 2, z + 2, block2, 4, 2);
		world.setBlock(x + 0, y + 3, z - 11, block1, 2, 2);
		world.setBlock(x + 0, y + 3, z - 10, block4, 0, 2);
		world.setBlock(x + 0, y + 3, z - 9, block4, 0, 2);
		world.setBlock(x + 0, y + 3, z - 8, block4, 0, 2);
		world.setBlock(x + 0, y + 3, z - 7, block4, 0, 2);
		world.setBlock(x + 0, y + 3, z - 6, block4, 0, 2);
		world.setBlock(x + 0, y + 3, z - 5, block4, 0, 2);
		world.setBlock(x + 0, y + 3, z - 4, block4, 0, 2);
		world.setBlock(x + 0, y + 3, z - 3, block4, 0, 2);
		world.setBlock(x + 0, y + 3, z - 2, block4, 0, 2);
		world.setBlock(x + 0, y + 3, z - 1, block4, 0, 2);
		world.setBlock(x + 0, y + 3, z + 0, block4, 0, 2);
		world.setBlock(x + 0, y + 3, z + 1, block4, 0, 2);
		world.setBlock(x + 0, y + 3, z + 2, block1, 3, 2);
		world.setBlock(x + 1, y + 0, z - 9, block3, 0, 2);
		world.setBlock(x + 1, y + 0, z - 8, block3, 0, 2);
		world.setBlock(x + 1, y + 0, z - 7, block3, 0, 2);
		world.setBlock(x + 1, y + 0, z - 6, block3, 0, 2);
		world.setBlock(x + 1, y + 0, z - 5, block3, 0, 2);
		world.setBlock(x + 1, y + 0, z - 4, block3, 0, 2);
		world.setBlock(x + 1, y + 0, z - 3, block3, 0, 2);
		world.setBlock(x + 1, y + 0, z - 2, block3, 0, 2);
		world.setBlock(x + 1, y + 0, z - 1, block3, 0, 2);
		world.setBlock(x + 1, y + 0, z + 0, block3, 0, 2);
		world.setBlock(x + 1, y + 1, z - 11, block1, 1, 2);
		world.setBlock(x + 1, y + 1, z - 10, block2, 4, 2);
		world.setBlock(x + 1, y + 1, z + 1, block2, 4, 2);
		world.setBlock(x + 1, y + 1, z + 2, block1, 1, 2);
		world.setBlock(x + 1, y + 2, z - 10, block2, 4, 2);
		world.setBlock(x + 1, y + 2, z + 1, block2, 4, 2);
		world.setBlock(x + 1, y + 3, z - 10, block2, 4, 2);
		world.setBlock(x + 1, y + 3, z - 9, block4, 0, 2);
		world.setBlock(x + 1, y + 3, z - 8, block4, 0, 2);
		world.setBlock(x + 1, y + 3, z - 7, block4, 0, 2);
		world.setBlock(x + 1, y + 3, z - 6, block4, 0, 2);
		world.setBlock(x + 1, y + 3, z - 5, block4, 0, 2);
		world.setBlock(x + 1, y + 3, z - 4, block4, 0, 2);
		world.setBlock(x + 1, y + 3, z - 3, block4, 0, 2);
		world.setBlock(x + 1, y + 3, z - 2, block4, 0, 2);
		world.setBlock(x + 1, y + 3, z - 1, block4, 0, 2);
		world.setBlock(x + 1, y + 3, z + 0, block4, 0, 2);
		world.setBlock(x + 1, y + 3, z + 1, block2, 4, 2);
		world.setBlock(x + 2, y + 1, z - 10, block1, 2, 2);
		world.setBlock(x + 2, y + 1, z - 9, block2, 4, 2);
		world.setBlock(x + 2, y + 1, z - 8, block2, 4, 2);
		world.setBlock(x + 2, y + 1, z - 7, block2, 4, 2);
		world.setBlock(x + 2, y + 1, z - 6, block2, 4, 2);
		world.setBlock(x + 2, y + 1, z - 5, block2, 4, 2);
		world.setBlock(x + 2, y + 1, z - 4, block2, 4, 2);
		world.setBlock(x + 2, y + 1, z - 3, block2, 4, 2);
		world.setBlock(x + 2, y + 1, z - 2, block2, 4, 2);
		world.setBlock(x + 2, y + 1, z - 1, block2, 4, 2);
		world.setBlock(x + 2, y + 1, z + 0, block2, 4, 2);
		world.setBlock(x + 2, y + 1, z + 1, block1, 3, 2);
		world.setBlock(x + 2, y + 2, z - 9, block2, 4, 2);
		world.setBlock(x + 2, y + 2, z - 8, block2, 4, 2);
		world.setBlock(x + 2, y + 2, z - 7, block2, 4, 2);
		world.setBlock(x + 2, y + 2, z - 6, block2, 4, 2);
		world.setBlock(x + 2, y + 2, z - 5, block2, 4, 2);
		world.setBlock(x + 2, y + 2, z - 4, block2, 4, 2);
		world.setBlock(x + 2, y + 2, z - 3, block2, 4, 2);
		world.setBlock(x + 2, y + 2, z - 2, block2, 4, 2);
		world.setBlock(x + 2, y + 2, z - 1, block2, 4, 2);
		world.setBlock(x + 2, y + 2, z + 0, block2, 4, 2);
		world.setBlock(x + 2, y + 3, z - 9, block1, 1, 2);
		world.setBlock(x + 2, y + 3, z - 8, block1, 1, 2);
		world.setBlock(x + 2, y + 3, z - 7, block1, 1, 2);
		world.setBlock(x + 2, y + 3, z - 6, block1, 1, 2);
		world.setBlock(x + 2, y + 3, z - 5, block1, 1, 2);
		world.setBlock(x + 2, y + 3, z - 4, block1, 1, 2);
		world.setBlock(x + 2, y + 3, z - 3, block1, 1, 2);
		world.setBlock(x + 2, y + 3, z - 2, block1, 1, 2);
		world.setBlock(x + 2, y + 3, z - 1, block1, 1, 2);
		world.setBlock(x + 2, y + 3, z + 0, block1, 1, 2);
		world.setBlock(x - 11, y + 0, z - 7, block2, 4, 2);
		world.setBlock(x - 11, y + 0, z - 6, block2, 4, 2);
		world.setBlock(x - 11, y + 0, z - 5, block2, 4, 2);
		world.setBlock(x - 11, y + 0, z - 4, block2, 4, 2);
		world.setBlock(x - 11, y + 0, z - 3, block2, 4, 2);
		world.setBlock(x - 11, y + 0, z - 2, block2, 4, 2);
		world.setBlock(x - 7, y + 0, z - 11, block2, 4, 2);
		world.setBlock(x - 7, y + 0, z + 2, block2, 4, 2);
		world.setBlock(x - 6, y + 0, z - 11, block2, 4, 2);
		world.setBlock(x - 6, y + 0, z + 2, block2, 4, 2);
		world.setBlock(x - 5, y + 0, z - 11, block2, 4, 2);
		world.setBlock(x - 5, y + 0, z + 2, block2, 4, 2);
		world.setBlock(x - 4, y + 0, z - 11, block2, 4, 2);
		world.setBlock(x - 4, y + 0, z + 2, block2, 4, 2);
		world.setBlock(x - 3, y + 0, z - 11, block2, 4, 2);
		world.setBlock(x - 3, y + 0, z + 2, block2, 4, 2);
		world.setBlock(x - 2, y + 0, z - 11, block2, 4, 2);
		world.setBlock(x - 2, y + 0, z + 2, block2, 4, 2);
		world.setBlock(x + 2, y + 0, z - 7, block2, 4, 2);
		world.setBlock(x + 2, y + 0, z - 6, block2, 4, 2);
		world.setBlock(x + 2, y + 0, z - 5, block2, 4, 2);
		world.setBlock(x + 2, y + 0, z - 4, block2, 4, 2);
		world.setBlock(x + 2, y + 0, z - 3, block2, 4, 2);
		world.setBlock(x + 2, y + 0, z - 2, block2, 4, 2);
	}
	
	@Override
	public void deconstruct(World world, ForgeDirection dir, int x, int y, int z)
	{
		
		Block block1 = Blocks.air;
		world.setBlock(x - 11, y + 1, z - 10, block1, 2, 2);
		Block block2 = Blocks.air;
		world.setBlock(x - 11, y + 1, z - 9, block2, 4, 2);
		world.setBlock(x - 11, y + 1, z - 8, block2, 4, 2);
		world.setBlock(x - 11, y + 1, z - 7, block2, 4, 2);
		world.setBlock(x - 11, y + 1, z - 6, block2, 4, 2);
		world.setBlock(x - 11, y + 1, z - 5, block2, 4, 2);
		world.setBlock(x - 11, y + 1, z - 4, block2, 4, 2);
		world.setBlock(x - 11, y + 1, z - 3, block2, 4, 2);
		world.setBlock(x - 11, y + 1, z - 2, block2, 4, 2);
		world.setBlock(x - 11, y + 1, z - 1, block2, 4, 2);
		world.setBlock(x - 11, y + 1, z + 0, block2, 4, 2);
		world.setBlock(x - 11, y + 1, z + 1, block1, 3, 2);
		world.setBlock(x - 11, y + 2, z - 9, block2, 4, 2);
		world.setBlock(x - 11, y + 2, z - 8, block2, 4, 2);
		world.setBlock(x - 11, y + 2, z - 7, block2, 4, 2);
		world.setBlock(x - 11, y + 2, z - 6, block2, 4, 2);
		world.setBlock(x - 11, y + 2, z - 5, block2, 4, 2);
		world.setBlock(x - 11, y + 2, z - 4, block2, 4, 2);
		world.setBlock(x - 11, y + 2, z - 3, block2, 4, 2);
		world.setBlock(x - 11, y + 2, z - 2, block2, 4, 2);
		world.setBlock(x - 11, y + 2, z - 1, block2, 4, 2);
		world.setBlock(x - 11, y + 2, z + 0, block2, 4, 2);
		world.setBlock(x - 11, y + 3, z - 9, block1, 0, 2);
		world.setBlock(x - 11, y + 3, z - 8, block1, 0, 2);
		world.setBlock(x - 11, y + 3, z - 7, block1, 0, 2);
		world.setBlock(x - 11, y + 3, z - 6, block1, 0, 2);
		world.setBlock(x - 11, y + 3, z - 5, block1, 0, 2);
		world.setBlock(x - 11, y + 3, z - 4, block1, 0, 2);
		world.setBlock(x - 11, y + 3, z - 3, block1, 0, 2);
		world.setBlock(x - 11, y + 3, z - 2, block1, 0, 2);
		world.setBlock(x - 11, y + 3, z - 1, block1, 0, 2);
		world.setBlock(x - 11, y + 3, z + 0, block1, 0, 2);
		Block block3 = Blocks.air;
		world.setBlock(x - 10, y + 0, z - 9, block3, 0, 2);
		world.setBlock(x - 10, y + 0, z - 8, block3, 0, 2);
		world.setBlock(x - 10, y + 0, z - 7, block3, 0, 2);
		world.setBlock(x - 10, y + 0, z - 6, block3, 0, 2);
		world.setBlock(x - 10, y + 0, z - 5, block3, 0, 2);
		world.setBlock(x - 10, y + 0, z - 4, block3, 0, 2);
		world.setBlock(x - 10, y + 0, z - 3, block3, 0, 2);
		world.setBlock(x - 10, y + 0, z - 2, block3, 0, 2);
		world.setBlock(x - 10, y + 0, z - 1, block3, 0, 2);
		world.setBlock(x - 10, y + 0, z + 0, block3, 0, 2);
		world.setBlock(x - 10, y + 1, z - 11, block1, 0, 2);
		world.setBlock(x - 10, y + 1, z - 10, block2, 4, 2);
		world.setBlock(x - 10, y + 1, z + 1, block2, 4, 2);
		world.setBlock(x - 10, y + 1, z + 2, block1, 0, 2);
		world.setBlock(x - 10, y + 2, z - 10, block2, 4, 2);
		world.setBlock(x - 10, y + 2, z + 1, block2, 4, 2);
		world.setBlock(x - 10, y + 3, z - 10, block2, 4, 2);
		Block block4 = Blocks.air;
		world.setBlock(x - 10, y + 3, z - 9, block4, 0, 2);
		world.setBlock(x - 10, y + 3, z - 8, block4, 0, 2);
		world.setBlock(x - 10, y + 3, z - 7, block4, 0, 2);
		world.setBlock(x - 10, y + 3, z - 6, block4, 0, 2);
		world.setBlock(x - 10, y + 3, z - 5, block4, 0, 2);
		world.setBlock(x - 10, y + 3, z - 4, block4, 0, 2);
		world.setBlock(x - 10, y + 3, z - 3, block4, 0, 2);
		world.setBlock(x - 10, y + 3, z - 2, block4, 0, 2);
		world.setBlock(x - 10, y + 3, z - 1, block4, 0, 2);
		world.setBlock(x - 10, y + 3, z + 0, block4, 0, 2);
		world.setBlock(x - 10, y + 3, z + 1, block2, 4, 2);
		world.setBlock(x - 9, y - 6, z - 8, block1, 4, 2);
		world.setBlock(x - 9, y - 6, z - 7, block1, 4, 2);
		world.setBlock(x - 9, y - 6, z - 6, block1, 4, 2);
		world.setBlock(x - 9, y - 6, z - 5, block1, 4, 2);
		world.setBlock(x - 9, y - 6, z - 4, block1, 4, 2);
		world.setBlock(x - 9, y - 6, z - 3, block1, 4, 2);
		world.setBlock(x - 9, y - 6, z - 2, block1, 4, 2);
		world.setBlock(x - 9, y - 6, z - 1, block1, 4, 2);
		world.setBlock(x - 9, y - 5, z - 8, block3, 0, 2);
		world.setBlock(x - 9, y - 5, z - 7, block3, 0, 2);
		world.setBlock(x - 9, y - 5, z - 6, block3, 0, 2);
		world.setBlock(x - 9, y - 5, z - 5, block3, 0, 2);
		world.setBlock(x - 9, y - 5, z - 4, block3, 0, 2);
		world.setBlock(x - 9, y - 5, z - 3, block3, 0, 2);
		world.setBlock(x - 9, y - 5, z - 2, block3, 0, 2);
		world.setBlock(x - 9, y - 5, z - 1, block3, 0, 2);
		world.setBlock(x - 9, y + 0, z - 10, block3, 0, 2);
		world.setBlock(x - 9, y + 0, z - 9, block3, 0, 2);
		world.setBlock(x - 9, y + 0, z - 8, block3, 0, 2);
		world.setBlock(x - 9, y + 0, z - 7, block3, 0, 2);
		world.setBlock(x - 9, y + 0, z - 6, block3, 0, 2);
		world.setBlock(x - 9, y + 0, z - 5, block3, 0, 2);
		world.setBlock(x - 9, y + 0, z - 4, block3, 0, 2);
		world.setBlock(x - 9, y + 0, z - 3, block3, 0, 2);
		world.setBlock(x - 9, y + 0, z - 2, block3, 0, 2);
		world.setBlock(x - 9, y + 0, z - 1, block3, 0, 2);
		world.setBlock(x - 9, y + 0, z + 0, block3, 0, 2);
		world.setBlock(x - 9, y + 0, z + 1, block3, 0, 2);
		world.setBlock(x - 9, y + 1, z - 11, block2, 4, 2);
		world.setBlock(x - 9, y + 1, z + 2, block2, 4, 2);
		world.setBlock(x - 9, y + 2, z - 11, block2, 4, 2);
		world.setBlock(x - 9, y + 2, z + 2, block2, 4, 2);
		world.setBlock(x - 9, y + 3, z - 11, block1, 2, 2);
		world.setBlock(x - 9, y + 3, z - 10, block4, 0, 2);
		world.setBlock(x - 9, y + 3, z - 9, block4, 0, 2);
		world.setBlock(x - 9, y + 3, z - 8, block4, 0, 2);
		world.setBlock(x - 9, y + 3, z - 7, block4, 0, 2);
		world.setBlock(x - 9, y + 3, z - 6, block4, 0, 2);
		world.setBlock(x - 9, y + 3, z - 5, block4, 0, 2);
		world.setBlock(x - 9, y + 3, z - 4, block4, 0, 2);
		world.setBlock(x - 9, y + 3, z - 3, block4, 0, 2);
		world.setBlock(x - 9, y + 3, z - 2, block4, 0, 2);
		world.setBlock(x - 9, y + 3, z - 1, block4, 0, 2);
		world.setBlock(x - 9, y + 3, z + 0, block4, 0, 2);
		world.setBlock(x - 9, y + 3, z + 1, block4, 0, 2);
		world.setBlock(x - 9, y + 3, z + 2, block1, 3, 2);
		world.setBlock(x - 8, y - 6, z - 9, block1, 6, 2);
		world.setBlock(x - 8, y - 6, z - 8, block2, 4, 2);
		world.setBlock(x - 8, y - 6, z - 7, block2, 4, 2);
		world.setBlock(x - 8, y - 6, z - 6, block2, 4, 2);
		world.setBlock(x - 8, y - 6, z - 5, block2, 4, 2);
		world.setBlock(x - 8, y - 6, z - 4, block2, 4, 2);
		world.setBlock(x - 8, y - 6, z - 3, block2, 4, 2);
		world.setBlock(x - 8, y - 6, z - 2, block2, 4, 2);
		world.setBlock(x - 8, y - 6, z - 1, block2, 4, 2);
		world.setBlock(x - 8, y - 6, z + 0, block1, 7, 2);
		world.setBlock(x - 8, y - 5, z - 9, block3, 0, 2);
		world.setBlock(x - 8, y - 5, z - 8, block3, 0, 2);
		world.setBlock(x - 8, y - 5, z - 7, block3, 0, 2);
		world.setBlock(x - 8, y - 5, z - 6, block3, 0, 2);
		world.setBlock(x - 8, y - 5, z - 5, block3, 0, 2);
		world.setBlock(x - 8, y - 5, z - 4, block3, 0, 2);
		world.setBlock(x - 8, y - 5, z - 3, block3, 0, 2);
		world.setBlock(x - 8, y - 5, z - 2, block3, 0, 2);
		world.setBlock(x - 8, y - 5, z - 1, block3, 0, 2);
		world.setBlock(x - 8, y - 5, z + 0, block3, 0, 2);
		world.setBlock(x - 8, y + 0, z - 10, block3, 0, 2);
		world.setBlock(x - 8, y + 0, z - 9, block3, 0, 2);
		world.setBlock(x - 8, y + 0, z - 8, block3, 0, 2);
		world.setBlock(x - 8, y + 0, z - 7, block3, 0, 2);
		world.setBlock(x - 8, y + 0, z - 6, block3, 0, 2);
		world.setBlock(x - 8, y + 0, z - 5, block3, 0, 2);
		world.setBlock(x - 8, y + 0, z - 4, block3, 0, 2);
		world.setBlock(x - 8, y + 0, z - 3, block3, 0, 2);
		world.setBlock(x - 8, y + 0, z - 2, block3, 0, 2);
		world.setBlock(x - 8, y + 0, z - 1, block3, 0, 2);
		world.setBlock(x - 8, y + 0, z + 0, block3, 0, 2);
		world.setBlock(x - 8, y + 0, z + 1, block3, 0, 2);
		world.setBlock(x - 8, y + 1, z - 11, block2, 4, 2);
		world.setBlock(x - 8, y + 1, z + 2, block2, 4, 2);
		world.setBlock(x - 8, y + 2, z - 11, block2, 4, 2);
		world.setBlock(x - 8, y + 2, z + 2, block2, 4, 2);
		world.setBlock(x - 8, y + 3, z - 11, block1, 2, 2);
		world.setBlock(x - 8, y + 3, z - 10, block4, 0, 2);
		world.setBlock(x - 8, y + 3, z - 9, block4, 0, 2);
		world.setBlock(x - 8, y + 3, z - 8, block4, 0, 2);
		world.setBlock(x - 8, y + 3, z - 7, block4, 0, 2);
		world.setBlock(x - 8, y + 3, z - 6, block4, 0, 2);
		world.setBlock(x - 8, y + 3, z - 5, block4, 0, 2);
		world.setBlock(x - 8, y + 3, z - 4, block4, 0, 2);
		world.setBlock(x - 8, y + 3, z - 3, block4, 0, 2);
		world.setBlock(x - 8, y + 3, z - 2, block4, 0, 2);
		world.setBlock(x - 8, y + 3, z - 1, block4, 0, 2);
		world.setBlock(x - 8, y + 3, z + 0, block4, 0, 2);
		world.setBlock(x - 8, y + 3, z + 1, block4, 0, 2);
		world.setBlock(x - 8, y + 3, z + 2, block1, 3, 2);
		world.setBlock(x - 7, y - 6, z - 9, block1, 6, 2);
		world.setBlock(x - 7, y - 6, z - 8, block2, 4, 2);
		world.setBlock(x - 7, y - 6, z - 7, block2, 4, 2);
		world.setBlock(x - 7, y - 6, z - 6, block2, 4, 2);
		world.setBlock(x - 7, y - 6, z - 5, block2, 4, 2);
		world.setBlock(x - 7, y - 6, z - 4, block2, 4, 2);
		world.setBlock(x - 7, y - 6, z - 3, block2, 4, 2);
		world.setBlock(x - 7, y - 6, z - 2, block2, 4, 2);
		world.setBlock(x - 7, y - 6, z - 1, block2, 4, 2);
		world.setBlock(x - 7, y - 6, z + 0, block1, 7, 2);
		world.setBlock(x - 7, y - 5, z - 9, block3, 0, 2);
		world.setBlock(x - 7, y - 5, z - 8, block3, 0, 2);
		world.setBlock(x - 7, y - 5, z - 7, block3, 0, 2);
		world.setBlock(x - 7, y - 5, z - 6, block3, 0, 2);
		world.setBlock(x - 7, y - 5, z - 5, block3, 0, 2);
		world.setBlock(x - 7, y - 5, z - 4, block3, 0, 2);
		world.setBlock(x - 7, y - 5, z - 3, block3, 0, 2);
		world.setBlock(x - 7, y - 5, z - 2, block3, 0, 2);
		world.setBlock(x - 7, y - 5, z - 1, block3, 0, 2);
		world.setBlock(x - 7, y - 5, z + 0, block3, 0, 2);
		world.setBlock(x - 7, y + 0, z - 10, block3, 0, 2);
		world.setBlock(x - 7, y + 0, z - 9, block3, 0, 2);
		world.setBlock(x - 7, y + 0, z - 8, block3, 0, 2);
		world.setBlock(x - 7, y + 0, z - 7, block3, 0, 2);
		world.setBlock(x - 7, y + 0, z - 6, block3, 0, 2);
		world.setBlock(x - 7, y + 0, z - 5, block3, 0, 2);
		world.setBlock(x - 7, y + 0, z - 4, block3, 0, 2);
		world.setBlock(x - 7, y + 0, z - 3, block3, 0, 2);
		world.setBlock(x - 7, y + 0, z - 2, block3, 0, 2);
		world.setBlock(x - 7, y + 0, z - 1, block3, 0, 2);
		world.setBlock(x - 7, y + 0, z + 0, block3, 0, 2);
		world.setBlock(x - 7, y + 0, z + 1, block3, 0, 2);
		world.setBlock(x - 7, y + 1, z - 11, block2, 4, 2);
		world.setBlock(x - 7, y + 1, z + 2, block2, 4, 2);
		world.setBlock(x - 7, y + 2, z - 11, block2, 4, 2);
		world.setBlock(x - 7, y + 2, z + 2, block2, 4, 2);
		world.setBlock(x - 7, y + 3, z - 11, block1, 2, 2);
		world.setBlock(x - 7, y + 3, z - 10, block4, 0, 2);
		world.setBlock(x - 7, y + 3, z - 9, block4, 0, 2);
		world.setBlock(x - 7, y + 3, z - 8, block4, 0, 2);
		world.setBlock(x - 7, y + 3, z - 7, block4, 0, 2);
		world.setBlock(x - 7, y + 3, z - 6, block4, 0, 2);
		world.setBlock(x - 7, y + 3, z - 5, block4, 0, 2);
		world.setBlock(x - 7, y + 3, z - 4, block4, 0, 2);
		world.setBlock(x - 7, y + 3, z - 3, block4, 0, 2);
		world.setBlock(x - 7, y + 3, z - 2, block4, 0, 2);
		world.setBlock(x - 7, y + 3, z - 1, block4, 0, 2);
		world.setBlock(x - 7, y + 3, z + 0, block4, 0, 2);
		world.setBlock(x - 7, y + 3, z + 1, block4, 0, 2);
		world.setBlock(x - 7, y + 3, z + 2, block1, 3, 2);
		world.setBlock(x - 6, y - 6, z - 9, block1, 6, 2);
		world.setBlock(x - 6, y - 6, z - 8, block2, 4, 2);
		world.setBlock(x - 6, y - 6, z - 7, block2, 4, 2);
		world.setBlock(x - 6, y - 6, z - 6, block2, 4, 2);
		world.setBlock(x - 6, y - 6, z - 5, block2, 4, 2);
		world.setBlock(x - 6, y - 6, z - 4, block2, 4, 2);
		world.setBlock(x - 6, y - 6, z - 3, block2, 4, 2);
		world.setBlock(x - 6, y - 6, z - 2, block2, 4, 2);
		world.setBlock(x - 6, y - 6, z - 1, block2, 4, 2);
		world.setBlock(x - 6, y - 6, z + 0, block1, 7, 2);
		world.setBlock(x - 6, y - 5, z - 9, block3, 0, 2);
		world.setBlock(x - 6, y - 5, z - 8, block3, 0, 2);
		world.setBlock(x - 6, y - 5, z - 7, block3, 0, 2);
		world.setBlock(x - 6, y - 5, z - 6, block3, 0, 2);
		world.setBlock(x - 6, y - 5, z - 5, block3, 0, 2);
		world.setBlock(x - 6, y - 5, z - 4, block3, 0, 2);
		world.setBlock(x - 6, y - 5, z - 3, block3, 0, 2);
		world.setBlock(x - 6, y - 5, z - 2, block3, 0, 2);
		world.setBlock(x - 6, y - 5, z - 1, block3, 0, 2);
		world.setBlock(x - 6, y - 5, z + 0, block3, 0, 2);
		world.setBlock(x - 6, y + 0, z - 10, block3, 0, 2);
		world.setBlock(x - 6, y + 0, z - 9, block3, 0, 2);
		world.setBlock(x - 6, y + 0, z - 8, block3, 0, 2);
		world.setBlock(x - 6, y + 0, z - 7, block3, 0, 2);
		world.setBlock(x - 6, y + 0, z - 6, block3, 0, 2);
		world.setBlock(x - 6, y + 0, z - 5, block3, 0, 2);
		world.setBlock(x - 6, y + 0, z - 4, block3, 0, 2);
		world.setBlock(x - 6, y + 0, z - 3, block3, 0, 2);
		world.setBlock(x - 6, y + 0, z - 2, block3, 0, 2);
		world.setBlock(x - 6, y + 0, z - 1, block3, 0, 2);
		world.setBlock(x - 6, y + 0, z + 0, block3, 0, 2);
		world.setBlock(x - 6, y + 0, z + 1, block3, 0, 2);
		world.setBlock(x - 6, y + 1, z - 11, block2, 4, 2);
		world.setBlock(x - 6, y + 1, z + 2, block2, 4, 2);
		world.setBlock(x - 6, y + 2, z - 11, block2, 4, 2);
		world.setBlock(x - 6, y + 2, z + 2, block2, 4, 2);
		world.setBlock(x - 6, y + 3, z - 11, block1, 2, 2);
		world.setBlock(x - 6, y + 3, z - 10, block4, 0, 2);
		world.setBlock(x - 6, y + 3, z - 9, block4, 0, 2);
		world.setBlock(x - 6, y + 3, z - 8, block4, 0, 2);
		world.setBlock(x - 6, y + 3, z - 7, block4, 0, 2);
		world.setBlock(x - 6, y + 3, z - 6, block4, 0, 2);
		world.setBlock(x - 6, y + 3, z - 5, block4, 0, 2);
		world.setBlock(x - 6, y + 3, z - 4, block4, 0, 2);
		world.setBlock(x - 6, y + 3, z - 3, block4, 0, 2);
		world.setBlock(x - 6, y + 3, z - 2, block4, 0, 2);
		world.setBlock(x - 6, y + 3, z - 1, block4, 0, 2);
		world.setBlock(x - 6, y + 3, z + 0, block4, 0, 2);
		world.setBlock(x - 6, y + 3, z + 1, block4, 0, 2);
		world.setBlock(x - 6, y + 3, z + 2, block1, 3, 2);
		world.setBlock(x - 5, y - 6, z - 9, block1, 6, 2);
		world.setBlock(x - 5, y - 6, z - 8, block2, 4, 2);
		world.setBlock(x - 5, y - 6, z - 7, block2, 4, 2);
		world.setBlock(x - 5, y - 6, z - 6, block2, 4, 2);
		world.setBlock(x - 5, y - 6, z - 5, block2, 4, 2);
		world.setBlock(x - 5, y - 6, z - 4, block2, 4, 2);
		world.setBlock(x - 5, y - 6, z - 3, block2, 4, 2);
		world.setBlock(x - 5, y - 6, z - 2, block2, 4, 2);
		world.setBlock(x - 5, y - 6, z - 1, block2, 4, 2);
		world.setBlock(x - 5, y - 6, z + 0, block1, 7, 2);
		world.setBlock(x - 5, y - 5, z - 9, block3, 0, 2);
		world.setBlock(x - 5, y - 5, z - 8, block3, 0, 2);
		world.setBlock(x - 5, y - 5, z - 7, block3, 0, 2);
		world.setBlock(x - 5, y - 5, z - 6, block3, 0, 2);
		world.setBlock(x - 5, y - 5, z - 5, block3, 0, 2);
		world.setBlock(x - 5, y - 5, z - 4, block3, 0, 2);
		world.setBlock(x - 5, y - 5, z - 3, block3, 0, 2);
		world.setBlock(x - 5, y - 5, z - 2, block3, 0, 2);
		world.setBlock(x - 5, y - 5, z - 1, block3, 0, 2);
		world.setBlock(x - 5, y - 5, z + 0, block3, 0, 2);
		world.setBlock(x - 5, y + 0, z - 10, block3, 0, 2);
		world.setBlock(x - 5, y + 0, z - 9, block3, 0, 2);
		world.setBlock(x - 5, y + 0, z - 8, block3, 0, 2);
		world.setBlock(x - 5, y + 0, z - 7, block3, 0, 2);
		world.setBlock(x - 5, y + 0, z - 6, block3, 0, 2);
		world.setBlock(x - 5, y + 0, z - 5, block3, 0, 2);
		world.setBlock(x - 5, y + 0, z - 4, block3, 0, 2);
		world.setBlock(x - 5, y + 0, z - 3, block3, 0, 2);
		world.setBlock(x - 5, y + 0, z - 2, block3, 0, 2);
		world.setBlock(x - 5, y + 0, z - 1, block3, 0, 2);
		world.setBlock(x - 5, y + 0, z + 0, block3, 0, 2);
		world.setBlock(x - 5, y + 0, z + 1, block3, 0, 2);
		world.setBlock(x - 5, y + 1, z - 11, block2, 4, 2);
		world.setBlock(x - 5, y + 1, z + 2, block2, 4, 2);
		world.setBlock(x - 5, y + 2, z - 11, block2, 4, 2);
		world.setBlock(x - 5, y + 2, z + 2, block2, 4, 2);
		world.setBlock(x - 5, y + 3, z - 11, block1, 2, 2);
		world.setBlock(x - 5, y + 3, z - 10, block4, 0, 2);
		world.setBlock(x - 5, y + 3, z - 9, block4, 0, 2);
		world.setBlock(x - 5, y + 3, z - 8, block4, 0, 2);
		world.setBlock(x - 5, y + 3, z - 7, block4, 0, 2);
		world.setBlock(x - 5, y + 3, z - 6, block4, 0, 2);
		world.setBlock(x - 5, y + 3, z - 5, block4, 0, 2);
		world.setBlock(x - 5, y + 3, z - 4, block4, 0, 2);
		world.setBlock(x - 5, y + 3, z - 3, block4, 0, 2);
		world.setBlock(x - 5, y + 3, z - 2, block4, 0, 2);
		world.setBlock(x - 5, y + 3, z - 1, block4, 0, 2);
		world.setBlock(x - 5, y + 3, z + 0, block4, 0, 2);
		world.setBlock(x - 5, y + 3, z + 1, block4, 0, 2);
		world.setBlock(x - 5, y + 3, z + 2, block1, 3, 2);
		world.setBlock(x - 4, y - 6, z - 9, block1, 6, 2);
		world.setBlock(x - 4, y - 6, z - 8, block2, 4, 2);
		world.setBlock(x - 4, y - 6, z - 7, block2, 4, 2);
		world.setBlock(x - 4, y - 6, z - 6, block2, 4, 2);
		world.setBlock(x - 4, y - 6, z - 5, block2, 4, 2);
		world.setBlock(x - 4, y - 6, z - 4, block2, 4, 2);
		world.setBlock(x - 4, y - 6, z - 3, block2, 4, 2);
		world.setBlock(x - 4, y - 6, z - 2, block2, 4, 2);
		world.setBlock(x - 4, y - 6, z - 1, block2, 4, 2);
		world.setBlock(x - 4, y - 6, z + 0, block1, 7, 2);
		world.setBlock(x - 4, y - 5, z - 9, block3, 0, 2);
		world.setBlock(x - 4, y - 5, z - 8, block3, 0, 2);
		world.setBlock(x - 4, y - 5, z - 7, block3, 0, 2);
		world.setBlock(x - 4, y - 5, z - 6, block3, 0, 2);
		world.setBlock(x - 4, y - 5, z - 5, block3, 0, 2);
		world.setBlock(x - 4, y - 5, z - 4, block3, 0, 2);
		world.setBlock(x - 4, y - 5, z - 3, block3, 0, 2);
		world.setBlock(x - 4, y - 5, z - 2, block3, 0, 2);
		world.setBlock(x - 4, y - 5, z - 1, block3, 0, 2);
		world.setBlock(x - 4, y - 5, z + 0, block3, 0, 2);
		world.setBlock(x - 4, y + 0, z - 10, block3, 0, 2);
		world.setBlock(x - 4, y + 0, z - 9, block3, 0, 2);
		world.setBlock(x - 4, y + 0, z - 8, block3, 0, 2);
		world.setBlock(x - 4, y + 0, z - 7, block3, 0, 2);
		world.setBlock(x - 4, y + 0, z - 6, block3, 0, 2);
		world.setBlock(x - 4, y + 0, z - 5, block3, 0, 2);
		world.setBlock(x - 4, y + 0, z - 4, block3, 0, 2);
		world.setBlock(x - 4, y + 0, z - 3, block3, 0, 2);
		world.setBlock(x - 4, y + 0, z - 2, block3, 0, 2);
		world.setBlock(x - 4, y + 0, z - 1, block3, 0, 2);
		world.setBlock(x - 4, y + 0, z + 0, block3, 0, 2);
		world.setBlock(x - 4, y + 0, z + 1, block3, 0, 2);
		world.setBlock(x - 4, y + 1, z - 11, block2, 4, 2);
		world.setBlock(x - 4, y + 1, z + 2, block2, 4, 2);
		world.setBlock(x - 4, y + 2, z - 11, block2, 4, 2);
		world.setBlock(x - 4, y + 2, z + 2, block2, 4, 2);
		world.setBlock(x - 4, y + 3, z - 11, block1, 2, 2);
		world.setBlock(x - 4, y + 3, z - 10, block4, 0, 2);
		world.setBlock(x - 4, y + 3, z - 9, block4, 0, 2);
		world.setBlock(x - 4, y + 3, z - 8, block4, 0, 2);
		world.setBlock(x - 4, y + 3, z - 7, block4, 0, 2);
		world.setBlock(x - 4, y + 3, z - 6, block4, 0, 2);
		world.setBlock(x - 4, y + 3, z - 5, block4, 0, 2);
		world.setBlock(x - 4, y + 3, z - 4, block4, 0, 2);
		world.setBlock(x - 4, y + 3, z - 3, block4, 0, 2);
		world.setBlock(x - 4, y + 3, z - 2, block4, 0, 2);
		world.setBlock(x - 4, y + 3, z - 1, block4, 0, 2);
		world.setBlock(x - 4, y + 3, z + 0, block4, 0, 2);
		world.setBlock(x - 4, y + 3, z + 1, block4, 0, 2);
		world.setBlock(x - 4, y + 3, z + 2, block1, 3, 2);
		world.setBlock(x - 3, y - 6, z - 9, block1, 6, 2);
		world.setBlock(x - 3, y - 6, z - 8, block2, 4, 2);
		world.setBlock(x - 3, y - 6, z - 7, block2, 4, 2);
		world.setBlock(x - 3, y - 6, z - 6, block2, 4, 2);
		world.setBlock(x - 3, y - 6, z - 5, block2, 4, 2);
		world.setBlock(x - 3, y - 6, z - 4, block2, 4, 2);
		world.setBlock(x - 3, y - 6, z - 3, block2, 4, 2);
		world.setBlock(x - 3, y - 6, z - 2, block2, 4, 2);
		world.setBlock(x - 3, y - 6, z - 1, block2, 4, 2);
		world.setBlock(x - 3, y - 6, z + 0, block1, 7, 2);
		world.setBlock(x - 3, y - 5, z - 9, block3, 0, 2);
		world.setBlock(x - 3, y - 5, z - 8, block3, 0, 2);
		world.setBlock(x - 3, y - 5, z - 7, block3, 0, 2);
		world.setBlock(x - 3, y - 5, z - 6, block3, 0, 2);
		world.setBlock(x - 3, y - 5, z - 5, block3, 0, 2);
		world.setBlock(x - 3, y - 5, z - 4, block3, 0, 2);
		world.setBlock(x - 3, y - 5, z - 3, block3, 0, 2);
		world.setBlock(x - 3, y - 5, z - 2, block3, 0, 2);
		world.setBlock(x - 3, y - 5, z - 1, block3, 0, 2);
		world.setBlock(x - 3, y - 5, z + 0, block3, 0, 2);
		world.setBlock(x - 3, y + 0, z - 10, block3, 0, 2);
		world.setBlock(x - 3, y + 0, z - 9, block3, 0, 2);
		world.setBlock(x - 3, y + 0, z - 8, block3, 0, 2);
		world.setBlock(x - 3, y + 0, z - 7, block3, 0, 2);
		world.setBlock(x - 3, y + 0, z - 6, block3, 0, 2);
		world.setBlock(x - 3, y + 0, z - 5, block3, 0, 2);
		world.setBlock(x - 3, y + 0, z - 4, block3, 0, 2);
		world.setBlock(x - 3, y + 0, z - 3, block3, 0, 2);
		world.setBlock(x - 3, y + 0, z - 2, block3, 0, 2);
		world.setBlock(x - 3, y + 0, z - 1, block3, 0, 2);
		world.setBlock(x - 3, y + 0, z + 0, block3, 0, 2);
		world.setBlock(x - 3, y + 0, z + 1, block3, 0, 2);
		world.setBlock(x - 3, y + 1, z - 11, block2, 4, 2);
		world.setBlock(x - 3, y + 1, z + 2, block2, 4, 2);
		world.setBlock(x - 3, y + 2, z - 11, block2, 4, 2);
		world.setBlock(x - 3, y + 2, z + 2, block2, 4, 2);
		world.setBlock(x - 3, y + 3, z - 11, block1, 2, 2);
		world.setBlock(x - 3, y + 3, z - 10, block4, 0, 2);
		world.setBlock(x - 3, y + 3, z - 9, block4, 0, 2);
		world.setBlock(x - 3, y + 3, z - 8, block4, 0, 2);
		world.setBlock(x - 3, y + 3, z - 7, block4, 0, 2);
		world.setBlock(x - 3, y + 3, z - 6, block4, 0, 2);
		world.setBlock(x - 3, y + 3, z - 5, block4, 0, 2);
		world.setBlock(x - 3, y + 3, z - 4, block4, 0, 2);
		world.setBlock(x - 3, y + 3, z - 3, block4, 0, 2);
		world.setBlock(x - 3, y + 3, z - 2, block4, 0, 2);
		world.setBlock(x - 3, y + 3, z - 1, block4, 0, 2);
		world.setBlock(x - 3, y + 3, z + 0, block4, 0, 2);
		world.setBlock(x - 3, y + 3, z + 1, block4, 0, 2);
		world.setBlock(x - 3, y + 3, z + 2, block1, 3, 2);
		world.setBlock(x - 2, y - 6, z - 9, block1, 6, 2);
		world.setBlock(x - 2, y - 6, z - 8, block2, 4, 2);
		world.setBlock(x - 2, y - 6, z - 7, block2, 4, 2);
		world.setBlock(x - 2, y - 6, z - 6, block2, 4, 2);
		world.setBlock(x - 2, y - 6, z - 5, block2, 4, 2);
		world.setBlock(x - 2, y - 6, z - 4, block2, 4, 2);
		world.setBlock(x - 2, y - 6, z - 3, block2, 4, 2);
		world.setBlock(x - 2, y - 6, z - 2, block2, 4, 2);
		world.setBlock(x - 2, y - 6, z - 1, block2, 4, 2);
		world.setBlock(x - 2, y - 6, z + 0, block1, 7, 2);
		world.setBlock(x - 2, y - 5, z - 9, block3, 0, 2);
		world.setBlock(x - 2, y - 5, z - 8, block3, 0, 2);
		world.setBlock(x - 2, y - 5, z - 7, block3, 0, 2);
		world.setBlock(x - 2, y - 5, z - 6, block3, 0, 2);
		world.setBlock(x - 2, y - 5, z - 5, block3, 0, 2);
		world.setBlock(x - 2, y - 5, z - 4, block3, 0, 2);
		world.setBlock(x - 2, y - 5, z - 3, block3, 0, 2);
		world.setBlock(x - 2, y - 5, z - 2, block3, 0, 2);
		world.setBlock(x - 2, y - 5, z - 1, block3, 0, 2);
		world.setBlock(x - 2, y - 5, z + 0, block3, 0, 2);
		world.setBlock(x - 2, y + 0, z - 10, block3, 0, 2);
		world.setBlock(x - 2, y + 0, z - 9, block3, 0, 2);
		world.setBlock(x - 2, y + 0, z - 8, block3, 0, 2);
		world.setBlock(x - 2, y + 0, z - 7, block3, 0, 2);
		world.setBlock(x - 2, y + 0, z - 6, block3, 0, 2);
		world.setBlock(x - 2, y + 0, z - 5, block3, 0, 2);
		world.setBlock(x - 2, y + 0, z - 4, block3, 0, 2);
		world.setBlock(x - 2, y + 0, z - 3, block3, 0, 2);
		world.setBlock(x - 2, y + 0, z - 2, block3, 0, 2);
		world.setBlock(x - 2, y + 0, z - 1, block3, 0, 2);
		world.setBlock(x - 2, y + 0, z + 0, block3, 0, 2);
		world.setBlock(x - 2, y + 0, z + 1, block3, 0, 2);
		world.setBlock(x - 2, y + 1, z - 11, block2, 4, 2);
		world.setBlock(x - 2, y + 1, z + 2, block2, 4, 2);
		world.setBlock(x - 2, y + 2, z - 11, block2, 4, 2);
		world.setBlock(x - 2, y + 2, z + 2, block2, 4, 2);
		world.setBlock(x - 2, y + 3, z - 11, block1, 2, 2);
		world.setBlock(x - 2, y + 3, z - 10, block4, 0, 2);
		world.setBlock(x - 2, y + 3, z - 9, block4, 0, 2);
		world.setBlock(x - 2, y + 3, z - 8, block4, 0, 2);
		world.setBlock(x - 2, y + 3, z - 7, block4, 0, 2);
		world.setBlock(x - 2, y + 3, z - 6, block4, 0, 2);
		world.setBlock(x - 2, y + 3, z - 5, block4, 0, 2);
		world.setBlock(x - 2, y + 3, z - 4, block4, 0, 2);
		world.setBlock(x - 2, y + 3, z - 3, block4, 0, 2);
		world.setBlock(x - 2, y + 3, z - 2, block4, 0, 2);
		world.setBlock(x - 2, y + 3, z - 1, block4, 0, 2);
		world.setBlock(x - 2, y + 3, z + 0, block4, 0, 2);
		world.setBlock(x - 2, y + 3, z + 1, block4, 0, 2);
		world.setBlock(x - 2, y + 3, z + 2, block1, 3, 2);
		world.setBlock(x - 1, y - 6, z - 9, block1, 6, 2);
		world.setBlock(x - 1, y - 6, z - 8, block2, 4, 2);
		world.setBlock(x - 1, y - 6, z - 7, block2, 4, 2);
		world.setBlock(x - 1, y - 6, z - 6, block2, 4, 2);
		world.setBlock(x - 1, y - 6, z - 5, block2, 4, 2);
		world.setBlock(x - 1, y - 6, z - 4, block2, 4, 2);
		world.setBlock(x - 1, y - 6, z - 3, block2, 4, 2);
		world.setBlock(x - 1, y - 6, z - 2, block2, 4, 2);
		world.setBlock(x - 1, y - 6, z - 1, block2, 4, 2);
		world.setBlock(x - 1, y - 6, z + 0, block1, 7, 2);
		world.setBlock(x - 1, y - 5, z - 9, block3, 0, 2);
		world.setBlock(x - 1, y - 5, z - 8, block3, 0, 2);
		world.setBlock(x - 1, y - 5, z - 7, block3, 0, 2);
		world.setBlock(x - 1, y - 5, z - 6, block3, 0, 2);
		world.setBlock(x - 1, y - 5, z - 5, block3, 0, 2);
		world.setBlock(x - 1, y - 5, z - 4, block3, 0, 2);
		world.setBlock(x - 1, y - 5, z - 3, block3, 0, 2);
		world.setBlock(x - 1, y - 5, z - 2, block3, 0, 2);
		world.setBlock(x - 1, y - 5, z - 1, block3, 0, 2);
		world.setBlock(x - 1, y - 5, z + 0, block3, 0, 2);
		world.setBlock(x - 1, y + 0, z - 10, block3, 0, 2);
		world.setBlock(x - 1, y + 0, z - 9, block3, 0, 2);
		world.setBlock(x - 1, y + 0, z - 8, block3, 0, 2);
		world.setBlock(x - 1, y + 0, z - 7, block3, 0, 2);
		world.setBlock(x - 1, y + 0, z - 6, block3, 0, 2);
		world.setBlock(x - 1, y + 0, z - 5, block3, 0, 2);
		world.setBlock(x - 1, y + 0, z - 4, block3, 0, 2);
		world.setBlock(x - 1, y + 0, z - 3, block3, 0, 2);
		world.setBlock(x - 1, y + 0, z - 2, block3, 0, 2);
		world.setBlock(x - 1, y + 0, z - 1, block3, 0, 2);
		world.setBlock(x - 1, y + 0, z + 0, block3, 0, 2);
		world.setBlock(x - 1, y + 0, z + 1, block3, 0, 2);
		world.setBlock(x - 1, y + 1, z - 11, block2, 4, 2);
		world.setBlock(x - 1, y + 1, z + 2, block2, 4, 2);
		world.setBlock(x - 1, y + 2, z - 11, block2, 4, 2);
		world.setBlock(x - 1, y + 2, z + 2, block2, 4, 2);
		world.setBlock(x - 1, y + 3, z - 11, block1, 2, 2);
		world.setBlock(x - 1, y + 3, z - 10, block4, 0, 2);
		world.setBlock(x - 1, y + 3, z - 9, block4, 0, 2);
		world.setBlock(x - 1, y + 3, z - 8, block4, 0, 2);
		world.setBlock(x - 1, y + 3, z - 7, block4, 0, 2);
		world.setBlock(x - 1, y + 3, z - 6, block4, 0, 2);
		world.setBlock(x - 1, y + 3, z - 5, block4, 0, 2);
		world.setBlock(x - 1, y + 3, z - 4, block4, 0, 2);
		world.setBlock(x - 1, y + 3, z - 3, block4, 0, 2);
		world.setBlock(x - 1, y + 3, z - 2, block4, 0, 2);
		world.setBlock(x - 1, y + 3, z - 1, block4, 0, 2);
		world.setBlock(x - 1, y + 3, z + 0, block4, 0, 2);
		world.setBlock(x - 1, y + 3, z + 1, block4, 0, 2);
		world.setBlock(x - 1, y + 3, z + 2, block1, 3, 2);
		world.setBlock(x + 0, y - 6, z - 8, block1, 5, 2);
		world.setBlock(x + 0, y - 6, z - 7, block1, 5, 2);
		world.setBlock(x + 0, y - 6, z - 6, block1, 5, 2);
		world.setBlock(x + 0, y - 6, z - 5, block1, 5, 2);
		world.setBlock(x + 0, y - 6, z - 4, block1, 5, 2);
		world.setBlock(x + 0, y - 6, z - 3, block1, 5, 2);
		world.setBlock(x + 0, y - 6, z - 2, block1, 5, 2);
		world.setBlock(x + 0, y - 6, z - 1, block1, 5, 2);
		world.setBlock(x + 0, y - 5, z - 8, block3, 0, 2);
		world.setBlock(x + 0, y - 5, z - 7, block3, 0, 2);
		world.setBlock(x + 0, y - 5, z - 6, block3, 0, 2);
		world.setBlock(x + 0, y - 5, z - 5, block3, 0, 2);
		world.setBlock(x + 0, y - 5, z - 4, block3, 0, 2);
		world.setBlock(x + 0, y - 5, z - 3, block3, 0, 2);
		world.setBlock(x + 0, y - 5, z - 2, block3, 0, 2);
		world.setBlock(x + 0, y - 5, z - 1, block3, 0, 2);
		world.setBlock(x + 0, y + 0, z - 10, block3, 0, 2);
		world.setBlock(x + 0, y + 0, z - 9, block3, 0, 2);
		world.setBlock(x + 0, y + 0, z - 8, block3, 0, 2);
		world.setBlock(x + 0, y + 0, z - 7, block3, 0, 2);
		world.setBlock(x + 0, y + 0, z - 6, block3, 0, 2);
		world.setBlock(x + 0, y + 0, z - 5, block3, 0, 2);
		world.setBlock(x + 0, y + 0, z - 4, block3, 0, 2);
		world.setBlock(x + 0, y + 0, z - 3, block3, 0, 2);
		world.setBlock(x + 0, y + 0, z - 2, block3, 0, 2);
		world.setBlock(x + 0, y + 0, z - 1, block3, 0, 2);
		world.setBlock(x + 0, y + 0, z + 0, block3, 0, 2);
		world.setBlock(x + 0, y + 0, z + 1, block3, 0, 2);
		world.setBlock(x + 0, y + 1, z - 11, block2, 4, 2);
		world.setBlock(x + 0, y + 1, z + 2, block2, 4, 2);
		world.setBlock(x + 0, y + 2, z - 11, block2, 4, 2);
		world.setBlock(x + 0, y + 2, z + 2, block2, 4, 2);
		world.setBlock(x + 0, y + 3, z - 11, block1, 2, 2);
		world.setBlock(x + 0, y + 3, z - 10, block4, 0, 2);
		world.setBlock(x + 0, y + 3, z - 9, block4, 0, 2);
		world.setBlock(x + 0, y + 3, z - 8, block4, 0, 2);
		world.setBlock(x + 0, y + 3, z - 7, block4, 0, 2);
		world.setBlock(x + 0, y + 3, z - 6, block4, 0, 2);
		world.setBlock(x + 0, y + 3, z - 5, block4, 0, 2);
		world.setBlock(x + 0, y + 3, z - 4, block4, 0, 2);
		world.setBlock(x + 0, y + 3, z - 3, block4, 0, 2);
		world.setBlock(x + 0, y + 3, z - 2, block4, 0, 2);
		world.setBlock(x + 0, y + 3, z - 1, block4, 0, 2);
		world.setBlock(x + 0, y + 3, z + 0, block4, 0, 2);
		world.setBlock(x + 0, y + 3, z + 1, block4, 0, 2);
		world.setBlock(x + 0, y + 3, z + 2, block1, 3, 2);
		world.setBlock(x + 1, y + 0, z - 9, block3, 0, 2);
		world.setBlock(x + 1, y + 0, z - 8, block3, 0, 2);
		world.setBlock(x + 1, y + 0, z - 7, block3, 0, 2);
		world.setBlock(x + 1, y + 0, z - 6, block3, 0, 2);
		world.setBlock(x + 1, y + 0, z - 5, block3, 0, 2);
		world.setBlock(x + 1, y + 0, z - 4, block3, 0, 2);
		world.setBlock(x + 1, y + 0, z - 3, block3, 0, 2);
		world.setBlock(x + 1, y + 0, z - 2, block3, 0, 2);
		world.setBlock(x + 1, y + 0, z - 1, block3, 0, 2);
		world.setBlock(x + 1, y + 0, z + 0, block3, 0, 2);
		world.setBlock(x + 1, y + 1, z - 11, block1, 1, 2);
		world.setBlock(x + 1, y + 1, z - 10, block2, 4, 2);
		world.setBlock(x + 1, y + 1, z + 1, block2, 4, 2);
		world.setBlock(x + 1, y + 1, z + 2, block1, 1, 2);
		world.setBlock(x + 1, y + 2, z - 10, block2, 4, 2);
		world.setBlock(x + 1, y + 2, z + 1, block2, 4, 2);
		world.setBlock(x + 1, y + 3, z - 10, block2, 4, 2);
		world.setBlock(x + 1, y + 3, z - 9, block4, 0, 2);
		world.setBlock(x + 1, y + 3, z - 8, block4, 0, 2);
		world.setBlock(x + 1, y + 3, z - 7, block4, 0, 2);
		world.setBlock(x + 1, y + 3, z - 6, block4, 0, 2);
		world.setBlock(x + 1, y + 3, z - 5, block4, 0, 2);
		world.setBlock(x + 1, y + 3, z - 4, block4, 0, 2);
		world.setBlock(x + 1, y + 3, z - 3, block4, 0, 2);
		world.setBlock(x + 1, y + 3, z - 2, block4, 0, 2);
		world.setBlock(x + 1, y + 3, z - 1, block4, 0, 2);
		world.setBlock(x + 1, y + 3, z + 0, block4, 0, 2);
		world.setBlock(x + 1, y + 3, z + 1, block2, 4, 2);
		world.setBlock(x + 2, y + 1, z - 10, block1, 2, 2);
		world.setBlock(x + 2, y + 1, z - 9, block2, 4, 2);
		world.setBlock(x + 2, y + 1, z - 8, block2, 4, 2);
		world.setBlock(x + 2, y + 1, z - 7, block2, 4, 2);
		world.setBlock(x + 2, y + 1, z - 6, block2, 4, 2);
		world.setBlock(x + 2, y + 1, z - 5, block2, 4, 2);
		world.setBlock(x + 2, y + 1, z - 4, block2, 4, 2);
		world.setBlock(x + 2, y + 1, z - 3, block2, 4, 2);
		world.setBlock(x + 2, y + 1, z - 2, block2, 4, 2);
		world.setBlock(x + 2, y + 1, z - 1, block2, 4, 2);
		world.setBlock(x + 2, y + 1, z + 0, block2, 4, 2);
		world.setBlock(x + 2, y + 1, z + 1, block1, 3, 2);
		world.setBlock(x + 2, y + 2, z - 9, block2, 4, 2);
		world.setBlock(x + 2, y + 2, z - 8, block2, 4, 2);
		world.setBlock(x + 2, y + 2, z - 7, block2, 4, 2);
		world.setBlock(x + 2, y + 2, z - 6, block2, 4, 2);
		world.setBlock(x + 2, y + 2, z - 5, block2, 4, 2);
		world.setBlock(x + 2, y + 2, z - 4, block2, 4, 2);
		world.setBlock(x + 2, y + 2, z - 3, block2, 4, 2);
		world.setBlock(x + 2, y + 2, z - 2, block2, 4, 2);
		world.setBlock(x + 2, y + 2, z - 1, block2, 4, 2);
		world.setBlock(x + 2, y + 2, z + 0, block2, 4, 2);
		world.setBlock(x + 2, y + 3, z - 9, block1, 1, 2);
		world.setBlock(x + 2, y + 3, z - 8, block1, 1, 2);
		world.setBlock(x + 2, y + 3, z - 7, block1, 1, 2);
		world.setBlock(x + 2, y + 3, z - 6, block1, 1, 2);
		world.setBlock(x + 2, y + 3, z - 5, block1, 1, 2);
		world.setBlock(x + 2, y + 3, z - 4, block1, 1, 2);
		world.setBlock(x + 2, y + 3, z - 3, block1, 1, 2);
		world.setBlock(x + 2, y + 3, z - 2, block1, 1, 2);
		world.setBlock(x + 2, y + 3, z - 1, block1, 1, 2);
		world.setBlock(x + 2, y + 3, z + 0, block1, 1, 2);
		
		block1 = GCBlocks.basicBlock;
		world.setBlock(x - 10, y + 0, z - 9, block1, 4, 2);
		world.setBlock(x - 10, y + 0, z - 8, block1, 4, 2);
		world.setBlock(x - 10, y + 0, z - 7, block1, 4, 2);
		world.setBlock(x - 10, y + 0, z - 6, block1, 4, 2);
		world.setBlock(x - 10, y + 0, z - 5, block1, 4, 2);
		world.setBlock(x - 10, y + 0, z - 4, block1, 4, 2);
		world.setBlock(x - 10, y + 0, z - 3, block1, 4, 2);
		world.setBlock(x - 10, y + 0, z - 2, block1, 4, 2);
		world.setBlock(x - 10, y + 0, z - 1, block1, 4, 2);
		world.setBlock(x - 10, y + 0, z + 0, block1, 4, 2);
		world.setBlock(x - 9, y - 5, z - 8, block1, 4, 2);
		world.setBlock(x - 9, y - 5, z - 7, block1, 4, 2);
		world.setBlock(x - 9, y - 5, z - 6, block1, 4, 2);
		world.setBlock(x - 9, y - 5, z - 5, block1, 4, 2);
		world.setBlock(x - 9, y - 5, z - 4, block1, 4, 2);
		world.setBlock(x - 9, y - 5, z - 3, block1, 4, 2);
		world.setBlock(x - 9, y - 5, z - 2, block1, 4, 2);
		world.setBlock(x - 9, y - 5, z - 1, block1, 4, 2);
		world.setBlock(x - 9, y + 0, z - 10, block1, 4, 2);
		
		BuildHandler.buildBuildPoint(world, x - 9, y, z - 9, 5);
		
		world.setBlock(x - 9, y + 0, z - 8, block1, 4, 2);
		world.setBlock(x - 9, y + 0, z - 7, block1, 4, 2);
		world.setBlock(x - 9, y + 0, z - 6, block1, 4, 2);
		world.setBlock(x - 9, y + 0, z - 5, block1, 4, 2);
		world.setBlock(x - 9, y + 0, z - 4, block1, 4, 2);
		world.setBlock(x - 9, y + 0, z - 3, block1, 4, 2);
		world.setBlock(x - 9, y + 0, z - 2, block1, 4, 2);
		world.setBlock(x - 9, y + 0, z - 1, block1, 4, 2);
		BuildHandler.buildBuildPoint(world, x - 9, y, z, 5);
		world.setBlock(x - 9, y + 0, z + 1, block1, 4, 2);
		world.setBlock(x - 8, y - 5, z - 9, block1, 4, 2);
		world.setBlock(x - 8, y - 5, z - 8, block1, 4, 2);
		world.setBlock(x - 8, y - 5, z - 7, block1, 4, 2);
		world.setBlock(x - 8, y - 5, z - 6, block1, 4, 2);
		world.setBlock(x - 8, y - 5, z - 5, block1, 4, 2);
		world.setBlock(x - 8, y - 5, z - 4, block1, 4, 2);
		world.setBlock(x - 8, y - 5, z - 3, block1, 4, 2);
		world.setBlock(x - 8, y - 5, z - 2, block1, 4, 2);
		world.setBlock(x - 8, y - 5, z - 1, block1, 4, 2);
		world.setBlock(x - 8, y - 5, z + 0, block1, 4, 2);
		world.setBlock(x - 8, y + 0, z - 10, block1, 4, 2);
		world.setBlock(x - 8, y + 0, z - 9, block1, 4, 2);
		world.setBlock(x - 8, y + 0, z - 8, block1, 4, 2);
		world.setBlock(x - 8, y + 0, z - 7, block1, 4, 2);
		world.setBlock(x - 8, y + 0, z - 6, block1, 4, 2);
		world.setBlock(x - 8, y + 0, z - 5, block1, 4, 2);
		world.setBlock(x - 8, y + 0, z - 4, block1, 4, 2);
		world.setBlock(x - 8, y + 0, z - 3, block1, 4, 2);
		world.setBlock(x - 8, y + 0, z - 2, block1, 4, 2);
		world.setBlock(x - 8, y + 0, z - 1, block1, 4, 2);
		world.setBlock(x - 8, y + 0, z + 0, block1, 4, 2);
		world.setBlock(x - 8, y + 0, z + 1, block1, 4, 2);
		world.setBlock(x - 7, y - 5, z - 9, block1, 4, 2);
		world.setBlock(x - 7, y - 5, z - 8, block1, 4, 2);
		world.setBlock(x - 7, y - 5, z - 7, block1, 4, 2);
		world.setBlock(x - 7, y - 5, z - 6, block1, 4, 2);
		world.setBlock(x - 7, y - 5, z - 5, block1, 4, 2);
		world.setBlock(x - 7, y - 5, z - 4, block1, 4, 2);
		world.setBlock(x - 7, y - 5, z - 3, block1, 4, 2);
		world.setBlock(x - 7, y - 5, z - 2, block1, 4, 2);
		world.setBlock(x - 7, y - 5, z - 1, block1, 4, 2);
		world.setBlock(x - 7, y - 5, z + 0, block1, 4, 2);
		world.setBlock(x - 7, y + 0, z - 10, block1, 4, 2);
		world.setBlock(x - 7, y + 0, z - 9, block1, 4, 2);
		world.setBlock(x - 7, y + 0, z - 8, block1, 4, 2);
		world.setBlock(x - 7, y + 0, z - 7, block1, 4, 2);
		world.setBlock(x - 7, y + 0, z - 6, block1, 4, 2);
		world.setBlock(x - 7, y + 0, z - 5, block1, 4, 2);
		world.setBlock(x - 7, y + 0, z - 4, block1, 4, 2);
		world.setBlock(x - 7, y + 0, z - 3, block1, 4, 2);
		world.setBlock(x - 7, y + 0, z - 2, block1, 4, 2);
		world.setBlock(x - 7, y + 0, z - 1, block1, 4, 2);
		world.setBlock(x - 7, y + 0, z + 0, block1, 4, 2);
		world.setBlock(x - 7, y + 0, z + 1, block1, 4, 2);
		world.setBlock(x - 6, y - 5, z - 9, block1, 4, 2);
		world.setBlock(x - 6, y - 5, z - 8, block1, 4, 2);
		world.setBlock(x - 6, y - 5, z - 7, block1, 4, 2);
		world.setBlock(x - 6, y - 5, z - 6, block1, 4, 2);
		world.setBlock(x - 6, y - 5, z - 5, block1, 4, 2);
		world.setBlock(x - 6, y - 5, z - 4, block1, 4, 2);
		world.setBlock(x - 6, y - 5, z - 3, block1, 4, 2);
		world.setBlock(x - 6, y - 5, z - 2, block1, 4, 2);
		world.setBlock(x - 6, y - 5, z - 1, block1, 4, 2);
		world.setBlock(x - 6, y - 5, z + 0, block1, 4, 2);
		world.setBlock(x - 6, y + 0, z - 10, block1, 4, 2);
		world.setBlock(x - 6, y + 0, z - 9, block1, 4, 2);
		world.setBlock(x - 6, y + 0, z - 8, block1, 4, 2);
		world.setBlock(x - 6, y + 0, z - 7, block1, 4, 2);
		world.setBlock(x - 6, y + 0, z - 6, block1, 4, 2);
		world.setBlock(x - 6, y + 0, z - 5, block1, 4, 2);
		world.setBlock(x - 6, y + 0, z - 4, block1, 4, 2);
		world.setBlock(x - 6, y + 0, z - 3, block1, 4, 2);
		world.setBlock(x - 6, y + 0, z - 2, block1, 4, 2);
		world.setBlock(x - 6, y + 0, z - 1, block1, 4, 2);
		world.setBlock(x - 6, y + 0, z + 0, block1, 4, 2);
		world.setBlock(x - 6, y + 0, z + 1, block1, 4, 2);
		world.setBlock(x - 5, y - 5, z - 9, block1, 4, 2);
		world.setBlock(x - 5, y - 5, z - 8, block1, 4, 2);
		world.setBlock(x - 5, y - 5, z - 7, block1, 4, 2);
		world.setBlock(x - 5, y - 5, z - 6, block1, 4, 2);
		world.setBlock(x - 5, y - 5, z - 5, block1, 4, 2);
		world.setBlock(x - 5, y - 5, z - 4, block1, 4, 2);
		world.setBlock(x - 5, y - 5, z - 3, block1, 4, 2);
		world.setBlock(x - 5, y - 5, z - 2, block1, 4, 2);
		world.setBlock(x - 5, y - 5, z - 1, block1, 4, 2);
		world.setBlock(x - 5, y - 5, z + 0, block1, 4, 2);
		world.setBlock(x - 5, y + 0, z - 10, block1, 4, 2);
		world.setBlock(x - 5, y + 0, z - 9, block1, 4, 2);
		world.setBlock(x - 5, y + 0, z - 8, block1, 4, 2);
		world.setBlock(x - 5, y + 0, z - 7, block1, 4, 2);
		world.setBlock(x - 5, y + 0, z - 6, block1, 4, 2);
		world.setBlock(x - 5, y + 0, z - 5, block1, 4, 2);
		world.setBlock(x - 5, y + 0, z - 4, block1, 4, 2);
		world.setBlock(x - 5, y + 0, z - 3, block1, 4, 2);
		world.setBlock(x - 5, y + 0, z - 2, block1, 4, 2);
		world.setBlock(x - 5, y + 0, z - 1, block1, 4, 2);
		world.setBlock(x - 5, y + 0, z + 0, block1, 4, 2);
		world.setBlock(x - 5, y + 0, z + 1, block1, 4, 2);
		world.setBlock(x - 4, y - 5, z - 9, block1, 4, 2);
		world.setBlock(x - 4, y - 5, z - 8, block1, 4, 2);
		world.setBlock(x - 4, y - 5, z - 7, block1, 4, 2);
		world.setBlock(x - 4, y - 5, z - 6, block1, 4, 2);
		world.setBlock(x - 4, y - 5, z - 5, block1, 4, 2);
		world.setBlock(x - 4, y - 5, z - 4, block1, 4, 2);
		world.setBlock(x - 4, y - 5, z - 3, block1, 4, 2);
		world.setBlock(x - 4, y - 5, z - 2, block1, 4, 2);
		world.setBlock(x - 4, y - 5, z - 1, block1, 4, 2);
		world.setBlock(x - 4, y - 5, z + 0, block1, 4, 2);
		world.setBlock(x - 4, y + 0, z - 10, block1, 4, 2);
		world.setBlock(x - 4, y + 0, z - 9, block1, 4, 2);
		world.setBlock(x - 4, y + 0, z - 8, block1, 4, 2);
		world.setBlock(x - 4, y + 0, z - 7, block1, 4, 2);
		world.setBlock(x - 4, y + 0, z - 6, block1, 4, 2);
		world.setBlock(x - 4, y + 0, z - 5, block1, 4, 2);
		world.setBlock(x - 4, y + 0, z - 4, block1, 4, 2);
		world.setBlock(x - 4, y + 0, z - 3, block1, 4, 2);
		world.setBlock(x - 4, y + 0, z - 2, block1, 4, 2);
		world.setBlock(x - 4, y + 0, z - 1, block1, 4, 2);
		world.setBlock(x - 4, y + 0, z + 0, block1, 4, 2);
		world.setBlock(x - 4, y + 0, z + 1, block1, 4, 2);
		world.setBlock(x - 3, y - 5, z - 9, block1, 4, 2);
		world.setBlock(x - 3, y - 5, z - 8, block1, 4, 2);
		world.setBlock(x - 3, y - 5, z - 7, block1, 4, 2);
		world.setBlock(x - 3, y - 5, z - 6, block1, 4, 2);
		world.setBlock(x - 3, y - 5, z - 5, block1, 4, 2);
		world.setBlock(x - 3, y - 5, z - 4, block1, 4, 2);
		world.setBlock(x - 3, y - 5, z - 3, block1, 4, 2);
		world.setBlock(x - 3, y - 5, z - 2, block1, 4, 2);
		world.setBlock(x - 3, y - 5, z - 1, block1, 4, 2);
		world.setBlock(x - 3, y - 5, z + 0, block1, 4, 2);
		world.setBlock(x - 3, y + 0, z - 10, block1, 4, 2);
		world.setBlock(x - 3, y + 0, z - 9, block1, 4, 2);
		world.setBlock(x - 3, y + 0, z - 8, block1, 4, 2);
		world.setBlock(x - 3, y + 0, z - 7, block1, 4, 2);
		world.setBlock(x - 3, y + 0, z - 6, block1, 4, 2);
		world.setBlock(x - 3, y + 0, z - 5, block1, 4, 2);
		world.setBlock(x - 3, y + 0, z - 4, block1, 4, 2);
		world.setBlock(x - 3, y + 0, z - 3, block1, 4, 2);
		world.setBlock(x - 3, y + 0, z - 2, block1, 4, 2);
		world.setBlock(x - 3, y + 0, z - 1, block1, 4, 2);
		world.setBlock(x - 3, y + 0, z + 0, block1, 4, 2);
		world.setBlock(x - 3, y + 0, z + 1, block1, 4, 2);
		world.setBlock(x - 2, y - 5, z - 9, block1, 4, 2);
		world.setBlock(x - 2, y - 5, z - 8, block1, 4, 2);
		world.setBlock(x - 2, y - 5, z - 7, block1, 4, 2);
		world.setBlock(x - 2, y - 5, z - 6, block1, 4, 2);
		world.setBlock(x - 2, y - 5, z - 5, block1, 4, 2);
		world.setBlock(x - 2, y - 5, z - 4, block1, 4, 2);
		world.setBlock(x - 2, y - 5, z - 3, block1, 4, 2);
		world.setBlock(x - 2, y - 5, z - 2, block1, 4, 2);
		world.setBlock(x - 2, y - 5, z - 1, block1, 4, 2);
		world.setBlock(x - 2, y - 5, z + 0, block1, 4, 2);
		world.setBlock(x - 2, y + 0, z - 10, block1, 4, 2);
		world.setBlock(x - 2, y + 0, z - 9, block1, 4, 2);
		world.setBlock(x - 2, y + 0, z - 8, block1, 4, 2);
		world.setBlock(x - 2, y + 0, z - 7, block1, 4, 2);
		world.setBlock(x - 2, y + 0, z - 6, block1, 4, 2);
		world.setBlock(x - 2, y + 0, z - 5, block1, 4, 2);
		world.setBlock(x - 2, y + 0, z - 4, block1, 4, 2);
		world.setBlock(x - 2, y + 0, z - 3, block1, 4, 2);
		world.setBlock(x - 2, y + 0, z - 2, block1, 4, 2);
		world.setBlock(x - 2, y + 0, z - 1, block1, 4, 2);
		world.setBlock(x - 2, y + 0, z + 0, block1, 4, 2);
		world.setBlock(x - 2, y + 0, z + 1, block1, 4, 2);
		world.setBlock(x - 1, y - 5, z - 9, block1, 4, 2);
		world.setBlock(x - 1, y - 5, z - 8, block1, 4, 2);
		world.setBlock(x - 1, y - 5, z - 7, block1, 4, 2);
		world.setBlock(x - 1, y - 5, z - 6, block1, 4, 2);
		world.setBlock(x - 1, y - 5, z - 5, block1, 4, 2);
		world.setBlock(x - 1, y - 5, z - 4, block1, 4, 2);
		world.setBlock(x - 1, y - 5, z - 3, block1, 4, 2);
		world.setBlock(x - 1, y - 5, z - 2, block1, 4, 2);
		world.setBlock(x - 1, y - 5, z - 1, block1, 4, 2);
		world.setBlock(x - 1, y - 5, z + 0, block1, 4, 2);
		world.setBlock(x - 1, y + 0, z - 10, block1, 4, 2);
		world.setBlock(x - 1, y + 0, z - 9, block1, 4, 2);
		world.setBlock(x - 1, y + 0, z - 8, block1, 4, 2);
		world.setBlock(x - 1, y + 0, z - 7, block1, 4, 2);
		world.setBlock(x - 1, y + 0, z - 6, block1, 4, 2);
		world.setBlock(x - 1, y + 0, z - 5, block1, 4, 2);
		world.setBlock(x - 1, y + 0, z - 4, block1, 4, 2);
		world.setBlock(x - 1, y + 0, z - 3, block1, 4, 2);
		world.setBlock(x - 1, y + 0, z - 2, block1, 4, 2);
		world.setBlock(x - 1, y + 0, z - 1, block1, 4, 2);
		world.setBlock(x - 1, y + 0, z + 0, block1, 4, 2);
		world.setBlock(x - 1, y + 0, z + 1, block1, 4, 2);
		world.setBlock(x + 0, y - 5, z - 8, block1, 4, 2);
		world.setBlock(x + 0, y - 5, z - 7, block1, 4, 2);
		world.setBlock(x + 0, y - 5, z - 6, block1, 4, 2);
		world.setBlock(x + 0, y - 5, z - 5, block1, 4, 2);
		world.setBlock(x + 0, y - 5, z - 4, block1, 4, 2);
		world.setBlock(x + 0, y - 5, z - 3, block1, 4, 2);
		world.setBlock(x + 0, y - 5, z - 2, block1, 4, 2);
		world.setBlock(x + 0, y - 5, z - 1, block1, 4, 2);
		world.setBlock(x + 0, y + 0, z - 10, block1, 4, 2);
		BuildHandler.buildBuildPoint(world, x, y, z - 9, 5);
		world.setBlock(x + 0, y + 0, z - 8, block1, 4, 2);
		world.setBlock(x + 0, y + 0, z - 7, block1, 4, 2);
		world.setBlock(x + 0, y + 0, z - 6, block1, 4, 2);
		world.setBlock(x + 0, y + 0, z - 5, block1, 4, 2);
		world.setBlock(x + 0, y + 0, z - 4, block1, 4, 2);
		world.setBlock(x + 0, y + 0, z - 3, block1, 4, 2);
		world.setBlock(x + 0, y + 0, z - 2, block1, 4, 2);
		world.setBlock(x + 0, y + 0, z - 1, block1, 4, 2);
		BuildHandler.buildBuildPoint(world, x, y, z, 5);
		world.setBlock(x + 0, y + 0, z + 1, block1, 4, 2);
		world.setBlock(x + 1, y + 0, z - 9, block1, 4, 2);
		world.setBlock(x + 1, y + 0, z - 8, block1, 4, 2);
		world.setBlock(x + 1, y + 0, z - 7, block1, 4, 2);
		world.setBlock(x + 1, y + 0, z - 6, block1, 4, 2);
		world.setBlock(x + 1, y + 0, z - 5, block1, 4, 2);
		world.setBlock(x + 1, y + 0, z - 4, block1, 4, 2);
		world.setBlock(x + 1, y + 0, z - 3, block1, 4, 2);
		world.setBlock(x + 1, y + 0, z - 2, block1, 4, 2);
		world.setBlock(x + 1, y + 0, z - 1, block1, 4, 2);
		world.setBlock(x + 1, y + 0, z + 0, block1, 4, 2);
		block1 = GCBlocks.tinStairs1;
		world.setBlock(x - 11, y + 0, z - 7, block1, 0, 2);
		world.setBlock(x - 11, y + 0, z - 6, block1, 0, 2);
		world.setBlock(x - 11, y + 0, z - 5, block1, 0, 2);
		world.setBlock(x - 11, y + 0, z - 4, block1, 0, 2);
		world.setBlock(x - 11, y + 0, z - 3, block1, 0, 2);
		world.setBlock(x - 11, y + 0, z - 2, block1, 0, 2);
		world.setBlock(x - 7, y + 0, z - 11, block1, 2, 2);
		world.setBlock(x - 7, y + 0, z + 2, block1, 3, 2);
		world.setBlock(x - 6, y + 0, z - 11, block1, 2, 2);
		world.setBlock(x - 6, y + 0, z + 2, block1, 3, 2);
		world.setBlock(x - 5, y + 0, z - 11, block1, 2, 2);
		world.setBlock(x - 5, y + 0, z + 2, block1, 3, 2);
		world.setBlock(x - 4, y + 0, z - 11, block1, 2, 2);
		world.setBlock(x - 4, y + 0, z + 2, block1, 3, 2);
		world.setBlock(x - 3, y + 0, z - 11, block1, 2, 2);
		world.setBlock(x - 3, y + 0, z + 2, block1, 3, 2);
		world.setBlock(x - 2, y + 0, z - 11, block1, 2, 2);
		world.setBlock(x - 2, y + 0, z + 2, block1, 3, 2);
		world.setBlock(x + 2, y + 0, z - 7, block1, 1, 2);
		world.setBlock(x + 2, y + 0, z - 6, block1, 1, 2);
		world.setBlock(x + 2, y + 0, z - 5, block1, 1, 2);
		world.setBlock(x + 2, y + 0, z - 4, block1, 1, 2);
		world.setBlock(x + 2, y + 0, z - 3, block1, 1, 2);
		world.setBlock(x + 2, y + 0, z - 2, block1, 1, 2);
		
	}
	
	@Override
	public boolean Check(World world, ForgeDirection dir, int x, int y, int z, int meta)
	{
		if (meta != 2 && meta != 5 && meta != -1 && meta != 0)
		{
			return false;
		}
		if (dir == ForgeDirection.UP)
		{
			return true;
		}
		return false;
	}
	
	@Override
	public void ClearWay(World world, ForgeDirection dir, int x, int y, int z)
	{
	}
	
	@Override
	public String getName()
	{
		return StatCollector.translateToLocal("builder.greenhouse.name");
	}
	
	@Override
	public boolean isHidden()
	{
		return false;
	}
	
	@Override
	public String getUnlocalizedName()
	{
		return "greenhouse";
	}
	
	@Override
	public Structure copy()
	{
		StructureGreenHouse Nstr = new StructureGreenHouse();
		Nstr.Configure(placementPos != null ? placementPos.clone() : new int[] { 0, 0, 0 }, placementRotation, placementDir);
		return Nstr;
	}
	
	@Override
	public List<OreDictItemStack> getRequiredItems()
	{
		List<OreDictItemStack> items = new ArrayList();
		items.add(new OreDictItemStack(new ItemStack(GCItems.basicItem, 64, 7), "plateTin"));
		items.add(new OreDictItemStack(new ItemStack(ItemMod.ironScaffold, 32, ItemMod.scaffold_meta)));
		items.add(new OreDictItemStack(new ItemStack(Blocks.glass, 64, 0)));
		items.add(new OreDictItemStack(new ItemStack(Blocks.glass, 64, 0)));
		items.add(new OreDictItemStack(new ItemStack(Blocks.glass, 12, 0)));
		return items;
	}
	
	@Override
	public StructureData getStructureData()
	{
		StructureData data = super.getStructureData();
		data.specialFunc = StatCollector.translateToLocal("builder.side_info.funcs.greenhouse.name");
		return data;
	}
	
}
